Workbook

Sheet MP
A1: Model Portfolio | D1: 전체 AUM (NAV) | F1: =VLOOKUP("300019", 아이타스41718_편드편입비정보!$C:$AX, 8, FALSE)/100000000 -> 230.87013 | J1: =VLOOKUP("300037", 아이타스41718_편드편입비정보!$C:$AX, 8, FALSE)/100000000 -> 192.54978 | N1: =VLOOKUP("300085", 아이타스41718_편드편입비정보!$C:$AX, 8, FALSE)/100000000 -> 210.06083 | R1: 주식수 계산기 | S1: 비중 | T1: 종목명 | U1: 인컴2 주식수 | V1: 블루1 주식수 | W1: 블루3 주식수 | X1: 현재가
A2: <파란글자만 key in> | D2: 채권 비중 | F2: =VLOOKUP("300019", 아이타스41718_편드편입비정보!$C:$AX, 16, FALSE)/100000000 -> 128.6128 | J2: =VLOOKUP("300037", 아이타스41718_편드편입비정보!$C:$AX, 16, FALSE)/100000000 -> 84.440585 | N2: =VLOOKUP("300085", 아이타스41718_편드편입비정보!$C:$AX, 16, FALSE)/100000000 -> 115.5814 | S2: 0.02 | T2: KODEX 레버리지 | U2: =IF(OR($S$2="",$T$2="",$X$2="",$X$2=0),"",ROUND($S$2*F4*100000000/$X$2,0)) -> 224 | V2: =IF(OR($S$2="",$T$2="",$X$2="",$X$2=0),"",ROUND($S$2*J4*100000000/$X$2,0)) -> 221 | W2: =IF(OR($S$2="",$T$2="",$X$2="",$X$2=0),"",ROUND($S$2*N4*100000000/$X$2,0)) -> 218 | X2: 130000
A3: =COUNT(A7:A71) -> 34 | B3: 종목 | C3: =B79 -> 0.959 | D3: 주식 가능금액 (현금포함) | F3: =F1-F2-F78 -> 96.979332 | G3: =F79 -> 72.378415 | H3: 현금 비중 | J3: =J1-J2-J78 -> 95.776573 | K3: =J79 -> 73.176565 | L3: 현금 비중 | N3: =N1-N2-N78 -> 94.479432 | O3: =N79 -> 71.83524 | P3: 현금 비중 | S3: > key in | X3: =IF($T$2="","",IFERROR(INDEX(인컴2!L:L,MATCH($T$2,인컴2!E:E,0)),IFERROR(INDEX(블루1!L:L,MATCH($T$2,블루1!E:E,0)),IFERROR(INDEX(블루3!L:L,MATCH($T$2,블루3!E:E,0)),"")))) | Y3: > 현재가 함수
D4: 현금 목표금액 (Risk off 시 20%) | E4: 0.15 | F4: =F3*($E$4) -> 14.5469 | G4: =F3-G3 -> 24.600917 | H4: =(F3-G3)/F3 -> 0.25367175 | J4: =J3*($E$4) -> 14.366486 | K4: =J3-K3 -> 22.600008 | L4: =(J3-K3)/J3 -> 0.23596593 | N4: =N3*($E$4) -> 14.171915 | O4: =N3-O3 -> 22.644192 | P4: =(N3-O3)/N3 -> 0.23967325
A5: No | B5: 섹터 | C5: 세부 | D5: 종목명 | E5: 목표 | F5: 인컴2 | J5: 블루1 | N5: 블루3 | R5: 종목명(원본) > 종목명 채우면 자동 매핑 | S5: 현재가
F6: 평가금액 | G6: 비중 | H6: 목표 차이 | I6: 수익률 | J6: 평가금액 | K6: 비중 | L6: 목표 차이 | M6: 수익률 | N6: 평가금액 | O6: 비중 | P6: 목표 차이 | Q6: 수익률 | U6: 누락 종목 필터링
A7: 1 | B7: 테크 | C7: 반도체 | D7: =IF(R7="","",IFERROR(INDEX(인컴2!E:E,MATCH(R7,인컴2!E:E,0)),IFERROR(INDEX(블루1!E:E,MATCH(R7,블루1!E:E,0)),IFERROR(INDEX(블루3!E:E,MATCH(R7,블루3!E:E,0)),R7)))) -> RISE 네트워크인프라 | E7: 0.13 | F7: =IF(D7="","",SUMIF(인컴2!E:E,D7,인컴2!N:N)/100000000) -> 11.97375 | G7: =IFERROR(F7/$G$3, "") -> 0.16543261 | H7: =IFERROR(($E7-G7)*G$3*100000000/$S7, "") -> -3212.7229 | I7: =IFERROR(INDEX(인컴2!Q:Q,MATCH(D7,인컴2!E:E,0))/100,"") -> 0.3086 | J7: =IF(D7="","",SUMIF(블루1!E:E,D7,블루1!N:N)/100000000) -> 11.97375 | K7: =IFERROR(J7/K$3, "") -> 0.16362821 | L7: =IFERROR(($E7-K7)*K$3*100000000/$S7, "") -> -3082.7392 | M7: =IFERROR(INDEX(블루1!Q:Q,MATCH(D7,블루1!E:E,0))/100,"") -> 0.3085 | N7: =IF(D7="","",SUMIF(블루3!E:E,D7,블루3!N:N)/100000000) -> 11.97375 | O7: =IFERROR(N7/O$3, "") -> 0.16668351 | P7: =IFERROR(($E7-O7)*O$3*100000000/$S7, "") -> -3301.1823 | Q7: =IFERROR(INDEX(블루3!Q:Q,MATCH(D7,블루3!E:E,0))/100,"") -> 0.3087 | R7: RISE 네트워크인프라 | S7: =IFERROR(INDEX(인컴2!$E$1:$Q$47, MATCH(R7, 인컴2!E:E, 0), 8), "") -> 79825 | U7: {=_xlfn.LET(_xlpm.a,_xlfn._xlws.FILTER(인컴2!E$3:E$500,인컴2!E$3:E$500<>""),_xlpm.b,_xlfn._xlws.FILTER(블루1!E$3:E$500,블루1!E$3:E$500<>""),_xlpm.c,_xlfn._xlws.FILTER(블루3!E$3:E$500,블루3!E$3:E$500<>""),_xlpm.all,_xlfn.UNIQUE(_xlfn.VSTACK(_xlpm.a,_xlpm.b,_xlpm.c)),IFERROR(_xlfn._xlws.SORT(_xlfn._xlws.FILTER(_xlpm.all,COUNTIF($D$7:$D$77,_xlpm.all)=0)),"누락 종목 없음"))} -> RF머트리얼즈
A8: 2 | B8: =SUM(E7:E22) -> 0.466 | C8: 중국 테크 | D8: =IF(R8="","",IFERROR(INDEX(인컴2!E:E,MATCH(R8,인컴2!E:E,0)),IFERROR(INDEX(블루1!E:E,MATCH(R8,블루1!E:E,0)),IFERROR(INDEX(블루3!E:E,MATCH(R8,블루3!E:E,0)),R8)))) -> TIME 차이나AI테크액티브 | E8: 0.03 | F8: =IF(D8="","",SUMIF(인컴2!E:E,D8,인컴2!N:N)/100000000) -> 3.2154 | G8: =IFERROR(F8/$G$3, "") -> 0.044424847 | H8: =IFERROR(($E8-G8)*G$3*100000000/$S8, "") -> -3896.4268 | I8: =IFERROR(INDEX(인컴2!Q:Q,MATCH(D8,인컴2!E:E,0))/100,"") -> 0.4207 | J8: =IF(D8="","",SUMIF(블루1!E:E,D8,블루1!N:N)/100000000) -> 2.6795 | K8: =IFERROR(J8/K$3, "") -> 0.036616914 | L8: =IFERROR(($E8-K8)*K$3*100000000/$S8, "") -> -1807.0649 | M8: =IFERROR(INDEX(블루1!Q:Q,MATCH(D8,블루1!E:E,0))/100,"") -> 0.2809 | N8: =IF(D8="","",SUMIF(블루3!E:E,D8,블루3!N:N)/100000000) -> 2.6795 | O8: =IFERROR(N8/O$3, "") -> 0.037300634 | P8: =IFERROR(($E8-O8)*O$3*100000000/$S8, "") -> -1957.2413 | Q8: =IFERROR(INDEX(블루3!Q:Q,MATCH(D8,블루3!E:E,0))/100,"") -> 0.2793 | R8: TIME 차이나AI테크액티브 | S8: =IFERROR(INDEX(인컴2!$E$1:$Q$47, MATCH(R8, 인컴2!E:E, 0), 8), "") -> 26795 | U8: SK스퀘어
A9: 3 | C9: 장비 | D9: =IF(R9="","",IFERROR(INDEX(인컴2!E:E,MATCH(R9,인컴2!E:E,0)),IFERROR(INDEX(블루1!E:E,MATCH(R9,블루1!E:E,0)),IFERROR(INDEX(블루3!E:E,MATCH(R9,블루3!E:E,0)),R9)))) -> 싸이맥스 | E9: 0.043 | F9: =IF(D9="","",SUMIF(인컴2!E:E,D9,인컴2!N:N)/100000000) -> 3.37 | G9: =IFERROR(F9/$G$3, "") -> 0.046560843 | H9: =IFERROR(($E9-G9)*G$3*100000000/$S9, "") -> -764.77197 | I9: =IFERROR(INDEX(인컴2!Q:Q,MATCH(D9,인컴2!E:E,0))/100,"") -> -0.0302 | J9: =IF(D9="","",SUMIF(블루1!E:E,D9,블루1!N:N)/100000000) -> 3.37 | K9: =IFERROR(J9/K$3, "") -> 0.046052995 | L9: =IFERROR(($E9-K9)*K$3*100000000/$S9, "") -> -662.93088 | M9: =IFERROR(INDEX(블루1!Q:Q,MATCH(D9,블루1!E:E,0))/100,"") -> -0.0303 | N9: =IF(D9="","",SUMIF(블루3!E:E,D9,블루3!N:N)/100000000) -> 3.37 | O9: =IFERROR(N9/O$3, "") -> 0.046912908 | P9: =IFERROR(($E9-O9)*O$3*100000000/$S9, "") -> -834.07917 | Q9: =IFERROR(INDEX(블루3!Q:Q,MATCH(D9,블루3!E:E,0))/100,"") -> -0.0303 | R9: 싸이맥스 | S9: =IFERROR(INDEX(인컴2!$E$1:$Q$47, MATCH(R9, 인컴2!E:E, 0), 8), "") -> 33700 | U9: SOL 초단기채권액티브
A10: 4 | C10: 설계 | D10: =IF(R10="","",IFERROR(INDEX(인컴2!E:E,MATCH(R10,인컴2!E:E,0)),IFERROR(INDEX(블루1!E:E,MATCH(R10,블루1!E:E,0)),IFERROR(INDEX(블루3!E:E,MATCH(R10,블루3!E:E,0)),R10)))) -> 에이직랜드 | E10: 0.033 | F10: =IF(D10="","",SUMIF(인컴2!E:E,D10,인컴2!N:N)/100000000) -> 2.375 | G10: =IFERROR(F10/$G$3, "") -> 0.03281365 | H10: =IFERROR(($E10-G10)*G$3*100000000/$S10, "") -> 56.790295 | I10: =IFERROR(INDEX(인컴2!Q:Q,MATCH(D10,인컴2!E:E,0))/100,"") -> -0.2244 | J10: =IF(D10="","",SUMIF(블루1!E:E,D10,블루1!N:N)/100000000) -> 2.375 | K10: =IFERROR(J10/K$3, "") -> 0.032455746 | L10: =IFERROR(($E10-K10)*K$3*100000000/$S10, "") -> 167.69114 | M10: =IFERROR(INDEX(블루1!Q:Q,MATCH(D10,블루1!E:E,0))/100,"") -> -0.2244 | N10: =IF(D10="","",SUMIF(블루3!E:E,D10,블루3!N:N)/100000000) -> 2.375 | O10: =IFERROR(N10/O$3, "") -> 0.033061767 | P10: =IFERROR(($E10-O10)*O$3*100000000/$S10, "") -> -18.682442 | Q10: =IFERROR(INDEX(블루3!Q:Q,MATCH(D10,블루3!E:E,0))/100,"") -> -0.2244 | R10: 에이직랜드 | S10: =IFERROR(INDEX(인컴2!$E$1:$Q$47, MATCH(R10, 인컴2!E:E, 0), 8), "") -> 23750 | U10: 두산
A11: 5 | C11: 기판 | D11: =IF(R11="","",IFERROR(INDEX(인컴2!E:E,MATCH(R11,인컴2!E:E,0)),IFERROR(INDEX(블루1!E:E,MATCH(R11,블루1!E:E,0)),IFERROR(INDEX(블루3!E:E,MATCH(R11,블루3!E:E,0)),R11)))) -> 대덕전자 | E11: 0.02 | F11: =IF(D11="","",SUMIF(인컴2!E:E,D11,인컴2!N:N)/100000000) -> 1.404 | G11: =IFERROR(F11/$G$3, "") -> 0.019398048 | H11: =IFERROR(($E11-G11)*G$3*100000000/$S11, "") -> 31.031553 | I11: =IFERROR(INDEX(인컴2!Q:Q,MATCH(D11,인컴2!E:E,0))/100,"") -> -0.2061 | J11: =IF(D11="","",SUMIF(블루1!E:E,D11,블루1!N:N)/100000000) -> 1.404 | K11: =IFERROR(J11/K$3, "") -> 0.01918647 | L11: =IFERROR(($E11-K11)*K$3*100000000/$S11, "") -> 42.401211 | M11: =IFERROR(INDEX(블루1!Q:Q,MATCH(D11,블루1!E:E,0))/100,"") -> -0.2061 | N11: =IF(D11="","",SUMIF(블루3!E:E,D11,블루3!N:N)/100000000) -> 1.404 | O11: =IFERROR(N11/O$3, "") -> 0.019544725 | P11: =IFERROR(($E11-O11)*O$3*100000000/$S11, "") -> 23.294017 | Q11: =IFERROR(INDEX(블루3!Q:Q,MATCH(D11,블루3!E:E,0))/100,"") -> -0.2061 | R11: 대덕전자 | S11: =IFERROR(INDEX(인컴2!$E$1:$Q$47, MATCH(R11, 인컴2!E:E, 0), 8), "") -> 140400 | U11: 리센스메디컬
A12: 6 | C12: 파운드리 | D12: =IF(R12="","",IFERROR(INDEX(인컴2!E:E,MATCH(R12,인컴2!E:E,0)),IFERROR(INDEX(블루1!E:E,MATCH(R12,블루1!E:E,0)),IFERROR(INDEX(블루3!E:E,MATCH(R12,블루3!E:E,0)),R12)))) -> DB하이텍 | E12: 0.02 | F12: =IF(D12="","",SUMIF(인컴2!E:E,D12,인컴2!N:N)/100000000) -> 1.8132 | G12: =IFERROR(F12/$G$3, "") -> 0.025051668 | H12: =IFERROR(($E12-G12)*G$3*100000000/$S12, "") -> -241.97995 | I12: =IFERROR(INDEX(인컴2!Q:Q,MATCH(D12,인컴2!E:E,0))/100,"") -> -0.173 | J12: =IF(D12="","",SUMIF(블루1!E:E,D12,블루1!N:N)/100000000) -> 1.8132 | K12: =IFERROR(J12/K$3, "") -> 0.024778425 | L12: =IFERROR(($E12-K12)*K$3*100000000/$S12, "") -> -231.41542 | M12: =IFERROR(INDEX(블루1!Q:Q,MATCH(D12,블루1!E:E,0))/100,"") -> -0.173 | N12: =IF(D12="","",SUMIF(블루3!E:E,D12,블루3!N:N)/100000000) -> 1.8132 | O12: =IFERROR(N12/O$3, "") -> 0.025241093 | P12: =IFERROR(($E12-O12)*O$3*100000000/$S12, "") -> -249.16956 | Q12: =IFERROR(INDEX(블루3!Q:Q,MATCH(D12,블루3!E:E,0))/100,"") -> -0.173 | R12: DB하이텍 | S12: =IFERROR(INDEX(인컴2!$E$1:$Q$47, MATCH(R12, 인컴2!E:E, 0), 8), "") -> 151100 | U12: 메쥬
A13: 7 | C13: SW | D13: =IF(R13="","",IFERROR(INDEX(인컴2!E:E,MATCH(R13,인컴2!E:E,0)),IFERROR(INDEX(블루1!E:E,MATCH(R13,블루1!E:E,0)),IFERROR(INDEX(블루3!E:E,MATCH(R13,블루3!E:E,0)),R13)))) -> NAVER | E13: 0.025 | F13: =IF(D13="","",SUMIF(인컴2!E:E,D13,인컴2!N:N)/100000000) -> 0 | G13: =IFERROR(F13/$G$3, "") -> 0 | H13: =IFERROR(($E13-G13)*G$3*100000000/$S13, "") -> 893.56068 | I13: =IFERROR(INDEX(인컴2!Q:Q,MATCH(D13,인컴2!E:E,0))/100,"") -> -0.1665 | J13: =IF(D13="","",SUMIF(블루1!E:E,D13,블루1!N:N)/100000000) -> 0 | K13: =IFERROR(J13/K$3, "") -> 0 | L13: =IFERROR(($E13-K13)*K$3*100000000/$S13, "") -> 903.41438 | M13: =IFERROR(INDEX(블루1!Q:Q,MATCH(D13,블루1!E:E,0))/100,"") -> -0.1665 | N13: =IF(D13="","",SUMIF(블루3!E:E,D13,블루3!N:N)/100000000) -> 0 | O13: =IFERROR(N13/O$3, "") -> 0 | P13: =IFERROR(($E13-O13)*O$3*100000000/$S13, "") -> 886.85481 | Q13: =IFERROR(INDEX(블루3!Q:Q,MATCH(D13,블루3!E:E,0))/100,"") -> -0.1667 | R13: NAVER | S13: =IFERROR(INDEX(인컴2!$E$1:$Q$47, MATCH(R13, 인컴2!E:E, 0), 8), "") -> 202500 | U13: 아이엠바이오로직스
A14: 8 | C14: 반도체 | D14: =IF(R14="","",IFERROR(INDEX(인컴2!E:E,MATCH(R14,인컴2!E:E,0)),IFERROR(INDEX(블루1!E:E,MATCH(R14,블루1!E:E,0)),IFERROR(INDEX(블루3!E:E,MATCH(R14,블루3!E:E,0)),R14)))) -> ACE 글로벌AI맞춤형반도체 | E14: 0.02 | F14: =IF(D14="","",SUMIF(인컴2!E:E,D14,인컴2!N:N)/100000000) -> 1.69092 | G14: =IFERROR(F14/$G$3, "") -> 0.023362214 | H14: =IFERROR(($E14-G14)*G$3*100000000/$S14, "") -> -877.89214 | I14: =IFERROR(INDEX(인컴2!Q:Q,MATCH(D14,인컴2!E:E,0))/100,"") -> 0.0253 | J14: =IF(D14="","",SUMIF(블루1!E:E,D14,블루1!N:N)/100000000) -> 1.69092 | K14: =IFERROR(J14/K$3, "") -> 0.023107398 | L14: =IFERROR(($E14-K14)*K$3*100000000/$S14, "") -> -820.30556 | M14: =IFERROR(INDEX(블루1!Q:Q,MATCH(D14,블루1!E:E,0))/100,"") -> 0.0253 | N14: =IF(D14="","",SUMIF(블루3!E:E,D14,블루3!N:N)/100000000) -> 1.69092 | O14: =IFERROR(N14/O$3, "") -> 0.023538865 | P14: =IFERROR(($E14-O14)*O$3*100000000/$S14, "") -> -917.08225 | Q14: =IFERROR(INDEX(블루3!Q:Q,MATCH(D14,블루3!E:E,0))/100,"") -> 0.0253 | R14: ACE 글로벌AI맞춤형반도체 | S14: =IFERROR(INDEX(인컴2!$E$1:$Q$47, MATCH(R14, 인컴2!E:E, 0), 8), "") -> 27720 | U14: 코스모로보틱스
A15: 9 | C15: 반도체 | D15: =IF(R15="","",IFERROR(INDEX(인컴2!E:E,MATCH(R15,인컴2!E:E,0)),IFERROR(INDEX(블루1!E:E,MATCH(R15,블루1!E:E,0)),IFERROR(INDEX(블루3!E:E,MATCH(R15,블루3!E:E,0)),R15)))) -> HANARO 미국AI메모리반도체TOP4+ | E15: 0.021 | F15: =IF(D15="","",SUMIF(인컴2!E:E,D15,인컴2!N:N)/100000000) -> 1.873125 | G15: =IFERROR(F15/$G$3, "") -> 0.025879608 | H15: =IFERROR(($E15-G15)*G$3*100000000/$S15, "") -> -2545.4291 | I15: =IFERROR(INDEX(인컴2!Q:Q,MATCH(D15,인컴2!E:E,0))/100,"") -> 0.1873 | J15: =IF(D15="","",SUMIF(블루1!E:E,D15,블루1!N:N)/100000000) -> 1.873125 | K15: =IFERROR(J15/K$3, "") -> 0.025597334 | L15: =IFERROR(($E15-K15)*K$3*100000000/$S15, "") -> -2424.628 | M15: =IFERROR(INDEX(블루1!Q:Q,MATCH(D15,블루1!E:E,0))/100,"") -> 0.1872 | N15: =IF(D15="","",SUMIF(블루3!E:E,D15,블루3!N:N)/100000000) -> 1.873125 | O15: =IFERROR(N15/O$3, "") -> 0.026075294 | P15: =IFERROR(($E15-O15)*O$3*100000000/$S15, "") -> -2627.6394 | Q15: =IFERROR(INDEX(블루3!Q:Q,MATCH(D15,블루3!E:E,0))/100,"") -> 0.1872 | R15: HANARO 미국AI메모리반도체TOP4+ | S15: =IFERROR(INDEX(인컴2!$E$1:$Q$47, MATCH(R15, 인컴2!E:E, 0), 8), "") -> 13875 | U15: 폴레드
A16: 10 | C16: 반도체 | D16: =IF(R16="","",IFERROR(INDEX(인컴2!E:E,MATCH(R16,인컴2!E:E,0)),IFERROR(INDEX(블루1!E:E,MATCH(R16,블루1!E:E,0)),IFERROR(INDEX(블루3!E:E,MATCH(R16,블루3!E:E,0)),R16)))) -> HANARO 반도체핵심공정주도주 | E16: 0.02 | F16: =IF(D16="","",SUMIF(인컴2!E:E,D16,인컴2!N:N)/100000000) -> 1.7017 | G16: =IFERROR(F16/$G$3, "") -> 0.023511153 | H16: =IFERROR(($E16-G16)*G$3*100000000/$S16, "") -> -1642.7388 | I16: =IFERROR(INDEX(인컴2!Q:Q,MATCH(D16,인컴2!E:E,0))/100,"") -> 0.0616 | J16: =IF(D16="","",SUMIF(블루1!E:E,D16,블루1!N:N)/100000000) -> 1.7017 | K16: =IFERROR(J16/K$3, "") -> 0.023254713 | L16: =IFERROR(($E16-K16)*K$3*100000000/$S16, "") -> -1539.552 | M16: =IFERROR(INDEX(블루1!Q:Q,MATCH(D16,블루1!E:E,0))/100,"") -> 0.0616 | N16: =IF(D16="","",SUMIF(블루3!E:E,D16,블루3!N:N)/100000000) -> 1.7017 | O16: =IFERROR(N16/O$3, "") -> 0.02368893 | P16: =IFERROR(($E16-O16)*O$3*100000000/$S16, "") -> -1712.9619 | Q16: =IFERROR(INDEX(블루3!Q:Q,MATCH(D16,블루3!E:E,0))/100,"") -> 0.0614 | R16: HANARO 반도체핵심공정주도주 | S16: =IFERROR(INDEX(인컴2!$E$1:$Q$47, MATCH(R16, 인컴2!E:E, 0), 8), "") -> 15470
A17: 11 | C17: 반도체 | D17: =IF(R17="","",IFERROR(INDEX(인컴2!E:E,MATCH(R17,인컴2!E:E,0)),IFERROR(INDEX(블루1!E:E,MATCH(R17,블루1!E:E,0)),IFERROR(INDEX(블루3!E:E,MATCH(R17,블루3!E:E,0)),R17)))) -> RISE 삼성전자단일종목레버리지 | E17: 0.027 | F17: =IF(D17="","",SUMIF(인컴2!E:E,D17,인컴2!N:N)/100000000) -> 0 | G17: =IFERROR(F17/$G$3, "") -> 0 | H17: =IFERROR(($E17-G17)*G$3*100000000/$S17, "") -> 9983.2297 | I17: =IFERROR(INDEX(인컴2!Q:Q,MATCH(D17,인컴2!E:E,0))/100,"") -> -0.1801 | J17: =IF(D17="","",SUMIF(블루1!E:E,D17,블루1!N:N)/100000000) -> 0 | K17: =IFERROR(J17/K$3, "") -> 0 | L17: =IFERROR(($E17-K17)*K$3*100000000/$S17, "") -> 10093.319 | M17: =IFERROR(INDEX(블루1!Q:Q,MATCH(D17,블루1!E:E,0))/100,"") -> -0.1801 | N17: =IF(D17="","",SUMIF(블루3!E:E,D17,블루3!N:N)/100000000) -> 0 | O17: =IFERROR(N17/O$3, "") -> 0 | P17: =IFERROR(($E17-O17)*O$3*100000000/$S17, "") -> 9908.309 | Q17: =IFERROR(INDEX(블루3!Q:Q,MATCH(D17,블루3!E:E,0))/100,"") -> -0.181 | R17: RISE 삼성전자단일종목레버리지 | S17: =IFERROR(INDEX(인컴2!$E$1:$Q$47, MATCH(R17, 인컴2!E:E, 0), 8), "") -> 19575
A18: 12 | C18: 반도체 | D18: =IF(R18="","",IFERROR(INDEX(인컴2!E:E,MATCH(R18,인컴2!E:E,0)),IFERROR(INDEX(블루1!E:E,MATCH(R18,블루1!E:E,0)),IFERROR(INDEX(블루3!E:E,MATCH(R18,블루3!E:E,0)),R18)))) -> SOL 반도체전공정 | E18: 0.021 | F18: =IF(D18="","",SUMIF(인컴2!E:E,D18,인컴2!N:N)/100000000) -> 1.7549 | G18: =IFERROR(F18/$G$3, "") -> 0.024246179 | H18: =IFERROR(($E18-G18)*G$3*100000000/$S18, "") -> -937.18901 | I18: =IFERROR(INDEX(인컴2!Q:Q,MATCH(D18,인컴2!E:E,0))/100,"") -> 0.0103 | J18: =IF(D18="","",SUMIF(블루1!E:E,D18,블루1!N:N)/100000000) -> 1.7549 | K18: =IFERROR(J18/K$3, "") -> 0.023981721 | L18: =IFERROR(($E18-K18)*K$3*100000000/$S18, "") -> -870.33161 | M18: =IFERROR(INDEX(블루1!Q:Q,MATCH(D18,블루1!E:E,0))/100,"") -> 0.0103 | N18: =IF(D18="","",SUMIF(블루3!E:E,D18,블루3!N:N)/100000000) -> 1.7549 | O18: =IFERROR(N18/O$3, "") -> 0.024429514 | P18: =IFERROR(($E18-O18)*O$3*100000000/$S18, "") -> -982.68831 | Q18: =IFERROR(INDEX(블루3!Q:Q,MATCH(D18,블루3!E:E,0))/100,"") -> 0.01 | R18: SOL 반도체전공정 | S18: =IFERROR(INDEX(인컴2!$E$1:$Q$47, MATCH(R18, 인컴2!E:E, 0), 8), "") -> 25070
A19: 13 | C19: 반도체 | D19: =IF(R19="","",IFERROR(INDEX(인컴2!E:E,MATCH(R19,인컴2!E:E,0)),IFERROR(INDEX(블루1!E:E,MATCH(R19,블루1!E:E,0)),IFERROR(INDEX(블루3!E:E,MATCH(R19,블루3!E:E,0)),R19)))) -> SOL 반도체후공정 | E19: 0.016 | F19: =IF(D19="","",SUMIF(인컴2!E:E,D19,인컴2!N:N)/100000000) -> 1.3653 | G19: =IFERROR(F19/$G$3, "") -> 0.018863359 | H19: =IFERROR(($E19-G19)*G$3*100000000/$S19, "") -> -683.07633 | I19: =IFERROR(INDEX(인컴2!Q:Q,MATCH(D19,인컴2!E:E,0))/100,"") -> -0.1227 | J19: =IF(D19="","",SUMIF(블루1!E:E,D19,블루1!N:N)/100000000) -> 1.3653 | K19: =IFERROR(J19/K$3, "") -> 0.018657613 | L19: =IFERROR(($E19-K19)*K$3*100000000/$S19, "") -> -640.98537 | M19: =IFERROR(INDEX(블루1!Q:Q,MATCH(D19,블루1!E:E,0))/100,"") -> -0.1226 | N19: =IF(D19="","",SUMIF(블루3!E:E,D19,블루3!N:N)/100000000) -> 1.3653 | O19: =IFERROR(N19/O$3, "") -> 0.019005992 | P19: =IFERROR(($E19-O19)*O$3*100000000/$S19, "") -> -711.72103 | Q19: =IFERROR(INDEX(블루3!Q:Q,MATCH(D19,블루3!E:E,0))/100,"") -> -0.1231 | R19: SOL 반도체후공정 | S19: =IFERROR(INDEX(인컴2!$E$1:$Q$47, MATCH(R19, 인컴2!E:E, 0), 8), "") -> 30340
A20: 14 | C20: 반도체 | D20: =IF(R20="","",IFERROR(INDEX(인컴2!E:E,MATCH(R20,인컴2!E:E,0)),IFERROR(INDEX(블루1!E:E,MATCH(R20,블루1!E:E,0)),IFERROR(INDEX(블루3!E:E,MATCH(R20,블루3!E:E,0)),R20)))) -> 제주반도체 | E20: 0.015 | F20: =IF(D20="","",SUMIF(인컴2!E:E,D20,인컴2!N:N)/100000000) -> 2.216 | G20: =IFERROR(F20/$G$3, "") -> 0.030616863 | H20: =IFERROR(($E20-G20)*G$3*100000000/$S20, "") -> -1020.1478 | I20: =IFERROR(INDEX(인컴2!Q:Q,MATCH(D20,인컴2!E:E,0))/100,"") -> -0.0614 | J20: =IF(D20="","",SUMIF(블루1!E:E,D20,블루1!N:N)/100000000) -> 2.216 | K20: =IFERROR(J20/K$3, "") -> 0.030282919 | L20: =IFERROR(($E20-K20)*K$3*100000000/$S20, "") -> -1009.3425 | M20: =IFERROR(INDEX(블루1!Q:Q,MATCH(D20,블루1!E:E,0))/100,"") -> -0.0613 | N20: =IF(D20="","",SUMIF(블루3!E:E,D20,블루3!N:N)/100000000) -> 2.216 | O20: =IFERROR(N20/O$3, "") -> 0.030848369 | P20: =IFERROR(($E20-O20)*O$3*100000000/$S20, "") -> -1027.5013 | Q20: =IFERROR(INDEX(블루3!Q:Q,MATCH(D20,블루3!E:E,0))/100,"") -> -0.0614 | R20: 제주반도체 | S20: =IFERROR(INDEX(인컴2!$E$1:$Q$47, MATCH(R20, 인컴2!E:E, 0), 8), "") -> 110800
A21: 15 | C21: 반도체 | D21: =IF(R21="","",IFERROR(INDEX(인컴2!E:E,MATCH(R21,인컴2!E:E,0)),IFERROR(INDEX(블루1!E:E,MATCH(R21,블루1!E:E,0)),IFERROR(INDEX(블루3!E:E,MATCH(R21,블루3!E:E,0)),R21)))) -> LG이노텍 | E21: 0.025 | F21: =IF(D21="","",SUMIF(인컴2!E:E,D21,인컴2!N:N)/100000000) -> 1.982 | G21: =IFERROR(F21/$G$3, "") -> 0.027383855 | H21: =IFERROR(($E21-G21)*G$3*100000000/$S21, "") -> -17.410658 | I21: =IFERROR(INDEX(인컴2!Q:Q,MATCH(D21,인컴2!E:E,0))/100,"") -> -0.2316 | J21: =IF(D21="","",SUMIF(블루1!E:E,D21,블루1!N:N)/100000000) -> 1.982 | K21: =IFERROR(J21/K$3, "") -> 0.027085174 | L21: =IFERROR(($E21-K21)*K$3*100000000/$S21, "") -> -15.397162 | M21: =IFERROR(INDEX(블루1!Q:Q,MATCH(D21,블루1!E:E,0))/100,"") -> -0.232 | N21: =IF(D21="","",SUMIF(블루3!E:E,D21,블루3!N:N)/100000000) -> 1.982 | O21: =IFERROR(N21/O$3, "") -> 0.027590915 | P21: =IFERROR(($E21-O21)*O$3*100000000/$S21, "") -> -18.780928 | Q21: =IFERROR(INDEX(블루3!Q:Q,MATCH(D21,블루3!E:E,0))/100,"") -> -0.232 | R21: LG이노텍 | S21: =IFERROR(INDEX(인컴2!$E$1:$Q$47, MATCH(R21, 인컴2!E:E, 0), 8), "") -> 991000
A22: 16 | C22: MLCC | D22: =IF(R22="","",IFERROR(INDEX(인컴2!E:E,MATCH(R22,인컴2!E:E,0)),IFERROR(INDEX(블루1!E:E,MATCH(R22,블루1!E:E,0)),IFERROR(INDEX(블루3!E:E,MATCH(R22,블루3!E:E,0)),R22)))) -> 삼성전기우 | F22: =IF(D22="","",SUMIF(인컴2!E:E,D22,인컴2!N:N)/100000000) -> 1.92812 | G22: =IFERROR(F22/$G$3, "") -> 0.026639434 | H22: =IFERROR(($E22-G22)*G$3*100000000/$S22, "") -> -236 | I22: =IFERROR(INDEX(인컴2!Q:Q,MATCH(D22,인컴2!E:E,0))/100,"") -> -0.1018 | J22: =IF(D22="","",SUMIF(블루1!E:E,D22,블루1!N:N)/100000000) -> 1.92812 | K22: =IFERROR(J22/K$3, "") -> 0.026348873 | L22: =IFERROR(($E22-K22)*K$3*100000000/$S22, "") -> -236 | M22: =IFERROR(INDEX(블루1!Q:Q,MATCH(D22,블루1!E:E,0))/100,"") -> -0.1018 | N22: =IF(D22="","",SUMIF(블루3!E:E,D22,블루3!N:N)/100000000) -> 1.92812 | O22: =IFERROR(N22/O$3, "") -> 0.026840865 | P22: =IFERROR(($E22-O22)*O$3*100000000/$S22, "") -> -236 | Q22: =IFERROR(INDEX(블루3!Q:Q,MATCH(D22,블루3!E:E,0))/100,"") -> -0.1022 | R22: 삼성전기우 | S22: =IFERROR(INDEX(인컴2!$E$1:$Q$47, MATCH(R22, 인컴2!E:E, 0), 8), "") -> 817000
C23: 테크 소계 | E23: =SUM(E7:E22) -> 0.466 | F23: =SUM(F7:F22) -> 38.663415 | G23: =IFERROR(F23/$F$3, "") -> 0.39867685 | J23: =SUM(J7:J22) -> 38.127515 | K23: =IFERROR(J23/J$3, "") -> 0.39808811 | N23: =SUM(N7:N22) -> 38.127515 | O23: =IFERROR(N23/N$3, "") -> 0.4035536
A24: 1 | B24: 금융 | C24: 보험 | D24: =IF(R24="","",IFERROR(INDEX(인컴2!E:E,MATCH(R24,인컴2!E:E,0)),IFERROR(INDEX(블루1!E:E,MATCH(R24,블루1!E:E,0)),IFERROR(INDEX(블루3!E:E,MATCH(R24,블루3!E:E,0)),R24)))) -> KODEX 보험 | E24: 0.035 | F24: =IF(D24="","",SUMIF(인컴2!E:E,D24,인컴2!N:N)/100000000) -> 0 | G24: =IFERROR(F24/$G$3, "") -> 0 | H24: =IFERROR(($E24-G24)*G$3*100000000/$S24, "") -> 12984.339 | I24: =IFERROR(INDEX(인컴2!Q:Q,MATCH(D24,인컴2!E:E,0))/100,"") -> -0.002 | J24: =IF(D24="","",SUMIF(블루1!E:E,D24,블루1!N:N)/100000000) -> 0 | K24: =IFERROR(J24/K$3, "") -> 0 | L24: =IFERROR(($E24-K24)*K$3*100000000/$S24, "") -> 13127.523 | M24: =IFERROR(INDEX(블루1!Q:Q,MATCH(D24,블루1!E:E,0))/100,"") -> -0.0024 | N24: =IF(D24="","",SUMIF(블루3!E:E,D24,블루3!N:N)/100000000) -> 0 | O24: =IFERROR(N24/O$3, "") -> 0 | P24: =IFERROR(($E24-O24)*O$3*100000000/$S24, "") -> 12886.896 | Q24: =IFERROR(INDEX(블루3!Q:Q,MATCH(D24,블루3!E:E,0))/100,"") -> -0.0022 | R24: KODEX 보험 | S24: =IFERROR(INDEX(인컴2!$E$1:$Q$47, MATCH(R24, 인컴2!E:E, 0), 8), "") -> 19510
B25: =SUM(E24:E26) -> 0.035 | D25: =IF(R25="","",IFERROR(INDEX(인컴2!E:E,MATCH(R25,인컴2!E:E,0)),IFERROR(INDEX(블루1!E:E,MATCH(R25,블루1!E:E,0)),IFERROR(INDEX(블루3!E:E,MATCH(R25,블루3!E:E,0)),R25)))) | F25: =IF(D25="","",SUMIF(인컴2!E:E,D25,인컴2!N:N)/100000000) | G25: =IFERROR(F25/$G$3, "") | H25: =IFERROR(($E25-G25)*G$3*100000000/$S25, "") | I25: =IFERROR(INDEX(인컴2!Q:Q,MATCH(D25,인컴2!E:E,0))/100,"") | J25: =IF(D25="","",SUMIF(블루1!E:E,D25,블루1!N:N)/100000000) | K25: =IFERROR(J25/K$3, "") | L25: =IFERROR(($E25-K25)*K$3*100000000/$S25, "") | M25: =IFERROR(INDEX(블루1!Q:Q,MATCH(D25,블루1!E:E,0))/100,"") | N25: =IF(D25="","",SUMIF(블루3!E:E,D25,블루3!N:N)/100000000) | O25: =IFERROR(N25/O$3, "") | P25: =IFERROR(($E25-O25)*O$3*100000000/$S25, "") | Q25: =IFERROR(INDEX(블루3!Q:Q,MATCH(D25,블루3!E:E,0))/100,"") | S25: =IFERROR(INDEX(인컴2!$E$1:$Q$47, MATCH(R25, 인컴2!E:E, 0), 8), "")
D26: =IF(R26="","",IFERROR(INDEX(인컴2!E:E,MATCH(R26,인컴2!E:E,0)),IFERROR(INDEX(블루1!E:E,MATCH(R26,블루1!E:E,0)),IFERROR(INDEX(블루3!E:E,MATCH(R26,블루3!E:E,0)),R26)))) | F26: =IF(D26="","",SUMIF(인컴2!E:E,D26,인컴2!N:N)/100000000) | G26: =IFERROR(F26/$G$3, "") | H26: =IFERROR(($E26-G26)*G$3*100000000/$S26, "") | I26: =IFERROR(INDEX(인컴2!Q:Q,MATCH(D26,인컴2!E:E,0))/100,"") | J26: =IF(D26="","",SUMIF(블루1!E:E,D26,블루1!N:N)/100000000) | K26: =IFERROR(J26/K$3, "") | L26: =IFERROR(($E26-K26)*K$3*100000000/$S26, "") | M26: =IFERROR(INDEX(블루1!Q:Q,MATCH(D26,블루1!E:E,0))/100,"") | N26: =IF(D26="","",SUMIF(블루3!E:E,D26,블루3!N:N)/100000000) | O26: =IFERROR(N26/O$3, "") | P26: =IFERROR(($E26-O26)*O$3*100000000/$S26, "") | Q26: =IFERROR(INDEX(블루3!Q:Q,MATCH(D26,블루3!E:E,0))/100,"") | S26: =IFERROR(INDEX(인컴2!$E$1:$Q$47, MATCH(R26, 인컴2!E:E, 0), 8), "")
C27: 금융 소계 | E27: =SUM(E24:E26) -> 0.035 | F27: =SUM(F24:F26) -> 0 | G27: =IFERROR(F27/$F$3, "") -> 0 | H27: =IFERROR(($E27-G27)*F$4/$S27, "") | J27: =SUM(J24:J26) -> 0 | K27: =IFERROR(J27/J$3, "") -> 0 | N27: =SUM(N24:N26) -> 0 | O27: =IFERROR(N27/N$3, "") -> 0 | S27: =IFERROR(INDEX(인컴2!$E$1:$Q$47, MATCH(R27, 인컴2!E:E, 0), 8), "")
A28: 1 | B28: 헬스케어 | C28: 바이오 | D28: =IF(R28="","",IFERROR(INDEX(인컴2!E:E,MATCH(R28,인컴2!E:E,0)),IFERROR(INDEX(블루1!E:E,MATCH(R28,블루1!E:E,0)),IFERROR(INDEX(블루3!E:E,MATCH(R28,블루3!E:E,0)),R28)))) -> TIGER 기술이전바이오액티브 | E28: 0.019 | F28: =IF(D28="","",SUMIF(인컴2!E:E,D28,인컴2!N:N)/100000000) -> 1.5686 | G28: =IFERROR(F28/$G$3, "") -> 0.021672207 | H28: =IFERROR(($E28-G28)*G$3*100000000/$S28, "") -> -2835.9254 | I28: =IFERROR(INDEX(인컴2!Q:Q,MATCH(D28,인컴2!E:E,0))/100,"") -> -0.299 | J28: =IF(D28="","",SUMIF(블루1!E:E,D28,블루1!N:N)/100000000) -> 1.5686 | K28: =IFERROR(J28/K$3, "") -> 0.021435824 | L28: =IFERROR(($E28-K28)*K$3*100000000/$S28, "") -> -2613.5669 | M28: =IFERROR(INDEX(블루1!Q:Q,MATCH(D28,블루1!E:E,0))/100,"") -> -0.299 | N28: =IF(D28="","",SUMIF(블루3!E:E,D28,블루3!N:N)/100000000) -> 1.5686 | O28: =IFERROR(N28/O$3, "") -> 0.021836079 | P28: =IFERROR(($E28-O28)*O$3*100000000/$S28, "") -> -2987.2499 | Q28: =IFERROR(INDEX(블루3!Q:Q,MATCH(D28,블루3!E:E,0))/100,"") -> -0.299 | R28: TIGER 기술이전바이오액티브 | S28: =IFERROR(INDEX(인컴2!$E$1:$Q$47, MATCH(R28, 인컴2!E:E, 0), 8), "") -> 6820
A29: 2 | B29: =SUM(E28:E33) -> 0.078 | C29: 바이오 | D29: =IF(R29="","",IFERROR(INDEX(인컴2!E:E,MATCH(R29,인컴2!E:E,0)),IFERROR(INDEX(블루1!E:E,MATCH(R29,블루1!E:E,0)),IFERROR(INDEX(블루3!E:E,MATCH(R29,블루3!E:E,0)),R29)))) -> 큐라클 | E29: 0.027 | F29: =IF(D29="","",SUMIF(인컴2!E:E,D29,인컴2!N:N)/100000000) -> 2.0689 | G29: =IFERROR(F29/$G$3, "") -> 0.028584489 | H29: =IFERROR(($E29-G29)*G$3*100000000/$S29, "") -> -942.34014 | I29: =IFERROR(INDEX(인컴2!Q:Q,MATCH(D29,인컴2!E:E,0))/100,"") -> -0.2147 | J29: =IF(D29="","",SUMIF(블루1!E:E,D29,블루1!N:N)/100000000) -> 2.0689 | K29: =IFERROR(J29/K$3, "") -> 0.028272713 | L29: =IFERROR(($E29-K29)*K$3*100000000/$S29, "") -> -765.26495 | M29: =IFERROR(INDEX(블루1!Q:Q,MATCH(D29,블루1!E:E,0))/100,"") -> -0.2147 | N29: =IF(D29="","",SUMIF(블루3!E:E,D29,블루3!N:N)/100000000) -> 2.0689 | O29: =IFERROR(N29/O$3, "") -> 0.028800628 | P29: =IFERROR(($E29-O29)*O$3*100000000/$S29, "") -> -1062.8473 | Q29: =IFERROR(INDEX(블루3!Q:Q,MATCH(D29,블루3!E:E,0))/100,"") -> -0.1849 | R29: 큐라클 | S29: =IFERROR(INDEX(인컴2!$E$1:$Q$47, MATCH(R29, 인컴2!E:E, 0), 8), "") -> 12170
A30: 3 | C30: 바이오 | D30: =IF(R30="","",IFERROR(INDEX(인컴2!E:E,MATCH(R30,인컴2!E:E,0)),IFERROR(INDEX(블루1!E:E,MATCH(R30,블루1!E:E,0)),IFERROR(INDEX(블루3!E:E,MATCH(R30,블루3!E:E,0)),R30)))) -> 앱클론 | E30: 0.017 | F30: =IF(D30="","",SUMIF(인컴2!E:E,D30,인컴2!N:N)/100000000) -> 0.7935 | G30: =IFERROR(F30/$G$3, "") -> 0.010963213 | H30: =IFERROR(($E30-G30)*G$3*100000000/$S30, "") -> 1651.9208 | I30: =IFERROR(INDEX(인컴2!Q:Q,MATCH(D30,인컴2!E:E,0))/100,"") -> -0.5023 | J30: =IF(D30="","",SUMIF(블루1!E:E,D30,블루1!N:N)/100000000) -> 0.7935 | K30: =IFERROR(J30/K$3, "") -> 0.010843636 | L30: =IFERROR(($E30-K30)*K$3*100000000/$S30, "") -> 1703.2197 | M30: =IFERROR(INDEX(블루1!Q:Q,MATCH(D30,블루1!E:E,0))/100,"") -> -0.5056 | N30: =IF(D30="","",SUMIF(블루3!E:E,D30,블루3!N:N)/100000000) -> 0.7935 | O30: =IFERROR(N30/O$3, "") -> 0.011046111 | P30: =IFERROR(($E30-O30)*O$3*100000000/$S30, "") -> 1617.0098 | Q30: =IFERROR(INDEX(블루3!Q:Q,MATCH(D30,블루3!E:E,0))/100,"") -> -0.4563 | R30: 앱클론 | S30: =IFERROR(INDEX(인컴2!$E$1:$Q$47, MATCH(R30, 인컴2!E:E, 0), 8), "") -> 26450
A31: 4 | C31: 바이오 | D31: =IF(R31="","",IFERROR(INDEX(인컴2!E:E,MATCH(R31,인컴2!E:E,0)),IFERROR(INDEX(블루1!E:E,MATCH(R31,블루1!E:E,0)),IFERROR(INDEX(블루3!E:E,MATCH(R31,블루3!E:E,0)),R31)))) -> 디앤디파마텍 | E31: 0.015 | F31: =IF(D31="","",SUMIF(인컴2!E:E,D31,인컴2!N:N)/100000000) -> 1.1532 | G31: =IFERROR(F31/$G$3, "") -> 0.015932927 | H31: =IFERROR(($E31-G31)*G$3*100000000/$S31, "") -> -70.264074 | I31: =IFERROR(INDEX(인컴2!Q:Q,MATCH(D31,인컴2!E:E,0))/100,"") -> -0.1303 | J31: =IF(D31="","",SUMIF(블루1!E:E,D31,블루1!N:N)/100000000) -> 1.1532 | K31: =IFERROR(J31/K$3, "") -> 0.015759144 | L31: =IFERROR(($E31-K31)*K$3*100000000/$S31, "") -> -57.805957 | M31: =IFERROR(INDEX(블루1!Q:Q,MATCH(D31,블루1!E:E,0))/100,"") -> -0.1303 | N31: =IF(D31="","",SUMIF(블루3!E:E,D31,블루3!N:N)/100000000) -> 1.1532 | O31: =IFERROR(N31/O$3, "") -> 0.016053402 | P31: =IFERROR(($E31-O31)*O$3*100000000/$S31, "") -> -78.742352 | Q31: =IFERROR(INDEX(블루3!Q:Q,MATCH(D31,블루3!E:E,0))/100,"") -> -0.1305 | R31: 디앤디파마텍 | S31: =IFERROR(INDEX(인컴2!$E$1:$Q$47, MATCH(R31, 인컴2!E:E, 0), 8), "") -> 96100
D32: =IF(R32="","",IFERROR(INDEX(인컴2!E:E,MATCH(R32,인컴2!E:E,0)),IFERROR(INDEX(블루1!E:E,MATCH(R32,블루1!E:E,0)),IFERROR(INDEX(블루3!E:E,MATCH(R32,블루3!E:E,0)),R32)))) | F32: =IF(D32="","",SUMIF(인컴2!E:E,D32,인컴2!N:N)/100000000) | G32: =IFERROR(F32/$G$3, "") | H32: =IFERROR(($E32-G32)*G$3*100000000/$S32, "") | I32: =IFERROR(INDEX(인컴2!Q:Q,MATCH(D32,인컴2!E:E,0))/100,"") | J32: =IF(D32="","",SUMIF(블루1!E:E,D32,블루1!N:N)/100000000) | K32: =IFERROR(J32/K$3, "") | L32: =IFERROR(($E32-K32)*K$3*100000000/$S32, "") | M32: =IFERROR(INDEX(블루1!Q:Q,MATCH(D32,블루1!E:E,0))/100,"") | N32: =IF(D32="","",SUMIF(블루3!E:E,D32,블루3!N:N)/100000000) | O32: =IFERROR(N32/O$3, "") | P32: =IFERROR(($E32-O32)*O$3*100000000/$S32, "") | Q32: =IFERROR(INDEX(블루3!Q:Q,MATCH(D32,블루3!E:E,0))/100,"") | S32: =IFERROR(INDEX(인컴2!$E$1:$Q$47, MATCH(R32, 인컴2!E:E, 0), 8), "")
D33: =IF(R33="","",IFERROR(INDEX(인컴2!E:E,MATCH(R33,인컴2!E:E,0)),IFERROR(INDEX(블루1!E:E,MATCH(R33,블루1!E:E,0)),IFERROR(INDEX(블루3!E:E,MATCH(R33,블루3!E:E,0)),R33)))) | F33: =IF(D33="","",SUMIF(인컴2!E:E,D33,인컴2!N:N)/100000000) | G33: =IFERROR(F33/$G$3, "") | H33: =IFERROR(($E33-G33)*G$3*100000000/$S33, "") | I33: =IFERROR(INDEX(인컴2!Q:Q,MATCH(D33,인컴2!E:E,0))/100,"") | J33: =IF(D33="","",SUMIF(블루1!E:E,D33,블루1!N:N)/100000000) | K33: =IFERROR(J33/K$3, "") | L33: =IFERROR(($E33-K33)*K$3*100000000/$S33, "") | M33: =IFERROR(INDEX(블루1!Q:Q,MATCH(D33,블루1!E:E,0))/100,"") | N33: =IF(D33="","",SUMIF(블루3!E:E,D33,블루3!N:N)/100000000) | O33: =IFERROR(N33/O$3, "") | P33: =IFERROR(($E33-O33)*O$3*100000000/$S33, "") | Q33: =IFERROR(INDEX(블루3!Q:Q,MATCH(D33,블루3!E:E,0))/100,"") | S33: =IFERROR(INDEX(인컴2!$E$1:$Q$47, MATCH(R33, 인컴2!E:E, 0), 8), "")
C34: 헬스케어 소계 | E34: =SUM(E28:E33) -> 0.078 | F34: =SUM(F28:F33) -> 5.5842 | G34: =IFERROR(F34/$F$3, "") -> 0.057581341 | H34: =IFERROR(($E34-G34)*F$4*100000000/$S34, "") | J34: =SUM(J28:J33) -> 5.5842 | K34: =IFERROR(J34/J$3, "") -> 0.058304446 | N34: =SUM(N28:N33) -> 5.5842 | O34: =IFERROR(N34/N$3, "") -> 0.059104928 | S34: =IFERROR(INDEX(인컴2!$E$1:$Q$47, MATCH(R34, 인컴2!E:E, 0), 8), "")
A35: 1 | B35: 방산/조선 | C35: 로봇 | D35: =IF(R35="","",IFERROR(INDEX(인컴2!E:E,MATCH(R35,인컴2!E:E,0)),IFERROR(INDEX(블루1!E:E,MATCH(R35,블루1!E:E,0)),IFERROR(INDEX(블루3!E:E,MATCH(R35,블루3!E:E,0)),R35)))) -> TIGER 코리아휴머노이드로봇산업 | E35: 0.039 | F35: =IF(D35="","",SUMIF(인컴2!E:E,D35,인컴2!N:N)/100000000) -> 2.5175 | G35: =IFERROR(F35/$G$3, "") -> 0.034782469 | H35: =IFERROR(($E35-G35)*G$3*100000000/$S35, "") -> 3031.3623 | I35: =IFERROR(INDEX(인컴2!Q:Q,MATCH(D35,인컴2!E:E,0))/100,"") -> -0.2378 | J35: =IF(D35="","",SUMIF(블루1!E:E,D35,블루1!N:N)/100000000) -> 2.5175 | K35: =IFERROR(J35/K$3, "") -> 0.034403091 | L35: =IFERROR(($E35-K35)*K$3*100000000/$S35, "") -> 3340.477 | M35: =IFERROR(INDEX(블루1!Q:Q,MATCH(D35,블루1!E:E,0))/100,"") -> -0.2378 | N35: =IF(D35="","",SUMIF(블루3!E:E,D35,블루3!N:N)/100000000) -> 2.5175 | O35: =IFERROR(N35/O$3, "") -> 0.035045474 | P35: =IFERROR(($E35-O35)*O$3*100000000/$S35, "") -> 2820.9966 | Q35: =IFERROR(INDEX(블루3!Q:Q,MATCH(D35,블루3!E:E,0))/100,"") -> -0.2378 | R35: TIGER 코리아휴머노이드로봇산업 | S35: =IFERROR(INDEX(인컴2!$E$1:$Q$47, MATCH(R35, 인컴2!E:E, 0), 8), "") -> 10070
B36: =SUM(E35:E37) -> 0.039 | D36: =IF(R36="","",IFERROR(INDEX(인컴2!E:E,MATCH(R36,인컴2!E:E,0)),IFERROR(INDEX(블루1!E:E,MATCH(R36,블루1!E:E,0)),IFERROR(INDEX(블루3!E:E,MATCH(R36,블루3!E:E,0)),R36)))) | F36: =IF(D36="","",SUMIF(인컴2!E:E,D36,인컴2!N:N)/100000000) | G36: =IFERROR(F36/$G$3, "") | H36: =IFERROR(($E36-G36)*G$3*100000000/$S36, "") | I36: =IFERROR(INDEX(인컴2!Q:Q,MATCH(D36,인컴2!E:E,0))/100,"") | J36: =IF(D36="","",SUMIF(블루1!E:E,D36,블루1!N:N)/100000000) | K36: =IFERROR(J36/K$3, "") | L36: =IFERROR(($E36-K36)*K$3*100000000/$S36, "") | M36: =IFERROR(INDEX(블루1!Q:Q,MATCH(D36,블루1!E:E,0))/100,"") | N36: =IF(D36="","",SUMIF(블루3!E:E,D36,블루3!N:N)/100000000) | O36: =IFERROR(N36/O$3, "") | P36: =IFERROR(($E36-O36)*O$3*100000000/$S36, "") | Q36: =IFERROR(INDEX(블루3!Q:Q,MATCH(D36,블루3!E:E,0))/100,"") | S36: =IFERROR(INDEX(인컴2!$E$1:$Q$47, MATCH(R36, 인컴2!E:E, 0), 8), "")
D37: =IF(R37="","",IFERROR(INDEX(인컴2!E:E,MATCH(R37,인컴2!E:E,0)),IFERROR(INDEX(블루1!E:E,MATCH(R37,블루1!E:E,0)),IFERROR(INDEX(블루3!E:E,MATCH(R37,블루3!E:E,0)),R37)))) | F37: =IF(D37="","",SUMIF(인컴2!E:E,D37,인컴2!N:N)/100000000) | G37: =IFERROR(F37/$G$3, "") | H37: =IFERROR(($E37-G37)*G$3*100000000/$S37, "") | I37: =IFERROR(INDEX(인컴2!Q:Q,MATCH(D37,인컴2!E:E,0))/100,"") | J37: =IF(D37="","",SUMIF(블루1!E:E,D37,블루1!N:N)/100000000) | K37: =IFERROR(J37/K$3, "") | L37: =IFERROR(($E37-K37)*K$3*100000000/$S37, "") | M37: =IFERROR(INDEX(블루1!Q:Q,MATCH(D37,블루1!E:E,0))/100,"") | N37: =IF(D37="","",SUMIF(블루3!E:E,D37,블루3!N:N)/100000000) | O37: =IFERROR(N37/O$3, "") | P37: =IFERROR(($E37-O37)*O$3*100000000/$S37, "") | Q37: =IFERROR(INDEX(블루3!Q:Q,MATCH(D37,블루3!E:E,0))/100,"") | S37: =IFERROR(INDEX(인컴2!$E$1:$Q$47, MATCH(R37, 인컴2!E:E, 0), 8), "")
C38: 방산/조선 소계 | E38: =SUM(E35:E37) -> 0.039 | F38: =SUM(F35:F37) -> 2.5175 | G38: =IFERROR(F38/$F$3, "") -> 0.025959139 | H38: =IFERROR(($E38-G38)*F$4*100000000/$S38, "") | J38: =SUM(J35:J37) -> 2.5175 | K38: =IFERROR(J38/J$3, "") -> 0.026285134 | N38: =SUM(N35:N37) -> 2.5175 | O38: =IFERROR(N38/N$3, "") -> 0.026646011 | S38: =IFERROR(INDEX(인컴2!$E$1:$Q$47, MATCH(R38, 인컴2!E:E, 0), 8), "")
B39: 기계 | D39: =IF(R39="","",IFERROR(INDEX(인컴2!E:E,MATCH(R39,인컴2!E:E,0)),IFERROR(INDEX(블루1!E:E,MATCH(R39,블루1!E:E,0)),IFERROR(INDEX(블루3!E:E,MATCH(R39,블루3!E:E,0)),R39)))) | F39: =IF(D39="","",SUMIF(인컴2!E:E,D39,인컴2!N:N)/100000000) | G39: =IFERROR(F39/$G$3, "") | H39: =IFERROR(($E39-G39)*G$3*100000000/$S39, "") | I39: =IFERROR(INDEX(인컴2!Q:Q,MATCH(D39,인컴2!E:E,0))/100,"") | J39: =IF(D39="","",SUMIF(블루1!E:E,D39,블루1!N:N)/100000000) | K39: =IFERROR(J39/K$3, "") | L39: =IFERROR(($E39-K39)*K$3*100000000/$S39, "") | M39: =IFERROR(INDEX(블루1!Q:Q,MATCH(D39,블루1!E:E,0))/100,"") | N39: =IF(D39="","",SUMIF(블루3!E:E,D39,블루3!N:N)/100000000) | O39: =IFERROR(N39/O$3, "") | P39: =IFERROR(($E39-O39)*O$3*100000000/$S39, "") | Q39: =IFERROR(INDEX(블루3!Q:Q,MATCH(D39,블루3!E:E,0))/100,"") | S39: =IFERROR(INDEX(인컴2!$E$1:$Q$47, MATCH(R39, 인컴2!E:E, 0), 8), "")
B40: =SUM(E39:E41) -> 0 | D40: =IF(R40="","",IFERROR(INDEX(인컴2!E:E,MATCH(R40,인컴2!E:E,0)),IFERROR(INDEX(블루1!E:E,MATCH(R40,블루1!E:E,0)),IFERROR(INDEX(블루3!E:E,MATCH(R40,블루3!E:E,0)),R40)))) | F40: =IF(D40="","",SUMIF(인컴2!E:E,D40,인컴2!N:N)/100000000) | G40: =IFERROR(F40/$G$3, "") | H40: =IFERROR(($E40-G40)*G$3*100000000/$S40, "") | I40: =IFERROR(INDEX(인컴2!Q:Q,MATCH(D40,인컴2!E:E,0))/100,"") | J40: =IF(D40="","",SUMIF(블루1!E:E,D40,블루1!N:N)/100000000) | K40: =IFERROR(J40/K$3, "") | L40: =IFERROR(($E40-K40)*K$3*100000000/$S40, "") | M40: =IFERROR(INDEX(블루1!Q:Q,MATCH(D40,블루1!E:E,0))/100,"") | N40: =IF(D40="","",SUMIF(블루3!E:E,D40,블루3!N:N)/100000000) | O40: =IFERROR(N40/O$3, "") | P40: =IFERROR(($E40-O40)*O$3*100000000/$S40, "") | Q40: =IFERROR(INDEX(블루3!Q:Q,MATCH(D40,블루3!E:E,0))/100,"") | S40: =IFERROR(INDEX(인컴2!$E$1:$Q$47, MATCH(R40, 인컴2!E:E, 0), 8), "")
...

Sheet 인컴2
A1: NO | B1: 펀드 | C1: 펀드명 | D1: 종목 | E1: 종목명 | F1: 전일 | J1: 당일 | O1: 전일 대비 손익 | P1: 취득액 대비 손익(전체) (LONG손익 +차입매도분손익) | Q1: 취득액 대비 손익비율 (전체) | R1: 전일대비 종목증감비율
F2: 보유주수 | G2: 종가 | H2: 취득액 | I2: LONG평가금액 +차입매도분평가금액 | J2: 체결기준 보유주수 | K2: 주문기준 보유주수 | L2: 현재가 | M2: 취득액 | N2: LONG평가금액 +차입매도분평가금액 ▼
A3: 1 | B3: 300019 | C3: 이지스 인컴플러스 일반사모투자신탁 제2호 | D3: KR7367760006 | E3: RISE 네트워크인프라 | F3: 13500 | G3: 89055 | H3: 791527161 | I3: 1202242500 | J3: 15000 | K3: 15000 | L3: 79825 | M3: 914996654 | N3: 1197375000 | O3: -128336993 | P3: 282378346 | Q3: 30.86 | R3: -10.36
A4: 2 | B4: 300019 | C4: 이지스 인컴플러스 일반사모투자신탁 제2호 | D4: KR7087010005 | E4: 펩트론 | F4: 2800 | G4: 205000 | H4: 767200000 | I4: 574000000 | J4: 2800 | K4: 2800 | L4: 188500 | M4: 767200000 | N4: 527800000 | O4: -46200000 | P4: -239400000 | Q4: -31.2 | R4: -8.04
A5: 3 | B5: 300019 | C5: 이지스 인컴플러스 일반사모투자신탁 제2호 | D5: KR7233740000 | E5: KODEX 코스닥150레버리지 | F5: 48000 | G5: 12085 | H5: 720810401 | I5: 580080000 | J5: 48000 | K5: 48000 | L5: 10175 | M5: 720810401 | N5: 488400000 | O5: -91680000 | P5: -232410401 | Q5: -32.24 | R5: -15.8
A6: 4 | B6: 300019 | C6: 이지스 인컴플러스 일반사모투자신탁 제2호 | D6: KR7160980009 | E6: 싸이맥스 | F6: 10000 | G6: 38100 | H6: 347526041 | I6: 381000000 | J6: 10000 | K6: 10000 | L6: 33700 | M6: 347526041 | N6: 337000000 | O6: -44000000 | P6: -10526041 | Q6: -3.02 | R6: -11.54
A7: 5 | B7: 300019 | C7: 이지스 인컴플러스 일반사모투자신탁 제2호 | D7: KR70043Y0003 | E7: TIME 차이나AI테크액티브 | F7: 10000 | G7: 28885 | H7: 171290074 | I7: 288850000 | J7: 12000 | K7: 12000 | L7: 26795 | M7: 226321662 | N7: 321540000 | O7: -22341588 | P7: 95218338 | Q7: 42.07 | R7: -7.23
A8: 6 | B8: 300019 | C8: 이지스 인컴플러스 일반사모투자신탁 제2호 | D8: KR70117V0007 | E8: TIGER 코리아AI전력기기TOP3플러스 | F8: 13000 | G8: 23775 | H8: 295962447 | I8: 309075000 | J8: 13000 | K8: 13000 | L8: 22200 | M8: 295962447 | N8: 288600000 | O8: -20475000 | P8: -7362447 | Q8: -2.48 | R8: -6.62
A9: 7 | B9: 300019 | C9: 이지스 인컴플러스 일반사모투자신탁 제2호 | D9: KR7466930005 | E9: SOL 자동차TOP3플러스 | F9: 9000 | G9: 33895 | H9: 279256958 | I9: 305055000 | J9: 9000 | K9: 9000 | L9: 30145 | M9: 279256958 | N9: 271305000 | O9: -33750000 | P9: -7951958 | Q9: -2.84 | R9: -11.06
A10: 8 | B10: 300019 | C10: 이지스 인컴플러스 일반사모투자신탁 제2호 | D10: KR7261140008 | E10: TIGER 우선주 | F10: 10000 | G10: 29175 | H10: 300715905 | I10: 291750000 | J10: 10000 | K10: 10000 | L10: 26875 | M10: 300715905 | N10: 268750000 | O10: -23000000 | P10: -31965905 | Q10: -10.62 | R10: -7.88
A11: 9 | B11: 300019 | C11: 이지스 인컴플러스 일반사모투자신탁 제2호 | D11: KR7034020008 | E11: 두산에너빌리티 | F11: 3000 | G11: 94200 | H11: 271800000 | I11: 282600000 | J11: 3000 | K11: 3000 | L11: 89200 | M11: 271800000 | N11: 267600000 | O11: -15000000 | P11: -4200000 | Q11: -1.54 | R11: -5.3
A12: 10 | B12: 300019 | C12: 이지스 인컴플러스 일반사모투자신탁 제2호 | D12: KR70148J0006 | E12: TIGER 코리아휴머노이드로봇산업 | F12: 30000 | G12: 11440 | H12: 396362402 | I12: 343200000 | J12: 25000 | K12: 25000 | L12: 10070 | M12: 330302002 | N12: 251750000 | O12: -40498960 | P12: -78552002 | Q12: -23.78 | R12: -11.97
A13: 11 | B13: 300019 | C13: 이지스 인컴플러스 일반사모투자신탁 제2호 | D13: KR7445090004 | E13: 에이직랜드 | F13: 10000 | G13: 27000 | H13: 306243044 | I13: 270000000 | J13: 10000 | K13: 10000 | L13: 23750 | M13: 306243044 | N13: 237500000 | O13: -32500000 | P13: -68743044 | Q13: -22.44 | R13: -12.03
A14: 12 | B14: 300019 | C14: 이지스 인컴플러스 일반사모투자신탁 제2호 | D14: KR7080220007 | E14: 제주반도체 | F14: 2000 | G14: 134000 | H14: 236117010 | I14: 268000000 | J14: 2000 | K14: 2000 | L14: 110800 | M14: 236117010 | N14: 221600000 | O14: -46400000 | P14: -14517010 | Q14: -6.14 | R14: -17.31
... A45: 43 | B45: 300019 | C45: 이지스 인컴플러스 일반사모투자신탁 제2호 | D45: KR7140700006 | E45: KODEX 보험 | F45: 15000 | G45: 20250 | H45: 301660855 | I45: 303750000 | J45: 0 | K45: 0 | L45: 19510 | M45: 0 | N45: 0 | O45: -2703200 | P45: -614055 | Q45: -0.2 | R45: -3.65
H46: 9562664837 | I46: 9583172185 | J46: 372501 | K46: 372582 | M46: 8863992956 | N46: 8082645050 | O46: -989853938 | P46: -888897025

Sheet 블루1
A1: NO | B1: 펀드 | C1: 펀드명 | D1: 종목 | E1: 종목명 | F1: 전일 | J1: 당일 | O1: 전일 대비 손익 | P1: 취득액 대비 손익(전체) (LONG손익 +차입매도분손익) | Q1: 취득액 대비 손익비율 (전체) | R1: 전일대비 종목증감비율
F2: 보유주수 | G2: 종가 | H2: 취득액 | I2: LONG평가금액 +차입매도분평가금액 | J2: 체결기준 보유주수 | K2: 주문기준 보유주수 | L2: 현재가 | M2: 취득액 | N2: LONG평가금액 +차입매도분평가금액 ▼
A3: 1 | B3: 300037 | C3: 이지스블루ON일반사모투자신탁제1호 | D3: KR7000150003 | E3: 두산 | F3: 0 | G3: 1631000 | H3: 0 | I3: 0 | J3: 86 | K3: 100 | L3: 1531000 | M3: 139712500 | N3: 131666000 | O3: -8046500 | P3: -8046500 | Q3: -5.75 | R3: -6.13
A4: 2 | B4: 300037 | C4: 이지스블루ON일반사모투자신탁제1호 | D4: KR7000990002 | E4: DB하이텍 | F4: 1200 | G4: 174000 | H4: 219264951 | I4: 208800000 | J4: 1200 | K4: 1200 | L4: 151100 | M4: 219264951 | N4: 181320000 | O4: -27480000 | P4: -37944951 | Q4: -17.3 | R4: -13.16
A5: 3 | B5: 300037 | C5: 이지스블루ON일반사모투자신탁제1호 | D5: KR7002990000 | E5: 금호건설 | F5: 55600 | G5: 4030 | H5: 199575645 | I5: 224068000 | J5: 55600 | K5: 55600 | L5: 3730 | M5: 199575645 | N5: 207388000 | O5: -16680000 | P5: 7812355 | Q5: 3.91 | R5: -7.44
A6: 4 | B6: 300037 | C6: 이지스블루ON일반사모투자신탁제1호 | D6: KR7003550001 | E6: LG | F6: 1800 | G6: 109900 | H6: 189284546 | I6: 197820000 | J6: 1800 | K6: 1800 | L6: 98600 | M6: 189284546 | N6: 177480000 | O6: -20340000 | P6: -11804546 | Q6: -6.23 | R6: -10.28
A7: 5 | B7: 300037 | C7: 이지스블루ON일반사모투자신탁제1호 | D7: KR70043Y0003 | E7: TIME 차이나AI테크액티브 | F7: 8000 | G7: 28885 | H7: 154153183 | I7: 231080000 | J7: 10000 | K7: 10000 | L7: 26795 | M7: 209184850 | N7: 267950000 | O7: -18161667 | P7: 58765150 | Q7: 28.09 | R7: -7.23
A8: 6 | B8: 300037 | C8: 이지스블루ON일반사모투자신탁제1호 | D8: KR70088M0003 | E8: 메쥬 | F8: 57 | G8: 17270 | H8: 1243512 | I8: 984390 | J8: 57 | K8: 57 | L8: 16110 | M8: 1243512 | N8: 918270 | O8: -66120 | P8: -325242 | Q8: -26.15 | R8: -6.71
A9: 7 | B9: 300037 | C9: 이지스블루ON일반사모투자신탁제1호 | D9: KR7009151002 | E9: 삼성전기우 | F9: 150 | G9: 954000 | H9: 141071807 | I9: 143100000 | J9: 236 | K9: 250 | L9: 817000 | M9: 214676807 | N9: 192812000 | O9: -23893000 | P9: -21864807 | Q9: -10.18 | R9: -14.36
A10: 8 | B10: 300037 | C10: 이지스블루ON일반사모투자신탁제1호 | D10: KR7010780005 | E10: 아이에스동서 | F10: 10100 | G10: 24250 | H10: 201062050 | I10: 244925000 | J10: 10100 | K10: 10100 | L10: 21050 | M10: 201062050 | N10: 212605000 | O10: -32320000 | P10: 11542950 | Q10: 5.74 | R10: -13.19
A11: 9 | B11: 300037 | C11: 이지스블루ON일반사모투자신탁제1호 | D11: KR7011070000 | E11: LG이노텍 | F11: 200 | G11: 1130000 | H11: 258095835 | I11: 226000000 | J11: 200 | K11: 200 | L11: 991000 | M11: 258095835 | N11: 198200000 | O11: -27800000 | P11: -59895835 | Q11: -23.2 | R11: -12.3
A12: 10 | B12: 300037 | C12: 이지스블루ON일반사모투자신탁제1호 | D12: KR70117V0007 | E12: TIGER 코리아AI전력기기TOP3플러스 | F12: 13000 | G12: 23775 | H12: 295959103 | I12: 309075000 | J12: 13000 | K12: 13000 | L12: 22200 | M12: 295959103 | N12: 288600000 | O12: -20475000 | P12: -7359103 | Q12: -2.48 | R12: -6.62
A13: 11 | B13: 300037 | C13: 이지스블루ON일반사모투자신탁제1호 | D13: KR70148J0006 | E13: TIGER 코리아휴머노이드로봇산업 | F13: 30000 | G13: 11440 | H13: 396360626 | I13: 343200000 | J13: 25000 | K13: 25000 | L13: 10070 | M13: 330300522 | N13: 251750000 | O13: -40499950 | P13: -78550522 | Q13: -23.78 | R13: -11.97
A14: 12 | B14: 300037 | C14: 이지스블루ON일반사모투자신탁제1호 | D14: KR70168K0008 | E14: TIGER 기술이전바이오액티브 | F14: 23000 | G14: 7175 | H14: 223781941 | I14: 165025000 | J14: 23000 | K14: 23000 | L14: 6820 | M14: 223781941 | N14: 156860000 | O14: -8165000 | P14: -66921941 | Q14: -29.9 | R14: -4.94
... A45: 43 | B45: 300037 | C45: 이지스블루ON일반사모투자신탁제1호 | D45: KR7494340003 | E45: ACE 글로벌AI맞춤형반도체 | F45: 6100 | G45: 29745 | H45: 164917685 | I45: 181444500 | J45: 6100 | K45: 6100 | L45: 27720 | M45: 164917685 | N45: 169092000 | O45: -12352500 | P45: 4174315 | Q45: 2.53 | R45: -6.8
H46: 10136817057 | I46: 10366471510 | J46: 688703 | K46: 688785 | M46: 9435361352 | N46: 8866111640 | O46: -987732532 | P46: -676928215

Sheet 블루3
A1: NO | B1: 펀드 | C1: 펀드명 | D1: 종목 | E1: 종목명 | F1: 전일 | J1: 당일 | O1: 전일 대비 손익 | P1: 취득액 대비 손익(전체) (LONG손익 +차입매도분손익) | Q1: 취득액 대비 손익비율 (전체) | R1: 전일대비 종목증감비율
F2: 보유주수 | G2: 종가 | H2: 취득액 | I2: LONG평가금액 +차입매도분평가금액 | J2: 체결기준 보유주수 | K2: 주문기준 보유주수 | L2: 현재가 | M2: 취득액 | N2: LONG평가금액 +차입매도분평가금액 ▼
A3: 1 | B3: 300085 | C3: 이지스블루ON일반사모투자신탁제3호 | D3: KR7000150003 | E3: 두산 | F3: 0 | G3: 1631000 | H3: 0 | I3: 0 | J3: 86 | K3: 100 | L3: 1531000 | M3: 139653000 | N3: 131666000 | O3: -7987000 | P3: -7987000 | Q3: -5.71 | R3: -6.13
A4: 2 | B4: 300085 | C4: 이지스블루ON일반사모투자신탁제3호 | D4: KR7000990002 | E4: DB하이텍 | F4: 1200 | G4: 174000 | H4: 219271160 | I4: 208800000 | J4: 1200 | K4: 1200 | L4: 151100 | M4: 219271160 | N4: 181320000 | O4: -27480000 | P4: -37951160 | Q4: -17.3 | R4: -13.16
A5: 3 | B5: 300085 | C5: 이지스블루ON일반사모투자신탁제3호 | D5: KR7003550001 | E5: LG | F5: 1800 | G5: 109900 | H5: 189285997 | I5: 197820000 | J5: 1800 | K5: 1800 | L5: 98600 | M5: 189285997 | N5: 177480000 | O5: -20340000 | P5: -11805997 | Q5: -6.23 | R5: -10.28
A6: 4 | B6: 300085 | C6: 이지스블루ON일반사모투자신탁제3호 | D6: KR70043Y0003 | E6: TIME 차이나AI테크액티브 | F6: 8000 | G6: 28885 | H6: 154372443 | I6: 231080000 | J6: 10000 | K6: 10000 | L6: 26795 | M6: 209435073 | N6: 267950000 | O6: -18192630 | P6: 58514927 | Q6: 27.93 | R6: -7.23
A7: 5 | B7: 300085 | C7: 이지스블루ON일반사모투자신탁제3호 | D7: KR7009151002 | E7: 삼성전기우 | F7: 150 | G7: 954000 | H7: 141189040 | I7: 143100000 | J7: 236 | K7: 250 | L7: 817000 | M7: 214770040 | N7: 192812000 | O7: -23869000 | P7: -21958040 | Q7: -10.22 | R7: -14.36
A8: 6 | B8: 300085 | C8: 이지스블루ON일반사모투자신탁제3호 | D8: KR7010780005 | E8: 아이에스동서 | F8: 8000 | G8: 24250 | H8: 207612084 | I8: 194000000 | J8: 8000 | K8: 8000 | L8: 21050 | M8: 207612084 | N8: 168400000 | O8: -25600000 | P8: -39212084 | Q8: -18.88 | R8: -13.19
A9: 7 | B9: 300085 | C9: 이지스블루ON일반사모투자신탁제3호 | D9: KR7011070000 | E9: LG이노텍 | F9: 200 | G9: 1130000 | H9: 258093330 | I9: 226000000 | J9: 200 | K9: 200 | L9: 991000 | M9: 258093330 | N9: 198200000 | O9: -27800000 | P9: -59893330 | Q9: -23.2 | R9: -12.3
A10: 8 | B10: 300085 | C10: 이지스블루ON일반사모투자신탁제3호 | D10: KR70117V0007 | E10: TIGER 코리아AI전력기기TOP3플러스 | F10: 13000 | G10: 23775 | H10: 296005977 | I10: 309075000 | J10: 13000 | K10: 13000 | L10: 22200 | M10: 296005977 | N10: 288600000 | O10: -20475000 | P10: -7405977 | Q10: -2.5 | R10: -6.62
A11: 9 | B11: 300085 | C11: 이지스블루ON일반사모투자신탁제3호 | D11: KR70148J0006 | E11: TIGER 코리아휴머노이드로봇산업 | F11: 30000 | G11: 11440 | H11: 396360719 | I11: 343200000 | J11: 25000 | K11: 25000 | L11: 10070 | M11: 330300599 | N11: 251750000 | O11: -40518805 | P11: -78550599 | Q11: -23.78 | R11: -11.97
A12: 10 | B12: 300085 | C12: 이지스블루ON일반사모투자신탁제3호 | D12: KR70168K0008 | E12: TIGER 기술이전바이오액티브 | F12: 23000 | G12: 7175 | H12: 223781940 | I12: 165025000 | J12: 23000 | K12: 23000 | L12: 6820 | M12: 223781940 | N12: 156860000 | O12: -8165000 | P12: -66921940 | Q12: -29.9 | R12: -4.94
A13: 11 | B13: 300085 | C13: 이지스블루ON일반사모투자신탁제3호 | D13: KR70181B0002 | E13: HANARO 미국AI메모리반도체TOP4+ | F13: 13500 | G13: 14735 | H13: 157767148 | I13: 198922500 | J13: 13500 | K13: 13500 | L13: 13875 | M13: 157767148 | N13: 187312500 | O13: -11610000 | P13: 29545352 | Q13: 18.72 | R13: -5.83
A14: 12 | B14: 300085 | C14: 이지스블루ON일반사모투자신탁제3호 | D14: KR70192M0006 | E14: RISE 삼성전자단일종목레버리지 | F14: 9000 | G14: 25955 | H14: 220984432 | I14: 233595000 | J14: 0 | K14: 0 | L14: 19575 | M14: 0 | N14: 0 | O14: -52618040 | P14: -40007472 | Q14: -18.1 | R14: -24.58
... A40: 38 | B40: 300085 | C40: 이지스블루ON일반사모투자신탁제3호 | D40: KR7494340003 | E40: ACE 글로벌AI맞춤형반도체 | F40: 6100 | G40: 29745 | H40: 164909761 | I40: 181444500 | J40: 6100 | K40: 6100 | L40: 27720 | M40: 164909761 | N40: 169092000 | O40: -12352500 | P40: 4182239 | Q40: 2.53 | R40: -6.8
H41: 20196067174 | I41: 20505719300 | J41: 581203 | K41: 581286 | M41: 19502400614 | N41: 19052134400 | O41: -939108530 | P41: -558029066

Sheet 아이타스41718_편드편입비정보
A1: No | B1: 처리일 | C1: 펀드코드 | D1: 펀드명 | E1: 펀드유형 | F1: 기준가 | G1: 기준가증감 | H1: 원본액 | I1: 원본액증감 | J1: 순자산(전) | K1: 순자산(후) | L1: 순자산증감 | M1: 총자산액 | N1: 국내자산 | P1: 주식 | R1: 채권 | T1: CD/CP | V1: 현금 | X1: 수익증권 | Z1: 장내선물옵션 | AB1: 기타파생 | AD1: 기타자산 | AF1: 해외자산 | AH1: 해외주식 | AJ1: 해외채권 | AL1: 해외현금 | AN1: 해외수익증권 | AP1: 해외파생 | AR1: 해외기타 | AT1: 주식+선물 | AU1: 주식 약관비상한 | AV1: 채권+선물 | AW1: 채권 약관비상한 | AX1: 수익자
N2: 평가액 | O2: 편입비 | P2: 평가액 | Q2: 편입비 | R2: 평가액 | S2: 편입비 | T2: 평가액 | U2: 편입비 | V2: 평가액 | W2: 편입비 | X2: 평가액 | Y2: 편입비 | Z2: 평가액 | AA2: 편입비 | AB2: 평가액 | AC2: 편입비 | AD2: 평가액 | AE2: 편입비 | AF2: 평가액 | AG2: 편입비 | AH2: 평가액 | AI2: 편입비 | AJ2: 평가액 | AK2: 편입비 | AL2: 평가액 | AM2: 편입비 | AN2: 평가액 | AO2: 편입비 | AP2: 평가액 | AQ2: 편입비 | AR2: 평가액 | AS2: 편입비
A3: 1 | B3: 46195 | C3: 300001 | D3: 이지스 인컴플러스 일반사모투자신탁 제1호 | E3: 혼합채권형 | F3: 1426.8 | G3: 6.003871 | H3: 11529804792 | I3: 0 | J3: 16450706803 | K3: 16450706803 | L3: 69223458 | M3: 17934731736 | N3: 17934731736 | O3: 109.02 | P3: 6468843500 | Q3: 39.32 | R3: 8934863000 | S3: 54.31 | T3: 0 | U3: 0 | V3: 619921455 | W3: 3.77 | X3: 0 | Y3: 0 | Z3: 0 | AA3: 0 | AB3: 0 | AC3: 0 | AD3: 1911103781 | AE3: 11.62 | AF3: 0 | AG3: 0 | AH3: 0 | AI3: 0 | AJ3: 0 | AK3: 0 | AL3: 0 | AM3: 0 | AN3: 0 | AO3: 0 | AP3: 0 | AQ3: 0 | AR3: 0 | AS3: 0 | AT3: 39.32 | AU3: 50 | AV3: 54.31 | AW3: 0
A4: 2 | B4: 46195 | C4: 300019 | D4: 이지스 인컴플러스 일반사모투자신탁 제2호 | E4: 혼합채권형 | F4: 1489.48 | G4: 4.727575 | H4: 15500000000 | I4: 0 | J4: 23087013220 | K4: 23087013220 | L4: 73277425 | M4: 23583605580 | N4: 23583605580 | O4: 102.15 | P4: 9583172185 | Q4: 41.51 | R4: 12861280000 | S4: 55.71 | T4: 0 | U4: 0 | V4: 388005315 | W4: 1.68 | X4: 0 | Y4: 0 | Z4: 0 | AA4: 0 | AB4: 0 | AC4: 0 | AD4: 751148080 | AE4: 3.25 | AF4: 0 | AG4: 0 | AH4: 0 | AI4: 0 | AJ4: 0 | AK4: 0 | AL4: 0 | AM4: 0 | AN4: 0 | AO4: 0 | AP4: 0 | AQ4: 0 | AR4: 0 | AS4: 0 | AT4: 41.51 | AU4: 50 | AV4: 55.71 | AW4: 0
A5: 3 | B5: 46195 | C5: 300037 | D5: 이지스블루ON일반사모투자신탁제1호 | E5: 혼합자산 | F5: 1203.44 | G5: 2.935121 | H5: 16000000000 | I5: 0 | J5: 19254978427 | K5: 19254978427 | L5: 46961937 | M5: 19730253989 | N5: 19730253989 | O5: 102.47 | P5: 10366471510 | Q5: 53.84 | R5: 8444058500 | S5: 43.85 | T5: 0 | U5: 0 | V5: 168593615 | W5: 0.88 | X5: 0 | Y5: 0 | Z5: 0 | AA5: 0 | AB5: 0 | AC5: 0 | AD5: 751130364 | AE5: 3.9 | AF5: 0 | AG5: 0 | AH5: 0 | AI5: 0 | AJ5: 0 | AK5: 0 | AL5: 0 | AM5: 0 | AN5: 0 | AO5: 0 | AP5: 0 | AQ5: 0 | AR5: 0 | AS5: 0 | AT5: 53.84 | AU5: 100 | AV5: 43.85 | AW5: 100
A6: 4 | B6: 46195 | C6: 300039 | D6: 이지스멀티드래곤일반사모투자신탁제2호 | E6: 혼합자산 | F6: 1210.11 | G6: -1.859562 | H6: 20500000000 | I6: 0 | J6: 24807310177 | K6: 24807310177 | L6: -38121029 | M6: 24820846716 | N6: 24820846716 | O6: 100.05 | P6: 3075015 | Q6: 0.01 | R6: 0 | S6: 0 | T6: 0 | U6: 0 | V6: 5037759594 | W6: 20.31 | X6: 18775837109 | Y6: 75.69 | Z6: 0 | AA6: 0 | AB6: 0 | AC6: 0 | AD6: 1004174998 | AE6: 4.05 | AF6: 0 | AG6: 0 | AH6: 0 | AI6: 0 | AJ6: 0 | AK6: 0 | AL6: 0 | AM6: 0 | AN6: 0 | AO6: 0 | AP6: 0 | AQ6: 0 | AR6: 0 | AS6: 0 | AT6: 0.01 | AU6: 100 | AV6: 0 | AW6: 0
A7: 5 | B7: 46195 | C7: 300061 | D7: 이지스블랙ON일반사모투자신탁제1호 | E7: 혼합자산 | F7: 1424.4 | G7: 0.647788 | H7: 20200000000 | I7: 0 | J7: 28772819015 | K7: 28772819015 | L7: 13085318 | M7: 29023245129 | N7: 20609827345 | O7: 71.63 | P7: 15615587850 | Q7: 54.27 | R7: 3301089000 | S7: 11.47 | T7: 0 | U7: 0 | V7: 678182675 | W7: 2.36 | X7: 0 | Y7: 0 | Z7: -5565520000 | AA7: -19.34 | AB7: 0 | AC7: 0 | AD7: 1014967820 | AE7: 3.53 | AF7: 8452955572 | AG7: 29.38 | AH7: 0 | AI7: 0 | AJ7: 0 | AK7: 0 | AL7: 2807095338 | AM7: 9.76 | AN7: 5645860234 | AO7: 19.62 | AP7: 2695665141 | AQ7: 9.37 | AR7: 0 | AS7: 0 | AT7: 51.75 | AU7: 100 | AV7: 11.47 | AW7: 100
A8: 6 | B8: 46195 | C8: 300080 | D8: 이지스블루ON일반사모투자신탁제2호 | E8: 주식형 | F8: 961.72 | G8: -7.565498 | H8: 11462570654 | I8: 0 | J8: 11023784760 | K8: 11023784760 | L8: -86720057 | M8: 11141163150 | N8: 11141163150 | O8: 101.06 | P8: 10241041775 | Q8: 92.9 | R8: 0 | S8: 0 | T8: 0 | U8: 0 | V8: 738229547 | W8: 6.7 | X8: 0 | Y8: 0 | Z8: 0 | AA8: 0 | AB8: 0 | AC8: 0 | AD8: 161891828 | AE8: 1.47 | AF8: 0 | AG8: 0 | AH8: 0 | AI8: 0 | AJ8: 0 | AK8: 0 | AL8: 0 | AM8: 0 | AN8: 0 | AO8: 0 | AP8: 0 | AQ8: 0 | AR8: 0 | AS8: 0 | AT8: 92.9 | AU8: 0 | AV8: 0 | AW8: 0
A9: 7 | B9: 46195 | C9: 300085 | D9: 이지스블루ON일반사모투자신탁제3호 | E9: 재간접형 | F9: 1045.19 | G9: 3.326354 | H9: 20097833000 | I9: 0 | J9: 21006083219 | K9: 21006083219 | L9: 66852509 | M9: 21521542354 | N9: 21521542354 | O9: 102.45 | P9: 8947579300 | Q9: 42.6 | R9: 11558140000 | S9: 55.02 | T9: 0 | U9: 0 | V9: 264915390 | W9: 1.26 | X9: 0 | Y9: 0 | Z9: 0 | AA9: 0 | AB9: 0 | AC9: 0 | AD9: 750907664 | AE9: 3.57 | AF9: 0 | AG9: 0 | AH9: 0 | AI9: 0 | AJ9: 0 | AK9: 0 | AL9: 0 | AM9: 0 | AN9: 0 | AO9: 0 | AP9: 0 | AQ9: 0 | AR9: 0 | AS9: 0 | AT9: 42.6 | AU9: 50 | AV9: 55.02 | AW9: 0
A10: 8 | B10: 46195 | C10: 300090 | D10: 이지스그린ON일반사모투자신탁제5호 | E10: 재간접형 | F10: 1023.94 | G10: -0.81189 | H10: 11719638270 | I10: 0 | J10: 12000154078 | K10: 12000154078 | L10: -9515054 | M10: 12908708189 | N10: 12908708189 | O10: 107.57 | P10: 5547876970 | Q10: 46.23 | R10: 6113932000 | S10: 50.95 | T10: 0 | U10: 0 | V10: 305619225 | W10: 2.55 | X10: 0 | Y10: 0 | Z10: 0 | AA10: 0 | AB10: 0 | AC10: 0 | AD10: 941279994 | AE10: 7.84 | AF10: 0 | AG10: 0 | AH10: 0 | AI10: 0 | AJ10: 0 | AK10: 0 | AL10: 0 | AM10: 0 | AN10: 0 | AO10: 0 | AP10: 0 | AQ10: 0 | AR10: 0 | AS10: 0 | AT10: 46.23 | AU10: 50 | AV10: 50.95 | AW10: 0
A11: 9 | B11: 46195 | C11: 300091 | D11: 이지스블루ON일반사모투자신탁제4호 | E11: 혼합자산 | F11: 1000.81 | G11: 0.770365 | H11: 5000000000 | I11: 0 | J11: 5004056272 | K11: 5004056272 | L11: 3851827 | M11: 8674761917 | N11: 8674761917 | O11: 173.35 | P11: 703390000 | Q11: 14.06 | R11: 2970550000 | S11: 59.36 | T11: 0 | U11: 0 | V11: 5000821917 | W11: 99.94 | X11: 0 | Y11: 0 | Z11: 0 | AA11: 0 | AB11: 0 | AC11: 0 | AD11: 0 | AE11: 0 | AF11: 0 | AG11: 0 | AH11: 0 | AI11: 0 | AJ11: 0 | AK11: 0 | AL11: 0 | AM11: 0 | AN11: 0 | AO11: 0 | AP11: 0 | AQ11: 0 | AR11: 0 | AS11: 0 | AT11: 14.06 | AU11: 0 | AV11: 59.36 | AW11: 0
