Workbook

Sheet MP
A1: Model Portfolio | D1: 전체 AUM (NAV) | F1: =VLOOKUP("300019",아이타스41718_편드편입비정보!$C:$AX,8,FALSE)/100000000 -> 216.87303 | J1: =VLOOKUP("300037",아이타스41718_편드편입비정보!$C:$AX,8,FALSE)/100000000 -> 182.49125 | N1: =VLOOKUP("300085",아이타스41718_편드편입비정보!$C:$AX,8,FALSE)/100000000 -> 196.78827 | R1: =VLOOKUP("300091",아이타스41718_편드편입비정보!$C:$AX,8,FALSE)/100000000 -> 47.834952 | V1: 주식수 계산기 | W1: 비중 | X1: 종목명 | Y1: 인컴2 주식수 | Z1: 블루1 주식수 | AA1: 블루3 주식수 | AB1: 현재가
A2: <파란글자만 key in> | D2: 채권 비중 | F2: =VLOOKUP("300019", 아이타스41718_편드편입비정보!$C:$AX, 16, FALSE)/100000000 -> 128.38331 | J2: =VLOOKUP("300037", 아이타스41718_편드편입비정보!$C:$AX, 16, FALSE)/100000000 -> 84.597055 | N2: =VLOOKUP("300085", 아이타스41718_편드편입비정보!$C:$AX, 16, FALSE)/100000000 -> 115.6991 | R2: =VLOOKUP("300091", 아이타스41718_편드편입비정보!$C:$AX, 16, FALSE)/100000000 -> 29.73575 | W2: 0.02 | X2: KODEX 레버리지 | Y2: =IF(OR($W$2="",$X$2="",$AB$2="",$AB$2=0),"",ROUND($W$2*F4*100000000/$AB$2,0)) -> 192 | Z2: =IF(OR($W$2="",$X$2="",$AB$2="",$AB$2=0),"",ROUND($W$2*J4*100000000/$AB$2,0)) -> 196 | AA2: =IF(OR($W$2="",$X$2="",$AB$2="",$AB$2=0),"",ROUND($W$2*N4*100000000/$AB$2,0)) -> 187 | AB2: 130000
A3: =COUNT(A7:A60) -> 34 | B3: 종목 | C3: =B70 -> 1.02 | D3: 주식 가능금액 (현금포함) | F3: =F1-F2-F69 -> 83.323716 | G3: =F70 -> 80.1512 | H3: 현금 비중 | J3: =J1-J2-J69 -> 85.104899 | K3: =J70 -> 80.83534 | L3: 현금 비중 | N3: =N1-N2-N69 -> 81.089173 | O3: =N70 -> 79.494935 | P3: 현금 비중 | R3: =R1-R2-R69 -> 16.275602 | S3: =R70 -> 14.381865 | T3: 현금 비중 | W3: > key in | AB3: =IF($X$2="","",IFERROR(INDEX(인컴2!L:L,MATCH($X$2,인컴2!E:E,0)),IFERROR(INDEX(블루1!L:L,MATCH($X$2,블루1!E:E,0)),IFERROR(INDEX(블루3!L:L,MATCH($X$2,블루3!E:E,0)),"")))) | AC3: > 현재가 함수
D4: 현금 목표금액 (Risk off 시 20%) | E4: 0.15 | F4: =F3*($E$4) -> 12.498557 | G4: =F3-G3 -> 3.1725155 | H4: =(F3-G3)/F3 -> 0.03807458 | J4: =J3*($E$4) -> 12.765735 | K4: =J3-K3 -> 4.2695591 | L4: =(J3-K3)/J3 -> 0.050168194 | N4: =N3*($E$4) -> 12.163376 | O4: =N3-O3 -> 1.594238 | P4: =(N3-O3)/N3 -> 0.019660306 | R4: =R3*($E$4) -> 2.4413404 | S4: =R3-S3 -> 1.8937373 | T4: =(R3-S3)/R3 -> 0.11635436
A5: No | B5: 섹터 | C5: 세부 | D5: 종목명 | E5: 목표 | F5: 인컴2 | J5: 블루1 | N5: 블루3 | R5: 블루4 | V5: 종목명(원본) > 종목명 채우면 자동 매핑 | W5: 현재가
F6: 평가 | G6: 비중 | H6: diff. | I6: 수익률 | J6: 평가금액 | K6: 비중 | L6: 목표 차이 | M6: 수익률 | N6: 평가금액 | O6: 비중 | P6: 목표 차이 | Q6: 수익률 | R6: 평가금액 | S6: 비중 | T6: 목표 차이 | U6: 수익률 | Y6: 누락 종목 필터링
A7: 1 | B7: 테크 | C7: 반도체 | D7: =IF(V7="","",IFERROR(INDEX(인컴2!E:E,MATCH(V7,인컴2!E:E,0)),IFERROR(INDEX(블루1!E:E,MATCH(V7,블루1!E:E,0)),IFERROR(INDEX(블루3!E:E,MATCH(V7,블루3!E:E,0)),V7)))) -> RISE 네트워크인프라 | E7: 0.15 | F7: =IF($D7="","",SUMIF(인컴2!$E:$E,$D7,인컴2!$N:$N)/100000000) -> 12.71685 | G7: =IFERROR(F7/F$3, "") -> 0.15261981 | H7: =IFERROR(IF(F7>0,($E7-G7)*G$3*100000000/$W7,""),"") -> -280.70486 | I7: =IFERROR(INDEX(인컴2!$Q:$Q,MATCH($D7,인컴2!$E:$E,0))/100,"") -> 0.1849 | J7: =IF($D7="","",SUMIF(블루1!$E:$E,$D7,블루1!$N:$N)/100000000) -> 12.7347 | K7: =IFERROR(J7/J$3, "") -> 0.14963533 | L7: =IFERROR(IF(J7>0,($E7-K7)*K$3*100000000/$W7,""),"") -> 39.40632 | M7: =IFERROR(INDEX(블루1!$Q:$Q,MATCH($D7,블루1!$E:$E,0))/100,"") -> 0.1865 | N7: =IF($D7="","",SUMIF(블루3!$E:$E,$D7,블루3!$N:$N)/100000000) -> 12.7347 | O7: =IFERROR(N7/N$3, "") -> 0.15704563 | P7: =IFERROR(IF(N7>0,($E7-O7)*O$3*100000000/$W7,""),"") -> -748.73558 | Q7: =IFERROR(INDEX(블루3!$Q:$Q,MATCH($D7,블루3!$E:$E,0))/100,"") -> 0.1864 | R7: =IF($D7="","",SUMIF(블루4!$E:$E,$D7,블루4!$N:$N)/100000000) -> 0 | S7: =IFERROR(R7/R$3, "") -> 0 | T7: =IFERROR(IF(R7>0,($E7-S7)*S$3*100000000/$W7,""),"") | U7: =IFERROR(INDEX(블루4!$Q:$Q,MATCH($D7,블루4!$E:$E,0))/100,"") | V7: RISE 네트워크인프라 | W7: =IFERROR(INDEX(인컴2!$E$1:$Q$47, MATCH(V7, 인컴2!E:E, 0), 8), "") -> 74805 | Y7: {=_xlfn.LET(_xlpm.a,_xlfn._xlws.FILTER(인컴2!E$3:E$500,인컴2!E$3:E$500<>""),_xlpm.b,_xlfn._xlws.FILTER(블루1!E$3:E$500,블루1!E$3:E$500<>""),_xlpm.c,_xlfn._xlws.FILTER(블루3!E$3:E$500,블루3!E$3:E$500<>""),_xlpm.d,_xlfn._xlws.FILTER(블루4!E$3:E$500,블루4!E$3:E$500<>""),_xlpm.all,_xlfn.UNIQUE(_xlfn.VSTACK(_xlpm.a,_xlpm.b,_xlpm.c,_xlpm.d)),IFERROR(_xlfn._xlws.SORT(_xlfn._xlws.FILTER(_xlpm.all,COUNTIF($D$7:$D$68,_xlpm.all)=0)),"누락 종목 없음"))} -> RF머트리얼즈
A8: 2 | B8: =SUM(E7:E23) -> 0.625 | C8: 반도체 | D8: =IF(V8="","",IFERROR(INDEX(인컴2!E:E,MATCH(V8,인컴2!E:E,0)),IFERROR(INDEX(블루1!E:E,MATCH(V8,블루1!E:E,0)),IFERROR(INDEX(블루3!E:E,MATCH(V8,블루3!E:E,0)),V8)))) -> 삼성전자 | E8: 0.04 | F8: =IF($D8="","",SUMIF(인컴2!$E:$E,$D8,인컴2!$N:$N)/100000000) -> 3.185 | G8: =IFERROR(F8/F$3, "") -> 0.038224412 | H8: =IFERROR(IF(F8>0,($E8-G8)*G$3*100000000/$W8,""),"") -> 44.683058 | I8: =IFERROR(INDEX(인컴2!$Q:$Q,MATCH($D8,인컴2!$E:$E,0))/100,"") -> -0.1142 | J8: =IF($D8="","",SUMIF(블루1!$E:$E,$D8,블루1!$N:$N)/100000000) -> 3.165 | K8: =IFERROR(J8/J$3, "") -> 0.037189398 | L8: =IFERROR(IF(J8>0,($E8-K8)*K$3*100000000/$W8,""),"") -> 71.333103 | M8: =IFERROR(INDEX(블루1!$Q:$Q,MATCH($D8,블루1!$E:$E,0))/100,"") -> -0.1197 | N8: =IF($D8="","",SUMIF(블루3!$E:$E,$D8,블루3!$N:$N)/100000000) -> 3.165 | O8: =IFERROR(N8/N$3, "") -> 0.039031105 | P8: =IFERROR(IF(N8>0,($E8-O8)*O$3*100000000/$W8,""),"") -> 24.182816 | Q8: =IFERROR(INDEX(블루3!$Q:$Q,MATCH($D8,블루3!$E:$E,0))/100,"") -> -0.1203 | R8: =IF($D8="","",SUMIF(블루4!$E:$E,$D8,블루4!$N:$N)/100000000) -> 2.532 | S8: =IFERROR(R8/R$3, "") -> 0.15557028 | T8: =IFERROR(IF(R8>0,($E8-S8)*S$3*100000000/$W8,""),"") -> -521.8575 | U8: =IFERROR(INDEX(블루4!$Q:$Q,MATCH($D8,블루4!$E:$E,0))/100,"") -> -0.1154 | V8: 삼성전자 | W8: =IFERROR(INDEX(인컴2!$E$1:$Q$47, MATCH(V8, 인컴2!E:E, 0), 8), "") -> 318500 | Y8: SOL 초단기채권액티브
A9: 3 | C9: 반도체 | D9: =IF(V9="","",IFERROR(INDEX(인컴2!E:E,MATCH(V9,인컴2!E:E,0)),IFERROR(INDEX(블루1!E:E,MATCH(V9,블루1!E:E,0)),IFERROR(INDEX(블루3!E:E,MATCH(V9,블루3!E:E,0)),V9)))) -> SK하이닉스 | E9: 0.04 | F9: =IF($D9="","",SUMIF(인컴2!$E:$E,$D9,인컴2!$N:$N)/100000000) -> 1.217 | G9: =IFERROR(F9/F$3, "") -> 0.014605686 | H9: =IFERROR(IF(F9>0,($E9-G9)*G$3*100000000/$W9,""),"") -> 83.623039 | I9: =IFERROR(INDEX(인컴2!$Q:$Q,MATCH($D9,인컴2!$E:$E,0))/100,"") -> 0.0833 | J9: =IF($D9="","",SUMIF(블루1!$E:$E,$D9,블루1!$N:$N)/100000000) -> 1.2145 | K9: =IFERROR(J9/J$3, "") -> 0.014270624 | L9: =IFERROR(IF(J9>0,($E9-K9)*K$3*100000000/$W9,""),"") -> 85.449584 | M9: =IFERROR(INDEX(블루1!$Q:$Q,MATCH($D9,블루1!$E:$E,0))/100,"") -> 0.0811 | N9: =IF($D9="","",SUMIF(블루3!$E:$E,$D9,블루3!$N:$N)/100000000) -> 1.2145 | O9: =IFERROR(N9/N$3, "") -> 0.014977339 | P9: =IFERROR(IF(N9>0,($E9-O9)*O$3*100000000/$W9,""),"") -> 81.724521 | Q9: =IFERROR(INDEX(블루3!$Q:$Q,MATCH($D9,블루3!$E:$E,0))/100,"") -> 0.0811 | R9: =IF($D9="","",SUMIF(블루4!$E:$E,$D9,블루4!$N:$N)/100000000) -> 1.9432 | S9: =IFERROR(R9/R$3, "") -> 0.11939343 | T9: =IFERROR(IF(R9>0,($E9-S9)*S$3*100000000/$W9,""),"") -> -46.911487 | U9: =IFERROR(INDEX(블루4!$Q:$Q,MATCH($D9,블루4!$E:$E,0))/100,"") -> -0.1302 | V9: SK하이닉스 | W9: =IFERROR(INDEX(인컴2!$E$1:$Q$47, MATCH(V9, 인컴2!E:E, 0), 8), "") -> 2434000 | Y9: 레몬헬스케어
A10: 4 | C10: 반도체 | D10: =IF(V10="","",IFERROR(INDEX(인컴2!E:E,MATCH(V10,인컴2!E:E,0)),IFERROR(INDEX(블루1!E:E,MATCH(V10,블루1!E:E,0)),IFERROR(INDEX(블루3!E:E,MATCH(V10,블루3!E:E,0)),V10)))) -> SK스퀘어 | E10: 0.02 | F10: =IF($D10="","",SUMIF(인컴2!$E:$E,$D10,인컴2!$N:$N)/100000000) -> 1.8249 | G10: =IFERROR(F10/F$3, "") -> 0.021901328 | H10: =IFERROR(IF(F10>0,($E10-G10)*G$3*100000000/$W10,""),"") -> -9.1858769 | I10: =IFERROR(INDEX(인컴2!$Q:$Q,MATCH($D10,인컴2!$E:$E,0))/100,"") -> -0.1374 | J10: =IF($D10="","",SUMIF(블루1!$E:$E,$D10,블루1!$N:$N)/100000000) -> 1.8073 | K10: =IFERROR(J10/J$3, "") -> 0.021236145 | L10: =IFERROR(IF(J10>0,($E10-K10)*K$3*100000000/$W10,""),"") -> -6.0231599 | M10: =IFERROR(INDEX(블루1!$Q:$Q,MATCH($D10,블루1!$E:$E,0))/100,"") -> -0.145 | N10: =IF($D10="","",SUMIF(블루3!$E:$E,$D10,블루3!$N:$N)/100000000) -> 1.8073 | O10: =IFERROR(N10/N$3, "") -> 0.022287809 | P10: =IFERROR(IF(N10>0,($E10-O10)*O$3*100000000/$W10,""),"") -> -10.962582 | Q10: =IFERROR(INDEX(블루3!$Q:$Q,MATCH($D10,블루3!$E:$E,0))/100,"") -> -0.1451 | R10: =IF($D10="","",SUMIF(블루4!$E:$E,$D10,블루4!$N:$N)/100000000) -> 0.8215 | S10: =IFERROR(R10/R$3, "") -> 0.050474322 | T10: =IFERROR(IF(R10>0,($E10-S10)*S$3*100000000/$W10,""),"") -> -26.418179 | U10: =IFERROR(INDEX(블루4!$Q:$Q,MATCH($D10,블루4!$E:$E,0))/100,"") -> -0.1224 | V10: SK스퀘어 | W10: =IFERROR(INDEX(인컴2!$E$1:$Q$47, MATCH(V10, 인컴2!E:E, 0), 8), "") -> 1659000 | Y10: 메쥬
A11: 5 | C11: MLCC | D11: =IF(V11="","",IFERROR(INDEX(인컴2!E:E,MATCH(V11,인컴2!E:E,0)),IFERROR(INDEX(블루1!E:E,MATCH(V11,블루1!E:E,0)),IFERROR(INDEX(블루3!E:E,MATCH(V11,블루3!E:E,0)),V11)))) -> 삼성전기우 | E11: 0.02 | F11: =IF($D11="","",SUMIF(인컴2!$E:$E,$D11,인컴2!$N:$N)/100000000) -> 1.6725 | G11: =IFERROR(F11/F$3, "") -> 0.020072317 | H11: =IFERROR(IF(F11>0,($E11-G11)*G$3*100000000/$W11,""),"") -> -0.8664072 | I11: =IFERROR(INDEX(인컴2!$Q:$Q,MATCH($D11,인컴2!$E:$E,0))/100,"") -> -0.2594 | J11: =IF($D11="","",SUMIF(블루1!$E:$E,$D11,블루1!$N:$N)/100000000) -> 1.6725 | K11: =IFERROR(J11/J$3, "") -> 0.019652218 | L11: =IFERROR(IF(J11>0,($E11-K11)*K$3*100000000/$W11,""),"") -> 4.2022577 | M11: =IFERROR(INDEX(블루1!$Q:$Q,MATCH($D11,블루1!$E:$E,0))/100,"") -> -0.2594 | N11: =IF($D11="","",SUMIF(블루3!$E:$E,$D11,블루3!$N:$N)/100000000) -> 1.6725 | O11: =IFERROR(N11/N$3, "") -> 0.020625442 | P11: =IFERROR(IF(N11>0,($E11-O11)*O$3*100000000/$W11,""),"") -> -7.431904 | Q11: =IFERROR(INDEX(블루3!$Q:$Q,MATCH($D11,블루3!$E:$E,0))/100,"") -> -0.2598 | R11: =IF($D11="","",SUMIF(블루4!$E:$E,$D11,블루4!$N:$N)/100000000) -> 1.6725 | S11: =IFERROR(R11/R$3, "") -> 0.10276117 | T11: =IFERROR(IF(R11>0,($E11-S11)*S$3*100000000/$W11,""),"") -> -177.9163 | U11: =IFERROR(INDEX(블루4!$Q:$Q,MATCH($D11,블루4!$E:$E,0))/100,"") -> -0.2594 | V11: 삼성전기우 | W11: =IFERROR(INDEX(인컴2!$E$1:$Q$47, MATCH(V11, 인컴2!E:E, 0), 8), "") -> 669000 | Y11: 아이엠바이오로직스
A12: 6 | C12: 소부장 | D12: =IF(V12="","",IFERROR(INDEX(인컴2!E:E,MATCH(V12,인컴2!E:E,0)),IFERROR(INDEX(블루1!E:E,MATCH(V12,블루1!E:E,0)),IFERROR(INDEX(블루3!E:E,MATCH(V12,블루3!E:E,0)),V12)))) -> HANARO 반도체핵심공정주도주 | E12: 0.035 | F12: =IF($D12="","",SUMIF(인컴2!$E:$E,$D12,인컴2!$N:$N)/100000000) -> 2.24925 | G12: =IFERROR(F12/F$3, "") -> 0.026994115 | H12: =IFERROR(IF(F12>0,($E12-G12)*G$3*100000000/$W12,""),"") -> 4279.3014 | I12: =IFERROR(INDEX(인컴2!$Q:$Q,MATCH($D12,인컴2!$E:$E,0))/100,"") -> 0.0032 | J12: =IF($D12="","",SUMIF(블루1!$E:$E,$D12,블루1!$N:$N)/100000000) -> 2.24175 | K12: =IFERROR(J12/J$3, "") -> 0.026341022 | L12: =IFERROR(IF(J12>0,($E12-K12)*K$3*100000000/$W12,""),"") -> 4667.899 | M12: =IFERROR(INDEX(블루1!$Q:$Q,MATCH($D12,블루1!$E:$E,0))/100,"") -> 0 | N12: =IF($D12="","",SUMIF(블루3!$E:$E,$D12,블루3!$N:$N)/100000000) -> 2.24175 | O12: =IFERROR(N12/N$3, "") -> 0.027645491 | P12: =IFERROR(IF(N12>0,($E12-O12)*O$3*100000000/$W12,""),"") -> 3898.9411 | Q12: =IFERROR(INDEX(블루3!$Q:$Q,MATCH($D12,블루3!$E:$E,0))/100,"") -> -0.0002 | R12: =IF($D12="","",SUMIF(블루4!$E:$E,$D12,블루4!$N:$N)/100000000) -> 0 | S12: =IFERROR(R12/R$3, "") -> 0 | T12: =IFERROR(IF(R12>0,($E12-S12)*S$3*100000000/$W12,""),"") | U12: =IFERROR(INDEX(블루4!$Q:$Q,MATCH($D12,블루4!$E:$E,0))/100,"") | V12: HANARO 반도체핵심공정주도주 | W12: =IFERROR(INDEX(인컴2!$E$1:$Q$47, MATCH(V12, 인컴2!E:E, 0), 8), "") -> 14995 | Y12: 져스텍
A13: 7 | C13: 소부장 | D13: =IF(V13="","",IFERROR(INDEX(인컴2!E:E,MATCH(V13,인컴2!E:E,0)),IFERROR(INDEX(블루1!E:E,MATCH(V13,블루1!E:E,0)),IFERROR(INDEX(블루3!E:E,MATCH(V13,블루3!E:E,0)),V13)))) -> SOL 반도체전공정 | E13: 0.035 | F13: =IF($D13="","",SUMIF(인컴2!$E:$E,$D13,인컴2!$N:$N)/100000000) -> 2.442 | G13: =IFERROR(F13/F$3, "") -> 0.029307382 | H13: =IFERROR(IF(F13>0,($E13-G13)*G$3*100000000/$W13,""),"") -> 1868.428 | I13: =IFERROR(INDEX(인컴2!$Q:$Q,MATCH($D13,인컴2!$E:$E,0))/100,"") -> -0.0229 | J13: =IF($D13="","",SUMIF(블루1!$E:$E,$D13,블루1!$N:$N)/100000000) -> 2.4405 | K13: =IFERROR(J13/J$3, "") -> 0.028676375 | L13: =IFERROR(IF(J13>0,($E13-K13)*K$3*100000000/$W13,""),"") -> 2093.253 | M13: =IFERROR(INDEX(블루1!$Q:$Q,MATCH($D13,블루1!$E:$E,0))/100,"") -> -0.0235 | N13: =IF($D13="","",SUMIF(블루3!$E:$E,$D13,블루3!$N:$N)/100000000) -> 2.4405 | O13: =IFERROR(N13/N$3, "") -> 0.030096496 | P13: =IFERROR(IF(N13>0,($E13-O13)*O$3*100000000/$W13,""),"") -> 1596.2478 | Q13: =IFERROR(INDEX(블루3!$Q:$Q,MATCH($D13,블루3!$E:$E,0))/100,"") -> -0.0237 | R13: =IF($D13="","",SUMIF(블루4!$E:$E,$D13,블루4!$N:$N)/100000000) -> 0 | S13: =IFERROR(R13/R$3, "") -> 0 | T13: =IFERROR(IF(R13>0,($E13-S13)*S$3*100000000/$W13,""),"") | U13: =IFERROR(INDEX(블루4!$Q:$Q,MATCH($D13,블루4!$E:$E,0))/100,"") | V13: SOL 반도체전공정 | W13: =IFERROR(INDEX(인컴2!$E$1:$Q$47, MATCH(V13, 인컴2!E:E, 0), 8), "") -> 24420 | Y13: 코스모로보틱스
A14: 8 | C14: 소부장 | D14: =IF(V14="","",IFERROR(INDEX(인컴2!E:E,MATCH(V14,인컴2!E:E,0)),IFERROR(INDEX(블루1!E:E,MATCH(V14,블루1!E:E,0)),IFERROR(INDEX(블루3!E:E,MATCH(V14,블루3!E:E,0)),V14)))) -> SOL 반도체후공정 | E14: 0.035 | F14: =IF($D14="","",SUMIF(인컴2!$E:$E,$D14,인컴2!$N:$N)/100000000) -> 1.90505 | G14: =IFERROR(F14/F$3, "") -> 0.022863239 | H14: =IFERROR(IF(F14>0,($E14-G14)*G$3*100000000/$W14,""),"") -> 3574.4111 | I14: =IFERROR(INDEX(인컴2!$Q:$Q,MATCH($D14,인컴2!$E:$E,0))/100,"") -> -0.1793 | J14: =IF($D14="","",SUMIF(블루1!$E:$E,$D14,블루1!$N:$N)/100000000) -> 1.904 | K14: =IFERROR(J14/J$3, "") -> 0.02237239 | L14: =IFERROR(IF(J14>0,($E14-K14)*K$3*100000000/$W14,""),"") -> 3750.7152 | M14: =IFERROR(INDEX(블루1!$Q:$Q,MATCH($D14,블루1!$E:$E,0))/100,"") -> -0.1798 | N14: =IF($D14="","",SUMIF(블루3!$E:$E,$D14,블루3!$N:$N)/100000000) -> 1.904 | O14: =IFERROR(N14/N$3, "") -> 0.023480323 | P14: =IFERROR(IF(N14>0,($E14-O14)*O$3*100000000/$W14,""),"") -> 3364.8942 | Q14: =IFERROR(INDEX(블루3!$Q:$Q,MATCH($D14,블루3!$E:$E,0))/100,"") -> -0.1801 | R14: =IF($D14="","",SUMIF(블루4!$E:$E,$D14,블루4!$N:$N)/100000000) -> 0 | S14: =IFERROR(R14/R$3, "") -> 0 | T14: =IFERROR(IF(R14>0,($E14-S14)*S$3*100000000/$W14,""),"") | U14: =IFERROR(INDEX(블루4!$Q:$Q,MATCH($D14,블루4!$E:$E,0))/100,"") | V14: SOL 반도체후공정 | W14: =IFERROR(INDEX(인컴2!$E$1:$Q$47, MATCH(V14, 인컴2!E:E, 0), 8), "") -> 27215 | Y14: 폴레드
A15: 9 | C15: 중국 테크 | D15: =IF(V15="","",IFERROR(INDEX(인컴2!E:E,MATCH(V15,인컴2!E:E,0)),IFERROR(INDEX(블루1!E:E,MATCH(V15,블루1!E:E,0)),IFERROR(INDEX(블루3!E:E,MATCH(V15,블루3!E:E,0)),V15)))) -> TIME 차이나AI테크액티브 | E15: 0.035 | F15: =IF($D15="","",SUMIF(인컴2!$E:$E,$D15,인컴2!$N:$N)/100000000) -> 3.4047 | G15: =IFERROR(F15/F$3, "") -> 0.040861116 | H15: =IFERROR(IF(F15>0,($E15-G15)*G$3*100000000/$W15,""),"") -> -1793.7208 | I15: =IFERROR(INDEX(인컴2!$Q:$Q,MATCH($D15,인컴2!$E:$E,0))/100,"") -> 0.3466 | J15: =IF($D15="","",SUMIF(블루1!$E:$E,$D15,블루1!$N:$N)/100000000) -> 2.8864 | K15: =IFERROR(J15/J$3, "") -> 0.033915791 | L15: =IFERROR(IF(J15>0,($E15-K15)*K$3*100000000/$W15,""),"") -> 334.64061 | M15: =IFERROR(INDEX(블루1!$Q:$Q,MATCH($D15,블루1!$E:$E,0))/100,"") -> 0.2246 | N15: =IF($D15="","",SUMIF(블루3!$E:$E,$D15,블루3!$N:$N)/100000000) -> 2.8864 | O15: =IFERROR(N15/N$3, "") -> 0.035595381 | P15: =IFERROR(IF(N15>0,($E15-O15)*O$3*100000000/$W15,""),"") -> -180.71694 | Q15: =IFERROR(INDEX(블루3!$Q:$Q,MATCH($D15,블루3!$E:$E,0))/100,"") -> 0.2231 | R15: =IF($D15="","",SUMIF(블루4!$E:$E,$D15,블루4!$N:$N)/100000000) -> 0 | S15: =IFERROR(R15/R$3, "") -> 0 | T15: =IFERROR(IF(R15>0,($E15-S15)*S$3*100000000/$W15,""),"") | U15: =IFERROR(INDEX(블루4!$Q:$Q,MATCH($D15,블루4!$E:$E,0))/100,"") | V15: TIME 차이나AI테크액티브 | W15: =IFERROR(INDEX(인컴2!$E$1:$Q$47, MATCH(V15, 인컴2!E:E, 0), 8), "") -> 26190
A16: 10 | C16: 미국 테크 | D16: =IF(V16="","",IFERROR(INDEX(인컴2!E:E,MATCH(V16,인컴2!E:E,0)),IFERROR(INDEX(블루1!E:E,MATCH(V16,블루1!E:E,0)),IFERROR(INDEX(블루3!E:E,MATCH(V16,블루3!E:E,0)),V16)))) -> HANARO 미국AI메모리반도체TOP4+ | E16: 0.03 | F16: =IF($D16="","",SUMIF(인컴2!$E:$E,$D16,인컴2!$N:$N)/100000000) -> 2.32915 | G16: =IFERROR(F16/F$3, "") -> 0.027953026 | H16: =IFERROR(IF(F16>0,($E16-G16)*G$3*100000000/$W16,""),"") -> 1303.1565 | I16: =IFERROR(INDEX(인컴2!$Q:$Q,MATCH($D16,인컴2!$E:$E,0))/100,"") -> 0.0309 | J16: =IF($D16="","",SUMIF(블루1!$E:$E,$D16,블루1!$N:$N)/100000000) -> 2.32545 | K16: =IFERROR(J16/J$3, "") -> 0.027324514 | L16: =IFERROR(IF(J16>0,($E16-K16)*K$3*100000000/$W16,""),"") -> 1717.8223 | M16: =IFERROR(INDEX(블루1!$Q:$Q,MATCH($D16,블루1!$E:$E,0))/100,"") -> 0.0292 | N16: =IF($D16="","",SUMIF(블루3!$E:$E,$D16,블루3!$N:$N)/100000000) -> 2.32545 | O16: =IFERROR(N16/N$3, "") -> 0.028677688 | P16: =IFERROR(IF(N16>0,($E16-O16)*O$3*100000000/$W16,""),"") -> 834.92541 | Q16: =IFERROR(INDEX(블루3!$Q:$Q,MATCH($D16,블루3!$E:$E,0))/100,"") -> 0.029 | R16: =IF($D16="","",SUMIF(블루4!$E:$E,$D16,블루4!$N:$N)/100000000) -> 0 | S16: =IFERROR(R16/R$3, "") -> 0 | T16: =IFERROR(IF(R16>0,($E16-S16)*S$3*100000000/$W16,""),"") | U16: =IFERROR(INDEX(블루4!$Q:$Q,MATCH($D16,블루4!$E:$E,0))/100,"") | V16: HANARO 미국AI메모리반도체TOP4+ | W16: =IFERROR(INDEX(인컴2!$E$1:$Q$47, MATCH(V16, 인컴2!E:E, 0), 8), "") -> 12590
A17: 11 | C17: 미국 테크 | D17: =IF(V17="","",IFERROR(INDEX(인컴2!E:E,MATCH(V17,인컴2!E:E,0)),IFERROR(INDEX(블루1!E:E,MATCH(V17,블루1!E:E,0)),IFERROR(INDEX(블루3!E:E,MATCH(V17,블루3!E:E,0)),V17)))) -> ACE 글로벌AI맞춤형반도체 | E17: 0.03 | F17: =IF($D17="","",SUMIF(인컴2!$E:$E,$D17,인컴2!$N:$N)/100000000) -> 2.0132 | G17: =IFERROR(F17/F$3, "") -> 0.024161189 | H17: =IFERROR(IF(F17>0,($E17-G17)*G$3*100000000/$W17,""),"") -> 1859.6771 | I17: =IFERROR(INDEX(인컴2!$Q:$Q,MATCH($D17,인컴2!$E:$E,0))/100,"") -> -0.0667 | J17: =IF($D17="","",SUMIF(블루1!$E:$E,$D17,블루1!$N:$N)/100000000) -> 2.0124 | K17: =IFERROR(J17/J$3, "") -> 0.023646112 | L17: =IFERROR(IF(J17>0,($E17-K17)*K$3*100000000/$W17,""),"") -> 2041.0041 | M17: =IFERROR(INDEX(블루1!$Q:$Q,MATCH($D17,블루1!$E:$E,0))/100,"") -> -0.0671 | N17: =IF($D17="","",SUMIF(블루3!$E:$E,$D17,블루3!$N:$N)/100000000) -> 2.0124 | O17: =IFERROR(N17/N$3, "") -> 0.024817123 | P17: =IFERROR(IF(N17>0,($E17-O17)*O$3*100000000/$W17,""),"") -> 1637.244 | Q17: =IFERROR(INDEX(블루3!$Q:$Q,MATCH($D17,블루3!$E:$E,0))/100,"") -> -0.0672 | R17: =IF($D17="","",SUMIF(블루4!$E:$E,$D17,블루4!$N:$N)/100000000) -> 0 | S17: =IFERROR(R17/R$3, "") -> 0 | T17: =IFERROR(IF(R17>0,($E17-S17)*S$3*100000000/$W17,""),"") | U17: =IFERROR(INDEX(블루4!$Q:$Q,MATCH($D17,블루4!$E:$E,0))/100,"") | V17: ACE 글로벌AI맞춤형반도체 | W17: =IFERROR(INDEX(인컴2!$E$1:$Q$47, MATCH(V17, 인컴2!E:E, 0), 8), "") -> 25165
A18: 12 | C18: 소부장 | D18: =IF(V18="","",IFERROR(INDEX(인컴2!E:E,MATCH(V18,인컴2!E:E,0)),IFERROR(INDEX(블루1!E:E,MATCH(V18,블루1!E:E,0)),IFERROR(INDEX(블루3!E:E,MATCH(V18,블루3!E:E,0)),V18)))) -> 싸이맥스 | E18: 0.045 | F18: =IF($D18="","",SUMIF(인컴2!$E:$E,$D18,인컴2!$N:$N)/100000000) -> 3.685 | G18: =IFERROR(F18/F$3, "") -> 0.044225104 | H18: =IFERROR(IF(F18>0,($E18-G18)*G$3*100000000/$W18,""),"") -> 168.54499 | I18: =IFERROR(INDEX(인컴2!$Q:$Q,MATCH($D18,인컴2!$E:$E,0))/100,"") -> 0.0603 | J18: =IF($D18="","",SUMIF(블루1!$E:$E,$D18,블루1!$N:$N)/100000000) -> 3.68 | K18: =IFERROR(J18/J$3, "") -> 0.043240754 | L18: =IFERROR(IF(J18>0,($E18-K18)*K$3*100000000/$W18,""),"") -> 385.91385 | M18: =IFERROR(INDEX(블루1!$Q:$Q,MATCH($D18,블루1!$E:$E,0))/100,"") -> 0.0588 | N18: =IF($D18="","",SUMIF(블루3!$E:$E,$D18,블루3!$N:$N)/100000000) -> 3.68 | O18: =IFERROR(N18/N$3, "") -> 0.045382138 | P18: =IFERROR(IF(N18>0,($E18-O18)*O$3*100000000/$W18,""),"") -> -82.436901 | Q18: =IFERROR(INDEX(블루3!$Q:$Q,MATCH($D18,블루3!$E:$E,0))/100,"") -> 0.0588 | R18: =IF($D18="","",SUMIF(블루4!$E:$E,$D18,블루4!$N:$N)/100000000) -> 0 | S18: =IFERROR(R18/R$3, "") -> 0 | T18: =IFERROR(IF(R18>0,($E18-S18)*S$3*100000000/$W18,""),"") | U18: =IFERROR(INDEX(블루4!$Q:$Q,MATCH($D18,블루4!$E:$E,0))/100,"") | V18: 싸이맥스 | W18: =IFERROR(INDEX(인컴2!$E$1:$Q$47, MATCH(V18, 인컴2!E:E, 0), 8), "") -> 36850
A19: 13 | C19: CCL | D19: =IF(V19="","",IFERROR(INDEX(인컴2!E:E,MATCH(V19,인컴2!E:E,0)),IFERROR(INDEX(블루1!E:E,MATCH(V19,블루1!E:E,0)),IFERROR(INDEX(블루3!E:E,MATCH(V19,블루3!E:E,0)),V19)))) -> 두산 | E19: 0.03 | F19: =IF($D19="","",SUMIF(인컴2!$E:$E,$D19,인컴2!$N:$N)/100000000) -> 2.5007 | G19: =IFERROR(F19/F$3, "") -> 0.030011864 | H19: =IFERROR(IF(F19>0,($E19-G19)*G$3*100000000/$W19,""),"") -> -0.064642873 | I19: =IFERROR(INDEX(인컴2!$Q:$Q,MATCH($D19,인컴2!$E:$E,0))/100,"") -> -0.0802 | J19: =IF($D19="","",SUMIF(블루1!$E:$E,$D19,블루1!$N:$N)/100000000) -> 2.4905 | K19: =IFERROR(J19/J$3, "") -> 0.029263885 | L19: =IFERROR(IF(J19>0,($E19-K19)*K$3*100000000/$W19,""),"") -> 4.0451453 | M19: =IFERROR(INDEX(블루1!$Q:$Q,MATCH($D19,블루1!$E:$E,0))/100,"") -> -0.084 | N19: =IF($D19="","",SUMIF(블루3!$E:$E,$D19,블루3!$N:$N)/100000000) -> 2.4905 | O19: =IFERROR(N19/N$3, "") -> 0.030713102 | P19: =IFERROR(IF(N19>0,($E19-O19)*O$3*100000000/$W19,""),"") -> -3.8537021 | Q19: =IFERROR(INDEX(블루3!$Q:$Q,MATCH($D19,블루3!$E:$E,0))/100,"") -> -0.084 | R19: =IF($D19="","",SUMIF(블루4!$E:$E,$D19,블루4!$N:$N)/100000000) -> 1.27455 | S19: =IFERROR(R19/R$3, "") -> 0.078310466 | T19: =IFERROR(IF(R19>0,($E19-S19)*S$3*100000000/$W19,""),"") -> -47.232807 | U19: =IFERROR(INDEX(블루4!$Q:$Q,MATCH($D19,블루4!$E:$E,0))/100,"") -> -0.0981 | V19: 두산 | W19: =IFERROR(INDEX(인컴2!$E$1:$Q$47, MATCH(V19, 인컴2!E:E, 0), 8), "") -> 1471000
A20: 14 | C20: 기판 | D20: =IF(V20="","",IFERROR(INDEX(인컴2!E:E,MATCH(V20,인컴2!E:E,0)),IFERROR(INDEX(블루1!E:E,MATCH(V20,블루1!E:E,0)),IFERROR(INDEX(블루3!E:E,MATCH(V20,블루3!E:E,0)),V20)))) -> 대덕전자 | E20: 0.02 | F20: =IF($D20="","",SUMIF(인컴2!$E:$E,$D20,인컴2!$N:$N)/100000000) -> 1.254 | G20: =IFERROR(F20/F$3, "") -> 0.015049737 | H20: =IFERROR(IF(F20>0,($E20-G20)*G$3*100000000/$W20,""),"") -> 316.40313 | I20: =IFERROR(INDEX(인컴2!$Q:$Q,MATCH($D20,인컴2!$E:$E,0))/100,"") -> -0.2909 | J20: =IF($D20="","",SUMIF(블루1!$E:$E,$D20,블루1!$N:$N)/100000000) -> 1.251 | K20: =IFERROR(J20/J$3, "") -> 0.014699506 | L20: =IFERROR(IF(J20>0,($E20-K20)*K$3*100000000/$W20,""),"") -> 341.68039 | M20: =IFERROR(INDEX(블루1!$Q:$Q,MATCH($D20,블루1!$E:$E,0))/100,"") -> -0.2926 | N20: =IF($D20="","",SUMIF(블루3!$E:$E,$D20,블루3!$N:$N)/100000000) -> 1.251 | O20: =IFERROR(N20/N$3, "") -> 0.01542746 | P20: =IFERROR(IF(N20>0,($E20-O20)*O$3*100000000/$W20,""),"") -> 289.86742 | Q20: =IFERROR(INDEX(블루3!$Q:$Q,MATCH($D20,블루3!$E:$E,0))/100,"") -> -0.2926 | R20: =IF($D20="","",SUMIF(블루4!$E:$E,$D20,블루4!$N:$N)/100000000) -> 0 | S20: =IFERROR(R20/R$3, "") -> 0 | T20: =IFERROR(IF(R20>0,($E20-S20)*S$3*100000000/$W20,""),"") | U20: =IFERROR(INDEX(블루4!$Q:$Q,MATCH($D20,블루4!$E:$E,0))/100,"") | V20: 대덕전자 | W20: =IFERROR(INDEX(인컴2!$E$1:$Q$47, MATCH(V20, 인컴2!E:E, 0), 8), "") -> 125400
A21: 15 | C21: 파운드리 | D21: =IF(V21="","",IFERROR(INDEX(인컴2!E:E,MATCH(V21,인컴2!E:E,0)),IFERROR(INDEX(블루1!E:E,MATCH(V21,블루1!E:E,0)),IFERROR(INDEX(블루3!E:E,MATCH(V21,블루3!E:E,0)),V21)))) -> DB하이텍 | E21: 0.02 | F21: =IF($D21="","",SUMIF(인컴2!$E:$E,$D21,인컴2!$N:$N)/100000000) -> 1.374 | G21: =IFERROR(F21/F$3, "") -> 0.016489903 | H21: =IFERROR(IF(F21>0,($E21-G21)*G$3*100000000/$W21,""),"") -> 245.71046 | I21: =IFERROR(INDEX(인컴2!$Q:$Q,MATCH($D21,인컴2!$E:$E,0))/100,"") -> -0.3733 | J21: =IF($D21="","",SUMIF(블루1!$E:$E,$D21,블루1!$N:$N)/100000000) -> 1.368 | K21: =IFERROR(J21/J$3, "") -> 0.01607428 | L21: =IFERROR(IF(J21>0,($E21-K21)*K$3*100000000/$W21,""),"") -> 277.15012 | M21: =IFERROR(INDEX(블루1!$Q:$Q,MATCH($D21,블루1!$E:$E,0))/100,"") -> -0.376 | N21: =IF($D21="","",SUMIF(블루3!$E:$E,$D21,블루3!$N:$N)/100000000) -> 1.368 | O21: =IFERROR(N21/N$3, "") -> 0.016870316 | P21: =IFERROR(IF(N21>0,($E21-O21)*O$3*100000000/$W21,""),"") -> 217.28734 | Q21: =IFERROR(INDEX(블루3!$Q:$Q,MATCH($D21,블루3!$E:$E,0))/100,"") -> -0.3761 | R21: =IF($D21="","",SUMIF(블루4!$E:$E,$D21,블루4!$N:$N)/100000000) -> 0 | S21: =IFERROR(R21/R$3, "") -> 0 | T21: =IFERROR(IF(R21>0,($E21-S21)*S$3*100000000/$W21,""),"") | U21: =IFERROR(INDEX(블루4!$Q:$Q,MATCH($D21,블루4!$E:$E,0))/100,"") | V21: DB하이텍 | W21: =IFERROR(INDEX(인컴2!$E$1:$Q$47, MATCH(V21, 인컴2!E:E, 0), 8), "") -> 114500
A22: 16 | C22: 소부장 | D22: =IF(V22="","",IFERROR(INDEX(인컴2!E:E,MATCH(V22,인컴2!E:E,0)),IFERROR(INDEX(블루1!E:E,MATCH(V22,블루1!E:E,0)),IFERROR(INDEX(블루3!E:E,MATCH(V22,블루3!E:E,0)),V22)))) -> 제주반도체 | E22: 0.02 | F22: =IF($D22="","",SUMIF(인컴2!$E:$E,$D22,인컴2!$N:$N)/100000000) -> 1.834 | G22: =IFERROR(F22/F$3, "") -> 0.02201054 | H22: =IFERROR(IF(F22>0,($E22-G22)*G$3*100000000/$W22,""),"") -> -175.73306 | I22: =IFERROR(INDEX(인컴2!$Q:$Q,MATCH($D22,인컴2!$E:$E,0))/100,"") -> -0.2232 | J22: =IF($D22="","",SUMIF(블루1!$E:$E,$D22,블루1!$N:$N)/100000000) -> 1.816 | K22: =IFERROR(J22/J$3, "") -> 0.021338372 | L22: =IFERROR(IF(J22>0,($E22-K22)*K$3*100000000/$W22,""),"") -> -117.98011 | M22: =IFERROR(INDEX(블루1!$Q:$Q,MATCH($D22,블루1!$E:$E,0))/100,"") -> -0.2307 | N22: =IF($D22="","",SUMIF(블루3!$E:$E,$D22,블루3!$N:$N)/100000000) -> 1.816 | O22: =IFERROR(N22/N$3, "") -> 0.022395098 | P22: =IFERROR(IF(N22>0,($E22-O22)*O$3*100000000/$W22,""),"") -> -207.63161 | Q22: =IFERROR(INDEX(블루3!$Q:$Q,MATCH($D22,블루3!$E:$E,0))/100,"") -> -0.2308 | R22: =IF($D22="","",SUMIF(블루4!$E:$E,$D22,블루4!$N:$N)/100000000) -> 0 | S22: =IFERROR(R22/R$3, "") -> 0 | T22: =IFERROR(IF(R22>0,($E22-S22)*S$3*100000000/$W22,""),"") | U22: =IFERROR(INDEX(블루4!$Q:$Q,MATCH($D22,블루4!$E:$E,0))/100,"") | V22: 제주반도체 | W22: =IFERROR(INDEX(인컴2!$E$1:$Q$47, MATCH(V22, 인컴2!E:E, 0), 8), "") -> 91700
A23: 17 | C23: 소부장 | D23: =IF(V23="","",IFERROR(INDEX(인컴2!E:E,MATCH(V23,인컴2!E:E,0)),IFERROR(INDEX(블루1!E:E,MATCH(V23,블루1!E:E,0)),IFERROR(INDEX(블루3!E:E,MATCH(V23,블루3!E:E,0)),V23)))) -> 에이직랜드 | E23: 0.02 | F23: =IF($D23="","",SUMIF(인컴2!$E:$E,$D23,인컴2!$N:$N)/100000000) -> 1.616 | G23: =IFERROR(F23/F$3, "") -> 0.019394238 | H23: =IFERROR(IF(F23>0,($E23-G23)*G$3*100000000/$W23,""),"") -> 240.35902 | I23: =IFERROR(INDEX(인컴2!$Q:$Q,MATCH($D23,인컴2!$E:$E,0))/100,"") -> -0.3403 | J23: =IF($D23="","",SUMIF(블루1!$E:$E,$D23,블루1!$N:$N)/100000000) -> 1.608 | K23: =IFERROR(J23/J$3, "") -> 0.018894329 | L23: =IFERROR(IF(J23>0,($E23-K23)*K$3*100000000/$W23,""),"") -> 442.46166 | M23: =IFERROR(INDEX(블루1!$Q:$Q,MATCH($D23,블루1!$E:$E,0))/100,"") -> -0.3436 | N23: =IF($D23="","",SUMIF(블루3!$E:$E,$D23,블루3!$N:$N)/100000000) -> 1.608 | O23: =IFERROR(N23/N$3, "") -> 0.019830021 | P23: =IFERROR(IF(N23>0,($E23-O23)*O$3*100000000/$W23,""),"") -> 66.893428 | Q23: =IFERROR(INDEX(블루3!$Q:$Q,MATCH($D23,블루3!$E:$E,0))/100,"") -> -0.3436 | R23: =IF($D23="","",SUMIF(블루4!$E:$E,$D23,블루4!$N:$N)/100000000) -> 0 | S23: =IFERROR(R23/R$3, "") -> 0 | T23: =IFERROR(IF(R23>0,($E23-S23)*S$3*100000000/$W23,""),"") | U23: =IFERROR(INDEX(블루4!$Q:$Q,MATCH($D23,블루4!$E:$E,0))/100,"") | V23: 에이직랜드 | W23: =IFERROR(INDEX(인컴2!$E$1:$Q$47, MATCH(V23, 인컴2!E:E, 0), 8), "") -> 20200
C24: 테크 소계 | E24: =SUM(E7:E23) -> 0.625 | F24: =SUM(F7:F23) -> 47.2233 | G24: =IFERROR(F24/F$3, "") -> 0.56674501 | J24: =SUM(J7:J23) -> 46.618 | K24: =IFERROR(J24/J$3, "") -> 0.54777105 | N24: =SUM(N7:N23) -> 46.618 | O24: =IFERROR(N24/N$3, "") -> 0.57489796 | R24: =SUM(R7:R23) -> 8.24375 | S24: =IFERROR(R24/R$3, "") -> 0.50650967
B25: 금융 | D25: =IF(V25="","",IFERROR(INDEX(인컴2!E:E,MATCH(V25,인컴2!E:E,0)),IFERROR(INDEX(블루1!E:E,MATCH(V25,블루1!E:E,0)),IFERROR(INDEX(블루3!E:E,MATCH(V25,블루3!E:E,0)),V25)))) | F25: =IF($D25="","",SUMIF(인컴2!$E:$E,$D25,인컴2!$N:$N)/100000000) | G25: =IFERROR(F25/F$3, "") | H25: =IFERROR(IF(F25>0,($E25-G25)*G$3*100000000/$W25,""),"") | I25: =IFERROR(INDEX(인컴2!$Q:$Q,MATCH($D25,인컴2!$E:$E,0))/100,"") | J25: =IF($D25="","",SUMIF(블루1!$E:$E,$D25,블루1!$N:$N)/100000000) | K25: =IFERROR(J25/J$3, "") | L25: =IFERROR(IF(J25>0,($E25-K25)*K$3*100000000/$W25,""),"") | M25: =IFERROR(INDEX(블루1!$Q:$Q,MATCH($D25,블루1!$E:$E,0))/100,"") | N25: =IF($D25="","",SUMIF(블루3!$E:$E,$D25,블루3!$N:$N)/100000000) | O25: =IFERROR(N25/N$3, "") | P25: =IFERROR(IF(N25>0,($E25-O25)*O$3*100000000/$W25,""),"") | Q25: =IFERROR(INDEX(블루3!$Q:$Q,MATCH($D25,블루3!$E:$E,0))/100,"") | R25: =IF($D25="","",SUMIF(블루4!$E:$E,$D25,블루4!$N:$N)/100000000) | S25: =IFERROR(R25/R$3, "") | T25: =IFERROR(IF(R25>0,($E25-S25)*S$3*100000000/$W25,""),"") | U25: =IFERROR(INDEX(블루4!$Q:$Q,MATCH($D25,블루4!$E:$E,0))/100,"") | W25: =IFERROR(INDEX(인컴2!$E$1:$Q$47, MATCH(V25, 인컴2!E:E, 0), 8), "")
B26: =SUM(E25:E27) -> 0 | D26: =IF(V26="","",IFERROR(INDEX(인컴2!E:E,MATCH(V26,인컴2!E:E,0)),IFERROR(INDEX(블루1!E:E,MATCH(V26,블루1!E:E,0)),IFERROR(INDEX(블루3!E:E,MATCH(V26,블루3!E:E,0)),V26)))) | F26: =IF($D26="","",SUMIF(인컴2!$E:$E,$D26,인컴2!$N:$N)/100000000) | G26: =IFERROR(F26/F$3, "") | H26: =IFERROR(IF(F26>0,($E26-G26)*G$3*100000000/$W26,""),"") | I26: =IFERROR(INDEX(인컴2!$Q:$Q,MATCH($D26,인컴2!$E:$E,0))/100,"") | J26: =IF($D26="","",SUMIF(블루1!$E:$E,$D26,블루1!$N:$N)/100000000) | K26: =IFERROR(J26/J$3, "") | L26: =IFERROR(IF(J26>0,($E26-K26)*K$3*100000000/$W26,""),"") | M26: =IFERROR(INDEX(블루1!$Q:$Q,MATCH($D26,블루1!$E:$E,0))/100,"") | N26: =IF($D26="","",SUMIF(블루3!$E:$E,$D26,블루3!$N:$N)/100000000) | O26: =IFERROR(N26/N$3, "") | P26: =IFERROR(IF(N26>0,($E26-O26)*O$3*100000000/$W26,""),"") | Q26: =IFERROR(INDEX(블루3!$Q:$Q,MATCH($D26,블루3!$E:$E,0))/100,"") | R26: =IF($D26="","",SUMIF(블루4!$E:$E,$D26,블루4!$N:$N)/100000000) | S26: =IFERROR(R26/R$3, "") | T26: =IFERROR(IF(R26>0,($E26-S26)*S$3*100000000/$W26,""),"") | U26: =IFERROR(INDEX(블루4!$Q:$Q,MATCH($D26,블루4!$E:$E,0))/100,"") | W26: =IFERROR(INDEX(인컴2!$E$1:$Q$47, MATCH(V26, 인컴2!E:E, 0), 8), "")
D27: =IF(V27="","",IFERROR(INDEX(인컴2!E:E,MATCH(V27,인컴2!E:E,0)),IFERROR(INDEX(블루1!E:E,MATCH(V27,블루1!E:E,0)),IFERROR(INDEX(블루3!E:E,MATCH(V27,블루3!E:E,0)),V27)))) | F27: =IF($D27="","",SUMIF(인컴2!$E:$E,$D27,인컴2!$N:$N)/100000000) | G27: =IFERROR(F27/F$3, "") | H27: =IFERROR(IF(F27>0,($E27-G27)*G$3*100000000/$W27,""),"") | I27: =IFERROR(INDEX(인컴2!$Q:$Q,MATCH($D27,인컴2!$E:$E,0))/100,"") | J27: =IF($D27="","",SUMIF(블루1!$E:$E,$D27,블루1!$N:$N)/100000000) | K27: =IFERROR(J27/J$3, "") | L27: =IFERROR(IF(J27>0,($E27-K27)*K$3*100000000/$W27,""),"") | M27: =IFERROR(INDEX(블루1!$Q:$Q,MATCH($D27,블루1!$E:$E,0))/100,"") | N27: =IF($D27="","",SUMIF(블루3!$E:$E,$D27,블루3!$N:$N)/100000000) | O27: =IFERROR(N27/N$3, "") | P27: =IFERROR(IF(N27>0,($E27-O27)*O$3*100000000/$W27,""),"") | Q27: =IFERROR(INDEX(블루3!$Q:$Q,MATCH($D27,블루3!$E:$E,0))/100,"") | R27: =IF($D27="","",SUMIF(블루4!$E:$E,$D27,블루4!$N:$N)/100000000) | S27: =IFERROR(R27/R$3, "") | T27: =IFERROR(IF(R27>0,($E27-S27)*S$3*100000000/$W27,""),"") | U27: =IFERROR(INDEX(블루4!$Q:$Q,MATCH($D27,블루4!$E:$E,0))/100,"") | W27: =IFERROR(INDEX(인컴2!$E$1:$Q$47, MATCH(V27, 인컴2!E:E, 0), 8), "")
C28: 금융 소계 | E28: =SUM(E25:E27) -> 0 | F28: =SUM(F25:F27) -> 0 | G28: =IFERROR(F28/F$3, "") -> 0 | H28: =IFERROR(($E28-G28)*F$4/$W28, "") | J28: =SUM(J25:J27) -> 0 | K28: =IFERROR(J28/J$3, "") -> 0 | N28: =SUM(N25:N27) -> 0 | O28: =IFERROR(N28/N$3, "") -> 0 | R28: =SUM(R25:R27) -> 0 | S28: =IFERROR(R28/R$3, "") -> 0 | W28: =IFERROR(INDEX(인컴2!$E$1:$Q$47, MATCH(V28, 인컴2!E:E, 0), 8), "")
A29: 1 | B29: 헬스케어 | C29: 바이오 | D29: =IF(V29="","",IFERROR(INDEX(인컴2!E:E,MATCH(V29,인컴2!E:E,0)),IFERROR(INDEX(블루1!E:E,MATCH(V29,블루1!E:E,0)),IFERROR(INDEX(블루3!E:E,MATCH(V29,블루3!E:E,0)),V29)))) -> TIGER 기술이전바이오액티브 | E29: 0.025 | F29: =IF($D29="","",SUMIF(인컴2!$E:$E,$D29,인컴2!$N:$N)/100000000) -> 2.0895 | G29: =IFERROR(F29/F$3, "") -> 0.025076894 | H29: =IFERROR(IF(F29>0,($E29-G29)*G$3*100000000/$W29,""),"") -> -88.48764 | I29: =IFERROR(INDEX(인컴2!$Q:$Q,MATCH($D29,인컴2!$E:$E,0))/100,"") -> -0.2452 | J29: =IF($D29="","",SUMIF(블루1!$E:$E,$D29,블루1!$N:$N)/100000000) -> 2.0835 | K29: =IFERROR(J29/J$3, "") -> 0.024481552 | L29: =IFERROR(IF(J29>0,($E29-K29)*K$3*100000000/$W29,""),"") -> 601.70756 | M29: =IFERROR(INDEX(블루1!$Q:$Q,MATCH($D29,블루1!$E:$E,0))/100,"") -> -0.2474 | N29: =IF($D29="","",SUMIF(블루3!$E:$E,$D29,블루3!$N:$N)/100000000) -> 2.0835 | O29: =IFERROR(N29/N$3, "") -> 0.025693936 | P29: =IFERROR(IF(N29>0,($E29-O29)*O$3*100000000/$W29,""),"") -> -792.02264 | Q29: =IFERROR(INDEX(블루3!$Q:$Q,MATCH($D29,블루3!$E:$E,0))/100,"") -> -0.2475 | R29: =IF($D29="","",SUMIF(블루4!$E:$E,$D29,블루4!$N:$N)/100000000) -> 0.6945 | S29: =IFERROR(R29/R$3, "") -> 0.042671232 | T29: =IFERROR(IF(R29>0,($E29-S29)*S$3*100000000/$W29,""),"") -> -3648.8912 | U29: =IFERROR(INDEX(블루4!$Q:$Q,MATCH($D29,블루4!$E:$E,0))/100,"") -> -0.0838 | V29: TIGER 기술이전바이오액티브 | W29: =IFERROR(INDEX(인컴2!$E$1:$Q$47, MATCH(V29, 인컴2!E:E, 0), 8), "") -> 6965
A30: 2 | B30: =SUM(E29:E31) -> 0.06 | C30: 바이오 | D30: =IF(V30="","",IFERROR(INDEX(인컴2!E:E,MATCH(V30,인컴2!E:E,0)),IFERROR(INDEX(블루1!E:E,MATCH(V30,블루1!E:E,0)),IFERROR(INDEX(블루3!E:E,MATCH(V30,블루3!E:E,0)),V30)))) -> 큐라클 | E30: 0.025 | F30: =IF($D30="","",SUMIF(인컴2!$E:$E,$D30,인컴2!$N:$N)/100000000) -> 1.9533 | G30: =IFERROR(F30/F$3, "") -> 0.023442306 | H30: =IFERROR(IF(F30>0,($E30-G30)*G$3*100000000/$W30,""),"") -> 1086.6064 | I30: =IFERROR(INDEX(인컴2!$Q:$Q,MATCH($D30,인컴2!$E:$E,0))/100,"") -> -0.2586 | J30: =IF($D30="","",SUMIF(블루1!$E:$E,$D30,블루1!$N:$N)/100000000) -> 1.9533 | K30: =IFERROR(J30/J$3, "") -> 0.022951675 | L30: =IFERROR(IF(J30>0,($E30-K30)*K$3*100000000/$W30,""),"") -> 1441.0534 | M30: =IFERROR(INDEX(블루1!$Q:$Q,MATCH($D30,블루1!$E:$E,0))/100,"") -> -0.2586 | N30: =IF($D30="","",SUMIF(블루3!$E:$E,$D30,블루3!$N:$N)/100000000) -> 1.9533 | O30: =IFERROR(N30/N$3, "") -> 0.024088296 | P30: =IFERROR(IF(N30>0,($E30-O30)*O$3*100000000/$W30,""),"") -> 630.77329 | Q30: =IFERROR(INDEX(블루3!$Q:$Q,MATCH($D30,블루3!$E:$E,0))/100,"") -> -0.2304 | R30: =IF($D30="","",SUMIF(블루4!$E:$E,$D30,블루4!$N:$N)/100000000) -> 0 | S30: =IFERROR(R30/R$3, "") -> 0 | T30: =IFERROR(IF(R30>0,($E30-S30)*S$3*100000000/$W30,""),"") | U30: =IFERROR(INDEX(블루4!$Q:$Q,MATCH($D30,블루4!$E:$E,0))/100,"") | V30: 큐라클 | W30: =IFERROR(INDEX(인컴2!$E$1:$Q$47, MATCH(V30, 인컴2!E:E, 0), 8), "") -> 11490
A31: 3 | C31: 바이오 | D31: =IF(V31="","",IFERROR(INDEX(인컴2!E:E,MATCH(V31,인컴2!E:E,0)),IFERROR(INDEX(블루1!E:E,MATCH(V31,블루1!E:E,0)),IFERROR(INDEX(블루3!E:E,MATCH(V31,블루3!E:E,0)),V31)))) -> 앱클론 | E31: 0.01 | F31: =IF($D31="","",SUMIF(인컴2!$E:$E,$D31,인컴2!$N:$N)/100000000) -> 0.771 | G31: =IFERROR(F31/F$3, "") -> 0.0092530679 | H31: =IFERROR(IF(F31>0,($E31-G31)*G$3*100000000/$W31,""),"") -> 232.94748 | I31: =IFERROR(INDEX(인컴2!$Q:$Q,MATCH($D31,인컴2!$E:$E,0))/100,"") -> -0.5164 | J31: =IF($D31="","",SUMIF(블루1!$E:$E,$D31,블루1!$N:$N)/100000000) -> 0.774 | K31: =IFERROR(J31/J$3, "") -> 0.0090946586 | L31: =IFERROR(IF(J31>0,($E31-K31)*K$3*100000000/$W31,""),"") -> 284.76102 | M31: =IFERROR(INDEX(블루1!$Q:$Q,MATCH($D31,블루1!$E:$E,0))/100,"") -> -0.5177 | N31: =IF($D31="","",SUMIF(블루3!$E:$E,$D31,블루3!$N:$N)/100000000) -> 0.774 | O31: =IFERROR(N31/N$3, "") -> 0.0095450474 | P31: =IFERROR(IF(N31>0,($E31-O31)*O$3*100000000/$W31,""),"") -> 140.7254 | Q31: =IFERROR(INDEX(블루3!$Q:$Q,MATCH($D31,블루3!$E:$E,0))/100,"") -> -0.4697 | R31: =IF($D31="","",SUMIF(블루4!$E:$E,$D31,블루4!$N:$N)/100000000) -> 0 | S31: =IFERROR(R31/R$3, "") -> 0 | T31: =IFERROR(IF(R31>0,($E31-S31)*S$3*100000000/$W31,""),"") | U31: =IFERROR(INDEX(블루4!$Q:$Q,MATCH($D31,블루4!$E:$E,0))/100,"") | V31: 앱클론 | W31: =IFERROR(INDEX(인컴2!$E$1:$Q$47, MATCH(V31, 인컴2!E:E, 0), 8), "") -> 25700
C32: 헬스케어 소계 | E32: =SUM(E29:E31) -> 0.06 | F32: =SUM(F29:F31) -> 4.8138 | G32: =IFERROR(F32/F$3, "") -> 0.057772268 | H32: =IFERROR(($E32-G32)*F$4*100000000/$W32, "") | J32: =SUM(J29:J31) -> 4.8108 | K32: =IFERROR(J32/J$3, "") -> 0.056527886 | N32: =SUM(N29:N31) -> 4.8108 | O32: =IFERROR(N32/N$3, "") -> 0.059327279 | R32: =SUM(R29:R31) -> 0.6945 | S32: =IFERROR(R32/R$3, "") -> 0.042671232 | W32: =IFERROR(INDEX(인컴2!$E$1:$Q$47, MATCH(V32, 인컴2!E:E, 0), 8), "")
A33: 1 | B33: 산업재 | C33: 전력기기 | D33: =IF(V33="","",IFERROR(INDEX(인컴2!E:E,MATCH(V33,인컴2!E:E,0)),IFERROR(INDEX(블루1!E:E,MATCH(V33,블루1!E:E,0)),IFERROR(INDEX(블루3!E:E,MATCH(V33,블루3!E:E,0)),V33)))) -> TIGER 코리아AI전력기기TOP3플러스 | E33: 0.035 | F33: =IF($D33="","",SUMIF(인컴2!$E:$E,$D33,인컴2!$N:$N)/100000000) -> 2.78785 | G33: =IFERROR(F33/F$3, "") -> 0.033458062 | H33: =IFERROR(IF(F33>0,($E33-G33)*G$3*100000000/$W33,""),"") -> 576.30319 | I33: =IFERROR(INDEX(인컴2!$Q:$Q,MATCH($D33,인컴2!$E:$E,0))/100,"") -> -0.058 | J33: =IF($D33="","",SUMIF(블루1!$E:$E,$D33,블루1!$N:$N)/100000000) -> 2.78915 | K33: =IFERROR(J33/J$3, "") -> 0.032773084 | L33: =IFERROR(IF(J33>0,($E33-K33)*K$3*100000000/$W33,""),"") -> 839.41953 | M33: =IFERROR(INDEX(블루1!$Q:$Q,MATCH($D33,블루1!$E:$E,0))/100,"") -> -0.0575 | N33: =IF($D33="","",SUMIF(블루3!$E:$E,$D33,블루3!$N:$N)/100000000) -> 2.78915 | O33: =IFERROR(N33/N$3, "") -> 0.034396084 | P33: =IFERROR(IF(N33>0,($E33-O33)*O$3*100000000/$W33,""),"") -> 223.86695 | Q33: =IFERROR(INDEX(블루3!$Q:$Q,MATCH($D33,블루3!$E:$E,0))/100,"") -> -0.0577 | R33: =IF($D33="","",SUMIF(블루4!$E:$E,$D33,블루4!$N:$N)/100000000) -> 0 | S33: =IFERROR(R33/R$3, "") -> 0 | T33: =IFERROR(IF(R33>0,($E33-S33)*S$3*100000000/$W33,""),"") | U33: =IFERROR(INDEX(블루4!$Q:$Q,MATCH($D33,블루4!$E:$E,0))/100,"") | V33: TIGER 코리아AI전력기기TOP3플러스 | W33: =IFERROR(INDEX(인컴2!$E$1:$Q$47, MATCH(V33, 인컴2!E:E, 0), 8), "") -> 21445
A34: 2 | B34: =SUM(E33:E38) -> 0.125 | C34: 원전 | D34: =IF(V34="","",IFERROR(INDEX(인컴2!E:E,MATCH(V34,인컴2!E:E,0)),IFERROR(INDEX(블루1!E:E,MATCH(V34,블루1!E:E,0)),IFERROR(INDEX(블루3!E:E,MATCH(V34,블루3!E:E,0)),V34)))) -> 두산에너빌리티 | E34: 0.03 | F34: =IF($D34="","",SUMIF(인컴2!$E:$E,$D34,인컴2!$N:$N)/100000000) -> 2.634 | G34: =IFERROR(F34/F$3, "") -> 0.031611648 | H34: =IFERROR(IF(F34>0,($E34-G34)*G$3*100000000/$W34,""),"") -> -147.12478 | I34: =IFERROR(INDEX(인컴2!$Q:$Q,MATCH($D34,인컴2!$E:$E,0))/100,"") -> -0.0309 | J34: =IF($D34="","",SUMIF(블루1!$E:$E,$D34,블루1!$N:$N)/100000000) -> 3.504 | K34: =IFERROR(J34/J$3, "") -> 0.041172718 | L34: =IFERROR(IF(J34>0,($E34-K34)*K$3*100000000/$W34,""),"") -> -1028.6452 | M34: =IFERROR(INDEX(블루1!$Q:$Q,MATCH($D34,블루1!$E:$E,0))/100,"") -> 0.3518 | N34: =IF($D34="","",SUMIF(블루3!$E:$E,$D34,블루3!$N:$N)/100000000) -> 2.628 | O34: =IFERROR(N34/N$3, "") -> 0.032408766 | P34: =IFERROR(IF(N34>0,($E34-O34)*O$3*100000000/$W34,""),"") -> -218.09187 | Q34: =IFERROR(INDEX(블루3!$Q:$Q,MATCH($D34,블루3!$E:$E,0))/100,"") -> -0.0717 | R34: =IF($D34="","",SUMIF(블루4!$E:$E,$D34,블루4!$N:$N)/100000000) -> 0 | S34: =IFERROR(R34/R$3, "") -> 0 | T34: =IFERROR(IF(R34>0,($E34-S34)*S$3*100000000/$W34,""),"") | U34: =IFERROR(INDEX(블루4!$Q:$Q,MATCH($D34,블루4!$E:$E,0))/100,"") | V34: 두산에너빌리티 | W34: =IFERROR(INDEX(인컴2!$E$1:$Q$47, MATCH(V34, 인컴2!E:E, 0), 8), "") -> 87800
A35: 3 | C35: 방산 | D35: =IF(V35="","",IFERROR(INDEX(인컴2!E:E,MATCH(V35,인컴2!E:E,0)),IFERROR(INDEX(블루1!E:E,MATCH(V35,블루1!E:E,0)),IFERROR(INDEX(블루3!E:E,MATCH(V35,블루3!E:E,0)),V35)))) -> 한화에어로스페이스 | E35: 0.015 | F35: =IF($D35="","",SUMIF(인컴2!$E:$E,$D35,인컴2!$N:$N)/100000000) -> 1.196 | G35: =IFERROR(F35/F$3, "") -> 0.014353657 | H35: =IFERROR(IF(F35>0,($E35-G35)*G$3*100000000/$W35,""),"") -> 4.3315383 | I35: =IFERROR(INDEX(인컴2!$Q:$Q,MATCH($D35,인컴2!$E:$E,0))/100,"") -> 0.0422 | J35: =IF($D35="","",SUMIF(블루1!$E:$E,$D35,블루1!$N:$N)/100000000) -> 1.191 | K35: =IFERROR(J35/J$3, "") -> 0.013994494 | L35: =IFERROR(IF(J35>0,($E35-K35)*K$3*100000000/$W35,""),"") -> 6.7960216 | M35: =IFERROR(INDEX(블루1!$Q:$Q,MATCH($D35,블루1!$E:$E,0))/100,"") -> 0.0378 | N35: =IF($D35="","",SUMIF(블루3!$E:$E,$D35,블루3!$N:$N)/100000000) -> 1.191 | O35: =IFERROR(N35/N$3, "") -> 0.014687534 | P35: =IFERROR(IF(N35>0,($E35-O35)*O$3*100000000/$W35,""),"") -> 2.0768771 | Q35: =IFERROR(INDEX(블루3!$Q:$Q,MATCH($D35,블루3!$E:$E,0))/100,"") -> 0.0385 | R35: =IF($D35="","",SUMIF(블루4!$E:$E,$D35,블루4!$N:$N)/100000000) -> 0.5955 | S35: =IFERROR(R35/R$3, "") -> 0.036588508 | T35: =IFERROR(IF(R35>0,($E35-S35)*S$3*100000000/$W35,""),"") -> -25.960117 | U35: =IFERROR(INDEX(블루4!$Q:$Q,MATCH($D35,블루4!$E:$E,0))/100,"") -> 0.0387 | V35: 한화에어로스페이스 | W35: =IFERROR(INDEX(인컴2!$E$1:$Q$47, MATCH(V35, 인컴2!E:E, 0), 8), "") -> 1196000
A36: 4 | C36: 건설 | D36: =IF(V36="","",IFERROR(INDEX(인컴2!E:E,MATCH(V36,인컴2!E:E,0)),IFERROR(INDEX(블루1!E:E,MATCH(V36,블루1!E:E,0)),IFERROR(INDEX(블루3!E:E,MATCH(V36,블루3!E:E,0)),V36)))) -> 아이에스동서 | E36: 0.02 | F36: =IF($D36="","",SUMIF(인컴2!$E:$E,$D36,인컴2!$N:$N)/100000000) -> 1.808 | G36: =IFERROR(F36/F$3, "") -> 0.021698504 | H36: =IFERROR(IF(F36>0,($E36-G36)*G$3*100000000/$W36,""),"") -> -602.37681 | I36: =IFERROR(INDEX(인컴2!$Q:$Q,MATCH($D36,인컴2!$E:$E,0))/100,"") -> -0.129 | J36: =IF($D36="","",SUMIF(블루1!$E:$E,$D36,블루1!$N:$N)/100000000) -> 2.2624 | K36: =IFERROR(J36/J$3, "") -> 0.026583664 | L36: =IFERROR(IF(J36>0,($E36-K36)*K$3*100000000/$W36,""),"") -> -2354.8349 | M36: =IFERROR(INDEX(블루1!$Q:$Q,MATCH($D36,블루1!$E:$E,0))/100,"") -> 0.1252 | N36: =IF($D36="","",SUMIF(블루3!$E:$E,$D36,블루3!$N:$N)/100000000) -> 1.792 | O36: =IFERROR(N36/N$3, "") -> 0.022099128 | P36: =IFERROR(IF(N36>0,($E36-O36)*O$3*100000000/$W36,""),"") -> -738.36297 | Q36: =IFERROR(INDEX(블루3!$Q:$Q,MATCH($D36,블루3!$E:$E,0))/100,"") -> -0.1368 | R36: =IF($D36="","",SUMIF(블루4!$E:$E,$D36,블루4!$N:$N)/100000000) -> 0.672 | S36: =IFERROR(R36/R$3, "") -> 0.041288794 | T36: =IFERROR(IF(R36>0,($E36-S36)*S$3*100000000/$W36,""),"") -> -1354.7459 | U36: =IFERROR(INDEX(블루4!$Q:$Q,MATCH($D36,블루4!$E:$E,0))/100,"") -> -0.0729 | V36: 아이에스동서 | W36: =IFERROR(INDEX(인컴2!$E$1:$Q$47, MATCH(V36, 인컴2!E:E, 0), 8), "") -> 22600
A37: 5 | C37: 로봇 | D37: =IF(V37="","",IFERROR(INDEX(인컴2!E:E,MATCH(V37,인컴2!E:E,0)),IFERROR(INDEX(블루1!E:E,MATCH(V37,블루1!E:E,0)),IFERROR(INDEX(블루3!E:E,MATCH(V37,블루3!E:E,0)),V37)))) -> TIGER 코리아휴머노이드로봇산업 | E37: 0.025 | F37: =IF($D37="","",SUMIF(인컴2!$E:$E,$D37,인컴2!$N:$N)/100000000) -> 1.867 | G37: =IFERROR(F37/F$3, "") -> 0.022406586 | H37: =IFERROR(IF(F37>0,($E37-G37)*G$3*100000000/$W37,""),"") -> 2226.73 | I37: =IFERROR(INDEX(인컴2!$Q:$Q,MATCH($D37,인컴2!$E:$E,0))/100,"") -> -0.2934 | J37: =IF($D37="","",SUMIF(블루1!$E:$E,$D37,블루1!$N:$N)/100000000) -> 1.862 | K37: =IFERROR(J37/J$3, "") -> 0.021878881 | L37: =IFERROR(IF(J37>0,($E37-K37)*K$3*100000000/$W37,""),"") -> 2702.6961 | M37: =IFERROR(INDEX(블루1!$Q:$Q,MATCH($D37,블루1!$E:$E,0))/100,"") -> -0.2953 | N37: =IF($D37="","",SUMIF(블루3!$E:$E,$D37,블루3!$N:$N)/100000000) -> 1.862 | O37: =IFERROR(N37/N$3, "") -> 0.022962375 | P37: =IFERROR(IF(N37>0,($E37-O37)*O$3*100000000/$W37,""),"") -> 1735.1994 | Q37: =IFERROR(INDEX(블루3!$Q:$Q,MATCH($D37,블루3!$E:$E,0))/100,"") -> -0.2953 | R37: =IF($D37="","",SUMIF(블루4!$E:$E,$D37,블루4!$N:$N)/100000000) -> 0 | S37: =IFERROR(R37/R$3, "") -> 0 | T37: =IFERROR(IF(R37>0,($E37-S37)*S$3*100000000/$W37,""),"") | U37: =IFERROR(INDEX(블루4!$Q:$Q,MATCH($D37,블루4!$E:$E,0))/100,"") | V37: TIGER 코리아휴머노이드로봇산업 | W37: =IFERROR(INDEX(인컴2!$E$1:$Q$47, MATCH(V37, 인컴2!E:E, 0), 8), "") -> 9335
A38: 6 | C38: 조선기자재 | D38: =IF(V38="","",IFERROR(INDEX(인컴2!E:E,MATCH(V38,인컴2!E:E,0)),IFERROR(INDEX(블루1!E:E,MATCH(V38,블루1!E:E,0)),IFERROR(INDEX(블루3!E:E,MATCH(V38,블루3!E:E,0)),V38)))) -> 세진중공업 | E38: 0 | F38: =IF($D38="","",SUMIF(인컴2!$E:$E,$D38,인컴2!$N:$N)/100000000) -> 0.02055 | G38: =IFERROR(F38/F$3, "") -> 0.00024662846 | H38: =IFERROR(IF(F38>0,($E38-G38)*G$3*100000000/$W38,""),"") -> -144.28881 | I38: =IFERROR(INDEX(인컴2!$Q:$Q,MATCH($D38,인컴2!$E:$E,0))/100,"") -> -0.0022 | J38: =IF($D38="","",SUMIF(블루1!$E:$E,$D38,블루1!$N:$N)/100000000) -> 0.01369 | K38: =IFERROR(J38/J$3, "") -> 0.0001608603 | L38: =IFERROR(IF(J38>0,($E38-K38)*K$3*100000000/$W38,""),"") -> -94.91385 | M38: =IFERROR(INDEX(블루1!$Q:$Q,MATCH($D38,블루1!$E:$E,0))/100,"") -> -0.0028 | N38: =IF($D38="","",SUMIF(블루3!$E:$E,$D38,블루3!$N:$N)/100000000) -> 0.02738 | O38: =IFERROR(N38/N$3, "") -> 0.00033765297 | P38: =IFERROR(IF(N38>0,($E38-O38)*O$3*100000000/$W38,""),"") -> -195.92482 | Q38: =IFERROR(INDEX(블루3!$Q:$Q,MATCH($D38,블루3!$E:$E,0))/100,"") -> -0.0035 | R38: =IF($D38="","",SUMIF(블루4!$E:$E,$D38,블루4!$N:$N)/100000000) -> 0.01369 | S38: =IFERROR(R38/R$3, "") -> 0.0008411363 | T38: =IFERROR(IF(R38>0,($E38-S38)*S$3*100000000/$W38,""),"") -> -88.300064 | U38: =IFERROR(INDEX(블루4!$Q:$Q,MATCH($D38,블루4!$E:$E,0))/100,"") -> -0.0032 | V38: 세진중공업 | W38: =IFERROR(INDEX(인컴2!$E$1:$Q$47, MATCH(V38, 인컴2!E:E, 0), 8), "") -> 13700
C39: 산업재 소계 | E39: =SUM(E33:E38) -> 0.125 | F39: =SUM(F33:F38) -> 10.3134 | G39: =IFERROR(F39/F$3, "") -> 0.12377509 | H39: =IFERROR(($E39-G39)*F$4*100000000/$W39, "") | J39: =SUM(J33:J38) -> 11.62224 | K39: =IFERROR(J39/J$3, "") -> 0.1365637 | N39: =SUM(N33:N38) -> 10.28953 | O39: =IFERROR(N39/N$3, "") -> 0.12689154 | R39: =SUM(R33:R38) -> 1.28119 | S39: =IFERROR(R39/R$3, "") -> 0.078718438 | W39: =IFERROR(INDEX(인컴2!$E$1:$Q$47, MATCH(V39, 인컴2!E:E, 0), 8), "")
B40: 에너지 | D40: =IF(V40="","",IFERROR(INDEX(인컴2!E:E,MATCH(V40,인컴2!E:E,0)),IFERROR(INDEX(블루1!E:E,MATCH(V40,블루1!E:E,0)),IFERROR(INDEX(블루3!E:E,MATCH(V40,블루3!E:E,0)),V40)))) | F40: =IF($D40="","",SUMIF(인컴2!$E:$E,$D40,인컴2!$N:$N)/100000000) | G40: =IFERROR(F40/F$3, "") | H40: =IFERROR(IF(F40>0,($E40-G40)*G$3*100000000/$W40,""),"") | I40: =IFERROR(INDEX(인컴2!$Q:$Q,MATCH($D40,인컴2!$E:$E,0))/100,"") | J40: =IF($D40="","",SUMIF(블루1!$E:$E,$D40,블루1!$N:$N)/100000000) | K40: =IFERROR(J40/J$3, "") | L40: =IFERROR(IF(J40>0,($E40-K40)*K$3*100000000/$W40,""),"") | M40: =IFERROR(INDEX(블루1!$Q:$Q,MATCH($D40,블루1!$E:$E,0))/100,"") | N40: =IF($D40="","",SUMIF(블루3!$E:$E,$D40,블루3!$N:$N)/100000000) | O40: =IFERROR(N40/N$3, "") | P40: =IFERROR(IF(N40>0,($E40-O40)*O$3*100000000/$W40,""),"") | Q40: =IFERROR(INDEX(블루3!$Q:$Q,MATCH($D40,블루3!$E:$E,0))/100,"") | R40: =IF($D40="","",SUMIF(블루4!$E:$E,$D40,블루4!$N:$N)/100000000) | S40: =IFERROR(R40/R$3, "") | T40: =IFERROR(IF(R40>0,($E40-S40)*S$3*100000000/$W40,""),"") | U40: =IFERROR(INDEX(블루4!$Q:$Q,MATCH($D40,블루4!$E:$E,0))/100,"") | W40: =IFERROR(INDEX(인컴2!$E$1:$Q$47, MATCH(V40, 인컴2!E:E, 0), 8), "")
...

Sheet 인컴2
A1: NO | B1: 펀드 | C1: 펀드명 | D1: 종목 | E1: 종목명 | F1: 전일 | J1: 당일 | O1: 전일 대비 손익 | P1: 취득액 대비 손익(전체) (LONG손익 +차입매도분손익) | Q1: 취득액 대비 손익비율 (전체) | R1: 전일대비 종목증감비율
F2: 보유주수 | G2: 종가 | H2: 취득액 | I2: LONG평가금액 +차입매도분평가금액 | J2: 체결기준 보유주수 | K2: 주문기준 보유주수 | L2: 현재가 | M2: 취득액 | N2: LONG평가금액 +차입매도분평가금액 ▼
A3: 1 | B3: 300019 | C3: 이지스 인컴플러스 일반사모투자신탁 제2호 | D3: KR7367760006 | E3: RISE 네트워크인프라 | F3: 17000 | G3: 75230 | H3: 1073226194 | I3: 1278910000 | J3: 17000 | K3: 17000 | L3: 74805 | M3: 1073226194 | N3: 1271685000 | O3: -7225000 | P3: 198458806 | Q3: 18.49 | R3: -0.56
A4: 2 | B4: 300019 | C4: 이지스 인컴플러스 일반사모투자신탁 제2호 | D4: KR7087010005 | E4: 펩트론 | F4: 2800 | G4: 180700 | H4: 767200000 | I4: 505960000 | J4: 2800 | K4: 2800 | L4: 184500 | M4: 767200000 | N4: 516600000 | O4: 10640000 | P4: -250600000 | Q4: -32.66 | R4: 2.1
A5: 3 | B5: 300019 | C5: 이지스 인컴플러스 일반사모투자신탁 제2호 | D5: KR7233740000 | E5: KODEX 코스닥150레버리지 | F5: 50000 | G5: 9050 | H5: 740273056 | I5: 452500000 | J5: 50000 | K5: 50000 | L5: 8715 | M5: 740273056 | N5: 435750000 | O5: -16750000 | P5: -304523056 | Q5: -41.13 | R5: -3.7
A6: 4 | B6: 300019 | C6: 이지스 인컴플러스 일반사모투자신탁 제2호 | D6: KR7160980009 | E6: 싸이맥스 | F6: 10000 | G6: 38550 | H6: 347526041 | I6: 385500000 | J6: 10000 | K6: 10000 | L6: 36850 | M6: 347526041 | N6: 368500000 | O6: -17000000 | P6: 20973959 | Q6: 6.03 | R6: -4.4
A7: 5 | B7: 300019 | C7: 이지스 인컴플러스 일반사모투자신탁 제2호 | D7: KR70043Y0003 | E7: TIME 차이나AI테크액티브 | F7: 13000 | G7: 25850 | H7: 252823876 | I7: 336050000 | J7: 13000 | K7: 13000 | L7: 26190 | M7: 252823876 | N7: 340470000 | O7: 4420000 | P7: 87646124 | Q7: 34.66 | R7: 1.31
A8: 6 | B8: 300019 | C8: 이지스 인컴플러스 일반사모투자신탁 제2호 | D8: KR7005930003 | E8: 삼성전자 | F8: 1000 | G8: 309500 | H8: 359572338 | I8: 309500000 | J8: 1000 | K8: 1000 | L8: 318500 | M8: 359572338 | N8: 318500000 | O8: 9000000 | P8: -41072338 | Q8: -11.42 | R8: 2.9
A9: 7 | B9: 300019 | C9: 이지스 인컴플러스 일반사모투자신탁 제2호 | D9: KR7466930005 | E9: SOL 자동차TOP3플러스 | F9: 10000 | G9: 30345 | H9: 308870498 | I9: 303450000 | J9: 10000 | K9: 10000 | L9: 30775 | M9: 308870498 | N9: 307750000 | O9: 4300000 | P9: -1120498 | Q9: -0.36 | R9: 1.41
A10: 8 | B10: 300019 | C10: 이지스 인컴플러스 일반사모투자신탁 제2호 | D10: KR70117V0007 | E10: TIGER 코리아AI전력기기TOP3플러스 | F10: 13000 | G10: 22210 | H10: 295962447 | I10: 288730000 | J10: 13000 | K10: 13000 | L10: 21445 | M10: 295962447 | N10: 278785000 | O10: -9945000 | P10: -17177447 | Q10: -5.8 | R10: -3.44
A11: 9 | B11: 300019 | C11: 이지스 인컴플러스 일반사모투자신탁 제2호 | D11: KR7261140008 | E11: TIGER 우선주 | F11: 10000 | G11: 26955 | H11: 300715905 | I11: 269550000 | J11: 10000 | K11: 10000 | L11: 27250 | M11: 300715905 | N11: 272500000 | O11: 2950000 | P11: -28215905 | Q11: -9.38 | R11: 1.09
A12: 10 | B12: 300019 | C12: 이지스 인컴플러스 일반사모투자신탁 제2호 | D12: KR7034020008 | E12: 두산에너빌리티 | F12: 3000 | G12: 86200 | H12: 271800000 | I12: 258600000 | J12: 3000 | K12: 3000 | L12: 87800 | M12: 271800000 | N12: 263400000 | O12: 4800000 | P12: -8400000 | Q12: -3.09 | R12: 1.85
A13: 11 | B13: 300019 | C13: 이지스 인컴플러스 일반사모투자신탁 제2호 | D13: KR7000150003 | E13: 두산 | F13: 170 | G13: 1433000 | H13: 271896410 | I13: 243610000 | J13: 170 | K13: 170 | L13: 1471000 | M13: 271896410 | N13: 250070000 | O13: 6460000 | P13: -21826410 | Q13: -8.02 | R13: 2.65
A14: 12 | B14: 300019 | C14: 이지스 인컴플러스 일반사모투자신탁 제2호 | D14: KR7475300000 | E14: SOL 반도체전공정 | F14: 10000 | G14: 25500 | H14: 249931704 | I14: 255000000 | J14: 10000 | K14: 10000 | L14: 24420 | M14: 249931704 | N14: 244200000 | O14: -10800000 | P14: -5731704 | Q14: -2.29 | R14: -4.23
... A44: 42 | B44: 300019 | C44: 이지스 인컴플러스 일반사모투자신탁 제2호 | D44: KR7365660000 | E44: 레몬헬스케어 | F44: 2 | G44: 0 | H44: 20200 | I44: 20200 | J44: 0 | K44: 0 | L44: 16250 | M44: 0 | N44: 0 | O44: 30660 | P44: 10460 | Q44: 51.78 | R44: 0
H45: 9616620162 | I45: 8585806765 | J45: 335747 | K45: 335747 | M45: 9616599962 | N45: 8538276035 | O45: -47479870 | P45: -1078313467

Sheet 블루1
A1: NO | B1: 펀드 | C1: 펀드명 | D1: 종목 | E1: 종목명 | F1: 전일 | J1: 당일 | O1: 전일 대비 손익 | P1: 취득액 대비 손익(전체) (LONG손익 +차입매도분손익) | Q1: 취득액 대비 손익비율 (전체) | R1: 전일대비 종목증감비율
F2: 보유주수 | G2: 종가 | H2: 취득액 | I2: LONG평가금액 +차입매도분평가금액 | J2: 체결기준 보유주수 | K2: 주문기준 보유주수 | L2: 현재가 | M2: 취득액 | N2: LONG평가금액 +차입매도분평가금액 ▼
A3: 1 | B3: 300037 | C3: 이지스블루ON일반사모투자신탁제1호 | D3: KR7000150003 | E3: 두산 | F3: 170 | G3: 1433000 | H3: 271896910 | I3: 243610000 | J3: 170 | K3: 170 | L3: 1465000 | M3: 271896910 | N3: 249050000 | O3: 5440000 | P3: -22846910 | Q3: -8.4 | R3: 2.23
A4: 2 | B4: 300037 | C4: 이지스블루ON일반사모투자신탁제1호 | D4: KR7000660001 | E4: SK하이닉스 | F4: 50 | G4: 2425000 | H4: 112333914 | I4: 121250000 | J4: 50 | K4: 50 | L4: 2429000 | M4: 112333914 | N4: 121450000 | O4: 200000 | P4: 9116086 | Q4: 8.11 | R4: 0.16
A5: 3 | B5: 300037 | C5: 이지스블루ON일반사모투자신탁제1호 | D5: KR70008T0003 | E5: SOL 화장품TOP3플러스 | F5: 7000 | G5: 14870 | H5: 104069873 | I5: 104090000 | J5: 7000 | K5: 7000 | L5: 15385 | M5: 104069873 | N5: 107695000 | O5: 3605000 | P5: 3625127 | Q5: 3.48 | R5: 3.46
A6: 4 | B6: 300037 | C6: 이지스블루ON일반사모투자신탁제1호 | D6: KR7000990002 | E6: DB하이텍 | F6: 1200 | G6: 120700 | H6: 219264951 | I6: 144840000 | J6: 1200 | K6: 1200 | L6: 114000 | M6: 219264951 | N6: 136800000 | O6: -8040000 | P6: -82464951 | Q6: -37.6 | R6: -5.55
A7: 5 | B7: 300037 | C7: 이지스블루ON일반사모투자신탁제1호 | D7: KR7002990000 | E7: 금호건설 | F7: 27800 | G7: 9500 | H7: 99787822 | I7: 264100000 | J7: 27800 | K7: 27800 | L7: 9110 | M7: 99787822 | N7: 253258000 | O7: -10842000 | P7: 153470178 | Q7: 153.79 | R7: -4.1
A8: 6 | B8: 300037 | C8: 이지스블루ON일반사모투자신탁제1호 | D8: KR7003550001 | E8: LG | F8: 2300 | G8: 101100 | H8: 238732025 | I8: 232530000 | J8: 2300 | K8: 2300 | L8: 102400 | M8: 238732025 | N8: 235520000 | O8: 2990000 | P8: -3212025 | Q8: -1.34 | R8: 1.28
A9: 7 | B9: 300037 | C9: 이지스블루ON일반사모투자신탁제1호 | D9: KR70043Y0003 | E9: TIME 차이나AI테크액티브 | F9: 11000 | G9: 25850 | H9: 235686795 | I9: 284350000 | J9: 11000 | K9: 11000 | L9: 26240 | M9: 235686795 | N9: 288640000 | O9: 4290000 | P9: 52953205 | Q9: 22.46 | R9: 1.5
A10: 8 | B10: 300037 | C10: 이지스블루ON일반사모투자신탁제1호 | D10: KR7005930003 | E10: 삼성전자 | F10: 1000 | G10: 309500 | H10: 359574088 | I10: 309500000 | J10: 1000 | K10: 1000 | L10: 316500 | M10: 359574088 | N10: 316500000 | O10: 7000000 | P10: -43074088 | Q10: -11.97 | R10: 2.26
A11: 9 | B11: 300037 | C11: 이지스블루ON일반사모투자신탁제1호 | D11: KR70088M0003 | E11: 메쥬 | F11: 57 | G11: 14510 | H11: 1243512 | I11: 827070 | J11: 57 | K11: 57 | L11: 14510 | M11: 1243512 | N11: 827070 | O11: 0 | P11: -416442 | Q11: -33.48 | R11: 0
A12: 10 | B12: 300037 | C12: 이지스블루ON일반사모투자신탁제1호 | D12: KR7009151002 | E12: 삼성전기우 | F12: 250 | G12: 695000 | H12: 225852663 | I12: 173750000 | J12: 250 | K12: 250 | L12: 669000 | M12: 225852663 | N12: 167250000 | O12: -6500000 | P12: -58602663 | Q12: -25.94 | R12: -3.74
A13: 11 | B13: 300037 | C13: 이지스블루ON일반사모투자신탁제1호 | D13: KR7010780005 | E13: 아이에스동서 | F13: 10100 | G13: 21900 | H13: 201062050 | I13: 221190000 | J13: 10100 | K13: 10100 | L13: 22400 | M13: 201062050 | N13: 226240000 | O13: 5050000 | P13: 25177950 | Q13: 12.52 | R13: 2.28
A14: 12 | B14: 300037 | C14: 이지스블루ON일반사모투자신탁제1호 | D14: KR70117V0007 | E14: TIGER 코리아AI전력기기TOP3플러스 | F14: 13000 | G14: 22210 | H14: 295959103 | I14: 288730000 | J14: 13000 | K14: 13000 | L14: 21455 | M14: 295959103 | N14: 278915000 | O14: -9815000 | P14: -17044103 | Q14: -5.75 | R14: -3.39
... A44: 42 | B44: 300037 | C44: 이지스블루ON일반사모투자신탁제1호 | D44: KR7494340003 | E44: ACE 글로벌AI맞춤형반도체 | F44: 8000 | G44: 24890 | H44: 215715755 | I44: 199120000 | J44: 8000 | K44: 8000 | L44: 25155 | M44: 215715755 | N44: 201240000 | O44: 2120000 | P44: -14475755 | Q44: -6.71 | R44: 1.06
H45: 10088779670 | I45: 9447451830 | J45: 624074 | K45: 624074 | M45: 10088759470 | N45: 9368547570 | O45: -78853400 | P45: -720201440

Sheet 블루3
A1: NO | B1: 펀드 | C1: 펀드명 | D1: 종목 | E1: 종목명 | F1: 전일 | J1: 당일 | O1: 전일 대비 손익 | P1: 취득액 대비 손익(전체) (LONG손익 +차입매도분손익) | Q1: 취득액 대비 손익비율 (전체) | R1: 전일대비 종목증감비율
F2: 보유주수 | G2: 종가 | H2: 취득액 | I2: LONG평가금액 +차입매도분평가금액 | J2: 체결기준 보유주수 | K2: 주문기준 보유주수 | L2: 현재가 | M2: 취득액 | N2: LONG평가금액 +차입매도분평가금액 ▼
A3: 1 | B3: 300085 | C3: 이지스블루ON일반사모투자신탁제3호 | D3: KR7000150003 | E3: 두산 | F3: 170 | G3: 1433000 | H3: 271912630 | I3: 243610000 | J3: 170 | K3: 170 | L3: 1465000 | M3: 271912630 | N3: 249050000 | O3: 5440000 | P3: -22862630 | Q3: -8.4 | R3: 2.23
A4: 2 | B4: 300085 | C4: 이지스블루ON일반사모투자신탁제3호 | D4: KR7000660001 | E4: SK하이닉스 | F4: 50 | G4: 2425000 | H4: 112333413 | I4: 121250000 | J4: 50 | K4: 50 | L4: 2429000 | M4: 112333413 | N4: 121450000 | O4: 200000 | P4: 9116587 | Q4: 8.11 | R4: 0.16
A5: 3 | B5: 300085 | C5: 이지스블루ON일반사모투자신탁제3호 | D5: KR70008T0003 | E5: SOL 화장품TOP3플러스 | F5: 7000 | G5: 14870 | H5: 104010625 | I5: 104090000 | J5: 7000 | K5: 7000 | L5: 15385 | M5: 104010625 | N5: 107695000 | O5: 3605000 | P5: 3684375 | Q5: 3.54 | R5: 3.46
A6: 4 | B6: 300085 | C6: 이지스블루ON일반사모투자신탁제3호 | D6: KR7000990002 | E6: DB하이텍 | F6: 1200 | G6: 120700 | H6: 219271160 | I6: 144840000 | J6: 1200 | K6: 1200 | L6: 114000 | M6: 219271160 | N6: 136800000 | O6: -8040000 | P6: -82471160 | Q6: -37.61 | R6: -5.55
A7: 5 | B7: 300085 | C7: 이지스블루ON일반사모투자신탁제3호 | D7: KR7003550001 | E7: LG | F7: 2300 | G7: 101100 | H7: 238750907 | I7: 232530000 | J7: 2300 | K7: 2300 | L7: 102400 | M7: 238750907 | N7: 235520000 | O7: 2990000 | P7: -3230907 | Q7: -1.35 | R7: 1.28
A8: 6 | B8: 300085 | C8: 이지스블루ON일반사모투자신탁제3호 | D8: KR70043Y0003 | E8: TIME 차이나AI테크액티브 | F8: 11000 | G8: 25850 | H8: 235986793 | I8: 284350000 | J8: 11000 | K8: 11000 | L8: 26240 | M8: 235986793 | N8: 288640000 | O8: 4290000 | P8: 52653207 | Q8: 22.31 | R8: 1.5
A9: 7 | B9: 300085 | C9: 이지스블루ON일반사모투자신탁제3호 | D9: KR7005930003 | E9: 삼성전자 | F9: 1000 | G9: 309500 | H9: 359781920 | I9: 309500000 | J9: 1000 | K9: 1000 | L9: 316500 | M9: 359781920 | N9: 316500000 | O9: 7000000 | P9: -43281920 | Q9: -12.03 | R9: 2.26
A10: 8 | B10: 300085 | C10: 이지스블루ON일반사모투자신탁제3호 | D10: KR7009151002 | E10: 삼성전기우 | F10: 250 | G10: 695000 | H10: 225975740 | I10: 173750000 | J10: 250 | K10: 250 | L10: 669000 | M10: 225975740 | N10: 167250000 | O10: -6500000 | P10: -58725740 | Q10: -25.98 | R10: -3.74
A11: 9 | B11: 300085 | C11: 이지스블루ON일반사모투자신탁제3호 | D11: KR7010780005 | E11: 아이에스동서 | F11: 8000 | G11: 21900 | H11: 207612084 | I11: 175200000 | J11: 8000 | K11: 8000 | L11: 22400 | M11: 207612084 | N11: 179200000 | O11: 4000000 | P11: -28412084 | Q11: -13.68 | R11: 2.28
A12: 10 | B12: 300085 | C12: 이지스블루ON일반사모투자신탁제3호 | D12: KR70117V0007 | E12: TIGER 코리아AI전력기기TOP3플러스 | F12: 13000 | G12: 22210 | H12: 296005977 | I12: 288730000 | J12: 13000 | K12: 13000 | L12: 21455 | M12: 296005977 | N12: 278915000 | O12: -9815000 | P12: -17090977 | Q12: -5.77 | R12: -3.39
A13: 11 | B13: 300085 | C13: 이지스블루ON일반사모투자신탁제3호 | D13: KR7012450003 | E13: 한화에어로스페이스 | F13: 100 | G13: 1175000 | H13: 114676849 | I13: 117500000 | J13: 100 | K13: 100 | L13: 1191000 | M13: 114676849 | N13: 119100000 | O13: 1600000 | P13: 4423151 | Q13: 3.85 | R13: 1.36
A14: 12 | B14: 300085 | C14: 이지스블루ON일반사모투자신탁제3호 | D14: KR70148J0006 | E14: TIGER 코리아휴머노이드로봇산업 | F14: 20000 | G14: 9435 | H14: 264240479 | I14: 188700000 | J14: 20000 | K14: 20000 | L14: 9310 | M14: 264240479 | N14: 186200000 | O14: -2500000 | P14: -78040479 | Q14: -29.53 | R14: -1.32
... A38: 36 | B38: 300085 | C38: 이지스블루ON일반사모투자신탁제3호 | D38: KR7494340003 | E38: ACE 글로벌AI맞춤형반도체 | F38: 8000 | G38: 24890 | H38: 215756091 | I38: 199120000 | J38: 8000 | K38: 8000 | L38: 25155 | M38: 215756091 | N38: 201240000 | O38: 2120000 | P38: -14516091 | Q38: -6.72 | R38: 1.06
H39: 20259769310 | I39: 19595464500 | J39: 544516 | K39: 544516 | M39: 20259769310 | N39: 19524597200 | O39: -70867300 | P39: -735172110

Sheet 블루4
A1: NO | B1: 펀드 | C1: 펀드명 | D1: 종목 | E1: 종목명 | F1: 전일 | J1: 당일 | O1: 전일 대비 손익 | P1: 취득액 대비 손익(전체) (LONG손익 +차입매도분손익) | Q1: 취득액 대비 손익비율 (전체) | R1: 전일대비 종목증감비율
F2: 보유주수 | G2: 종가 | H2: 취득액 | I2: LONG평가금액 +차입매도분평가금액 | J2: 체결기준 보유주수 | K2: 주문기준 보유주수 | L2: 현재가 | M2: 취득액 | N2: LONG평가금액 +차입매도분평가금액 ▼
A3: 1 | B3: 300091 | C3: 이지스블루ON일반사모투자신탁제4호 | D3: KR7000150003 | E3: 두산 | F3: 87 | G3: 1433000 | H3: 141320880 | I3: 124671000 | J3: 87 | K3: 87 | L3: 1465000 | M3: 141320880 | N3: 127455000 | O3: 2784000 | P3: -13865880 | Q3: -9.81 | R3: 2.23
A4: 2 | B4: 300091 | C4: 이지스블루ON일반사모투자신탁제4호 | D4: KR7000660001 | E4: SK하이닉스 | F4: 80 | G4: 2425000 | H4: 223412998 | I4: 194000000 | J4: 80 | K4: 80 | L4: 2429000 | M4: 223412998 | N4: 194320000 | O4: 320000 | P4: -29092998 | Q4: -13.02 | R4: 0.16
A5: 3 | B5: 300091 | C5: 이지스블루ON일반사모투자신탁제4호 | D5: KR70008T0003 | E5: SOL 화장품TOP3플러스 | F5: 7000 | G5: 14870 | H5: 104069874 | I5: 104090000 | J5: 7000 | K5: 7000 | L5: 15385 | M5: 104069874 | N5: 107695000 | O5: 3605000 | P5: 3625126 | Q5: 3.48 | R5: 3.46
A6: 4 | B6: 300091 | C6: 이지스블루ON일반사모투자신탁제4호 | D6: KR7005930003 | E6: 삼성전자 | F6: 800 | G6: 309500 | H6: 286252099 | I6: 247600000 | J6: 800 | K6: 800 | L6: 316500 | M6: 286252099 | N6: 253200000 | O6: 5600000 | P6: -33052099 | Q6: -11.54 | R6: 2.26
A7: 5 | B7: 300091 | C7: 이지스블루ON일반사모투자신탁제4호 | D7: KR7009150004 | E7: 삼성전기 | F7: 94 | G7: 1989000 | H7: 202986871 | I7: 186966000 | J7: 94 | K7: 94 | L7: 1940000 | M7: 202986871 | N7: 182360000 | O7: -4606000 | P7: -20626871 | Q7: -10.16 | R7: -2.46
A8: 6 | B8: 300091 | C8: 이지스블루ON일반사모투자신탁제4호 | D8: KR7009151002 | E8: 삼성전기우 | F8: 250 | G8: 695000 | H8: 225852724 | I8: 173750000 | J8: 250 | K8: 250 | L8: 669000 | M8: 225852724 | N8: 167250000 | O8: -6500000 | P8: -58602724 | Q8: -25.94 | R8: -3.74
A9: 7 | B9: 300091 | C9: 이지스블루ON일반사모투자신탁제4호 | D9: KR7010780005 | E9: 아이에스동서 | F9: 3000 | G9: 21900 | H9: 72491440 | I9: 65700000 | J9: 3000 | K9: 3000 | L9: 22400 | M9: 72491440 | N9: 67200000 | O9: 1500000 | P9: -5291440 | Q9: -7.29 | R9: 2.28
A10: 8 | B10: 300091 | C10: 이지스블루ON일반사모투자신탁제4호 | D10: KR7012450003 | E10: 한화에어로스페이스 | F10: 50 | G10: 1175000 | H10: 57330421 | I10: 58750000 | J10: 50 | K10: 50 | L10: 1191000 | M10: 57330421 | N10: 59550000 | O10: 800000 | P10: 2219579 | Q10: 3.87 | R10: 1.36
A11: 9 | B11: 300091 | C11: 이지스블루ON일반사모투자신탁제4호 | D11: KR70168K0008 | E11: TIGER 기술이전바이오액티브 | F11: 10000 | G11: 7180 | H11: 75810415 | I11: 71800000 | J11: 10000 | K11: 10000 | L11: 6945 | M11: 75810415 | N11: 69450000 | O11: -2350000 | P11: -6360415 | Q11: -8.38 | R11: -3.27
A12: 10 | B12: 300091 | C12: 이지스블루ON일반사모투자신탁제4호 | D12: KR7075580001 | E12: 세진중공업 | F12: 100 | G12: 13430 | H12: 1373412 | I12: 1343000 | J12: 100 | K12: 100 | L12: 13690 | M12: 1373412 | N12: 1369000 | O12: 26000 | P12: -4412 | Q12: -0.32 | R12: 1.93
A13: 11 | B13: 300091 | C13: 이지스블루ON일반사모투자신탁제4호 | D13: KR7214450009 | E13: 파마리서치 | F13: 350 | G13: 341000 | H13: 115111022 | I13: 119350000 | J13: 350 | K13: 350 | L13: 325500 | M13: 115111022 | N13: 113925000 | O13: -5425000 | P13: -1186022 | Q13: -1.03 | R13: -4.54
A14: 12 | B14: 300091 | C14: 이지스블루ON일반사모투자신탁제4호 | D14: KR7233740000 | E14: KODEX 코스닥150레버리지 | F14: 10000 | G14: 9050 | H14: 109366001 | I14: 90500000 | J14: 10000 | K14: 10000 | L14: 8705 | M14: 109366001 | N14: 87050000 | O14: -3450000 | P14: -22316001 | Q14: -20.4 | R14: -3.81
... A17: 15 | B17: 300091 | C17: 이지스블루ON일반사모투자신탁제4호 | D17: KR7469830004 | E17: SOL 초단기채권액티브 | F17: 55000 | G17: 54065 | H17: 2971439015 | I17: 2973575000 | J17: 55000 | K17: 55000 | L17: 54070 | M17: 2971439015 | N17: 2973850000 | O17: 275000 | P17: 2410985 | Q17: 0.08 | R17: 0
H18: 4784077283 | I18: 4597752500 | J18: 90361 | K18: 90361 | M18: 4784077283 | N18: 4594396500 | O18: -3356000 | P18: -189680783

Sheet 아이타스41718_편드편입비정보
