Workbook

Sheet POST IPO 보고서
B2: POST IPO 모니터링 보고서
B3: 기준일: 2026-06-23 | 분석 대상: 77개 종목 | 2년 이내 신규 상장주
B6: 전체 종목 | D6: A등급 | F6: B등급 | H6: 50점 이상 종목수 | J6: RSI>65
B7: 77 | D7: 2 | F7: 3 | H7: 24 | J7: =COUNTIF(INDEX(전체!$A:$XFD,0,MATCH("RSI(14)",전체!$1:$1,0)),">=65")
B10: ▶ 추천종목 (종합스코어 50점 이상) | Q10: 구분 | R10: 종목수
B11: 순위 | C11: 종목명 | D11: 종합점수 | E11: 모멘텀 | F11: 수급 | G11: 거래량 | H11: RSI | I11: 등급 | J11: RSI신호 | K11: 등급변화 | L11: 점수변화량 | M11: 모멘텀Δ | N11: 수급Δ | O11: 거래량Δ | Q11: 강세 (A+B등급) | R11: 5
B12: 1 | C12: 달바글로벌 | D12: 92.4 | E12: 96.9 | F12: 97.2 | G12: 73.7 | H12: 51.42 | I12: A | K12: =IFERROR(IF(I12=INDEX(전체_전일자!1:1048576,MATCH(C12,전체_전일자!B:B,0),MATCH("등급",전체_전일자!1:1,0)),"유지",INDEX(전체_전일자!1:1048576,MATCH(C12,전체_전일자!B:B,0),MATCH("등급",전체_전일자!1:1,0))&" → "&I12),"") | L12: =IFERROR(D12-INDEX(전체_전일자!1:1048576,MATCH(C12,전체_전일자!B:B,0),MATCH("종합스코어",전체_전일자!1:1,0)),"") | M12: =IFERROR(E12-INDEX(전체_전일자!1:1048576,MATCH(C12,전체_전일자!B:B,0),MATCH("모멘텀스코어",전체_전일자!1:1,0)),"") | N12: =IFERROR(F12-INDEX(전체_전일자!1:1048576,MATCH(C12,전체_전일자!B:B,0),MATCH("수급스코어",전체_전일자!1:1,0)),"") | O12: =IFERROR(G12-INDEX(전체_전일자!1:1048576,MATCH(C12,전체_전일자!B:B,0),MATCH("거래량스코어",전체_전일자!1:1,0)),"") | Q12: 중립 (C등급) | R12: 19
B13: 2 | C13: 시프트업 | D13: 85.5 | E13: 99 | F13: 75.2 | G13: 90.8 | H13: 57.96 | I13: A | K13: =IFERROR(IF(I13=INDEX(전체_전일자!1:1048576,MATCH(C13,전체_전일자!B:B,0),MATCH("등급",전체_전일자!1:1,0)),"유지",INDEX(전체_전일자!1:1048576,MATCH(C13,전체_전일자!B:B,0),MATCH("등급",전체_전일자!1:1,0))&" → "&I13),"") | L13: =IFERROR(D13-INDEX(전체_전일자!1:1048576,MATCH(C13,전체_전일자!B:B,0),MATCH("종합스코어",전체_전일자!1:1,0)),"") | M13: =IFERROR(E13-INDEX(전체_전일자!1:1048576,MATCH(C13,전체_전일자!B:B,0),MATCH("모멘텀스코어",전체_전일자!1:1,0)),"") | N13: =IFERROR(F13-INDEX(전체_전일자!1:1048576,MATCH(C13,전체_전일자!B:B,0),MATCH("수급스코어",전체_전일자!1:1,0)),"") | O13: =IFERROR(G13-INDEX(전체_전일자!1:1048576,MATCH(C13,전체_전일자!B:B,0),MATCH("거래량스코어",전체_전일자!1:1,0)),"") | Q13: 약세 (D+F등급) | R13: 48
B14: 3 | C14: 듀켐바이오 | D14: 67.8 | E14: 93.1 | F14: 48.2 | G14: 78.9 | H14: 41.58 | I14: B | K14: =IFERROR(IF(I14=INDEX(전체_전일자!1:1048576,MATCH(C14,전체_전일자!B:B,0),MATCH("등급",전체_전일자!1:1,0)),"유지",INDEX(전체_전일자!1:1048576,MATCH(C14,전체_전일자!B:B,0),MATCH("등급",전체_전일자!1:1,0))&" → "&I14),"") | L14: =IFERROR(D14-INDEX(전체_전일자!1:1048576,MATCH(C14,전체_전일자!B:B,0),MATCH("종합스코어",전체_전일자!1:1,0)),"") | M14: =IFERROR(E14-INDEX(전체_전일자!1:1048576,MATCH(C14,전체_전일자!B:B,0),MATCH("모멘텀스코어",전체_전일자!1:1,0)),"") | N14: =IFERROR(F14-INDEX(전체_전일자!1:1048576,MATCH(C14,전체_전일자!B:B,0),MATCH("수급스코어",전체_전일자!1:1,0)),"") | O14: =IFERROR(G14-INDEX(전체_전일자!1:1048576,MATCH(C14,전체_전일자!B:B,0),MATCH("거래량스코어",전체_전일자!1:1,0)),"")
B15: 4 | C15: 케이뱅크 | D15: 67.3 | E15: 73.5 | F15: 86.9 | G15: 9.2 | H15: 46.76 | I15: B | K15: =IFERROR(IF(I15=INDEX(전체_전일자!1:1048576,MATCH(C15,전체_전일자!B:B,0),MATCH("등급",전체_전일자!1:1,0)),"유지",INDEX(전체_전일자!1:1048576,MATCH(C15,전체_전일자!B:B,0),MATCH("등급",전체_전일자!1:1,0))&" → "&I15),"") | L15: =IFERROR(D15-INDEX(전체_전일자!1:1048576,MATCH(C15,전체_전일자!B:B,0),MATCH("종합스코어",전체_전일자!1:1,0)),"") | M15: =IFERROR(E15-INDEX(전체_전일자!1:1048576,MATCH(C15,전체_전일자!B:B,0),MATCH("모멘텀스코어",전체_전일자!1:1,0)),"") | N15: =IFERROR(F15-INDEX(전체_전일자!1:1048576,MATCH(C15,전체_전일자!B:B,0),MATCH("수급스코어",전체_전일자!1:1,0)),"") | O15: =IFERROR(G15-INDEX(전체_전일자!1:1048576,MATCH(C15,전체_전일자!B:B,0),MATCH("거래량스코어",전체_전일자!1:1,0)),"")
B16: 5 | C16: 삼양엔씨켐 | D16: 65.5 | E16: 67.1 | F16: 60.8 | G16: 75 | H16: 50.34 | I16: B | K16: =IFERROR(IF(I16=INDEX(전체_전일자!1:1048576,MATCH(C16,전체_전일자!B:B,0),MATCH("등급",전체_전일자!1:1,0)),"유지",INDEX(전체_전일자!1:1048576,MATCH(C16,전체_전일자!B:B,0),MATCH("등급",전체_전일자!1:1,0))&" → "&I16),"") | L16: =IFERROR(D16-INDEX(전체_전일자!1:1048576,MATCH(C16,전체_전일자!B:B,0),MATCH("종합스코어",전체_전일자!1:1,0)),"") | M16: =IFERROR(E16-INDEX(전체_전일자!1:1048576,MATCH(C16,전체_전일자!B:B,0),MATCH("모멘텀스코어",전체_전일자!1:1,0)),"") | N16: =IFERROR(F16-INDEX(전체_전일자!1:1048576,MATCH(C16,전체_전일자!B:B,0),MATCH("수급스코어",전체_전일자!1:1,0)),"") | O16: =IFERROR(G16-INDEX(전체_전일자!1:1048576,MATCH(C16,전체_전일자!B:B,0),MATCH("거래량스코어",전체_전일자!1:1,0)),"")
B17: 6 | C17: 와이제이링크 | D17: 65 | E17: 18.3 | F17: 83.4 | G17: 88.8 | H17: 28.35 | I17: C | K17: =IFERROR(IF(I17=INDEX(전체_전일자!1:1048576,MATCH(C17,전체_전일자!B:B,0),MATCH("등급",전체_전일자!1:1,0)),"유지",INDEX(전체_전일자!1:1048576,MATCH(C17,전체_전일자!B:B,0),MATCH("등급",전체_전일자!1:1,0))&" → "&I17),"") | L17: =IFERROR(D17-INDEX(전체_전일자!1:1048576,MATCH(C17,전체_전일자!B:B,0),MATCH("종합스코어",전체_전일자!1:1,0)),"") | M17: =IFERROR(E17-INDEX(전체_전일자!1:1048576,MATCH(C17,전체_전일자!B:B,0),MATCH("모멘텀스코어",전체_전일자!1:1,0)),"") | N17: =IFERROR(F17-INDEX(전체_전일자!1:1048576,MATCH(C17,전체_전일자!B:B,0),MATCH("수급스코어",전체_전일자!1:1,0)),"") | O17: =IFERROR(G17-INDEX(전체_전일자!1:1048576,MATCH(C17,전체_전일자!B:B,0),MATCH("거래량스코어",전체_전일자!1:1,0)),"")
B18: 7 | C18: 산일전기 | D18: 62.9 | E18: 68.6 | F18: 57.5 | G18: 67.8 | H18: 42.84 | I18: C | K18: =IFERROR(IF(I18=INDEX(전체_전일자!1:1048576,MATCH(C18,전체_전일자!B:B,0),MATCH("등급",전체_전일자!1:1,0)),"유지",INDEX(전체_전일자!1:1048576,MATCH(C18,전체_전일자!B:B,0),MATCH("등급",전체_전일자!1:1,0))&" → "&I18),"") | L18: =IFERROR(D18-INDEX(전체_전일자!1:1048576,MATCH(C18,전체_전일자!B:B,0),MATCH("종합스코어",전체_전일자!1:1,0)),"") | M18: =IFERROR(E18-INDEX(전체_전일자!1:1048576,MATCH(C18,전체_전일자!B:B,0),MATCH("모멘텀스코어",전체_전일자!1:1,0)),"") | N18: =IFERROR(F18-INDEX(전체_전일자!1:1048576,MATCH(C18,전체_전일자!B:B,0),MATCH("수급스코어",전체_전일자!1:1,0)),"") | O18: =IFERROR(G18-INDEX(전체_전일자!1:1048576,MATCH(C18,전체_전일자!B:B,0),MATCH("거래량스코어",전체_전일자!1:1,0)),"")
B19: 8 | C19: 큐리오시스 | D19: 62.5 | E19: 52.3 | F19: 55.1 | G19: 96.1 | H19: 37.39 | I19: C | K19: =IFERROR(IF(I19=INDEX(전체_전일자!1:1048576,MATCH(C19,전체_전일자!B:B,0),MATCH("등급",전체_전일자!1:1,0)),"유지",INDEX(전체_전일자!1:1048576,MATCH(C19,전체_전일자!B:B,0),MATCH("등급",전체_전일자!1:1,0))&" → "&I19),"") | L19: =IFERROR(D19-INDEX(전체_전일자!1:1048576,MATCH(C19,전체_전일자!B:B,0),MATCH("종합스코어",전체_전일자!1:1,0)),"") | M19: =IFERROR(E19-INDEX(전체_전일자!1:1048576,MATCH(C19,전체_전일자!B:B,0),MATCH("모멘텀스코어",전체_전일자!1:1,0)),"") | N19: =IFERROR(F19-INDEX(전체_전일자!1:1048576,MATCH(C19,전체_전일자!B:B,0),MATCH("수급스코어",전체_전일자!1:1,0)),"") | O19: =IFERROR(G19-INDEX(전체_전일자!1:1048576,MATCH(C19,전체_전일자!B:B,0),MATCH("거래량스코어",전체_전일자!1:1,0)),"")
B20: 9 | C20: 로킷헬스케어 | D20: 61.1 | E20: 37.6 | F20: 73.9 | G20: 64.5 | H20: 26.51 | I20: C | K20: =IFERROR(IF(I20=INDEX(전체_전일자!1:1048576,MATCH(C20,전체_전일자!B:B,0),MATCH("등급",전체_전일자!1:1,0)),"유지",INDEX(전체_전일자!1:1048576,MATCH(C20,전체_전일자!B:B,0),MATCH("등급",전체_전일자!1:1,0))&" → "&I20),"") | L20: =IFERROR(D20-INDEX(전체_전일자!1:1048576,MATCH(C20,전체_전일자!B:B,0),MATCH("종합스코어",전체_전일자!1:1,0)),"") | M20: =IFERROR(E20-INDEX(전체_전일자!1:1048576,MATCH(C20,전체_전일자!B:B,0),MATCH("모멘텀스코어",전체_전일자!1:1,0)),"") | N20: =IFERROR(F20-INDEX(전체_전일자!1:1048576,MATCH(C20,전체_전일자!B:B,0),MATCH("수급스코어",전체_전일자!1:1,0)),"") | O20: =IFERROR(G20-INDEX(전체_전일자!1:1048576,MATCH(C20,전체_전일자!B:B,0),MATCH("거래량스코어",전체_전일자!1:1,0)),"")
B21: 10 | C21: 오름테라퓨틱 | D21: 60.6 | E21: 60 | F21: 80.9 | G21: 10.5 | H21: 37.63 | I21: C | K21: =IFERROR(IF(I21=INDEX(전체_전일자!1:1048576,MATCH(C21,전체_전일자!B:B,0),MATCH("등급",전체_전일자!1:1,0)),"유지",INDEX(전체_전일자!1:1048576,MATCH(C21,전체_전일자!B:B,0),MATCH("등급",전체_전일자!1:1,0))&" → "&I21),"") | L21: =IFERROR(D21-INDEX(전체_전일자!1:1048576,MATCH(C21,전체_전일자!B:B,0),MATCH("종합스코어",전체_전일자!1:1,0)),"") | M21: =IFERROR(E21-INDEX(전체_전일자!1:1048576,MATCH(C21,전체_전일자!B:B,0),MATCH("모멘텀스코어",전체_전일자!1:1,0)),"") | N21: =IFERROR(F21-INDEX(전체_전일자!1:1048576,MATCH(C21,전체_전일자!B:B,0),MATCH("수급스코어",전체_전일자!1:1,0)),"") | O21: =IFERROR(G21-INDEX(전체_전일자!1:1048576,MATCH(C21,전체_전일자!B:B,0),MATCH("거래량스코어",전체_전일자!1:1,0)),"")
B22: 11 | C22: 링크솔루션 | D22: 60 | E22: 18.1 | F22: 76 | G22: 82.9 | H22: 24.02 | I22: C | K22: =IFERROR(IF(I22=INDEX(전체_전일자!1:1048576,MATCH(C22,전체_전일자!B:B,0),MATCH("등급",전체_전일자!1:1,0)),"유지",INDEX(전체_전일자!1:1048576,MATCH(C22,전체_전일자!B:B,0),MATCH("등급",전체_전일자!1:1,0))&" → "&I22),"") | L22: =IFERROR(D22-INDEX(전체_전일자!1:1048576,MATCH(C22,전체_전일자!B:B,0),MATCH("종합스코어",전체_전일자!1:1,0)),"") | M22: =IFERROR(E22-INDEX(전체_전일자!1:1048576,MATCH(C22,전체_전일자!B:B,0),MATCH("모멘텀스코어",전체_전일자!1:1,0)),"") | N22: =IFERROR(F22-INDEX(전체_전일자!1:1048576,MATCH(C22,전체_전일자!B:B,0),MATCH("수급스코어",전체_전일자!1:1,0)),"") | O22: =IFERROR(G22-INDEX(전체_전일자!1:1048576,MATCH(C22,전체_전일자!B:B,0),MATCH("거래량스코어",전체_전일자!1:1,0)),"")
B23: 12 | C23: 클로봇 | D23: 59.8 | E23: 41.6 | F23: 84.7 | G23: 25 | H23: 29.99 | I23: C | K23: =IFERROR(IF(I23=INDEX(전체_전일자!1:1048576,MATCH(C23,전체_전일자!B:B,0),MATCH("등급",전체_전일자!1:1,0)),"유지",INDEX(전체_전일자!1:1048576,MATCH(C23,전체_전일자!B:B,0),MATCH("등급",전체_전일자!1:1,0))&" → "&I23),"") | L23: =IFERROR(D23-INDEX(전체_전일자!1:1048576,MATCH(C23,전체_전일자!B:B,0),MATCH("종합스코어",전체_전일자!1:1,0)),"") | M23: =IFERROR(E23-INDEX(전체_전일자!1:1048576,MATCH(C23,전체_전일자!B:B,0),MATCH("모멘텀스코어",전체_전일자!1:1,0)),"") | N23: =IFERROR(F23-INDEX(전체_전일자!1:1048576,MATCH(C23,전체_전일자!B:B,0),MATCH("수급스코어",전체_전일자!1:1,0)),"") | O23: =IFERROR(G23-INDEX(전체_전일자!1:1048576,MATCH(C23,전체_전일자!B:B,0),MATCH("거래량스코어",전체_전일자!1:1,0)),"")
B24: 13 | C24: 그래피 | D24: 58 | E24: 35.3 | F24: 61.7 | G24: 82.9 | H24: 25.48 | I24: C | K24: =IFERROR(IF(I24=INDEX(전체_전일자!1:1048576,MATCH(C24,전체_전일자!B:B,0),MATCH("등급",전체_전일자!1:1,0)),"유지",INDEX(전체_전일자!1:1048576,MATCH(C24,전체_전일자!B:B,0),MATCH("등급",전체_전일자!1:1,0))&" → "&I24),"") | L24: =IFERROR(D24-INDEX(전체_전일자!1:1048576,MATCH(C24,전체_전일자!B:B,0),MATCH("종합스코어",전체_전일자!1:1,0)),"") | M24: =IFERROR(E24-INDEX(전체_전일자!1:1048576,MATCH(C24,전체_전일자!B:B,0),MATCH("모멘텀스코어",전체_전일자!1:1,0)),"") | N24: =IFERROR(F24-INDEX(전체_전일자!1:1048576,MATCH(C24,전체_전일자!B:B,0),MATCH("수급스코어",전체_전일자!1:1,0)),"") | O24: =IFERROR(G24-INDEX(전체_전일자!1:1048576,MATCH(C24,전체_전일자!B:B,0),MATCH("거래량스코어",전체_전일자!1:1,0)),"")
B25: 14 | C25: 더즌 | D25: 56.2 | E25: 27.9 | F25: 57.8 | G25: 94.7 | H25: 23.42 | I25: C | K25: =IFERROR(IF(I25=INDEX(전체_전일자!1:1048576,MATCH(C25,전체_전일자!B:B,0),MATCH("등급",전체_전일자!1:1,0)),"유지",INDEX(전체_전일자!1:1048576,MATCH(C25,전체_전일자!B:B,0),MATCH("등급",전체_전일자!1:1,0))&" → "&I25),"") | L25: =IFERROR(D25-INDEX(전체_전일자!1:1048576,MATCH(C25,전체_전일자!B:B,0),MATCH("종합스코어",전체_전일자!1:1,0)),"") | M25: =IFERROR(E25-INDEX(전체_전일자!1:1048576,MATCH(C25,전체_전일자!B:B,0),MATCH("모멘텀스코어",전체_전일자!1:1,0)),"") | N25: =IFERROR(F25-INDEX(전체_전일자!1:1048576,MATCH(C25,전체_전일자!B:B,0),MATCH("수급스코어",전체_전일자!1:1,0)),"") | O25: =IFERROR(G25-INDEX(전체_전일자!1:1048576,MATCH(C25,전체_전일자!B:B,0),MATCH("거래량스코어",전체_전일자!1:1,0)),"")
... B35: 24 | C35: 뉴로핏 | D35: 50.1 | E35: 29.9 | F35: 66.4 | G35: 39.5 | H35: 28.46 | I35: C | K35: =IFERROR(IF(I35=INDEX(전체_전일자!1:1048576,MATCH(C35,전체_전일자!B:B,0),MATCH("등급",전체_전일자!1:1,0)),"유지",INDEX(전체_전일자!1:1048576,MATCH(C35,전체_전일자!B:B,0),MATCH("등급",전체_전일자!1:1,0))&" → "&I35),"") | L35: =IFERROR(D35-INDEX(전체_전일자!1:1048576,MATCH(C35,전체_전일자!B:B,0),MATCH("종합스코어",전체_전일자!1:1,0)),"") | M35: =IFERROR(E35-INDEX(전체_전일자!1:1048576,MATCH(C35,전체_전일자!B:B,0),MATCH("모멘텀스코어",전체_전일자!1:1,0)),"") | N35: =IFERROR(F35-INDEX(전체_전일자!1:1048576,MATCH(C35,전체_전일자!B:B,0),MATCH("수급스코어",전체_전일자!1:1,0)),"") | O35: =IFERROR(G35-INDEX(전체_전일자!1:1048576,MATCH(C35,전체_전일자!B:B,0),MATCH("거래량스코어",전체_전일자!1:1,0)),"")

Sheet 추천종목
A1: 코드 | B1: 코드명 | C1: 상장일 | D1: 현재가 | E1: 거래대금(억) | F1: 종합스코어 | G1: 모멘텀스코어 | H1: 수급스코어 | I1: 거래량스코어 | J1: RSI변화량 | K1: RSI(14) | L1: 전일RSI(14) | M1: RVOL(20) | N1: 기관_일간 | O1: 외국인_일간 | P1: 10일선돌파 | Q1: 20일선돌파 | R1: 60일선돌파 | S1: 변동성(30D) | T1: BB폭
A2: A483650 | B2: 달바글로벌 | D2: 207500 | E2: 456.9 | F2: 92.4 | G2: 96.9 | H2: 97.2 | I2: 73.7 | J2: 3 | K2: 51.42 | L2: 48.4 | M2: 1.14 | N2: 790.5 | O2: 221.4 | P2: 1 | Q2: 1 | R2: 1 | S2: 5.15 | T2: 30797.21
A3: A462870 | B3: 시프트업 | D3: 33250 | E3: 73.8 | F3: 85.5 | G3: 99 | H3: 75.2 | I3: 90.8 | J3: 3.6 | K3: 57.96 | L3: 54.37 | M3: 1.37 | N3: 82.9 | O3: 17.7 | P3: 1 | Q3: 1 | R3: 1 | S3: 3.52 | T3: 6408.4
A4: A176750 | B4: 듀켐바이오 | D4: 6560 | E4: 2.4 | F4: 67.8 | G4: 93.1 | H4: 48.2 | I4: 78.9 | J4: 0.2 | K4: 41.58 | L4: 41.37 | M4: 1.23 | N4: 0 | O4: -0.5 | P4: 1 | Q4: 1 | R4: 0 | S4: 3.8 | T4: 1904.24
A5: A279570 | B5: 케이뱅크 | D5: 6050 | E5: 212 | F5: 67.3 | G5: 73.5 | H5: 86.9 | I5: 9.2 | J5: -3.9 | K5: 46.76 | L5: 50.64 | M5: 0.51 | N5: 199.9 | O5: 24.3 | P5: 0 | Q5: 0 | R5: 0 | S5: 3.75 | T5: 2276.05
A6: A482630 | B6: 삼양엔씨켐 | D6: 18060 | E6: 115.4 | F6: 65.5 | G6: 67.1 | H6: 60.8 | I6: 75 | J6: -10.7 | K6: 50.34 | L6: 61.02 | M6: 1.16 | N6: 17.1 | O6: -55.4 | P6: 1 | Q6: 1 | R6: 0 | S6: 7.99 | T6: 9145.02
A7: A209640 | B7: 와이제이링크 | D7: 3995 | E7: 47.7 | F7: 65 | G7: 18.3 | H7: 83.4 | I7: 88.8 | J7: -2.8 | K7: 28.35 | L7: 31.14 | M7: 1.33 | N7: 41.1 | O7: 150.2 | P7: 0 | Q7: 0 | R7: 0 | S7: 5.61 | T7: 4858.12
A8: A062040 | B8: 산일전기 | D8: 222000 | E8: 800.8 | F8: 62.9 | G8: 68.6 | H8: 57.5 | I8: 67.8 | J8: -2.6 | K8: 42.84 | L8: 45.49 | M8: 1.08 | N8: 618.2 | O8: 117.8 | P8: 0 | Q8: 0 | R8: 0 | S8: 4.72 | T8: 70212.25
A9: A494120 | B9: 큐리오시스 | D9: 25650 | E9: 41.8 | F9: 62.5 | G9: 52.3 | H9: 55.1 | I9: 96.1 | J9: 4.8 | K9: 37.39 | L9: 32.62 | M9: 1.5 | N9: 87.5 | O9: -28.3 | P9: 0 | Q9: 0 | R9: 0 | S9: 7.88 | T9: 19865.8
A10: A376900 | B10: 로킷헬스케어 | D10: 36950 | E10: 67.3 | F10: 61.1 | G10: 37.6 | H10: 73.9 | I10: 64.5 | J10: -2.2 | K10: 26.51 | L10: 28.67 | M10: 1.05 | N10: 40.8 | O10: 264 | P10: 0 | Q10: 0 | R10: 0 | S10: 6.51 | T10: 23493.26
A11: A475830 | B11: 오름테라퓨틱 | D11: 56400 | E11: 81 | F11: 60.6 | G11: 60 | H11: 80.9 | I11: 10.5 | J11: -3.2 | K11: 37.63 | L11: 40.81 | M11: 0.53 | N11: 88.8 | O11: 218.1 | P11: 0 | Q11: 0 | R11: 0 | S11: 6.52 | T11: 19506.14
A12: A474650 | B12: 링크솔루션 | D12: 30600 | E12: 30.5 | F12: 60 | G12: 18.1 | H12: 76 | I12: 82.9 | J12: -3.9 | K12: 24.02 | L12: 27.92 | M12: 1.24 | N12: 0.6 | O12: 99.3 | P12: 0 | Q12: 0 | R12: 0 | S12: 4.41 | T12: 21797.02
A13: A466100 | B13: 클로봇 | D13: 30400 | E13: 71.7 | F13: 59.8 | G13: 41.6 | H13: 84.7 | I13: 25 | J13: -3.7 | K13: 29.99 | L13: 33.69 | M13: 0.66 | N13: 46.8 | O13: 229 | P13: 0 | Q13: 0 | R13: 0 | S13: 4.94 | T13: 19033.12
... A51: A336680 | B51: 탑런토탈솔루션 | D51: 2680 | E51: 0.7 | F51: 41.8 | G51: 45.3 | H51: 48.2 | I51: 20.4 | J51: -4.2 | K51: 20.33 | L51: 24.56 | M51: 0.62 | N51: 0 | O51: 0.1 | P51: 0 | Q51: 0 | R51: 0 | S51: 2.18 | T51: 735.49

Sheet A등급
A1: 코드 | B1: 코드명 | C1: 상장일 | D1: days_since_ipo | E1: 기관_일간 | F1: 기관_5일 | G1: 기관_20일 | H1: 외국인_일간 | I1: 외국인_5일 | J1: 외국인_20일 | K1: 현재가 | L1: 거래량 | M1: 거래대금(억) | N1: 20일평균거래량 | O1: RVOL(20) | P1: 변동성(30D) | Q1: RSI(14) | R1: 전일RSI(14) | S1: RSI변화량 | T1: 1일수익률(%) | U1: 20일수익률(%) | V1: 10일이평 | W1: 20일이평 | X1: 60일이평 | Y1: 10일선돌파 | Z1: 20일선돌파 | AA1: 60일선돌파 | AB1: BB폭 | AC1: 시가총액(억) | AD1: 모멘텀스코어 | AE1: 수급스코어 | AF1: 거래량스코어 | AG1: 종합스코어 | AH1: 등급
A2: A483650 | B2: 달바글로벌 | E2: 790.5 | F2: 1535.5 | G2: 1138.8 | H2: 221.4 | I2: 1910.7 | J2: 5502.1 | K2: 207500 | L2: 220213 | M2: 456.9 | N2: 192917.2 | O2: 1.14 | P2: 5.15 | Q2: 51.42 | R2: 48.4 | S2: 3 | T2: 3.49 | U2: -5.25 | V2: 202560 | W2: 200435 | X2: 200346.67 | Y2: 1 | Z2: 1 | AA2: 1 | AB2: 30797.21 | AC2: 27279 | AD2: 96.9 | AE2: 97.2 | AF2: 73.7 | AG2: 92.4 | AH2: A
A3: A462870 | B3: 시프트업 | E3: 82.9 | F3: 131.2 | G3: 954.5 | H3: 17.7 | I3: 314.1 | J3: 10.5 | K3: 33250 | L3: 221827 | M3: 73.8 | N3: 162004.15 | O3: 1.37 | P3: 3.52 | Q3: 57.96 | R3: 54.37 | S3: 3.6 | T3: 2.94 | U3: 12.71 | V3: 32055 | W3: 30955 | X3: 31877.5 | Y3: 1 | Z3: 1 | AA3: 1 | AB3: 6408.4 | AC3: 19532 | AD3: 99 | AE3: 75.2 | AF3: 90.8 | AG3: 85.5 | AH3: A

Sheet 전체
A1: 코드 | B1: 코드명 | C1: 상장일 | D1: days_since_ipo | E1: 기관_일간 | F1: 기관_5일 | G1: 기관_20일 | H1: 외국인_일간 | I1: 외국인_5일 | J1: 외국인_20일 | K1: 현재가 | L1: 거래량 | M1: 거래대금(억) | N1: 20일평균거래량 | O1: RVOL(20) | P1: 변동성(30D) | Q1: RSI(14) | R1: 전일RSI(14) | S1: RSI변화량 | T1: 1일수익률(%) | U1: 20일수익률(%) | V1: 10일이평 | W1: 20일이평 | X1: 60일이평 | Y1: 10일선돌파 | Z1: 20일선돌파 | AA1: 60일선돌파 | AB1: BB폭 | AC1: 시가총액(억) | AD1: 모멘텀스코어 | AE1: 수급스코어 | AF1: 거래량스코어 | AG1: 종합스코어 | AH1: 등급
A2: A107640 | B2: 한중엔시에스 | E2: -107.6 | F2: -253.8 | G2: -821.6 | H2: 113.4 | I2: 95.6 | J2: -700.5 | K2: 34500 | L2: 106584 | M2: 36.8 | N2: 123090.35 | O2: 0.87 | P2: 5.03 | Q2: 28.32 | R2: 32.8 | S2: -4.5 | T2: -10.16 | U2: -34.16 | V2: 41425 | W2: 44595 | X2: 52881.667 | Y2: 0 | Z2: 0 | AA2: 0 | AB2: 20789.31 | AC2: 3164 | AD2: 29.2 | AE2: 34.1 | AF2: 46.7 | AG2: 35.2 | AH2: D
A3: A464080 | B3: 에스오에스랩 | E3: 7.6 | F3: -1.4 | G3: 352.5 | H3: 16.6 | I3: -99.7 | J3: -91.8 | K3: 10120 | L3: 188804 | M3: 19.1 | N3: 388409.6 | O3: 0.49 | P3: 6.92 | Q3: 37.17 | R3: 40.92 | S3: -3.8 | T3: -8.5 | U3: -27.87 | V3: 11789 | W3: 11969.5 | X3: 14283.667 | Y3: 0 | Z3: 0 | AA3: 0 | AB3: 5262.13 | AC3: 1795 | AD3: 46 | AE3: 49.9 | AF3: 7.9 | AG3: 40.3 | AH3: D
A4: A160190 | B4: 하이젠알앤엠 | E4: -4.6 | F4: 38.4 | G4: 133.6 | H4: 33.4 | I4: 118 | J4: 582.5 | K4: 21250 | L4: 101406 | M4: 21.5 | N4: 178707.95 | O4: 0.57 | P4: 5.44 | Q4: 26.62 | R4: 31.29 | S4: -4.7 | T4: -12.37 | U4: -40.97 | V4: 25950 | W4: 28325 | X4: 35566.667 | Y4: 0 | Z4: 0 | AA4: 0 | AB4: 14783.03 | AC4: 6826 | AD4: 14.4 | AE4: 67.8 | AF4: 15.8 | AG4: 41.4 | AH4: D
A5: A295310 | B5: 에이치브이엠 | E5: -616.9 | F5: -2042.9 | G5: -2063.9 | H5: 991.4 | I5: 3381.5 | J5: 3375.4 | K5: 55000 | L5: 383856 | M5: 211.1 | N5: 376266.2 | O5: 1.02 | P5: 10.4 | Q5: 29.98 | R5: 31.81 | S5: -1.8 | T5: -8.94 | U5: -51.33 | V5: 83230 | W5: 94960 | X5: 93263.333 | Y5: 0 | Z5: 0 | AA5: 0 | AB5: 77079.33 | AC5: 6385 | AD5: 21.1 | AE5: 52 | AF5: 63.2 | AG5: 45 | AH5: D
A6: A462350 | B6: 이노스페이스 | E6: -551 | F6: -744 | G6: -1535.6 | H6: 199.3 | I6: -97.7 | J6: 501.7 | K6: 8710 | L6: 1387599 | M6: 120.9 | N6: 563413.45 | O6: 2.46 | P6: 5.61 | Q6: 27.33 | R6: 34.69 | S6: -7.4 | T6: -16.41 | U6: -32.79 | V6: 11804.1 | W6: 12093 | X6: 12603.067 | Y6: 0 | Z6: 0 | AA6: 0 | AB6: 4409.07 | AC6: 1850 | AD6: 21.2 | AE6: 33.8 | AF6: 100 | AG6: 43.3 | AH6: D
A7: A462870 | B7: 시프트업 | E7: 82.9 | F7: 131.2 | G7: 954.5 | H7: 17.7 | I7: 314.1 | J7: 10.5 | K7: 33250 | L7: 221827 | M7: 73.8 | N7: 162004.15 | O7: 1.37 | P7: 3.52 | Q7: 57.96 | R7: 54.37 | S7: 3.6 | T7: 2.94 | U7: 12.71 | V7: 32055 | W7: 30955 | X7: 31877.5 | Y7: 1 | Z7: 1 | AA7: 1 | AB7: 6408.4 | AC7: 19532 | AD7: 99 | AE7: 75.2 | AF7: 90.8 | AG7: 85.5 | AH7: A
A8: A062040 | B8: 산일전기 | E8: 618.2 | F8: -2157.6 | G8: -570.1 | H8: 117.8 | I8: 2436.1 | J8: -927.6 | K8: 222000 | L8: 360735 | M8: 800.8 | N8: 333086.25 | O8: 1.08 | P8: 4.72 | Q8: 42.84 | R8: 45.49 | S8: -2.6 | T8: -3.27 | U8: -21.42 | V8: 234750 | W8: 237300 | X8: 225170 | Y8: 0 | Z8: 0 | AA8: 0 | AB8: 70212.25 | AC8: 68426 | AD8: 68.6 | AE8: 57.5 | AF8: 67.8 | AG8: 62.9 | AH8: C
A9: A079900 | B9: 전진건설로봇 | E9: -10.1 | F9: -121.8 | G9: -307.4 | H9: 66.5 | I9: 131.9 | J9: 16.2 | K9: 41800 | L9: 101771 | M9: 42.5 | N9: 81623.95 | O9: 1.25 | P9: 5.59 | Q9: 30.82 | R9: 36.41 | S9: -5.6 | T9: -12 | U9: -32.14 | V9: 52745 | W9: 54280 | X9: 59813.333 | Y9: 0 | Z9: 0 | AA9: 0 | AB9: 19382.4 | AC9: 6019 | AD9: 30.6 | AE9: 45.9 | AF9: 85.5 | AG9: 49.2 | AH9: D
A10: A389650 | B10: 넥스트바이오메디컬 | E10: 12.2 | F10: -40.1 | G10: 327.9 | H10: 32 | I10: -168.2 | J10: -294 | K10: 38700 | L10: 50753 | M10: 19.6 | N10: 82370.05 | O10: 0.62 | P10: 5.99 | Q10: 38.2 | R10: 40.49 | S10: -2.3 | T10: -3.97 | U10: -20.12 | V10: 40965 | W10: 42007.5 | X10: 54881.667 | Y10: 0 | Z10: 0 | AA10: 0 | AB10: 9665.46 | AC10: 3373 | AD10: 64.9 | AE10: 45.9 | AF10: 20.4 | AG10: 46.5 | AH10: D
A11: A461300 | B11: 아이스크림미디어 | E11: -56.8 | F11: -200.9 | G11: -698.6 | H11: 4 | I11: 65.2 | J11: 261.3 | K11: 15700 | L11: 88291 | M11: 13.9 | N11: 71093.4 | O11: 1.24 | P11: 3.01 | Q11: 40.03 | R11: 46.42 | S11: -6.4 | T11: -5.25 | U11: -15.23 | V11: 16654 | W11: 16740 | X11: 16872.167 | Y11: 0 | Z11: 0 | AA11: 0 | AB11: 2128.74 | AC11: 2081 | AD11: 66.5 | AE11: 32.9 | AF11: 82.9 | AG11: 53 | AH11: C
A12: A308430 | B12: 셀비온 | E12: -0.2 | F12: 32.8 | G12: 126.2 | H12: 13.5 | I12: -28.9 | J12: 55.8 | K12: 16100 | L12: 43862 | M12: 7.1 | N12: 64280.2 | O12: 0.68 | P12: 3.69 | Q12: 21.85 | R12: 22.8 | S12: -0.9 | T12: -2.42 | U12: -31.49 | V12: 17552 | W12: 18994.5 | X12: 27299.833 | Y12: 0 | Z12: 0 | AA12: 0 | AB12: 8528.22 | AC12: 2116 | AD12: 44.8 | AE12: 54.4 | AF12: 27 | AG12: 46 | AH12: D
A13: A209640 | B13: 와이제이링크 | E13: 41.1 | F13: 46.6 | G13: 36.7 | H13: 150.2 | I13: 339.8 | J13: 375.7 | K13: 3995 | L13: 1195201 | M13: 47.7 | N13: 898658.45 | O13: 1.33 | P13: 5.61 | Q13: 28.35 | R13: 31.14 | S13: -2.8 | T13: -9.1 | U13: -55.61 | V13: 4795 | W13: 5662 | X13: 6273.9167 | Y13: 0 | Z13: 0 | AA13: 0 | AB13: 4858.12 | AC13: 1159 | AD13: 18.3 | AE13: 83.4 | AF13: 88.8 | AG13: 65 | AH13: C
... A54: A439260 | B54: 대한조선 | E54: -34.5 | F54: 70.3 | G54: -134 | H54: 115.4 | I54: -320.7 | J54: -1241.6 | K54: 53600 | L54: 130765 | M54: 70.1 | N54: 98869.6 | O54: 1.32 | P54: 2.9 | Q54: 24.25 | R54: 29.24 | S54: -5 | T54: -7.27 | U54: -23.65 | V54: 61130 | W54: 62135 | X54: 77128.333 | Y54: 0 | Z54: 0 | AA54: 0 | AB54: 13478.44 | AC54: 20987 | AD54: 41.3 | AE54: 41.9 | AF54: 86.8 | AG54: 50.7 | AH54: C
A55: A309710 | B55: 아이티켐 | E55: 0 | F55: 0 | G55: 0 | H55: 0 | I55: 0 | J55: 0 | K55: 21000 | L55: 0 | M55: 0 | N55: 0 | P55: 0 | Q55: 40.81 | R55: 40.81 | S55: 0 | T55: 0 | U55: 0 | V55: 21000 | W55: 21000 | X55: 21517.5 | Y55: 0 | Z55: 0 | AA55: 0 | AB55: 0 | AC55: 2684 | AD55: 74.4 | AE55: 48.3 | AH55: -
A56: A456160 | B56: 지투지바이오 | E56: -4.3 | F56: -766 | G56: -2435.9 | H56: 150.3 | I56: 781.2 | J56: 2073.6 | K56: 37650 | L56: 140139 | M56: 52.8 | N56: 217238.95 | O56: 0.65 | P56: 5.37 | Q56: 25.92 | R56: 28.8 | S56: -2.9 | T56: -8.28 | U56: -40.14 | V56: 44740 | W56: 50305 | X56: 65063.333 | Y56: 0 | Z56: 0 | AA56: 0 | AB56: 29845.86 | AC56: 6727 | AD56: 25.6 | AE56: 55.7 | AF56: 23 | AG56: 40.1 | AH56: D
A57: A484590 | B57: 삼양컴텍 | E57: 0 | F57: -26.7 | G57: -409.4 | H57: 4.6 | I57: -134.3 | J57: 31.5 | K57: 7510 | L57: 233672 | M57: 17.5 | N57: 426864.4 | O57: 0.55 | P57: 5.25 | Q57: 37.07 | R57: 40.83 | S57: -3.8 | T57: -7.17 | U57: -27.09 | V57: 8375 | W57: 8341 | X57: 10717.667 | Y57: 0 | Z57: 0 | AA57: 0 | AB57: 3337.59 | AC57: 3037 | AD57: 52 | AE57: 35.6 | AF57: 12.5 | AG57: 35.9 | AH57: D
A58: A125490 | B58: 한라캐스트 | E58: -19.2 | F58: -109.5 | G58: 1194.3 | H58: 117 | I58: 131.4 | J58: -672.5 | K58: 9230 | L58: 727236 | M58: 67.1 | N58: 1057770.2 | O58: 0.69 | P58: 6.07 | Q58: 29.82 | R58: 33.24 | S58: -3.4 | T58: -9.78 | U58: -41.99 | V58: 11632 | W58: 12621.5 | X58: 14461.333 | Y58: 0 | Z58: 0 | AA58: 0 | AB58: 7207.91 | AC58: 3329 | AD58: 22.4 | AE58: 50.8 | AF58: 29.6 | AG58: 38 | AH58: D
A59: A318060 | B59: 그래피 | E59: 21.7 | F59: 22.9 | G59: 46.3 | H59: -3.3 | I59: 28.6 | J59: 213.4 | K59: 17030 | L59: 183514 | M59: 31.3 | N59: 147887.6 | O59: 1.24 | P59: 4.77 | Q59: 25.48 | R59: 27.77 | S59: -2.3 | T59: -6.94 | U59: -36.81 | V59: 20847 | W59: 22173.5 | X59: 31170.333 | Y59: 0 | Z59: 0 | AA59: 0 | AB59: 8694.94 | AC59: 1935 | AD59: 35.3 | AE59: 61.7 | AF59: 82.9 | AG59: 58 | AH59: C
A60: A488280 | B60: 에스투더블유 | E60: -3.7 | F60: -27.1 | G60: -181.4 | H60: -29.3 | I60: -1.2 | J60: -32 | K60: 14010 | L60: 253512 | M60: 35.5 | N60: 205769.25 | O60: 1.23 | P60: 8.77 | Q60: 37.19 | R60: 36.26 | S60: 0.9 | T60: 1.82 | U60: -44.62 | V60: 15191 | W60: 17638 | X60: 19702 | Y60: 0 | Z60: 0 | AA60: 0 | AB60: 14780.97 | AC60: 1478 | AD60: 48.2 | AE60: 31.6 | AF60: 78.9 | AG60: 46 | AH60: D
A61: A317450 | B61: 명인제약 | E61: -0.7 | F61: -35.6 | G61: -600.2 | H61: -13.7 | I61: -36.6 | J61: 261.5 | K61: 41150 | L61: 20689 | M61: 8.5 | N61: 24944.15 | O61: 0.83 | P61: 2.47 | Q61: 29.81 | R61: 34.53 | S61: -4.7 | T61: -4.3 | U61: -20.1 | V61: 43605 | W61: 44750 | X61: 51351.667 | Y61: 0 | Z61: 0 | AA61: 0 | AB61: 8783.17 | AC61: 6059 | AD61: 56.8 | AE61: 33.4 | AF61: 43.4 | AG61: 42.4 | AH61: D
A62: A486990 | B62: 노타 | E62: -102.9 | F62: -287.4 | G62: -1790.8 | H62: 32.7 | I62: 7.4 | J62: -254.8 | K62: 22100 | L62: 222881 | M62: 49.3 | N62: 718030.95 | O62: 0.31 | P62: 8.42 | Q62: 34.17 | R62: 36.84 | S62: -2.7 | T62: -6.95 | U62: -25.59 | V62: 25640 | W62: 29572.5 | X62: 32145.833 | Y62: 0 | Z62: 0 | AA62: 0 | AB62: 20333.47 | AC62: 4664 | AD62: 53.1 | AE62: 27.2 | AF62: 2.6 | AG62: 30 | AH62: F
A63: A469610 | B63: 이노테크 | E63: -2 | F63: -9.4 | G63: -43.6 | H63: 16.8 | I63: -57.4 | J63: -61.4 | K63: 13820 | L63: 138640 | M63: 19.2 | N63: 172507.4 | O63: 0.8 | P63: 8.48 | Q63: 38.57 | R63: 43.2 | S63: -4.6 | T63: -12.09 | U63: -32.42 | V63: 16004 | W63: 16660.5 | X63: 20200.667 | Y63: 0 | Z63: 0 | AA63: 0 | AB63: 9808.6 | AC63: 1206 | AD63: 35.3 | AE63: 41.3 | AF63: 42.1 | AG63: 39.7 | AH63: D
A64: A494120 | B64: 큐리오시스 | E64: 87.5 | F64: 250.8 | G64: 131.5 | H64: -28.3 | I64: -412.4 | J64: 216.1 | K64: 25650 | L64: 162818 | M64: 41.8 | N64: 108202.45 | O64: 1.5 | P64: 7.88 | Q64: 37.39 | R64: 32.62 | S64: 4.8 | T64: 10.32 | U64: -40.62 | V64: 27150 | W64: 29727.5 | X64: 45791.667 | Y64: 0 | Z64: 0 | AA64: 0 | AB64: 19865.8 | AC64: 2098 | AD64: 52.3 | AE64: 55.1 | AF64: 96.1 | AG64: 62.5 | AH64: C
A65: A061090 | B65: 세나테크놀로지 | E65: -51.6 | F65: -135.4 | G65: -15.8 | H65: 27.4 | I65: 29.1 | J65: -23.3 | K65: 30400 | L65: 45779 | M65: 13.9 | N65: 70549.95 | O65: 0.65 | P65: 6.84 | Q65: 30.47 | R65: 34.53 | S65: -4.1 | T65: -10.32 | U65: -35.46 | V65: 38470 | W65: 42477.5 | X65: 41780 | Y65: 0 | Z65: 0 | AA65: 0 | AB65: 21883.28 | AC65: 1666 | AD65: 30.7 | AE65: 38 | AF65: 23 | AG65: 32.8 | AH65: D
A66: A403850 | B66: 더핑크퐁컴퍼니 | E66: -9.4 | F66: -19.7 | G66: -62.6 | H66: -13.4 | I66: -37.7 | J66: 36.2 | K66: 10480 | L66: 65588 | M66: 6.9 | N66: 73911.45 | O66: 0.89 | P66: 4.24 | Q66: 33.78 | R66: 38.18 | S66: -4.4 | T66: -6.76 | U66: -22.54 | V66: 11583 | W66: 11751 | X66: 14641.333 | Y66: 0 | Z66: 0 | AA66: 0 | AB66: 2791.33 | AC66: 1459 | AD66: 55.6 | AE66: 31.9 | AF66: 48.7 | AG66: 42.4 | AH66: D
A67: A388210 | B67: 씨엠티엑스 | E67: 8.2 | F67: 35.8 | G67: -790.5 | H67: -71.3 | I67: -185.9 | J67: 399.2 | K67: 94500 | L67: 70845 | M67: 66.9 | N67: 99565.45 | O67: 0.71 | P67: 5.96 | Q67: 37.1 | R67: 43 | S67: -5.9 | T67: -9.57 | U67: -22.92 | V67: 107580 | W67: 108445 | X67: 125598.33 | Y67: 0 | Z67: 0 | AA67: 0 | AB67: 29186.7 | AC67: 8959 | AD67: 46.5 | AE67: 42.7 | AF67: 33.6 | AG67: 42 | AH67: D
... A74: A279570 | B74: 케이뱅크 | E74: 199.9 | F74: 2905.5 | G74: 10962.5 | H74: 24.3 | I74: 508.6 | J74: 1595.3 | K74: 6050 | L74: 3503485 | M74: 212 | N74: 6823049.8 | O74: 0.51 | P74: 3.75 | Q74: 46.76 | R74: 50.64 | S74: -3.9 | T74: -3.66 | U74: 9.4 | V74: 6604 | W74: 6119.5 | X74: 6060.1667 | Y74: 0 | Z74: 0 | AA74: 0 | AB74: 2276.05 | AC74: 23733 | AD74: 73.5 | AE74: 86.9 | AF74: 9.2 | AG74: 67.3 | AH74: B
A75: A493280 | B75: 아이엠바이오로직스 | K75: 20500 | L75: 88659 | M75: 18.2 | N75: 93626.95 | O75: 0.95 | P75: 6.88 | Q75: 22.94 | R75: 24.77 | S75: -1.8 | T75: -9.29 | U75: -45.98 | V75: 25605 | W75: 28322.5 | X75: 42917.5 | Y75: 0 | Z75: 0 | AA75: 0 | AB75: 17809.83 | AC75: 3514 | AD75: 13.9 | AF75: 54.6 | AH75: -
A76: A394420 | B76: 리센스메디컬 | K76: 21400 | L76: 338129 | M76: 72.4 | N76: 254269.1 | O76: 1.33 | P76: 5.74 | Q76: 50.18 | R76: 53.03 | S76: -2.9 | T76: -3.82 | U76: -26.71 | V76: 20040 | W76: 21799.5 | Y76: 1 | Z76: 0 | AA76: 0 | AB76: 13762.74 | AC76: 2285 | AD76: 84 | AF76: 88.8 | AH76: -
A77: A439960 | B77: 코스모로보틱스 | K77: 18100 | L77: 1309515 | M77: 237 | N77: 4457775.8 | O77: 0.29 | Q77: 51.4 | R77: 54.04 | S77: -2.6 | T77: -11.71 | U77: -61.12 | V77: 22542 | W77: 28046 | Y77: 0 | Z77: 0 | AA77: 0 | AB77: 30321.96 | AC77: 6003 | AD77: 24.4 | AF77: 1.3 | AH77: -
A78: A477850 | B78: 마키나락스 | K78: 13750 | L78: 550848 | M78: 75.7 | N78: 1717148.6 | O78: 0.32 | Q78: 69.08 | R78: 70.59 | S78: -1.5 | T78: -11.23 | U78: -74.82 | V78: 18601 | W78: 25110.5 | Y78: 0 | Z78: 0 | AA78: 0 | AB78: 34080.94 | AC78: 2461 | AD78: 25.8 | AF78: 3.9 | AH78: -

Sheet 전체_전일자
A1: 코드 | B1: 코드명 | C1: 상장일 | D1: days_since_ipo | E1: 기관_일간 | F1: 기관_5일 | G1: 기관_20일 | H1: 외국인_일간 | I1: 외국인_5일 | J1: 외국인_20일 | K1: 현재가 | L1: 거래량 | M1: 거래대금(억) | N1: 20일평균거래량 | O1: RVOL(20) | P1: 변동성(30D) | Q1: RSI(14) | R1: 전일RSI(14) | S1: RSI변화량 | T1: 1일수익률(%) | U1: 20일수익률(%) | V1: 10일이평 | W1: 20일이평 | X1: 60일이평 | Y1: 10일선돌파 | Z1: 20일선돌파 | AA1: 60일선돌파 | AB1: BB폭 | AC1: 시가총액(억) | AD1: 모멘텀스코어 | AE1: 수급스코어 | AF1: 거래량스코어 | AG1: 종합스코어 | AH1: 등급
A2: A107640 | B2: 한중엔시에스 | E2: -79.7 | F2: -124.6 | G2: -715.4 | H2: 123 | I2: -74.8 | J2: -931.5 | K2: 38400 | L2: 82998 | M2: 31.9 | N2: 122564.75 | O2: 0.68 | P2: 4.78 | Q2: 32.8 | R2: 34.55 | S2: -1.8 | T2: -3.4 | U2: -23.96 | V2: 42150 | W2: 45490 | X2: 53185 | Y2: 0 | Z2: 0 | AA2: 0 | AB2: 19661.8 | AC2: 3164 | AD2: 36 | AE2: 31.9 | AF2: 55.9 | AG2: 37.9 | AH2: D
A3: A464080 | B3: 에스오에스랩 | E3: -4.7 | F3: 149.2 | G3: 348.9 | H3: -6.9 | I3: -121.4 | J3: -75.2 | K3: 11060 | L3: 135421 | M3: 15 | N3: 393874.35 | O3: 0.34 | P3: 7.02 | Q3: 40.92 | R3: 41.92 | S3: -1 | T3: -2.12 | U3: -13.73 | V3: 11841 | W3: 12165 | X3: 14398.167 | Y3: 0 | Z3: 0 | AA3: 0 | AB3: 5266.73 | AC3: 1795 | AD3: 57.5 | AE3: 45.3 | AF3: 8.6 | AG3: 41.6 | AH3: D
A4: A160190 | B4: 하이젠알앤엠 | E4: 3.2 | F4: 45.4 | G4: 145.4 | H4: 27.7 | I4: 107 | J4: 446.3 | K4: 24250 | L4: 70555 | M4: 17.1 | N4: 179219.85 | O4: 0.39 | P4: 5.08 | Q4: 31.29 | R4: 33.18 | S4: -1.9 | T4: -4.15 | U4: -33.1 | V4: 26535 | W4: 29062.5 | X4: 35885 | Y4: 0 | Z4: 0 | AA4: 0 | AB4: 14728.05 | AC4: 6826 | AD4: 25 | AE4: 80.2 | AF4: 12.5 | AG4: 50.1 | AH4: C
A5: A295310 | B5: 에이치브이엠 | E5: -83.9 | F5: -2103 | G5: -1501 | H5: 529.8 | I5: 2472 | J5: 2299 | K5: 60400 | L5: 246930 | M5: 149.1 | N5: 368518.7 | O5: 0.67 | P5: 10.43 | Q5: 31.81 | R5: 33.72 | S5: -1.9 | T5: -8.21 | U5: -45.54 | V5: 87570 | W5: 97860 | X5: 94215 | Y5: 0 | Z5: 0 | AA5: 0 | AB5: 69206.75 | AC5: 6385 | AD5: 10.3 | AE5: 53 | AF5: 53.3 | AG5: 40.2 | AH5: D
A6: A462350 | B6: 이노스페이스 | E6: -44.1 | F6: -273 | G6: -985 | H6: -11.5 | I6: -315.5 | J6: 335.2 | K6: 10420 | L6: 299454 | M6: 31.2 | N6: 511850.3 | O6: 0.59 | P6: 5.03 | Q6: 34.69 | R6: 38.58 | S6: -3.9 | T6: -6.21 | U6: -19.49 | V6: 12207.4 | W6: 12305.5 | X6: 12689.1 | Y6: 0 | Z6: 0 | AA6: 0 | AB6: 3187.94 | AC6: 1850 | AD6: 34.4 | AE6: 22.3 | AF6: 38.2 | AG6: 29.1 | AH6: F
A7: A462870 | B7: 시프트업 | E7: 44.1 | F7: 64.1 | G7: 853.7 | H7: -85.6 | I7: 261.7 | J7: 1.2 | K7: 32300 | L7: 164893 | M7: 53.3 | N7: 154147.3 | O7: 1.07 | P7: 3.51 | Q7: 54.37 | R7: 59.32 | S7: -5 | T7: -3 | U7: 11.96 | V7: 32060 | W7: 30767.5 | X7: 31848.333 | Y7: 1 | Z7: 1 | AA7: 1 | AB7: 6163.21 | AC7: 19532 | AD7: 84.7 | AE7: 66.7 | AF7: 89.5 | AG7: 76.7 | AH7: B
A8: A062040 | B8: 산일전기 | E8: -635.4 | F8: -1767.1 | G8: 286.2 | H8: 1003.8 | I8: 807.9 | J8: -3737.7 | K8: 229500 | L8: 162899 | M8: 373.9 | N8: 330722.6 | O8: 0.49 | P8: 4.76 | Q8: 45.49 | R8: 47.69 | S8: -2.2 | T8: -2.55 | U8: -16.85 | V8: 235050 | W8: 240325 | X8: 224233.33 | Y8: 0 | Z8: 0 | AA8: 1 | AB8: 78933.58 | AC8: 68426 | AD8: 54.9 | AE8: 49.2 | AF8: 25 | AG8: 46.1 | AH8: D
A9: A079900 | B9: 전진건설로봇 | E9: -3 | F9: -159.4 | G9: -329.7 | H9: -0.1 | I9: -29.2 | J9: -82.8 | K9: 47500 | L9: 80294 | M9: 38.1 | N9: 79977.45 | O9: 1 | P9: 5.22 | Q9: 36.41 | R9: 38.63 | S9: -2.2 | T9: -3.94 | U9: -19.63 | V9: 53745 | W9: 55270 | X9: 60045 | Y9: 0 | Z9: 0 | AA9: 0 | AB9: 16681.18 | AC9: 6019 | AD9: 41.3 | AE9: 31.7 | AF9: 86.8 | AG9: 45.6 | AH9: D
A10: A389650 | B10: 넥스트바이오메디컬 | E10: 19.6 | F10: 22.6 | G10: 350.5 | H10: -15.8 | I10: -183.1 | J10: -274.9 | K10: 40300 | L10: 48658 | M10: 19.6 | N10: 83897.55 | O10: 0.58 | P10: 5.96 | Q10: 40.49 | R10: 40.49 | S10: 0 | T10: 0 | U10: -12.39 | V10: 41190 | W10: 42495 | X10: 55503.333 | Y10: 0 | Z10: 0 | AA10: 0 | AB10: 10680.43 | AC10: 3373 | AD10: 64.4 | AE10: 49.6 | AF10: 35.5 | AG10: 51.2 | AH10: C
A11: A461300 | B11: 아이스크림미디어 | E11: -4.9 | F11: -126.9 | G11: -643.1 | H11: -35 | I11: 65.7 | J11: 284 | K11: 16570 | L11: 49765 | M11: 8.2 | N11: 69145.85 | O11: 0.72 | P11: 2.86 | Q11: 46.42 | R11: 50.37 | S11: -3.9 | T11: -2.7 | U11: -8.71 | V11: 16758 | W11: 16881 | X11: 16909.833 | Y11: 0 | Z11: 0 | AA11: 0 | AB11: 2425.46 | AC11: 2081 | AD11: 61.3 | AE11: 37.5 | AF11: 67.8 | AG11: 50.7 | AH11: C
A12: A308430 | B12: 셀비온 | E12: 3.4 | F12: 48.3 | G12: 147.5 | H12: -8.9 | I12: -48.1 | J12: -109.3 | K12: 16500 | L12: 33562 | M12: 5.5 | N12: 76643.9 | O12: 0.44 | P12: 3.68 | Q12: 22.8 | R12: 23.56 | S12: -0.8 | T12: -1.9 | U12: -38.55 | V12: 17735 | W12: 19364.5 | X12: 27543.167 | Y12: 0 | Z12: 0 | AA12: 0 | AB12: 8948.59 | AC12: 2116 | AD12: 25.2 | AE12: 54.9 | AF12: 18.4 | AG12: 38.7 | AH12: D
A13: A209640 | B13: 와이제이링크 | E13: 0.9 | F13: 3.7 | G13: -4.4 | H13: 100.4 | I13: 218.1 | J13: 239.5 | K13: 4395 | L13: 630614 | M13: 27.7 | N13: 889235.25 | O13: 0.71 | P13: 5.75 | Q13: 31.14 | R13: 31.29 | S13: -0.1 | T13: -0.45 | U13: -48.11 | V13: 4940.5 | W13: 5912.25 | X13: 6289.75 | Y13: 0 | Z13: 0 | AA13: 0 | AB13: 5412.02 | AC13: 1159 | AD13: 31 | AE13: 76.4 | AF13: 61.2 | AG13: 59.7 | AH13: C
... A54: A439260 | B54: 대한조선 | E54: -29.6 | F54: 153.9 | G54: -106.8 | H54: -173.7 | I54: -545.6 | J54: -1499.4 | K54: 57800 | L54: 86328 | M54: 49.9 | N54: 96221.1 | O54: 0.9 | P54: 2.69 | Q54: 29.24 | R54: 33.52 | S54: -4.3 | T54: -4.62 | U54: -15 | V54: 61860 | W54: 62965 | X54: 77723.333 | Y54: 0 | Z54: 0 | AA54: 0 | AB54: 12822.03 | AC54: 20987 | AD54: 35.1 | AE54: 26.4 | AF54: 82.2 | AG54: 40.2 | AH54: D
A55: A309710 | B55: 아이티켐 | E55: 0 | F55: 0 | G55: 0 | H55: 0 | I55: 0 | J55: 0 | K55: 21000 | L55: 0 | M55: 0 | N55: 0 | P55: 0 | Q55: 40.81 | R55: 40.81 | S55: 0 | T55: 0 | U55: 0 | V55: 21000 | W55: 21000 | X55: 21699.167 | Y55: 0 | Z55: 0 | AA55: 0 | AB55: 0 | AC55: 2684 | AD55: 69.6 | AE55: 55.3 | AH55: -
A56: A456160 | B56: 지투지바이오 | E56: -126.7 | F56: -757.7 | G56: -2017.4 | H56: 179.1 | I56: 753 | J56: 2163.2 | K56: 41050 | L56: 160767 | M56: 66 | N56: 227843.4 | O56: 0.71 | P56: 5.25 | Q56: 28.8 | R56: 29.93 | S56: -1.1 | T56: -2.96 | U56: -27.73 | V56: 45810 | W56: 51567.5 | X56: 65754.167 | Y56: 0 | Z56: 0 | AA56: 0 | AB56: 29394.92 | AC56: 6727 | AD56: 33.2 | AE56: 50.7 | AF56: 61.2 | AG56: 47.6 | AH56: D
A57: A484590 | B57: 삼양컴텍 | E57: -11.1 | F57: 0.9 | G57: -363.9 | H57: 15.3 | I57: -86.9 | J57: 57.9 | K57: 8090 | L57: 224385 | M57: 18.2 | N57: 426708.1 | O57: 0.53 | P57: 5.13 | Q57: 40.83 | R57: 46.59 | S57: -5.8 | T57: -8.59 | U57: -14.39 | V57: 8343 | W57: 8480.5 | X57: 10796.5 | Y57: 0 | Z57: 0 | AA57: 0 | AB57: 3653.2 | AC57: 3037 | AD57: 38.2 | AE57: 44.4 | AF57: 31.6 | AG57: 40 | AH57: D
A58: A125490 | B58: 한라캐스트 | E58: -7.7 | F58: -51 | G58: 1206.3 | H58: 37.1 | I58: -29 | J58: -736.3 | K58: 10230 | L58: 475158 | M58: 48.6 | N58: 1061712 | O58: 0.45 | P58: 6.42 | Q58: 33.24 | R58: 34.42 | S58: -1.2 | T58: -3.03 | U58: -34.34 | V58: 11889 | W58: 12955.5 | X58: 14578.167 | Y58: 0 | Z58: 0 | AA58: 0 | AB58: 7044.05 | AC58: 3329 | AD58: 29.4 | AE58: 46.7 | AF58: 19.7 | AG58: 36.1 | AH58: D
A59: A318060 | B59: 그래피 | E59: 6.2 | F59: 24.1 | G59: 24.7 | H59: 29.2 | I59: 32.5 | J59: 240.2 | K59: 18300 | L59: 103423 | M59: 18.9 | N59: 144646.5 | O59: 0.72 | P59: 4.75 | Q59: 27.77 | R59: 28.98 | S59: -1.2 | T59: -3.38 | U59: -30.15 | V59: 21424 | W59: 22669.5 | X59: 31670.667 | Y59: 0 | Z59: 0 | AA59: 0 | AB59: 8291.75 | AC59: 1935 | AD59: 27.7 | AE59: 74 | AF59: 67.8 | AG59: 58.9 | AH59: C
A60: A488280 | B60: 에스투더블유 | E60: -0.3 | F60: -23.4 | G60: -195.3 | H60: -14.1 | I60: 4.7 | J60: -54 | K60: 13760 | L60: 122457 | M60: 16.9 | N60: 207908.95 | O60: 0.59 | P60: 8.75 | Q60: 36.26 | R60: 38.43 | S60: -2.2 | T60: -6.9 | U60: -41.45 | V60: 15390 | W60: 18202.5 | X60: 19718 | Y60: 0 | Z60: 0 | AA60: 0 | AB60: 15805.49 | AC60: 1478 | AD60: 18.2 | AE60: 41.2 | AF60: 38.2 | AG60: 33.7 | AH60: D
A61: A317450 | B61: 명인제약 | E61: -4.3 | F61: -217.3 | G61: -643.1 | H61: -7.3 | I61: 81.3 | J61: 322.1 | K61: 43000 | L61: 16205 | M61: 7 | N61: 25117.65 | O61: 0.65 | P61: 2.39 | Q61: 34.53 | R61: 35.96 | S61: -1.4 | T61: -1.15 | U61: -12.42 | V61: 43870 | W61: 45267.5 | X61: 51612.5 | Y61: 0 | Z61: 0 | AA61: 0 | AB61: 9946.91 | AC61: 6059 | AD61: 57 | AE61: 40.6 | AF61: 51.3 | AG61: 47.7 | AH61: D
A62: A486990 | B62: 노타 | E62: 2.6 | F62: -153.8 | G62: -1678.6 | H62: -5.3 | I62: -33.2 | J62: -257.2 | K62: 23750 | L62: 188181 | M62: 44.7 | N62: 713082.75 | O62: 0.26 | P62: 8.38 | Q62: 36.84 | R62: 35.28 | S62: 1.6 | T62: 2.37 | U62: -14.26 | V62: 26450 | W62: 29952.5 | X62: 32483.333 | Y62: 0 | Z62: 0 | AA62: 0 | AB62: 19143.72 | AC62: 4664 | AD62: 63.8 | AE62: 34.1 | AF62: 2.6 | AG62: 36.7 | AH62: D
A63: A469610 | B63: 이노테크 | E63: -0.1 | F63: -7.4 | G63: -50.5 | H63: -8.2 | I63: -88.3 | J63: -69.1 | K63: 15720 | L63: 118298 | M63: 18.6 | N63: 172820.75 | O63: 0.68 | P63: 8.24 | Q63: 43.2 | R63: 46.48 | S63: -3.3 | T63: -7.09 | U63: -16.47 | V63: 16051 | W63: 16992 | X63: 20310.333 | Y63: 0 | Z63: 0 | AA63: 0 | AB63: 9974.16 | AC63: 1206 | AD63: 39.7 | AE63: 40 | AF63: 55.9 | AG63: 43.1 | AH63: D
A64: A494120 | B64: 큐리오시스 | E64: 42.1 | F64: 224 | G64: -2.7 | H64: 9.7 | I64: -580.9 | J64: 344.1 | K64: 23250 | L64: 151158 | M64: 35.1 | N64: 103780.4 | O64: 1.46 | P64: 7.61 | Q64: 32.62 | R64: 34.99 | S64: -2.4 | T64: -9 | U64: -43.36 | V64: 27245 | W64: 30605 | X64: 46337.5 | Y64: 0 | Z64: 0 | AA64: 0 | AB64: 22676.76 | AC64: 2098 | AD64: 11.3 | AE64: 63.9 | AF64: 94.7 | AG64: 54.3 | AH64: C
A65: A061090 | B65: 세나테크놀로지 | E65: -0.4 | F65: -84.6 | G65: 31.2 | H65: -0.9 | I65: -46.9 | J65: 38.1 | K65: 33900 | L65: 17586 | M65: 6 | N65: 72108.35 | O65: 0.24 | P65: 8.74 | Q65: 34.53 | R65: 35.93 | S65: -1.4 | T65: -3.14 | U65: -17.01 | V65: 39870 | W65: 43312.5 | X65: 41908.333 | Y65: 0 | Z65: 0 | AA65: 0 | AB65: 19186.54 | AC65: 1666 | AD65: 43.8 | AE65: 43.6 | AF65: 1.3 | AG65: 35.2 | AH65: D
A66: A403850 | B66: 더핑크퐁컴퍼니 | E66: 3.1 | F66: -11.5 | G66: -51.9 | H66: -37.1 | I66: -27.9 | J66: 66.2 | K66: 11240 | L66: 141125 | M66: 15.9 | N66: 72842.55 | O66: 1.94 | P66: 4.13 | Q66: 38.18 | R66: 37.28 | S66: 0.9 | T66: 0.81 | U66: -12.94 | V66: 11626 | W66: 11903.5 | X66: 14752.5 | Y66: 0 | Z66: 0 | AA66: 0 | AB66: 2942.6 | AC66: 1459 | AD66: 64 | AE66: 47.4 | AF66: 97.4 | AG66: 62.4 | AH66: C
A67: A388210 | B67: 씨엠티엑스 | E67: -13 | F67: -38.4 | G67: -624 | H67: -81.5 | I67: -102.9 | J67: 303.5 | K67: 104500 | L67: 71879 | M67: 75.1 | N67: 101419.4 | O67: 0.71 | P67: 5.74 | Q67: 43 | R67: 41.97 | S67: 1 | T67: 1.16 | U67: -9.21 | V67: 108880 | W67: 109850 | X67: 126540 | Y67: 0 | Z67: 0 | AA67: 0 | AB67: 28722.81 | AC67: 8959 | AD67: 69.1 | AE67: 28.6 | AF67: 61.2 | AG67: 47.3 | AH67: D
... A74: A279570 | B74: 케이뱅크 | E74: 220.6 | F74: 4221.9 | G74: 10928.4 | H74: -93.7 | I74: 89.5 | J74: 1715.9 | K74: 6280 | L74: 4841665 | M74: 304.1 | N74: 6735229.2 | O74: 0.72 | P74: 3.68 | Q74: 50.64 | R74: 65.31 | S74: -14.7 | T74: -9.64 | U74: 18.71 | V74: 6577 | W74: 6093.5 | X74: 6064.6667 | Y74: 0 | Z74: 1 | AA74: 1 | AB74: 2333.18 | AC74: 23733 | AD74: 49.2 | AE74: 76 | AF74: 67.8 | AG74: 66.3 | AH74: B
A75: A493280 | B75: 아이엠바이오로직스 | K75: 22600 | L75: 428269 | M75: 96.8 | N75: 94025 | O75: 4.55 | P75: 6.75 | Q75: 24.77 | R75: 26.11 | S75: -1.3 | T75: -6.03 | U75: -37.22 | V75: 26170 | W75: 29195 | X75: 43779.167 | Y75: 0 | Z75: 0 | AA75: 0 | AB75: 18171.62 | AC75: 3514 | AD75: 12.7 | AF75: 100 | AH75: -
A76: A394420 | B76: 리센스메디컬 | K76: 22250 | L76: 193843 | M76: 43.1 | N76: 258233.6 | O76: 0.75 | P76: 5.72 | Q76: 53.03 | R76: 53.2 | S76: -0.2 | T76: -0.22 | U76: -18.5 | V76: 19825 | W76: 22189.5 | Y76: 1 | Z76: 1 | AA76: 0 | AB76: 15187.68 | AC76: 2285 | AD76: 81.9 | AF76: 73.7 | AH76: -
A77: A439960 | B77: 코스모로보틱스 | K77: 20500 | L77: 1533032 | M77: 314.3 | N77: 4644048.4 | O77: 0.33 | Q77: 54.04 | R77: 56.51 | S77: -2.5 | T77: -9.69 | U77: -62.32 | V77: 23362 | W77: 29468.5 | Y77: 0 | Z77: 0 | AA77: 0 | AB77: 32891.11 | AC77: 6003 | AD77: 20.4 | AF77: 6.6 | AH77: -
A78: A477850 | B78: 마키나락스 | K78: 15490 | L78: 627768 | M78: 97.2 | N78: 2157831.8 | O78: 0.29 | Q78: 70.59 | R78: 71.48 | S78: -0.9 | T78: -6.4 | U78: -80.14 | V78: 19416 | W78: 27153 | Y78: 0 | Z78: 0 | AA78: 0 | AB78: 41075.75 | AC78: 2461 | AD78: 25.5 | AF78: 5.3 | AH78: -

Sheet RSI과매도
A1: 코드 | B1: 코드명 | C1: 상장일 | D1: days_since_ipo | E1: 기관_일간 | F1: 기관_5일 | G1: 기관_20일 | H1: 외국인_일간 | I1: 외국인_5일 | J1: 외국인_20일 | K1: 현재가 | L1: 거래량 | M1: 거래대금(억) | N1: 20일평균거래량 | O1: RVOL(20) | P1: 변동성(30D) | Q1: RSI(14) | R1: 전일RSI(14) | S1: RSI변화량 | T1: 1일수익률(%) | U1: 20일수익률(%) | V1: 10일이평 | W1: 20일이평 | X1: 60일이평 | Y1: 10일선돌파 | Z1: 20일선돌파 | AA1: 60일선돌파 | AB1: BB폭 | AC1: 시가총액(억) | AD1: 모멘텀스코어 | AE1: 수급스코어 | AF1: 거래량스코어 | AG1: 종합스코어 | AH1: 등급
A2: A475560 | B2: 더본코리아 | E2: 3.6 | F2: 1.3 | G2: -2.1 | H2: 3.6 | I2: -14.6 | J2: 18.5 | K2: 14430 | L2: 16545 | M2: 2.4 | N2: 15546.85 | O2: 1.06 | P2: 1.96 | Q2: 19.89 | R2: 23.42 | S2: -3.5 | T2: -4.18 | U2: -22.34 | V2: 15636 | W2: 16181.5 | X2: 19056.833 | Y2: 0 | Z2: 0 | AA2: 0 | AB2: 3487.45 | AC2: 2284 | AD2: 47.8 | AE2: 51.6 | AF2: 65.8 | AG2: 53.3 | AH2: C
A3: A336680 | B3: 탑런토탈솔루션 | E3: 0 | F3: 0 | G3: 0 | H3: 0.1 | I3: -0.6 | J3: -0.1 | K3: 2680 | L3: 25384 | M3: 0.7 | N3: 40903.8 | O3: 0.62 | P3: 2.18 | Q3: 20.33 | R3: 24.56 | S3: -4.2 | T3: -5.3 | U3: -23.32 | V3: 2953 | W3: 3062.25 | X3: 3532 | Y3: 0 | Z3: 0 | AA3: 0 | AB3: 735.49 | AC3: 1051 | AD3: 45.3 | AE3: 48.2 | AF3: 20.4 | AG3: 41.8 | AH3: D
A4: A308430 | B4: 셀비온 | E4: -0.2 | F4: 32.8 | G4: 126.2 | H4: 13.5 | I4: -28.9 | J4: 55.8 | K4: 16100 | L4: 43862 | M4: 7.1 | N4: 64280.2 | O4: 0.68 | P4: 3.69 | Q4: 21.85 | R4: 22.8 | S4: -0.9 | T4: -2.42 | U4: -31.49 | V4: 17552 | W4: 18994.5 | X4: 27299.833 | Y4: 0 | Z4: 0 | AA4: 0 | AB4: 8528.22 | AC4: 2116 | AD4: 44.8 | AE4: 54.4 | AF4: 27 | AG4: 46 | AH4: D
A5: A493280 | B5: 아이엠바이오로직스 | K5: 20500 | L5: 88659 | M5: 18.2 | N5: 93626.95 | O5: 0.95 | P5: 6.88 | Q5: 22.94 | R5: 24.77 | S5: -1.8 | T5: -9.29 | U5: -45.98 | V5: 25605 | W5: 28322.5 | X5: 42917.5 | Y5: 0 | Z5: 0 | AA5: 0 | AB5: 17809.83 | AC5: 3514 | AD5: 13.9 | AF5: 54.6 | AH5: -
A6: A488900 | B6: 비츠로넥스텍 | E6: -7 | F6: -31.5 | G6: -220.8 | H6: 36.4 | I6: 75.7 | J6: 242.4 | K6: 8540 | L6: 113440 | M6: 9.7 | N6: 102597.45 | O6: 1.11 | P6: 4.92 | Q6: 23.07 | R6: 25.6 | S6: -2.5 | T6: -8.57 | U6: -45.26 | V6: 10616 | W6: 11689.5 | X6: 16157.167 | Y6: 0 | Z6: 0 | AA6: 0 | AB6: 6793.92 | AC6: 2449 | AD6: 16.5 | AE6: 49.1 | AF6: 72.4 | AG6: 44 | AH6: D
A7: A459510 | B7: 나우로보틱스 | E7: -1.6 | F7: -11.5 | G7: -394.5 | H7: 42.3 | I7: 33.1 | J7: 69.7 | K7: 14340 | L7: 91226 | M7: 13.1 | N7: 92003.2 | O7: 0.99 | P7: 4.48 | Q7: 23.32 | R7: 26.98 | S7: -3.7 | T7: -10.26 | U7: -45.16 | V7: 17773 | W7: 19715 | X7: 22539.167 | Y7: 0 | Z7: 0 | AA7: 0 | AB7: 10841.43 | AC7: 1918 | AD7: 13.3 | AE7: 51.7 | AF7: 59.9 | AG7: 41.8 | AH7: D
A8: A462860 | B8: 더즌 | E8: 0 | F8: 0 | G8: 4.3 | H8: 16.8 | I8: 32.1 | J8: 178.4 | K8: 2080 | L8: 332666 | M8: 6.9 | N8: 225046 | O8: 1.48 | P8: 3.95 | Q8: 23.42 | R8: 28.63 | S8: -5.2 | T8: -9.76 | U8: -31.47 | V8: 2445 | W8: 2570.25 | X8: 3150.25 | Y8: 0 | Z8: 0 | AA8: 0 | AB8: 795.6 | AC8: 1485 | AD8: 27.9 | AE8: 57.8 | AF8: 94.7 | AG8: 56.2 | AH8: C
A9: A474650 | B9: 링크솔루션 | E9: 0.6 | F9: 8 | G9: 38 | H9: 99.3 | I9: 295.2 | J9: 703.3 | K9: 30600 | L9: 99577 | M9: 30.5 | N9: 80170.3 | O9: 1.24 | P9: 4.41 | Q9: 24.02 | R9: 27.92 | S9: -3.9 | T9: -10.92 | U9: -39.41 | V9: 38455 | W9: 41497.5 | X9: 52620.833 | Y9: 0 | Z9: 0 | AA9: 0 | AB9: 21797.02 | AC9: 1762 | AD9: 18.1 | AE9: 76 | AF9: 82.9 | AG9: 60 | AH9: C
A10: A439260 | B10: 대한조선 | E10: -34.5 | F10: 70.3 | G10: -134 | H10: 115.4 | I10: -320.7 | J10: -1241.6 | K10: 53600 | L10: 130765 | M10: 70.1 | N10: 98869.6 | O10: 1.32 | P10: 2.9 | Q10: 24.25 | R10: 29.24 | S10: -5 | T10: -7.27 | U10: -23.65 | V10: 61130 | W10: 62135 | X10: 77128.333 | Y10: 0 | Z10: 0 | AA10: 0 | AB10: 13478.44 | AC10: 20987 | AD10: 41.3 | AE10: 41.9 | AF10: 86.8 | AG10: 50.7 | AH10: C
A11: A474170 | B11: 루미르 | E11: -4.5 | F11: -17.4 | G11: -141 | H11: 40.7 | I11: 181.8 | J11: 221.8 | K11: 7890 | L11: 206913 | M11: 16.3 | N11: 243573.45 | O11: 0.85 | P11: 4.9 | Q11: 24.51 | R11: 26.88 | S11: -2.4 | T11: -6.41 | U11: -38.74 | V11: 9287 | W11: 10284 | X11: 13085.667 | Y11: 0 | Z11: 0 | AA11: 0 | AB11: 5661.28 | AC11: 1367 | AD11: 34.2 | AE11: 56 | AF11: 44.7 | AG11: 47.2 | AH11: D
A12: A394800 | B12: 쓰리빌리언 | E12: 0.7 | F12: -23.4 | G12: -432.5 | H12: 34.9 | I12: 4.8 | J12: 436.7 | K12: 6010 | L12: 170281 | M12: 10.2 | N12: 225451.25 | O12: 0.76 | P12: 4.36 | Q12: 24.58 | R12: 27.26 | S12: -2.7 | T12: -7.25 | U12: -41.02 | V12: 6956 | W12: 7753 | X12: 10510.167 | Y12: 0 | Z12: 0 | AA12: 0 | AB12: 4308.41 | AC12: 1967 | AD12: 26.6 | AE12: 53.2 | AF12: 38.2 | AG12: 42.2 | AH12: D
A13: A478340 | B13: 나라스페이스테크놀로지 | E13: -38.1 | F13: -125.4 | G13: -145.1 | H13: 178.4 | I13: 408 | J13: 613.2 | K13: 14320 | L13: 309679 | M13: 44.3 | N13: 195946.05 | O13: 1.58 | P13: 6.62 | Q13: 24.59 | R13: 27.73 | S13: -3.1 | T13: -13.26 | U13: -50.79 | V13: 19519 | W13: 22092 | X13: 30775.667 | Y13: 0 | Z13: 0 | AA13: 0 | AB13: 15733.56 | AC13: 1635 | AD13: 6.6 | AE13: 56.7 | AF13: 97.4 | AG13: 49.8 | AH13: D
A14: A289930 | B14: 웨이비스 | E14: 8.6 | F14: -0.9 | G14: 21.4 | H14: -10.7 | I14: -64.9 | J14: -266.8 | K14: 8710 | L14: 174408 | M14: 15.2 | N14: 177784.1 | O14: 0.98 | P14: 4.24 | Q14: 24.64 | R14: 26.91 | S14: -2.3 | T14: -6.94 | U14: -39.64 | V14: 10412 | W14: 11257 | X14: 16179.5 | Y14: 0 | Z14: 0 | AA14: 0 | AB14: 5558.75 | AC14: 1137 | AD14: 31.6 | AE14: 43 | AF14: 57.9 | AG14: 42.6 | AH14: D
A15: A458650 | B15: 성우 | E15: 14.4 | F15: 14.4 | G15: 131.1 | H15: 5.2 | I15: 6.5 | J15: -157.9 | K15: 8900 | L15: 61897 | M15: 5.5 | N15: 71283.9 | O15: 0.87 | P15: 3.7 | Q15: 24.88 | R15: 27.54 | S15: -2.7 | T15: -5.42 | U15: -38.11 | V15: 10501 | W15: 11142.5 | X15: 12546.833 | Y15: 0 | Z15: 0 | AA15: 0 | AB15: 4695.26 | AC15: 1309 | AD15: 36.8 | AE15: 57.9 | AF15: 46.7 | AG15: 49.3 | AH15: D
A16: A318060 | B16: 그래피 | E16: 21.7 | F16: 22.9 | G16: 46.3 | H16: -3.3 | I16: 28.6 | J16: 213.4 | K16: 17030 | L16: 183514 | M16: 31.3 | N16: 147887.6 | O16: 1.24 | P16: 4.77 | Q16: 25.48 | R16: 27.77 | S16: -2.3 | T16: -6.94 | U16: -36.81 | V16: 20847 | W16: 22173.5 | X16: 31170.333 | Y16: 0 | Z16: 0 | AA16: 0 | AB16: 8694.94 | AC16: 1935 | AD16: 35.3 | AE16: 61.7 | AF16: 82.9 | AG16: 58 | AH16: C
A17: A456160 | B17: 지투지바이오 | E17: -4.3 | F17: -766 | G17: -2435.9 | H17: 150.3 | I17: 781.2 | J17: 2073.6 | K17: 37650 | L17: 140139 | M17: 52.8 | N17: 217238.95 | O17: 0.65 | P17: 5.37 | Q17: 25.92 | R17: 28.8 | S17: -2.9 | T17: -8.28 | U17: -40.14 | V17: 44740 | W17: 50305 | X17: 65063.333 | Y17: 0 | Z17: 0 | AA17: 0 | AB17: 29845.86 | AC17: 6727 | AD17: 25.6 | AE17: 55.7 | AF17: 23 | AG17: 40.1 | AH17: D
... A35: A466100 | B35: 클로봇 | E35: 46.8 | F35: -1.9 | G35: 673.7 | H35: 229 | I35: 571 | J35: 556.8 | K35: 30400 | L35: 235819 | M35: 71.7 | N35: 356212.65 | O35: 0.66 | P35: 4.94 | Q35: 29.99 | R35: 33.69 | S35: -3.7 | T35: -8.02 | U35: -27.88 | V35: 35050 | W35: 38837.5 | X35: 44490 | Y35: 0 | Z35: 0 | AA35: 0 | AB35: 19033.12 | AC35: 8312 | AD35: 41.6 | AE35: 84.7 | AF35: 25 | AG35: 59.8 | AH35: C

Sheet 외국인순매수TOP
A1: 코드 | B1: 코드명 | C1: 상장일 | D1: days_since_ipo | E1: 기관_일간 | F1: 기관_5일 | G1: 기관_20일 | H1: 외국인_일간 | I1: 외국인_5일 | J1: 외국인_20일 | K1: 현재가 | L1: 거래량 | M1: 거래대금(억) | N1: 20일평균거래량 | O1: RVOL(20) | P1: 변동성(30D) | Q1: RSI(14) | R1: 전일RSI(14) | S1: RSI변화량 | T1: 1일수익률(%) | U1: 20일수익률(%) | V1: 10일이평 | W1: 20일이평 | X1: 60일이평 | Y1: 10일선돌파 | Z1: 20일선돌파 | AA1: 60일선돌파 | AB1: BB폭 | AC1: 시가총액(억) | AD1: 모멘텀스코어 | AE1: 수급스코어 | AF1: 거래량스코어 | AG1: 종합스코어 | AH1: 등급
A2: A295310 | B2: 에이치브이엠 | E2: -616.9 | F2: -2042.9 | G2: -2063.9 | H2: 991.4 | I2: 3381.5 | J2: 3375.4 | K2: 55000 | L2: 383856 | M2: 211.1 | N2: 376266.2 | O2: 1.02 | P2: 10.4 | Q2: 29.98 | R2: 31.81 | S2: -1.8 | T2: -8.94 | U2: -51.33 | V2: 83230 | W2: 94960 | X2: 93263.333 | Y2: 0 | Z2: 0 | AA2: 0 | AB2: 77079.33 | AC2: 6385 | AD2: 21.1 | AE2: 52 | AF2: 63.2 | AG2: 45 | AH2: D
A3: A064400 | B3: LG씨엔에스 | E3: -702.4 | F3: -2604.4 | G3: -581.8 | H3: 543.8 | I3: 683 | J3: -6456.9 | K3: 80000 | L3: 1283084 | M3: 1026.5 | N3: 3144180 | O3: 0.41 | P3: 10.01 | Q3: 42.14 | R3: 47.94 | S3: -5.8 | T3: -10.61 | U3: -3.85 | V3: 90680 | W3: 100725 | X3: 78376.667 | Y3: 0 | Z3: 0 | AA3: 1 | AB3: 69032.15 | AC3: 76249 | AD3: 52.7 | AE3: 39.7 | AF3: 6.6 | AG3: 37 | AH3: D
A4: A476830 | B4: 알지노믹스 | E4: -162.2 | F4: -2921.6 | G4: -6261.1 | H4: 382.4 | I4: -87.6 | J4: 1589.4 | K4: 82000 | L4: 208768 | M4: 171.2 | N4: 297227.95 | O4: 0.7 | P4: 6.58 | Q4: 30.32 | R4: 33.27 | S4: -3 | T4: -8.48 | U4: -43.64 | V4: 92450 | W4: 104760 | X4: 155713.33 | Y4: 0 | Z4: 0 | AA4: 0 | AB4: 73569.28 | AC4: 12248 | AD4: 26.6 | AE4: 35.2 | AF4: 31.6 | AG4: 31.9 | AH4: D
A5: A376900 | B5: 로킷헬스케어 | E5: 40.8 | F5: -84.1 | G5: 72.8 | H5: 264 | I5: 589.8 | J5: 100.7 | K5: 36950 | L5: 182223 | M5: 67.3 | N5: 174344.2 | O5: 1.05 | P5: 6.51 | Q5: 26.51 | R5: 28.67 | S5: -2.2 | T5: -7.63 | U5: -31.19 | V5: 46975 | W5: 50507.5 | X5: 77629.167 | Y5: 0 | Z5: 0 | AA5: 0 | AB5: 23493.26 | AC5: 7619 | AD5: 37.6 | AE5: 73.9 | AF5: 64.5 | AG5: 61.1 | AH5: C
A6: A466100 | B6: 클로봇 | E6: 46.8 | F6: -1.9 | G6: 673.7 | H6: 229 | I6: 571 | J6: 556.8 | K6: 30400 | L6: 235819 | M6: 71.7 | N6: 356212.65 | O6: 0.66 | P6: 4.94 | Q6: 29.99 | R6: 33.69 | S6: -3.7 | T6: -8.02 | U6: -27.88 | V6: 35050 | W6: 38837.5 | X6: 44490 | Y6: 0 | Z6: 0 | AA6: 0 | AB6: 19033.12 | AC6: 8312 | AD6: 41.6 | AE6: 84.7 | AF6: 25 | AG6: 59.8 | AH6: C
A7: A483650 | B7: 달바글로벌 | E7: 790.5 | F7: 1535.5 | G7: 1138.8 | H7: 221.4 | I7: 1910.7 | J7: 5502.1 | K7: 207500 | L7: 220213 | M7: 456.9 | N7: 192917.2 | O7: 1.14 | P7: 5.15 | Q7: 51.42 | R7: 48.4 | S7: 3 | T7: 3.49 | U7: -5.25 | V7: 202560 | W7: 200435 | X7: 200346.67 | Y7: 1 | Z7: 1 | AA7: 1 | AB7: 30797.21 | AC7: 27279 | AD7: 96.9 | AE7: 97.2 | AF7: 73.7 | AG7: 92.4 | AH7: A
A8: A475830 | B8: 오름테라퓨틱 | E8: 88.8 | F8: 415.8 | G8: 7295.8 | H8: 218.1 | I8: 226.5 | J8: -3924.7 | K8: 56400 | L8: 143704 | M8: 81 | N8: 273596.8 | O8: 0.53 | P8: 6.52 | Q8: 37.63 | R8: 40.81 | S8: -3.2 | T8: -6.47 | U8: -21.56 | V8: 64280 | W8: 64980 | X8: 77356.667 | Y8: 0 | Z8: 0 | AA8: 0 | AB8: 19506.14 | AC8: 12467 | AD8: 60 | AE8: 80.9 | AF8: 10.5 | AG8: 60.6 | AH8: C
A9: A462350 | B9: 이노스페이스 | E9: -551 | F9: -744 | G9: -1535.6 | H9: 199.3 | I9: -97.7 | J9: 501.7 | K9: 8710 | L9: 1387599 | M9: 120.9 | N9: 563413.45 | O9: 2.46 | P9: 5.61 | Q9: 27.33 | R9: 34.69 | S9: -7.4 | T9: -16.41 | U9: -32.79 | V9: 11804.1 | W9: 12093 | X9: 12603.067 | Y9: 0 | Z9: 0 | AA9: 0 | AB9: 4409.07 | AC9: 1850 | AD9: 21.2 | AE9: 33.8 | AF9: 100 | AG9: 43.3 | AH9: D
A10: A448900 | B10: 한국피아이엠 | E10: -144.5 | F10: -434.2 | G10: 1179.8 | H10: 184.2 | I10: 62 | J10: -277.3 | K10: 59100 | L10: 177339 | M10: 104.8 | N10: 126469.65 | O10: 1.4 | P10: 8.62 | Q10: 33.59 | R10: 38.52 | S10: -4.9 | T10: -15.93 | U10: -44.61 | V10: 77880 | W10: 84600 | X10: 97678.333 | Y10: 0 | Z10: 0 | AA10: 0 | AB10: 50253.6 | AC10: 3535 | AD10: 17.7 | AE10: 45.3 | AF10: 92.8 | AG10: 46.5 | AH10: D
A11: A478340 | B11: 나라스페이스테크놀로지 | E11: -38.1 | F11: -125.4 | G11: -145.1 | H11: 178.4 | I11: 408 | J11: 613.2 | K11: 14320 | L11: 309679 | M11: 44.3 | N11: 195946.05 | O11: 1.58 | P11: 6.62 | Q11: 24.59 | R11: 27.73 | S11: -3.1 | T11: -13.26 | U11: -50.79 | V11: 19519 | W11: 22092 | X11: 30775.667 | Y11: 0 | Z11: 0 | AA11: 0 | AB11: 15733.56 | AC11: 1635 | AD11: 6.6 | AE11: 56.7 | AF11: 97.4 | AG11: 49.8 | AH11: D
A12: A456160 | B12: 지투지바이오 | E12: -4.3 | F12: -766 | G12: -2435.9 | H12: 150.3 | I12: 781.2 | J12: 2073.6 | K12: 37650 | L12: 140139 | M12: 52.8 | N12: 217238.95 | O12: 0.65 | P12: 5.37 | Q12: 25.92 | R12: 28.8 | S12: -2.9 | T12: -8.28 | U12: -40.14 | V12: 44740 | W12: 50305 | X12: 65063.333 | Y12: 0 | Z12: 0 | AA12: 0 | AB12: 29845.86 | AC12: 6727 | AD12: 25.6 | AE12: 55.7 | AF12: 23 | AG12: 40.1 | AH12: D
A13: A209640 | B13: 와이제이링크 | E13: 41.1 | F13: 46.6 | G13: 36.7 | H13: 150.2 | I13: 339.8 | J13: 375.7 | K13: 3995 | L13: 1195201 | M13: 47.7 | N13: 898658.45 | O13: 1.33 | P13: 5.61 | Q13: 28.35 | R13: 31.14 | S13: -2.8 | T13: -9.1 | U13: -55.61 | V13: 4795 | W13: 5662 | X13: 6273.9167 | Y13: 0 | Z13: 0 | AA13: 0 | AB13: 4858.12 | AC13: 1159 | AD13: 18.3 | AE13: 83.4 | AF13: 88.8 | AG13: 65 | AH13: C
... A21: A217590 | B21: 티엠씨 | E21: -78.7 | F21: 1364.7 | G21: 787 | H21: 95.8 | I21: 152.2 | J21: 536.6 | K21: 14270 | L21: 306586 | M21: 43.7 | N21: 557997.15 | O21: 0.55 | P21: 9.92 | Q21: 31.96 | R21: 35.47 | S21: -3.5 | T21: -12.18 | U21: -46.85 | V21: 18920 | W21: 20056 | X21: 24644.333 | Y21: 0 | Z21: 0 | AA21: 0 | AB21: 12972.93 | AC21: 3332 | AD21: 17.1 | AE21: 69.5 | AF21: 12.5 | AG21: 42.4 | AH21: D

Sheet 기관순매수TOP
A1: 코드 | B1: 코드명 | C1: 상장일 | D1: days_since_ipo | E1: 기관_일간 | F1: 기관_5일 | G1: 기관_20일 | H1: 외국인_일간 | I1: 외국인_5일 | J1: 외국인_20일 | K1: 현재가 | L1: 거래량 | M1: 거래대금(억) | N1: 20일평균거래량 | O1: RVOL(20) | P1: 변동성(30D) | Q1: RSI(14) | R1: 전일RSI(14) | S1: RSI변화량 | T1: 1일수익률(%) | U1: 20일수익률(%) | V1: 10일이평 | W1: 20일이평 | X1: 60일이평 | Y1: 10일선돌파 | Z1: 20일선돌파 | AA1: 60일선돌파 | AB1: BB폭 | AC1: 시가총액(억) | AD1: 모멘텀스코어 | AE1: 수급스코어 | AF1: 거래량스코어 | AG1: 종합스코어 | AH1: 등급
A2: A483650 | B2: 달바글로벌 | E2: 790.5 | F2: 1535.5 | G2: 1138.8 | H2: 221.4 | I2: 1910.7 | J2: 5502.1 | K2: 207500 | L2: 220213 | M2: 456.9 | N2: 192917.2 | O2: 1.14 | P2: 5.15 | Q2: 51.42 | R2: 48.4 | S2: 3 | T2: 3.49 | U2: -5.25 | V2: 202560 | W2: 200435 | X2: 200346.67 | Y2: 1 | Z2: 1 | AA2: 1 | AB2: 30797.21 | AC2: 27279 | AD2: 96.9 | AE2: 97.2 | AF2: 73.7 | AG2: 92.4 | AH2: A
A3: A062040 | B3: 산일전기 | E3: 618.2 | F3: -2157.6 | G3: -570.1 | H3: 117.8 | I3: 2436.1 | J3: -927.6 | K3: 222000 | L3: 360735 | M3: 800.8 | N3: 333086.25 | O3: 1.08 | P3: 4.72 | Q3: 42.84 | R3: 45.49 | S3: -2.6 | T3: -3.27 | U3: -21.42 | V3: 234750 | W3: 237300 | X3: 225170 | Y3: 0 | Z3: 0 | AA3: 0 | AB3: 70212.25 | AC3: 68426 | AD3: 68.6 | AE3: 57.5 | AF3: 67.8 | AG3: 62.9 | AH3: C
A4: A279570 | B4: 케이뱅크 | E4: 199.9 | F4: 2905.5 | G4: 10962.5 | H4: 24.3 | I4: 508.6 | J4: 1595.3 | K4: 6050 | L4: 3503485 | M4: 212 | N4: 6823049.8 | O4: 0.51 | P4: 3.75 | Q4: 46.76 | R4: 50.64 | S4: -3.9 | T4: -3.66 | U4: 9.4 | V4: 6604 | W4: 6119.5 | X4: 6060.1667 | Y4: 0 | Z4: 0 | AA4: 0 | AB4: 2276.05 | AC4: 23733 | AD4: 73.5 | AE4: 86.9 | AF4: 9.2 | AG4: 67.3 | AH4: B
A5: A475830 | B5: 오름테라퓨틱 | E5: 88.8 | F5: 415.8 | G5: 7295.8 | H5: 218.1 | I5: 226.5 | J5: -3924.7 | K5: 56400 | L5: 143704 | M5: 81 | N5: 273596.8 | O5: 0.53 | P5: 6.52 | Q5: 37.63 | R5: 40.81 | S5: -3.2 | T5: -6.47 | U5: -21.56 | V5: 64280 | W5: 64980 | X5: 77356.667 | Y5: 0 | Z5: 0 | AA5: 0 | AB5: 19506.14 | AC5: 12467 | AD5: 60 | AE5: 80.9 | AF5: 10.5 | AG5: 60.6 | AH5: C
A6: A494120 | B6: 큐리오시스 | E6: 87.5 | F6: 250.8 | G6: 131.5 | H6: -28.3 | I6: -412.4 | J6: 216.1 | K6: 25650 | L6: 162818 | M6: 41.8 | N6: 108202.45 | O6: 1.5 | P6: 7.88 | Q6: 37.39 | R6: 32.62 | S6: 4.8 | T6: 10.32 | U6: -40.62 | V6: 27150 | W6: 29727.5 | X6: 45791.667 | Y6: 0 | Z6: 0 | AA6: 0 | AB6: 19865.8 | AC6: 2098 | AD6: 52.3 | AE6: 55.1 | AF6: 96.1 | AG6: 62.5 | AH6: C
A7: A462870 | B7: 시프트업 | E7: 82.9 | F7: 131.2 | G7: 954.5 | H7: 17.7 | I7: 314.1 | J7: 10.5 | K7: 33250 | L7: 221827 | M7: 73.8 | N7: 162004.15 | O7: 1.37 | P7: 3.52 | Q7: 57.96 | R7: 54.37 | S7: 3.6 | T7: 2.94 | U7: 12.71 | V7: 32055 | W7: 30955 | X7: 31877.5 | Y7: 1 | Z7: 1 | AA7: 1 | AB7: 6408.4 | AC7: 19532 | AD7: 99 | AE7: 75.2 | AF7: 90.8 | AG7: 85.5 | AH7: A
A8: A491000 | B8: 리브스메드 | E8: 49 | F8: 202.7 | G8: -1567.2 | H8: 133.4 | I8: 487.2 | J8: -259.3 | K8: 35850 | L8: 200216 | M8: 71.8 | N8: 335485.5 | O8: 0.6 | P8: 6.68 | Q8: 30.95 | R8: 32.46 | S8: -1.5 | T8: -4.4 | U8: -50.76 | V8: 40595 | W8: 46187.5 | X8: 58812.5 | Y8: 0 | Z8: 0 | AA8: 0 | AB8: 36328.99 | AC8: 8814 | AD8: 36.6 | AE8: 69.5 | AF8: 18.4 | AG8: 49.4 | AH8: D
A9: A466100 | B9: 클로봇 | E9: 46.8 | F9: -1.9 | G9: 673.7 | H9: 229 | I9: 571 | J9: 556.8 | K9: 30400 | L9: 235819 | M9: 71.7 | N9: 356212.65 | O9: 0.66 | P9: 4.94 | Q9: 29.99 | R9: 33.69 | S9: -3.7 | T9: -8.02 | U9: -27.88 | V9: 35050 | W9: 38837.5 | X9: 44490 | Y9: 0 | Z9: 0 | AA9: 0 | AB9: 19033.12 | AC9: 8312 | AD9: 41.6 | AE9: 84.7 | AF9: 25 | AG9: 59.8 | AH9: C
A10: A209640 | B10: 와이제이링크 | E10: 41.1 | F10: 46.6 | G10: 36.7 | H10: 150.2 | I10: 339.8 | J10: 375.7 | K10: 3995 | L10: 1195201 | M10: 47.7 | N10: 898658.45 | O10: 1.33 | P10: 5.61 | Q10: 28.35 | R10: 31.14 | S10: -2.8 | T10: -9.1 | U10: -55.61 | V10: 4795 | W10: 5662 | X10: 6273.9167 | Y10: 0 | Z10: 0 | AA10: 0 | AB10: 4858.12 | AC10: 1159 | AD10: 18.3 | AE10: 83.4 | AF10: 88.8 | AG10: 65 | AH10: C
A11: A376900 | B11: 로킷헬스케어 | E11: 40.8 | F11: -84.1 | G11: 72.8 | H11: 264 | I11: 589.8 | J11: 100.7 | K11: 36950 | L11: 182223 | M11: 67.3 | N11: 174344.2 | O11: 1.05 | P11: 6.51 | Q11: 26.51 | R11: 28.67 | S11: -2.2 | T11: -7.63 | U11: -31.19 | V11: 46975 | W11: 50507.5 | X11: 77629.167 | Y11: 0 | Z11: 0 | AA11: 0 | AB11: 23493.26 | AC11: 7619 | AD11: 37.6 | AE11: 73.9 | AF11: 64.5 | AG11: 61.1 | AH11: C
A12: A318060 | B12: 그래피 | E12: 21.7 | F12: 22.9 | G12: 46.3 | H12: -3.3 | I12: 28.6 | J12: 213.4 | K12: 17030 | L12: 183514 | M12: 31.3 | N12: 147887.6 | O12: 1.24 | P12: 4.77 | Q12: 25.48 | R12: 27.77 | S12: -2.3 | T12: -6.94 | U12: -36.81 | V12: 20847 | W12: 22173.5 | X12: 31170.333 | Y12: 0 | Z12: 0 | AA12: 0 | AB12: 8694.94 | AC12: 1935 | AD12: 35.3 | AE12: 61.7 | AF12: 82.9 | AG12: 58 | AH12: C
A13: A031210 | B13: 서울보증보험 | E13: 19 | F13: 132.5 | G13: -587.3 | H13: -37.2 | I13: -192.2 | J13: 106.2 | K13: 41750 | L13: 37129 | M13: 15.5 | N13: 63140.8 | O13: 0.59 | P13: 2.83 | Q13: 36.52 | R13: 40.71 | S13: -4.2 | T13: -2.91 | U13: -8.44 | V13: 44420 | W13: 43985 | X13: 46830 | Y13: 0 | Z13: 0 | AA13: 0 | AB13: 4883.89 | AC13: 28278 | AD13: 68.6 | AE13: 43.9 | AF13: 17.1 | AG13: 46 | AH13: D
... A21: A464080 | B21: 에스오에스랩 | E21: 7.6 | F21: -1.4 | G21: 352.5 | H21: 16.6 | I21: -99.7 | J21: -91.8 | K21: 10120 | L21: 188804 | M21: 19.1 | N21: 388409.6 | O21: 0.49 | P21: 6.92 | Q21: 37.17 | R21: 40.92 | S21: -3.8 | T21: -8.5 | U21: -27.87 | V21: 11789 | W21: 11969.5 | X21: 14283.667 | Y21: 0 | Z21: 0 | AA21: 0 | AB21: 5262.13 | AC21: 1795 | AD21: 46 | AE21: 49.9 | AF21: 7.9 | AG21: 40.3 | AH21: D

Sheet RVOL_TOP
A1: 코드 | B1: 코드명 | C1: 상장일 | D1: days_since_ipo | E1: 기관_일간 | F1: 기관_5일 | G1: 기관_20일 | H1: 외국인_일간 | I1: 외국인_5일 | J1: 외국인_20일 | K1: 현재가 | L1: 거래량 | M1: 거래대금(억) | N1: 20일평균거래량 | O1: RVOL(20) | P1: 변동성(30D) | Q1: RSI(14) | R1: 전일RSI(14) | S1: RSI변화량 | T1: 1일수익률(%) | U1: 20일수익률(%) | V1: 10일이평 | W1: 20일이평 | X1: 60일이평 | Y1: 10일선돌파 | Z1: 20일선돌파 | AA1: 60일선돌파 | AB1: BB폭 | AC1: 시가총액(억) | AD1: 모멘텀스코어 | AE1: 수급스코어 | AF1: 거래량스코어 | AG1: 종합스코어 | AH1: 등급
A2: A462350 | B2: 이노스페이스 | E2: -551 | F2: -744 | G2: -1535.6 | H2: 199.3 | I2: -97.7 | J2: 501.7 | K2: 8710 | L2: 1387599 | M2: 120.9 | N2: 563413.45 | O2: 2.46 | P2: 5.61 | Q2: 27.33 | R2: 34.69 | S2: -7.4 | T2: -16.41 | U2: -32.79 | V2: 11804.1 | W2: 12093 | X2: 12603.067 | Y2: 0 | Z2: 0 | AA2: 0 | AB2: 4409.07 | AC2: 1850 | AD2: 21.2 | AE2: 33.8 | AF2: 100 | AG2: 43.3 | AH2: D
A3: A473980 | B3: 노머스 | E3: -32.9 | F3: -185.9 | G3: -39.7 | H3: 50.8 | I3: 106.9 | J3: 179.2 | K3: 10010 | L3: 124378 | M3: 12.5 | N3: 65374.7 | O3: 1.9 | P3: 5.41 | Q3: 27.27 | R3: 30.55 | S3: -3.3 | T3: -8.42 | U3: -35.21 | V3: 12457 | W3: 13095 | X3: 15990.5 | Y3: 0 | Z3: 0 | AA3: 0 | AB3: 5097.25 | AC3: 1135 | AD3: 32.6 | AE3: 46.5 | AF3: 98.7 | AG3: 52.8 | AH3: C
A4: A478340 | B4: 나라스페이스테크놀로지 | E4: -38.1 | F4: -125.4 | G4: -145.1 | H4: 178.4 | I4: 408 | J4: 613.2 | K4: 14320 | L4: 309679 | M4: 44.3 | N4: 195946.05 | O4: 1.58 | P4: 6.62 | Q4: 24.59 | R4: 27.73 | S4: -3.1 | T4: -13.26 | U4: -50.79 | V4: 19519 | W4: 22092 | X4: 30775.667 | Y4: 0 | Z4: 0 | AA4: 0 | AB4: 15733.56 | AC4: 1635 | AD4: 6.6 | AE4: 56.7 | AF4: 97.4 | AG4: 49.8 | AH4: D
A5: A494120 | B5: 큐리오시스 | E5: 87.5 | F5: 250.8 | G5: 131.5 | H5: -28.3 | I5: -412.4 | J5: 216.1 | K5: 25650 | L5: 162818 | M5: 41.8 | N5: 108202.45 | O5: 1.5 | P5: 7.88 | Q5: 37.39 | R5: 32.62 | S5: 4.8 | T5: 10.32 | U5: -40.62 | V5: 27150 | W5: 29727.5 | X5: 45791.667 | Y5: 0 | Z5: 0 | AA5: 0 | AB5: 19865.8 | AC5: 2098 | AD5: 52.3 | AE5: 55.1 | AF5: 96.1 | AG5: 62.5 | AH5: C
A6: A462860 | B6: 더즌 | E6: 0 | F6: 0 | G6: 4.3 | H6: 16.8 | I6: 32.1 | J6: 178.4 | K6: 2080 | L6: 332666 | M6: 6.9 | N6: 225046 | O6: 1.48 | P6: 3.95 | Q6: 23.42 | R6: 28.63 | S6: -5.2 | T6: -9.76 | U6: -31.47 | V6: 2445 | W6: 2570.25 | X6: 3150.25 | Y6: 0 | Z6: 0 | AA6: 0 | AB6: 795.6 | AC6: 1485 | AD6: 27.9 | AE6: 57.8 | AF6: 94.7 | AG6: 56.2 | AH6: C
