Workbook

Sheet POST IPO 보고서
B2: POST IPO 모니터링 보고서
B3: 기준일: 2026-07-09 | 분석 대상: 70개 종목 | 2년 이내 신규 상장주
B6: 전체 종목 | D6: A등급 | F6: B등급 | H6: 50점 이상 종목수 | J6: RSI>65
B7: 70 | D7: 1 | F7: 6 | H7: 26 | J7: =COUNTIF(INDEX(전체!$A:$XFD,0,MATCH("RSI(14)",전체!$1:$1,0)),">=65")
B10: ▶ 추천종목 (종합스코어 50점 이상) | Q10: 구분 | R10: 종목수
B11: 순위 | C11: 종목명 | D11: 종합점수 | E11: 모멘텀 | F11: 수급 | G11: 거래량 | H11: RSI | I11: 등급 | J11: RSI신호 | K11: 등급변화 | L11: 점수변화량 | M11: 모멘텀Δ | N11: 수급Δ | O11: 거래량Δ | Q11: 강세 (A+B등급) | R11: 7
B12: 1 | C12: 더핑크퐁컴퍼니 | D12: 81.8 | E12: 91.6 | F12: 69.2 | G12: 98.5 | H12: 44.9 | I12: A | K12: =IFERROR(IF(I12=INDEX(전체_전일자!1:1048576,MATCH(C12,전체_전일자!B:B,0),MATCH("등급",전체_전일자!1:1,0)),"유지",INDEX(전체_전일자!1:1048576,MATCH(C12,전체_전일자!B:B,0),MATCH("등급",전체_전일자!1:1,0))&" → "&I12),"") | L12: =IFERROR(D12-INDEX(전체_전일자!1:1048576,MATCH(C12,전체_전일자!B:B,0),MATCH("종합스코어",전체_전일자!1:1,0)),"") | M12: =IFERROR(E12-INDEX(전체_전일자!1:1048576,MATCH(C12,전체_전일자!B:B,0),MATCH("모멘텀스코어",전체_전일자!1:1,0)),"") | N12: =IFERROR(F12-INDEX(전체_전일자!1:1048576,MATCH(C12,전체_전일자!B:B,0),MATCH("수급스코어",전체_전일자!1:1,0)),"") | O12: =IFERROR(G12-INDEX(전체_전일자!1:1048576,MATCH(C12,전체_전일자!B:B,0),MATCH("거래량스코어",전체_전일자!1:1,0)),"") | Q12: 중립 (C등급) | R12: 17
B13: 2 | C13: 클로봇 | D13: 78 | E13: 48.6 | F13: 91.1 | G13: 89.6 | H13: 33.14 | I13: B | K13: =IFERROR(IF(I13=INDEX(전체_전일자!1:1048576,MATCH(C13,전체_전일자!B:B,0),MATCH("등급",전체_전일자!1:1,0)),"유지",INDEX(전체_전일자!1:1048576,MATCH(C13,전체_전일자!B:B,0),MATCH("등급",전체_전일자!1:1,0))&" → "&I13),"") | L13: =IFERROR(D13-INDEX(전체_전일자!1:1048576,MATCH(C13,전체_전일자!B:B,0),MATCH("종합스코어",전체_전일자!1:1,0)),"") | M13: =IFERROR(E13-INDEX(전체_전일자!1:1048576,MATCH(C13,전체_전일자!B:B,0),MATCH("모멘텀스코어",전체_전일자!1:1,0)),"") | N13: =IFERROR(F13-INDEX(전체_전일자!1:1048576,MATCH(C13,전체_전일자!B:B,0),MATCH("수급스코어",전체_전일자!1:1,0)),"") | O13: =IFERROR(G13-INDEX(전체_전일자!1:1048576,MATCH(C13,전체_전일자!B:B,0),MATCH("거래량스코어",전체_전일자!1:1,0)),"") | Q13: 약세 (D+F등급) | R13: 39
B14: 3 | C14: KB발해인프라 | D14: 69.7 | E14: 85.3 | F14: 51.2 | G14: 92.5 | H14: 63.81 | I14: B | K14: =IFERROR(IF(I14=INDEX(전체_전일자!1:1048576,MATCH(C14,전체_전일자!B:B,0),MATCH("등급",전체_전일자!1:1,0)),"유지",INDEX(전체_전일자!1:1048576,MATCH(C14,전체_전일자!B:B,0),MATCH("등급",전체_전일자!1:1,0))&" → "&I14),"") | L14: =IFERROR(D14-INDEX(전체_전일자!1:1048576,MATCH(C14,전체_전일자!B:B,0),MATCH("종합스코어",전체_전일자!1:1,0)),"") | M14: =IFERROR(E14-INDEX(전체_전일자!1:1048576,MATCH(C14,전체_전일자!B:B,0),MATCH("모멘텀스코어",전체_전일자!1:1,0)),"") | N14: =IFERROR(F14-INDEX(전체_전일자!1:1048576,MATCH(C14,전체_전일자!B:B,0),MATCH("수급스코어",전체_전일자!1:1,0)),"") | O14: =IFERROR(G14-INDEX(전체_전일자!1:1048576,MATCH(C14,전체_전일자!B:B,0),MATCH("거래량스코어",전체_전일자!1:1,0)),"")
B15: 4 | C15: 노머스 | D15: 69.4 | E15: 81.6 | F15: 51.7 | G15: 95.5 | H15: 46.18 | I15: B | K15: =IFERROR(IF(I15=INDEX(전체_전일자!1:1048576,MATCH(C15,전체_전일자!B:B,0),MATCH("등급",전체_전일자!1:1,0)),"유지",INDEX(전체_전일자!1:1048576,MATCH(C15,전체_전일자!B:B,0),MATCH("등급",전체_전일자!1:1,0))&" → "&I15),"") | L15: =IFERROR(D15-INDEX(전체_전일자!1:1048576,MATCH(C15,전체_전일자!B:B,0),MATCH("종합스코어",전체_전일자!1:1,0)),"") | M15: =IFERROR(E15-INDEX(전체_전일자!1:1048576,MATCH(C15,전체_전일자!B:B,0),MATCH("모멘텀스코어",전체_전일자!1:1,0)),"") | N15: =IFERROR(F15-INDEX(전체_전일자!1:1048576,MATCH(C15,전체_전일자!B:B,0),MATCH("수급스코어",전체_전일자!1:1,0)),"") | O15: =IFERROR(G15-INDEX(전체_전일자!1:1048576,MATCH(C15,전체_전일자!B:B,0),MATCH("거래량스코어",전체_전일자!1:1,0)),"")
B16: 5 | C16: 도우인시스 | D16: 67.1 | E16: 93.3 | F16: 46.6 | G16: 79.1 | H16: 46.6 | I16: B | K16: =IFERROR(IF(I16=INDEX(전체_전일자!1:1048576,MATCH(C16,전체_전일자!B:B,0),MATCH("등급",전체_전일자!1:1,0)),"유지",INDEX(전체_전일자!1:1048576,MATCH(C16,전체_전일자!B:B,0),MATCH("등급",전체_전일자!1:1,0))&" → "&I16),"") | L16: =IFERROR(D16-INDEX(전체_전일자!1:1048576,MATCH(C16,전체_전일자!B:B,0),MATCH("종합스코어",전체_전일자!1:1,0)),"") | M16: =IFERROR(E16-INDEX(전체_전일자!1:1048576,MATCH(C16,전체_전일자!B:B,0),MATCH("모멘텀스코어",전체_전일자!1:1,0)),"") | N16: =IFERROR(F16-INDEX(전체_전일자!1:1048576,MATCH(C16,전체_전일자!B:B,0),MATCH("수급스코어",전체_전일자!1:1,0)),"") | O16: =IFERROR(G16-INDEX(전체_전일자!1:1048576,MATCH(C16,전체_전일자!B:B,0),MATCH("거래량스코어",전체_전일자!1:1,0)),"")
B17: 6 | C17: 달바글로벌 | D17: 66.5 | E17: 42.3 | F17: 77.1 | G17: 76.1 | H17: 43.55 | I17: B | K17: =IFERROR(IF(I17=INDEX(전체_전일자!1:1048576,MATCH(C17,전체_전일자!B:B,0),MATCH("등급",전체_전일자!1:1,0)),"유지",INDEX(전체_전일자!1:1048576,MATCH(C17,전체_전일자!B:B,0),MATCH("등급",전체_전일자!1:1,0))&" → "&I17),"") | L17: =IFERROR(D17-INDEX(전체_전일자!1:1048576,MATCH(C17,전체_전일자!B:B,0),MATCH("종합스코어",전체_전일자!1:1,0)),"") | M17: =IFERROR(E17-INDEX(전체_전일자!1:1048576,MATCH(C17,전체_전일자!B:B,0),MATCH("모멘텀스코어",전체_전일자!1:1,0)),"") | N17: =IFERROR(F17-INDEX(전체_전일자!1:1048576,MATCH(C17,전체_전일자!B:B,0),MATCH("수급스코어",전체_전일자!1:1,0)),"") | O17: =IFERROR(G17-INDEX(전체_전일자!1:1048576,MATCH(C17,전체_전일자!B:B,0),MATCH("거래량스코어",전체_전일자!1:1,0)),"")
B18: 7 | C18: 씨엠티엑스 | D18: 65.6 | E18: 47.8 | F18: 64.9 | G18: 94 | H18: 34.49 | I18: B | K18: =IFERROR(IF(I18=INDEX(전체_전일자!1:1048576,MATCH(C18,전체_전일자!B:B,0),MATCH("등급",전체_전일자!1:1,0)),"유지",INDEX(전체_전일자!1:1048576,MATCH(C18,전체_전일자!B:B,0),MATCH("등급",전체_전일자!1:1,0))&" → "&I18),"") | L18: =IFERROR(D18-INDEX(전체_전일자!1:1048576,MATCH(C18,전체_전일자!B:B,0),MATCH("종합스코어",전체_전일자!1:1,0)),"") | M18: =IFERROR(E18-INDEX(전체_전일자!1:1048576,MATCH(C18,전체_전일자!B:B,0),MATCH("모멘텀스코어",전체_전일자!1:1,0)),"") | N18: =IFERROR(F18-INDEX(전체_전일자!1:1048576,MATCH(C18,전체_전일자!B:B,0),MATCH("수급스코어",전체_전일자!1:1,0)),"") | O18: =IFERROR(G18-INDEX(전체_전일자!1:1048576,MATCH(C18,전체_전일자!B:B,0),MATCH("거래량스코어",전체_전일자!1:1,0)),"")
B19: 8 | C19: 서울보증보험 | D19: 63.4 | E19: 76 | F19: 56.7 | G19: 61.2 | H19: 45.92 | I19: C | K19: =IFERROR(IF(I19=INDEX(전체_전일자!1:1048576,MATCH(C19,전체_전일자!B:B,0),MATCH("등급",전체_전일자!1:1,0)),"유지",INDEX(전체_전일자!1:1048576,MATCH(C19,전체_전일자!B:B,0),MATCH("등급",전체_전일자!1:1,0))&" → "&I19),"") | L19: =IFERROR(D19-INDEX(전체_전일자!1:1048576,MATCH(C19,전체_전일자!B:B,0),MATCH("종합스코어",전체_전일자!1:1,0)),"") | M19: =IFERROR(E19-INDEX(전체_전일자!1:1048576,MATCH(C19,전체_전일자!B:B,0),MATCH("모멘텀스코어",전체_전일자!1:1,0)),"") | N19: =IFERROR(F19-INDEX(전체_전일자!1:1048576,MATCH(C19,전체_전일자!B:B,0),MATCH("수급스코어",전체_전일자!1:1,0)),"") | O19: =IFERROR(G19-INDEX(전체_전일자!1:1048576,MATCH(C19,전체_전일자!B:B,0),MATCH("거래량스코어",전체_전일자!1:1,0)),"")
B20: 9 | C20: 세나테크놀로지 | D20: 61.5 | E20: 86.4 | F20: 50.3 | G20: 52.2 | H20: 51.53 | I20: C | K20: =IFERROR(IF(I20=INDEX(전체_전일자!1:1048576,MATCH(C20,전체_전일자!B:B,0),MATCH("등급",전체_전일자!1:1,0)),"유지",INDEX(전체_전일자!1:1048576,MATCH(C20,전체_전일자!B:B,0),MATCH("등급",전체_전일자!1:1,0))&" → "&I20),"") | L20: =IFERROR(D20-INDEX(전체_전일자!1:1048576,MATCH(C20,전체_전일자!B:B,0),MATCH("종합스코어",전체_전일자!1:1,0)),"") | M20: =IFERROR(E20-INDEX(전체_전일자!1:1048576,MATCH(C20,전체_전일자!B:B,0),MATCH("모멘텀스코어",전체_전일자!1:1,0)),"") | N20: =IFERROR(F20-INDEX(전체_전일자!1:1048576,MATCH(C20,전체_전일자!B:B,0),MATCH("수급스코어",전체_전일자!1:1,0)),"") | O20: =IFERROR(G20-INDEX(전체_전일자!1:1048576,MATCH(C20,전체_전일자!B:B,0),MATCH("거래량스코어",전체_전일자!1:1,0)),"")
B21: 10 | C21: 산일전기 | D21: 61.2 | E21: 49.7 | F21: 68 | G21: 61.2 | H21: 35.08 | I21: C | K21: =IFERROR(IF(I21=INDEX(전체_전일자!1:1048576,MATCH(C21,전체_전일자!B:B,0),MATCH("등급",전체_전일자!1:1,0)),"유지",INDEX(전체_전일자!1:1048576,MATCH(C21,전체_전일자!B:B,0),MATCH("등급",전체_전일자!1:1,0))&" → "&I21),"") | L21: =IFERROR(D21-INDEX(전체_전일자!1:1048576,MATCH(C21,전체_전일자!B:B,0),MATCH("종합스코어",전체_전일자!1:1,0)),"") | M21: =IFERROR(E21-INDEX(전체_전일자!1:1048576,MATCH(C21,전체_전일자!B:B,0),MATCH("모멘텀스코어",전체_전일자!1:1,0)),"") | N21: =IFERROR(F21-INDEX(전체_전일자!1:1048576,MATCH(C21,전체_전일자!B:B,0),MATCH("수급스코어",전체_전일자!1:1,0)),"") | O21: =IFERROR(G21-INDEX(전체_전일자!1:1048576,MATCH(C21,전체_전일자!B:B,0),MATCH("거래량스코어",전체_전일자!1:1,0)),"")
B22: 11 | C22: 에이유브랜즈 | D22: 59.5 | E22: 84 | F22: 34 | G22: 86.6 | H22: 56.08 | I22: C | K22: =IFERROR(IF(I22=INDEX(전체_전일자!1:1048576,MATCH(C22,전체_전일자!B:B,0),MATCH("등급",전체_전일자!1:1,0)),"유지",INDEX(전체_전일자!1:1048576,MATCH(C22,전체_전일자!B:B,0),MATCH("등급",전체_전일자!1:1,0))&" → "&I22),"") | L22: =IFERROR(D22-INDEX(전체_전일자!1:1048576,MATCH(C22,전체_전일자!B:B,0),MATCH("종합스코어",전체_전일자!1:1,0)),"") | M22: =IFERROR(E22-INDEX(전체_전일자!1:1048576,MATCH(C22,전체_전일자!B:B,0),MATCH("모멘텀스코어",전체_전일자!1:1,0)),"") | N22: =IFERROR(F22-INDEX(전체_전일자!1:1048576,MATCH(C22,전체_전일자!B:B,0),MATCH("수급스코어",전체_전일자!1:1,0)),"") | O22: =IFERROR(G22-INDEX(전체_전일자!1:1048576,MATCH(C22,전체_전일자!B:B,0),MATCH("거래량스코어",전체_전일자!1:1,0)),"")
B23: 12 | C23: 리브스메드 | D23: 59.5 | E23: 87.7 | F23: 48.8 | G23: 44 | H23: 42.93 | I23: C | K23: =IFERROR(IF(I23=INDEX(전체_전일자!1:1048576,MATCH(C23,전체_전일자!B:B,0),MATCH("등급",전체_전일자!1:1,0)),"유지",INDEX(전체_전일자!1:1048576,MATCH(C23,전체_전일자!B:B,0),MATCH("등급",전체_전일자!1:1,0))&" → "&I23),"") | L23: =IFERROR(D23-INDEX(전체_전일자!1:1048576,MATCH(C23,전체_전일자!B:B,0),MATCH("종합스코어",전체_전일자!1:1,0)),"") | M23: =IFERROR(E23-INDEX(전체_전일자!1:1048576,MATCH(C23,전체_전일자!B:B,0),MATCH("모멘텀스코어",전체_전일자!1:1,0)),"") | N23: =IFERROR(F23-INDEX(전체_전일자!1:1048576,MATCH(C23,전체_전일자!B:B,0),MATCH("수급스코어",전체_전일자!1:1,0)),"") | O23: =IFERROR(G23-INDEX(전체_전일자!1:1048576,MATCH(C23,전체_전일자!B:B,0),MATCH("거래량스코어",전체_전일자!1:1,0)),"")
B24: 13 | C24: 온코닉테라퓨틱스 | D24: 55.8 | E24: 22.8 | F24: 61.6 | G24: 91 | H24: 25.92 | I24: C | K24: =IFERROR(IF(I24=INDEX(전체_전일자!1:1048576,MATCH(C24,전체_전일자!B:B,0),MATCH("등급",전체_전일자!1:1,0)),"유지",INDEX(전체_전일자!1:1048576,MATCH(C24,전체_전일자!B:B,0),MATCH("등급",전체_전일자!1:1,0))&" → "&I24),"") | L24: =IFERROR(D24-INDEX(전체_전일자!1:1048576,MATCH(C24,전체_전일자!B:B,0),MATCH("종합스코어",전체_전일자!1:1,0)),"") | M24: =IFERROR(E24-INDEX(전체_전일자!1:1048576,MATCH(C24,전체_전일자!B:B,0),MATCH("모멘텀스코어",전체_전일자!1:1,0)),"") | N24: =IFERROR(F24-INDEX(전체_전일자!1:1048576,MATCH(C24,전체_전일자!B:B,0),MATCH("수급스코어",전체_전일자!1:1,0)),"") | O24: =IFERROR(G24-INDEX(전체_전일자!1:1048576,MATCH(C24,전체_전일자!B:B,0),MATCH("거래량스코어",전체_전일자!1:1,0)),"")
B25: 14 | C25: 프로티나 | D25: 55.7 | E25: 38.6 | F25: 59.3 | G25: 72.4 | H25: 31.99 | I25: C | K25: =IFERROR(IF(I25=INDEX(전체_전일자!1:1048576,MATCH(C25,전체_전일자!B:B,0),MATCH("등급",전체_전일자!1:1,0)),"유지",INDEX(전체_전일자!1:1048576,MATCH(C25,전체_전일자!B:B,0),MATCH("등급",전체_전일자!1:1,0))&" → "&I25),"") | L25: =IFERROR(D25-INDEX(전체_전일자!1:1048576,MATCH(C25,전체_전일자!B:B,0),MATCH("종합스코어",전체_전일자!1:1,0)),"") | M25: =IFERROR(E25-INDEX(전체_전일자!1:1048576,MATCH(C25,전체_전일자!B:B,0),MATCH("모멘텀스코어",전체_전일자!1:1,0)),"") | N25: =IFERROR(F25-INDEX(전체_전일자!1:1048576,MATCH(C25,전체_전일자!B:B,0),MATCH("수급스코어",전체_전일자!1:1,0)),"") | O25: =IFERROR(G25-INDEX(전체_전일자!1:1048576,MATCH(C25,전체_전일자!B:B,0),MATCH("거래량스코어",전체_전일자!1:1,0)),"")
... B37: 26 | C37: 더본코리아 | D37: 50 | E37: 45.2 | F37: 49.5 | G37: 58.2 | H37: 37.76 | I37: D | K37: =IFERROR(IF(I37=INDEX(전체_전일자!1:1048576,MATCH(C37,전체_전일자!B:B,0),MATCH("등급",전체_전일자!1:1,0)),"유지",INDEX(전체_전일자!1:1048576,MATCH(C37,전체_전일자!B:B,0),MATCH("등급",전체_전일자!1:1,0))&" → "&I37),"") | L37: =IFERROR(D37-INDEX(전체_전일자!1:1048576,MATCH(C37,전체_전일자!B:B,0),MATCH("종합스코어",전체_전일자!1:1,0)),"") | M37: =IFERROR(E37-INDEX(전체_전일자!1:1048576,MATCH(C37,전체_전일자!B:B,0),MATCH("모멘텀스코어",전체_전일자!1:1,0)),"") | N37: =IFERROR(F37-INDEX(전체_전일자!1:1048576,MATCH(C37,전체_전일자!B:B,0),MATCH("수급스코어",전체_전일자!1:1,0)),"") | O37: =IFERROR(G37-INDEX(전체_전일자!1:1048576,MATCH(C37,전체_전일자!B:B,0),MATCH("거래량스코어",전체_전일자!1:1,0)),"")

Sheet 추천종목
A1: 코드 | B1: 코드명 | C1: 상장일 | D1: 현재가 | E1: 거래대금(억) | F1: 종합스코어 | G1: 모멘텀스코어 | H1: 수급스코어 | I1: 거래량스코어 | J1: RSI변화량 | K1: RSI(14) | L1: 전일RSI(14) | M1: RVOL(20) | N1: 기관_일간 | O1: 외국인_일간 | P1: 10일선돌파 | Q1: 20일선돌파 | R1: 60일선돌파 | S1: 변동성(30D) | T1: BB폭
A2: A403850 | B2: 더핑크퐁컴퍼니 | D2: 10900 | E2: 18.8 | F2: 81.8 | G2: 91.6 | H2: 69.2 | I2: 98.5 | J2: 4.8 | K2: 44.9 | L2: 40.14 | M2: 1.99 | N2: 58.5 | O2: -30.1 | P2: 1 | Q2: 0 | R2: 0 | S2: 4.52 | T2: 2486.86
A3: A466100 | B3: 클로봇 | D3: 25150 | E3: 61.1 | F3: 78 | G3: 48.6 | H3: 91.1 | I3: 89.6 | J3: 2.2 | K3: 33.14 | L3: 30.95 | M3: 1.1 | N3: 154.2 | O3: 66.2 | P3: 0 | Q3: 0 | R3: 0 | S3: 5.76 | T3: 13383.89
A4: A415640 | B4: KB발해인프라 | D4: 10730 | E4: 20.2 | F4: 69.7 | G4: 85.3 | H4: 51.2 | I4: 92.5 | J4: -0.3 | K4: 63.81 | L4: 64.13 | M4: 1.17 | N4: -15.2 | O4: 26.2 | P4: 1 | Q4: 1 | R4: 1 | S4: 2.01 | T4: 1367.33
A5: A473980 | B5: 노머스 | D5: 11490 | E5: 11.8 | F5: 69.4 | G5: 81.6 | H5: 51.7 | I5: 95.5 | J5: 2.8 | K5: 46.18 | L5: 43.38 | M5: 1.26 | N5: 80.4 | O5: -58.7 | P5: 1 | Q5: 1 | R5: 0 | S5: 5.9 | T5: 4543.4
A6: A484120 | B6: 도우인시스 | D6: 15800 | E6: 2.9 | F6: 67.1 | G6: 93.3 | H6: 46.6 | I6: 79.1 | J6: 3 | K6: 46.6 | L6: 43.56 | M6: 0.96 | N6: 0 | O6: 9.6 | P6: 1 | Q6: 0 | R6: 0 | S6: 6.51 | T6: 5803.52
A7: A483650 | B7: 달바글로벌 | D7: 199900 | E7: 308.7 | F7: 66.5 | G7: 42.3 | H7: 77.1 | I7: 76.1 | J7: -6.6 | K7: 43.55 | L7: 50.19 | M7: 0.86 | N7: -389.5 | O7: 308.8 | P7: 0 | Q7: 0 | R7: 0 | S7: 5.04 | T7: 60619.2
A8: A388210 | B8: 씨엠티엑스 | D8: 75900 | E8: 68.5 | F8: 65.6 | G8: 47.8 | H8: 64.9 | I8: 94 | J8: 7.4 | K8: 34.49 | L8: 27.08 | M8: 1.23 | N8: 196.5 | O8: 34.1 | P8: 0 | Q8: 0 | R8: 0 | S8: 6.48 | T8: 52083.07
A9: A031210 | B9: 서울보증보험 | D9: 42350 | E9: 14.1 | F9: 63.4 | G9: 76 | H9: 56.7 | I9: 61.2 | J9: -2 | K9: 45.92 | L9: 47.95 | M9: 0.73 | N9: 37.7 | O9: -24.4 | P9: 1 | Q9: 0 | R9: 0 | S9: 2.56 | T9: 7225.03
A10: A061090 | B10: 세나테크놀로지 | D10: 37500 | E10: 6.3 | F10: 61.5 | G10: 86.4 | H10: 50.3 | I10: 52.2 | J10: 2.8 | K10: 51.53 | L10: 48.74 | M10: 0.65 | N10: 0.3 | O10: -3.7 | P10: 1 | Q10: 1 | R10: 0 | S10: 6.14 | T10: 16799.71
A11: A062040 | B11: 산일전기 | D11: 179600 | E11: 433.1 | F11: 61.2 | G11: 49.7 | H11: 68 | I11: 61.2 | J11: 0.6 | K11: 35.08 | L11: 34.51 | M11: 0.73 | N11: 196 | O11: 342.1 | P11: 0 | Q11: 0 | R11: 0 | S11: 5.32 | T11: 89632.53
A12: A481070 | B12: 에이유브랜즈 | D12: 15010 | E12: 3.8 | F12: 59.5 | G12: 84 | H12: 34 | I12: 86.6 | J12: -0.4 | K12: 56.08 | L12: 56.5 | M12: 1.05 | N12: -4.7 | O12: -15.9 | P12: 1 | Q12: 1 | R12: 0 | S12: 5.42 | T12: 3737.85
A13: A491000 | B13: 리브스메드 | D13: 36750 | E13: 48.8 | F13: 59.5 | G13: 87.7 | H13: 48.8 | I13: 44 | J13: 4.3 | K13: 42.93 | L13: 38.63 | M13: 0.61 | N13: 58.3 | O13: -33.4 | P13: 1 | Q13: 0 | R13: 0 | S13: 6.98 | T13: 12886
... A51: A079900 | B51: 전진건설로봇 | D51: 33950 | E51: 12.5 | F51: 39.6 | G51: 18.3 | H51: 58.6 | I51: 23.9 | J51: -0.6 | K51: 26.57 | L51: 27.17 | M51: 0.47 | N51: 2.1 | O51: 47.1 | P51: 0 | Q51: 0 | R51: 0 | S51: 5.59 | T51: 34149.96

Sheet A등급
A1: 코드 | B1: 코드명 | C1: 상장일 | D1: days_since_ipo | E1: 기관_일간 | F1: 기관_5일 | G1: 기관_20일 | H1: 외국인_일간 | I1: 외국인_5일 | J1: 외국인_20일 | K1: 현재가 | L1: 거래량 | M1: 거래대금(억) | N1: 20일평균거래량 | O1: RVOL(20) | P1: 변동성(30D) | Q1: RSI(14) | R1: 전일RSI(14) | S1: RSI변화량 | T1: 1일수익률(%) | U1: 20일수익률(%) | V1: 10일이평 | W1: 20일이평 | X1: 60일이평 | Y1: 10일선돌파 | Z1: 20일선돌파 | AA1: 60일선돌파 | AB1: BB폭 | AC1: 시가총액(억) | AD1: 모멘텀스코어 | AE1: 수급스코어 | AF1: 거래량스코어 | AG1: 종합스코어 | AH1: 등급
A2: A403850 | B2: 더핑크퐁컴퍼니 | E2: 58.5 | F2: 109.5 | G2: 123 | H2: -30.1 | I2: 256.3 | J2: 255.6 | K2: 10900 | L2: 172250 | M2: 18.8 | N2: 86743.65 | O2: 1.99 | P2: 4.52 | Q2: 44.9 | R2: 40.14 | S2: 4.8 | T2: 4.41 | U2: -4.55 | V2: 10753 | W2: 11077 | X2: 13527.5 | Y2: 1 | Z2: 0 | AA2: 0 | AB2: 2486.86 | AC2: 1564 | AD2: 91.6 | AE2: 69.2 | AF2: 98.5 | AG2: 81.8 | AH2: A

Sheet 전체
A1: 코드 | B1: 코드명 | C1: 상장일 | D1: days_since_ipo | E1: 기관_일간 | F1: 기관_5일 | G1: 기관_20일 | H1: 외국인_일간 | I1: 외국인_5일 | J1: 외국인_20일 | K1: 현재가 | L1: 거래량 | M1: 거래대금(억) | N1: 20일평균거래량 | O1: RVOL(20) | P1: 변동성(30D) | Q1: RSI(14) | R1: 전일RSI(14) | S1: RSI변화량 | T1: 1일수익률(%) | U1: 20일수익률(%) | V1: 10일이평 | W1: 20일이평 | X1: 60일이평 | Y1: 10일선돌파 | Z1: 20일선돌파 | AA1: 60일선돌파 | AB1: BB폭 | AC1: 시가총액(억) | AD1: 모멘텀스코어 | AE1: 수급스코어 | AF1: 거래량스코어 | AG1: 종합스코어 | AH1: 등급
A2: A062040 | B2: 산일전기 | E2: 196 | F2: -2399.1 | G2: 4360.4 | H2: 342.1 | I2: 398.5 | J2: -4665.6 | K2: 179600 | L2: 241174 | M2: 433.1 | N2: 331192 | O2: 0.73 | P2: 5.32 | Q2: 35.08 | R2: 34.51 | S2: 0.6 | T2: 0.79 | U2: -15.68 | V2: 215270 | W2: 226060 | X2: 239951.67 | Y2: 0 | Z2: 0 | AA2: 0 | AB2: 89632.53 | AC2: 54986 | AD2: 49.7 | AE2: 68 | AF2: 61.2 | AG2: 61.2 | AH2: C
A3: A079900 | B3: 전진건설로봇 | E3: 2.1 | F3: -38.4 | G3: -300.8 | H3: 47.1 | I3: 45.5 | J3: 246.3 | K3: 33950 | L3: 36761 | M3: 12.5 | N3: 78904.5 | O3: 0.47 | P3: 5.59 | Q3: 26.57 | R3: 27.17 | S3: -0.6 | T3: -1.59 | U3: -33.04 | V3: 37405 | W3: 44050 | X3: 55719.167 | Y3: 0 | Z3: 0 | AA3: 0 | AB3: 34149.96 | AC3: 4954 | AD3: 18.3 | AE3: 58.6 | AF3: 23.9 | AG3: 39.6 | AH3: D
A4: A389650 | B4: 넥스트바이오메디컬 | E4: 5.1 | F4: 84.5 | G4: 507.9 | H4: 0.4 | I4: -92.7 | J4: -388.1 | K4: 37700 | L4: 35175 | M4: 13.3 | N4: 57263.8 | O4: 0.61 | P4: 6.74 | Q4: 41.16 | R4: 43.84 | S4: -2.7 | T4: -4.19 | U4: -7.14 | V4: 40320 | W4: 40745 | X4: 49074.167 | Y4: 0 | Z4: 0 | AA4: 0 | AB4: 7236.55 | AC4: 3121 | AD4: 41.5 | AE4: 53.1 | AF4: 44 | AG4: 47.8 | AH4: D
A5: A461300 | B5: 아이스크림미디어 | E5: -0.9 | F5: -13 | G5: -366.8 | H5: -37.5 | I5: -18.5 | J5: 147.7 | K5: 15710 | L5: 36027 | M5: 5.7 | N5: 50745.45 | O5: 0.71 | P5: 2.99 | Q5: 41.86 | R5: 48.06 | S5: -6.2 | T5: -4.15 | U5: -2.72 | V5: 16282 | W5: 16497.5 | X5: 16890.833 | Y5: 0 | Z5: 0 | AA5: 0 | AB5: 1819.01 | AC5: 2093 | AD5: 46.7 | AE5: 28.9 | AF5: 56.7 | AG5: 39.8 | AH5: D
A6: A308430 | B6: 셀비온 | E6: 1.4 | F6: 5.1 | G6: 134.1 | H6: 10.7 | I6: 6.7 | J6: -126.7 | K6: 14520 | L6: 26990 | M6: 3.9 | N6: 36771.15 | O6: 0.73 | P6: 4.63 | Q6: 30.29 | R6: 31.19 | S6: -0.9 | T6: -1.89 | U6: -18.38 | V6: 16254 | W6: 16764 | X6: 24424.5 | Y6: 0 | Z6: 0 | AA6: 0 | AB6: 4476.54 | AC6: 1874 | AD6: 32.2 | AE6: 60.6 | AF6: 61.2 | AG6: 52.2 | AH6: C
A7: A474170 | B7: 루미르 | E7: -0.2 | F7: -0.9 | G7: -37.6 | H7: 6.1 | I7: 33.2 | J7: 173.4 | K7: 6630 | L7: 60196 | M7: 4 | N7: 148222.25 | O7: 0.41 | P7: 4.37 | Q7: 27.96 | R7: 26.04 | S7: 1.9 | T7: 2 | U7: -35.82 | V7: 7209 | W7: 7997.5 | X7: 11746.833 | Y7: 0 | Z7: 0 | AA7: 0 | AB7: 4043.84 | AC7: 1181 | AD7: 31.3 | AE7: 53.1 | AF7: 14.2 | AG7: 38.8 | AH7: D
A8: A475400 | B8: 씨메스 | E8: 4.3 | F8: -37 | G8: -28.9 | H8: 5.7 | I8: 77 | J8: 114.9 | K8: 16180 | L8: 29191 | M8: 4.7 | N8: 47442.7 | O8: 0.62 | P8: 5.38 | Q8: 29.58 | R8: 28.79 | S8: 0.8 | T8: 0.94 | U8: -33.82 | V8: 18059 | W8: 20302.5 | X8: 26976.667 | Y8: 0 | Z8: 0 | AA8: 0 | AB8: 12050.57 | AC8: 1910 | AD8: 31.7 | AE8: 54.4 | AF8: 46.3 | AG8: 46 | AH8: D
A9: A466100 | B9: 클로봇 | E9: 154.2 | F9: 251.8 | G9: 281.2 | H9: 66.2 | I9: 263.5 | J9: 1226.9 | K9: 25150 | L9: 243091 | M9: 61.1 | N9: 221270.75 | O9: 1.1 | P9: 5.76 | Q9: 33.14 | R9: 30.95 | S9: 2.2 | T9: 2.65 | U9: -26.35 | V9: 27486.7 | W9: 30072.7 | X9: 38696.15 | Y9: 0 | Z9: 0 | AA9: 0 | AB9: 13383.89 | AC9: 6403 | AD9: 48.6 | AE9: 91.1 | AF9: 89.6 | AG9: 78 | AH9: B
A10: A458650 | B10: 성우 | E10: 0 | F10: 0.7 | G10: 18.9 | H10: 1.1 | I10: 2.3 | J10: 16 | K10: 8010 | L10: 17277 | M10: 1.4 | N10: 30397.25 | O10: 0.57 | P10: 3.96 | Q10: 31.18 | R10: 29.04 | S10: 2.1 | T10: 1.78 | U10: -28.1 | V10: 8492 | W10: 9246.5 | X10: 11752.667 | Y10: 0 | Z10: 0 | AA10: 0 | AB10: 4570.13 | AC10: 1205 | AD10: 43.5 | AE10: 51.2 | AF10: 37.3 | AG10: 46.1 | AH10: D
A11: A336680 | B11: 탑런토탈솔루션 | E11: 0 | F11: 0 | G11: 0 | H11: 1.8 | I11: 10.3 | J11: 5.5 | K11: 2585 | L11: 29183 | M11: 0.8 | N11: 21527.4 | O11: 1.36 | P11: 2.57 | Q11: 29.69 | R11: 31.05 | S11: -1.4 | T11: -1.34 | U11: -14.4 | V11: 2713 | W11: 2800.5 | X11: 3333.75 | Y11: 0 | Z11: 0 | AA11: 0 | AB11: 597.46 | AC11: 1012 | AD11: 35.9 | AE11: 50.5 | AF11: 97 | AG11: 55.4 | AH11: C
A12: A376270 | B12: HEM파마 | E12: -7.1 | F12: -11.5 | G12: 17.1 | H12: -8.5 | I12: -44.5 | J12: -79.2 | K12: 39900 | L12: 9120 | M12: 3.6 | N12: 15589.95 | O12: 0.58 | P12: 5.09 | Q12: 36.8 | R12: 37.25 | S12: -0.5 | T12: -0.75 | U12: -6.01 | V12: 42670 | W12: 45067.5 | X12: 53419.167 | Y12: 0 | Z12: 0 | AA12: 0 | AB12: 14563.14 | AC12: 2874 | AD12: 52 | AE12: 28.4 | AF12: 40.3 | AG12: 37.9 | AH12: D
A13: A475560 | B13: 더본코리아 | E13: 0 | F13: -1.4 | G13: 11.7 | H13: 1.7 | I13: 5.6 | J13: 18.5 | K13: 14390 | L13: 13573 | M13: 2 | N13: 18879.45 | O13: 0.72 | P13: 3.05 | Q13: 37.76 | R13: 39.78 | S13: -2 | T13: -1.77 | U13: -10.29 | V13: 14661 | W13: 15058.5 | X13: 17773.5 | Y13: 0 | Z13: 0 | AA13: 0 | AB13: 2553.12 | AC13: 2134 | AD13: 45.2 | AE13: 49.5 | AF13: 58.2 | AG13: 50 | AH13: D
... A45: A439260 | B45: 대한조선 | E45: 0.8 | F45: -171 | G45: -22.5 | H45: 47 | I45: 403.3 | J45: 255 | K45: 47000 | L45: 44207 | M45: 20.8 | N45: 79055.7 | O45: 0.56 | P45: 3.5 | Q45: 28.4 | R45: 29.16 | S45: -0.8 | T45: -1.36 | U45: -21.67 | V45: 51045 | W45: 55467.5 | X45: 69895.833 | Y45: 0 | Z45: 0 | AA45: 0 | AB45: 22342.45 | AC45: 17902 | AD45: 30.8 | AE45: 63.7 | AF45: 33.6 | AG45: 47.8 | AH45: D
A46: A309710 | B46: 아이티켐 | E46: 0 | F46: 0 | G46: 0 | H46: 0 | I46: 0 | J46: 0 | K46: 21000 | L46: 0 | M46: 0 | N46: 0 | P46: 0 | Q46: 18.31 | R46: 18.31 | S46: 0 | T46: 0 | U46: 0 | V46: 21000 | W46: 21000 | X46: 21000 | Y46: 0 | Z46: 0 | AA46: 0 | AB46: 0 | AC46: 2684 | AD46: 46.1 | AE46: 46.5 | AH46: -
A47: A456160 | B47: 지투지바이오 | E47: -109.8 | F47: -607.6 | G47: -1174.4 | H47: 111.2 | I47: 498.1 | J47: 893.5 | K47: 31600 | L47: 139130 | M47: 44 | N47: 188483.65 | O47: 0.74 | P47: 6.9 | Q47: 30.28 | R47: 30.71 | S47: -0.4 | T47: -1.4 | U47: -31.6 | V47: 37600 | W47: 40565 | X47: 58581.667 | Y47: 0 | Z47: 0 | AA47: 0 | AB47: 19327.92 | AC47: 5255 | AD47: 24.8 | AE47: 50.1 | AF47: 64.9 | AG47: 45.5 | AH47: D
A48: A484590 | B48: 삼양컴텍 | E48: -11.1 | F48: -12.4 | G48: -116.7 | H48: 6.1 | I48: -132.9 | J48: -53.7 | K48: 5820 | L48: 326710 | M48: 19 | N48: 377527.35 | O48: 0.87 | P48: 6.04 | Q48: 32.24 | R48: 32.81 | S48: -0.6 | T48: -1.69 | U48: -26.33 | V48: 6793 | W48: 7541.5 | X48: 9676.8333 | Y48: 0 | Z48: 0 | AA48: 0 | AB48: 4248.04 | AC48: 2398 | AD48: 31.6 | AE48: 28 | AF48: 77.6 | AG48: 39 | AH48: D
A49: A125490 | B49: 한라캐스트 | E49: 21.4 | F49: 33.8 | G49: 431.7 | H49: 45.2 | I49: 159 | J49: -253.7 | K49: 7530 | L49: 388592 | M49: 29.3 | N49: 606329 | O49: 0.64 | P49: 5.56 | Q49: 28.33 | R49: 28.22 | S49: 0.1 | T49: 0.13 | U49: -40.66 | V49: 8502 | W49: 9754 | X49: 13353.833 | Y49: 0 | Z49: 0 | AA49: 0 | AB49: 6864.32 | AC49: 2749 | AD49: 21.7 | AE49: 74.6 | AF49: 49.3 | AG49: 53.7 | AH49: C
A50: A318060 | B50: 그래피 | E50: -4.6 | F50: -31.6 | G50: 25.7 | H50: -51 | I50: -178 | J50: -152.1 | K50: 17540 | L50: 128655 | M50: 22.6 | N50: 117710.9 | O50: 1.09 | P50: 5.87 | Q50: 40.69 | R50: 45.52 | S50: -4.8 | T50: -7.83 | U50: -21.7 | V50: 17028 | W50: 18454.5 | X50: 26354.833 | Y50: 1 | Z50: 0 | AA50: 0 | AB50: 8994.69 | AC50: 1960 | AD50: 51.9 | AE50: 22 | AF50: 88.1 | AG50: 44.2 | AH50: D
A51: A488280 | B51: 에스투더블유 | E51: -1.6 | F51: -7.8 | G51: -66.2 | H51: 12.6 | I51: 60.6 | J51: 152 | K51: 9550 | L51: 44146 | M51: 4.2 | N51: 108830.55 | O51: 0.41 | P51: 6.75 | Q51: 29.86 | R51: 29.56 | S51: 0.3 | T51: 0.53 | U51: -36.59 | V51: 10816 | W51: 12833 | X51: 19005.833 | Y51: 0 | Z51: 0 | AA51: 0 | AB51: 9033.37 | AC51: 1032 | AD51: 27 | AE51: 50.1 | AF51: 14.2 | AG51: 36 | AH51: D
A52: A317450 | B52: 명인제약 | E52: -0.5 | F52: 7 | G52: -536.8 | H52: -1.7 | I52: 18.2 | J52: 376.1 | K52: 42000 | L52: 10358 | M52: 4.4 | N52: 22670.25 | O52: 0.46 | P52: 3.04 | Q52: 42.58 | R52: 45.81 | S52: -3.2 | T52: -2.33 | U52: -3 | V52: 42390 | W52: 42800 | X52: 48755 | Y52: 0 | Z52: 0 | AA52: 0 | AB52: 5316.77 | AC52: 6132 | AD52: 50 | AE52: 47.7 | AF52: 21.6 | AG52: 43.2 | AH52: D
A53: A486990 | B53: 노타 | E53: -0.4 | F53: -37 | G53: -974.3 | H53: 56.1 | I53: -9.1 | J53: 120.7 | K53: 18010 | L53: 103371 | M53: 18.6 | N53: 202482.8 | O53: 0.51 | P53: 8.48 | Q53: 31.94 | R53: 31.97 | S53: 0 | T53: -0.11 | U53: -33.91 | V53: 20206 | W53: 22395.5 | X53: 29232.667 | Y53: 0 | Z53: 0 | AA53: 0 | AB53: 11408.93 | AC53: 3844 | AD53: 30 | AE53: 44.2 | AF53: 28.4 | AG53: 36.8 | AH53: D
A54: A469610 | B54: 이노테크 | E54: -5 | F54: -31.5 | G54: -45.9 | H54: 12.7 | I54: -3.5 | J54: -27.1 | K54: 13240 | L54: 74005 | M54: 9.8 | N54: 194445.2 | O54: 0.38 | P54: 9.22 | Q54: 40.83 | R54: 41.07 | S54: -0.2 | T54: -0.6 | U54: -6.96 | V54: 14157 | W54: 15229.5 | X54: 19367 | Y54: 0 | Z54: 0 | AA54: 0 | AB54: 7509.61 | AC54: 1184 | AD54: 53.8 | AE54: 37.5 | AF54: 7.5 | AG54: 36.4 | AH54: D
A55: A494120 | B55: 큐리오시스 | E55: 20.9 | F55: 203.5 | G55: 636.7 | H55: -14 | I55: -65.8 | J55: -505.2 | K55: 24200 | L55: 46941 | M55: 11.4 | N55: 118563.6 | O55: 0.4 | P55: 8.64 | Q55: 40.42 | R55: 42.21 | S55: -1.8 | T55: -4.35 | U55: -10.37 | V55: 25160 | W55: 26360 | X55: 39245 | Y55: 0 | Z55: 0 | AA55: 0 | AB55: 9330.94 | AC55: 1846 | AD55: 37.8 | AE55: 54.3 | AF55: 9.7 | AG55: 40.4 | AH55: D
A56: A061090 | B56: 세나테크놀로지 | E56: 0.3 | F56: 46.7 | G56: -139.8 | H56: -3.7 | I56: 12.8 | J56: -17 | K56: 37500 | L56: 16685 | M56: 6.3 | N56: 25570.25 | O56: 0.65 | P56: 6.14 | Q56: 51.53 | R56: 48.74 | S56: 2.8 | T56: 3.31 | U56: -13.39 | V56: 33910 | W56: 34910 | X56: 40955 | Y56: 1 | Z56: 1 | AA56: 0 | AB56: 16799.71 | AC56: 2050 | AD56: 86.4 | AE56: 50.3 | AF56: 52.2 | AG56: 61.5 | AH56: C
A57: A403850 | B57: 더핑크퐁컴퍼니 | E57: 58.5 | F57: 109.5 | G57: 123 | H57: -30.1 | I57: 256.3 | J57: 255.6 | K57: 10900 | L57: 172250 | M57: 18.8 | N57: 86743.65 | O57: 1.99 | P57: 4.52 | Q57: 44.9 | R57: 40.14 | S57: 4.8 | T57: 4.41 | U57: -4.55 | V57: 10753 | W57: 11077 | X57: 13527.5 | Y57: 1 | Z57: 0 | AA57: 0 | AB57: 2486.86 | AC57: 1564 | AD57: 91.6 | AE57: 69.2 | AF57: 98.5 | AG57: 81.8 | AH57: A
A58: A388210 | B58: 씨엠티엑스 | E58: 196.5 | F58: -120.2 | G58: -275.1 | H58: 34.1 | I58: 564.1 | J58: 108.6 | K58: 75900 | L58: 90294 | M58: 68.5 | N58: 73644.5 | O58: 1.23 | P58: 6.48 | Q58: 34.49 | R58: 27.08 | S58: 7.4 | T58: 10.16 | U58: -31.81 | V58: 84650 | W58: 94660 | X58: 117265 | Y58: 0 | Z58: 0 | AA58: 0 | AB58: 52083.07 | AC58: 7328 | AD58: 47.8 | AE58: 64.9 | AF58: 94 | AG58: 65.6 | AH58: B
... A65: A279570 | B65: 케이뱅크 | E65: -14.1 | F65: 3.2 | G65: 8199 | H65: 26.6 | I65: -271.1 | J65: 309 | K65: 5300 | L65: 864368 | M65: 45.8 | N65: 4344194.2 | O65: 0.2 | P65: 3.91 | Q65: 36.3 | R65: 36.65 | S65: -0.4 | T65: -0.38 | U65: -14.79 | V65: 5545 | W65: 6062.5 | X65: 5966 | Y65: 0 | Z65: 0 | AA65: 0 | AB65: 2441.34 | AC65: 21502 | AD65: 47.6 | AE65: 51.8 | AF65: 1.5 | AG65: 40.5 | AH65: D
A66: A493280 | B66: 아이엠바이오로직스 | K66: 20300 | L66: 81517 | M66: 16.5 | N66: 106215.35 | O66: 0.77 | P66: 6.72 | Q66: 32.81 | R66: 33.12 | S66: -0.3 | T66: -0.98 | U66: -24.54 | V66: 21650 | W66: 23170 | X66: 36200.833 | Y66: 0 | Z66: 0 | AA66: 0 | AB66: 10129.64 | AC66: 3012 | AD66: 37.3 | AF66: 67.2 | AH66: -
A67: A394420 | B67: 리센스메디컬 | K67: 13600 | L67: 225913 | M67: 30.7 | N67: 279473.6 | O67: 0.81 | P67: 9.38 | Q67: 36.65 | R67: 37.54 | S67: -0.9 | T67: -3.41 | U67: -25.07 | V67: 16661 | W67: 18501 | X67: 23244.333 | Y67: 0 | Z67: 0 | AA67: 0 | AB67: 10445.04 | AC67: 1487 | AD67: 31.8 | AF67: 72.4 | AH67: -
A68: A439960 | B68: 코스모로보틱스 | K68: 12210 | L68: 681977 | M68: 83.3 | N68: 2189341.5 | O68: 0.31 | P68: 9.26 | Q68: 43.77 | R68: 43.64 | S68: 0.1 | T68: 0.49 | U68: -38.92 | V68: 13900 | W68: 17889.5 | Y68: 0 | Z68: 0 | AA68: 0 | AB68: 19052.02 | AC68: 3962 | AD68: 37.7 | AF68: 4.5 | AH68: -
A69: A477850 | B69: 마키나락스 | K69: 29650 | L69: 5670663 | M69: 1681.4 | N69: 2759232.7 | O69: 2.06 | P69: 12.65 | Q69: 71.1 | R69: 69.76 | S69: 1.3 | T69: 9.41 | U69: 47.51 | V69: 22611 | W69: 20117.5 | Y69: 1 | Z69: 1 | AA69: 0 | AB69: 18765.04 | AC69: 5264 | AD69: 99.6 | AF69: 100 | AH69: -
A70: A153890 | B70: 져스텍 | K70: 12510 | L70: 1030863 | M70: 129 | T70: -4.36 | Y70: 0 | Z70: 0 | AA70: 0 | AC70: 1507 | AH70: -
A71: A475040 | B71: 스트라드비젼 | K71: 4495 | L71: 4555338 | M71: 204.8 | T71: 0.78 | Y71: 0 | Z71: 0 | AA71: 0 | AC71: 2394 | AH71: -

Sheet 전체_전일자
A1: 코드 | B1: 코드명 | C1: 상장일 | D1: days_since_ipo | E1: 기관_일간 | F1: 기관_5일 | G1: 기관_20일 | H1: 외국인_일간 | I1: 외국인_5일 | J1: 외국인_20일 | K1: 현재가 | L1: 거래량 | M1: 거래대금(억) | N1: 20일평균거래량 | O1: RVOL(20) | P1: 변동성(30D) | Q1: RSI(14) | R1: 전일RSI(14) | S1: RSI변화량 | T1: 1일수익률(%) | U1: 20일수익률(%) | V1: 10일이평 | W1: 20일이평 | X1: 60일이평 | Y1: 10일선돌파 | Z1: 20일선돌파 | AA1: 60일선돌파 | AB1: BB폭 | AC1: 시가총액(억) | AD1: 모멘텀스코어 | AE1: 수급스코어 | AF1: 거래량스코어 | AG1: 종합스코어 | AH1: 등급
A2: A062040 | B2: 산일전기 | E2: -1112.6 | F2: -1875.2 | G2: 6834.9 | H2: 1784.4 | I2: -1823.4 | J2: -7952.4 | K2: 178200 | L2: 448109 | M2: 798.5 | N2: 335915.95 | O2: 1.33 | P2: 5.3 | Q2: 34.51 | R2: 37.89 | S2: -3.4 | T2: -7.86 | U2: -18.44 | V2: 220260 | W2: 227730 | X2: 239516.67 | Y2: 0 | Z2: 0 | AA2: 0 | AB2: 79993.71 | AC2: 54986 | AD2: 34.9 | AE2: 33.2 | AF2: 89.6 | AG2: 45 | AH2: D
A3: A079900 | B3: 전진건설로봇 | E3: 0 | F3: -42.3 | G3: -259.3 | H3: 23.3 | I3: -36.6 | J3: 193.8 | K3: 34500 | L3: 56106 | M3: 19.4 | N3: 79685.1 | O3: 0.7 | P3: 5.61 | Q3: 27.17 | R3: 30.8 | S3: -3.6 | T3: -8.12 | U3: -32.22 | V3: 37980 | W3: 44887.5 | X3: 56283.333 | Y3: 0 | Z3: 0 | AA3: 0 | AB3: 33298.16 | AC3: 4954 | AD3: 15.9 | AE3: 48.1 | AF3: 41.8 | AG3: 37.2 | AH3: D
A4: A389650 | B4: 넥스트바이오메디컬 | E4: 9.6 | F4: 91 | G4: 507.1 | H4: -72.2 | I4: -136 | J4: -366.8 | K4: 39350 | L4: 47422 | M4: 18.7 | N4: 57273.75 | O4: 0.83 | P4: 6.72 | Q4: 43.84 | R4: 47.22 | S4: -3.4 | T4: -4.72 | U4: 1.16 | V4: 40515 | W4: 40890 | X4: 49555.833 | Y4: 0 | Z4: 0 | AA4: 0 | AB4: 6680.6 | AC4: 3121 | AD4: 64.7 | AE4: 50.5 | AF4: 56.7 | AG4: 56 | AH4: C
A5: A461300 | B5: 아이스크림미디어 | E5: -7.9 | F5: -7.1 | G5: -431 | H5: 12.1 | I5: 9.6 | J5: 217 | K5: 16390 | L5: 23008 | M5: 3.8 | N5: 52311.05 | O5: 0.44 | P5: 2.91 | Q5: 48.06 | R5: 46.1 | S5: 2 | T5: 1.11 | U5: 0.92 | V5: 16392 | W5: 16519.5 | X5: 16888 | Y5: 0 | Z5: 0 | AA5: 0 | AB5: 1703.38 | AC5: 2093 | AD5: 73.9 | AE5: 48.1 | AF5: 9 | AG5: 48 | AH5: D
A6: A308430 | B6: 셀비온 | E6: 0.3 | F6: 8.6 | G6: 137.1 | H6: 5.8 | I6: -16.6 | J6: -140.7 | K6: 14800 | L6: 34823 | M6: 5.2 | N6: 37476.4 | O6: 0.93 | P6: 4.63 | Q6: 31.19 | R6: 35.38 | S6: -4.2 | T6: -7.5 | U6: -16.29 | V6: 16399 | W6: 16927.5 | X6: 24685 | Y6: 0 | Z6: 0 | AA6: 0 | AB6: 4052.83 | AC6: 1874 | AD6: 35.2 | AE6: 57.9 | AF6: 67.2 | AG6: 53 | AH6: C
A7: A474170 | B7: 루미르 | E7: -0.6 | F7: -1 | G7: -38.1 | H7: 8.3 | I7: 20.7 | J7: 165.3 | K7: 6500 | L7: 66984 | M7: 4.4 | N7: 153381.6 | O7: 0.44 | P7: 4.33 | Q7: 26.04 | R7: 28.49 | S7: -2.4 | T7: -6.47 | U7: -36.27 | V7: 7317 | W7: 8182.5 | X7: 11865.5 | Y7: 0 | Z7: 0 | AA7: 0 | AB7: 4319.89 | AC7: 1181 | AD7: 17 | AE7: 56.2 | AF7: 9 | AG7: 35 | AH7: D
A8: A475400 | B8: 씨메스 | E8: -9.6 | F8: -66 | G8: -28.1 | H8: 25.1 | I8: 65.6 | J8: 123.3 | K8: 16030 | L8: 42936 | M8: 6.9 | N8: 48247.1 | O8: 0.89 | P8: 5.4 | Q8: 28.79 | R8: 30.51 | S8: -1.7 | T8: -4.81 | U8: -33.35 | V8: 18411 | W8: 20716 | X8: 27206.167 | Y8: 0 | Z8: 0 | AA8: 0 | AB8: 11943.44 | AC8: 1910 | AD8: 29 | AE8: 50 | AF8: 63.4 | AG8: 46.4 | AH8: D
A9: A466100 | B9: 클로봇 | E9: 21 | F9: 90.5 | G9: 357.2 | H9: 59.8 | I9: 185.6 | J9: 1217 | K9: 24500 | L9: 134601 | M9: 33 | N9: 224691.35 | O9: 0.6 | P9: 5.79 | Q9: 30.95 | R9: 33.97 | S9: -3 | T9: -7.2 | U9: -23.25 | V9: 27889 | W9: 30522.5 | X9: 38978.683 | Y9: 0 | Z9: 0 | AA9: 0 | AB9: 13029.9 | AC9: 6403 | AD9: 32 | AE9: 88.5 | AF9: 30.6 | AG9: 60 | AH9: C
A10: A458650 | B10: 성우 | E10: 0 | F10: 0.7 | G10: 18.9 | H10: -3 | I10: -4.6 | J10: 15.3 | K10: 7870 | L10: 18856 | M10: 1.5 | N10: 30728.55 | O10: 0.61 | P10: 3.98 | Q10: 29.04 | R10: 32.09 | S10: -3.1 | T10: -5.52 | U10: -26.45 | V10: 8506 | W10: 9403 | X10: 11830.333 | Y10: 0 | Z10: 0 | AA10: 0 | AB10: 4705.25 | AC10: 1205 | AD10: 33.1 | AE10: 51.4 | AF10: 35.1 | AG10: 42.6 | AH10: D
A11: A336680 | B11: 탑런토탈솔루션 | E11: 0 | F11: 0 | G11: 0 | H11: 1.2 | I11: 8.9 | J11: 3.9 | K11: 2620 | L11: 11431 | M11: 0.3 | N11: 20863.55 | O11: 0.55 | P11: 2.56 | Q11: 31.05 | R11: 34.36 | S11: -3.3 | T11: -2.96 | U11: -12.67 | V11: 2722.5 | W11: 2822.25 | X11: 3354.9167 | Y11: 0 | Z11: 0 | AA11: 0 | AB11: 592.27 | AC11: 1012 | AD11: 51.2 | AE11: 53.5 | AF11: 22.4 | AG11: 46.6 | AH11: D
A12: A376270 | B12: HEM파마 | E12: -7.2 | F12: 0 | G12: 24.4 | H12: 2.9 | I12: -42.7 | J12: -69.8 | K12: 40200 | L12: 17695 | M12: 7.1 | N12: 15617.4 | O12: 1.13 | P12: 5.26 | Q12: 37.25 | R12: 40.82 | S12: -3.6 | T12: -5.41 | U12: -6.07 | V12: 43015 | W12: 45195 | X12: 53802.5 | Y12: 0 | Z12: 0 | AA12: 0 | AB12: 13997.99 | AC12: 2874 | AD12: 53.9 | AE12: 43.6 | AF12: 82.1 | AG12: 54.4 | AH12: C
A13: A475560 | B13: 더본코리아 | E13: -0.1 | F13: -1.3 | G13: 14.6 | H13: 1.6 | I13: 6.7 | J13: 19.8 | K13: 14650 | L13: 11430 | M13: 1.7 | N13: 18638.8 | O13: 0.61 | P13: 3.06 | Q13: 39.78 | R13: 43.71 | S13: -3.9 | T13: -3.11 | U13: -6.69 | V13: 14662 | W13: 15141 | X13: 17885.333 | Y13: 0 | Z13: 0 | AA13: 0 | AB13: 2612.03 | AC13: 2134 | AD13: 60.9 | AE13: 51.6 | AF13: 35.1 | AG13: 51.1 | AH13: C
... A45: A439260 | B45: 대한조선 | E45: -102.7 | F45: -124.2 | G45: -76.1 | H45: 95.4 | I45: 292.7 | J45: 124.9 | K45: 47650 | L45: 101875 | M45: 48.5 | N45: 81034.4 | O45: 1.26 | P45: 3.53 | Q45: 29.16 | R45: 33.15 | S45: -4 | T45: -6.2 | U45: -22.01 | V45: 51705 | W45: 56117.5 | X45: 70575.833 | Y45: 0 | Z45: 0 | AA45: 0 | AB45: 21248.56 | AC45: 17902 | AD45: 35 | AE45: 49.1 | AF45: 85.1 | AG45: 52.1 | AH45: C
A46: A309710 | B46: 아이티켐 | E46: 0 | F46: 0 | G46: 0 | H46: 0 | I46: 0 | J46: 0 | K46: 21000 | L46: 0 | M46: 0 | N46: 0 | P46: 0 | Q46: 18.31 | R46: 18.31 | S46: 0 | T46: 0 | U46: 0 | V46: 21000 | W46: 21000 | X46: 21000 | Y46: 0 | Z46: 0 | AA46: 0 | AB46: 0 | AC46: 2684 | AD46: 55.1 | AE46: 50.6 | AH46: -
A47: A456160 | B47: 지투지바이오 | E47: -163 | F47: -417.9 | G47: -1244.2 | H47: 183.3 | I47: -82.3 | J47: 971.7 | K47: 32050 | L47: 178455 | M47: 57.2 | N47: 189052.6 | O47: 0.94 | P47: 6.92 | Q47: 30.71 | R47: 34.1 | S47: -3.4 | T47: -9.72 | U47: -31.37 | V47: 38460 | W47: 41295 | X47: 59241.667 | Y47: 0 | Z47: 0 | AA47: 0 | AB47: 18059.56 | AC47: 5255 | AD47: 16.3 | AE47: 37.2 | AF47: 68.7 | AG47: 37.2 | AH47: D
A48: A484590 | B48: 삼양컴텍 | E48: -13.3 | F48: 1.5 | G48: -166.8 | H48: -30.1 | I48: -155.6 | J48: -220.8 | K48: 5920 | L48: 378801 | M48: 22.4 | N48: 461277.1 | O48: 0.82 | P48: 6.06 | Q48: 32.81 | R48: 36.1 | S48: -3.3 | T48: -8.5 | U48: -19.35 | V48: 6913 | W48: 7645.5 | X48: 9779.6667 | Y48: 0 | Z48: 0 | AA48: 0 | AB48: 3950.28 | AC48: 2398 | AD48: 30.9 | AE48: 27.4 | AF48: 55.2 | AG48: 34 | AH48: D
A49: A125490 | B49: 한라캐스트 | E49: 9.4 | F49: 11.6 | G49: 1343.2 | H49: 67.1 | I49: 68 | J49: -1076.3 | K49: 7520 | L49: 570176 | M49: 42.9 | N49: 744998.95 | O49: 0.77 | P49: 5.54 | Q49: 28.22 | R49: 31.12 | S49: -2.9 | T49: -8.29 | U49: -35.78 | V49: 8644 | W49: 10012 | X49: 13450.833 | Y49: 0 | Z49: 0 | AA49: 0 | AB49: 6999.5 | AC49: 2749 | AD49: 13.7 | AE49: 75 | AF49: 48.5 | AG49: 51.3 | AH49: C
A50: A318060 | B50: 그래피 | E50: -35.7 | F50: -28.2 | G50: 29.5 | H50: -129.7 | I50: -154.3 | J50: -96.1 | K50: 19030 | L50: 304189 | M50: 57.9 | N50: 114056.25 | O50: 2.67 | P50: 5.75 | Q50: 45.52 | R50: 41.26 | S50: 4.3 | T50: 5.43 | U50: -12.91 | V50: 16941 | W50: 18697.5 | X50: 26665.833 | Y50: 1 | Z50: 1 | AA50: 0 | AB50: 9578.32 | AC50: 1960 | AD50: 85.2 | AE50: 21.3 | AF50: 98.5 | AG50: 55.9 | AH50: C
A51: A488280 | B51: 에스투더블유 | E51: -1.8 | F51: -10 | G51: -66.7 | H51: 10.1 | I51: 18.9 | J51: 136.7 | K51: 9500 | L51: 64274 | M51: 6.1 | N51: 111840.7 | O51: 0.57 | P51: 6.82 | Q51: 29.56 | R51: 31.55 | S51: -2 | T51: -7.59 | U51: -35.59 | V51: 11131 | W51: 13108.5 | X51: 19114.833 | Y51: 0 | Z51: 0 | AA51: 0 | AB51: 8702.44 | AC51: 1032 | AD51: 18.8 | AE51: 51.8 | AF51: 23.9 | AG51: 36.3 | AH51: D
A52: A317450 | B52: 명인제약 | E52: 5.5 | F52: 4.4 | G52: -544.4 | H52: 5.7 | I52: 25.7 | J52: 384 | K52: 43000 | L52: 19595 | M52: 8.4 | N52: 22644.6 | O52: 0.87 | P52: 3.03 | Q52: 45.81 | R52: 48.55 | S52: -2.7 | T52: -1.83 | U52: -1.71 | V52: 42270 | W52: 42865 | X52: 49010 | Y52: 1 | Z52: 1 | AA52: 0 | AB52: 5280.95 | AC52: 6132 | AD52: 89.6 | AE52: 64.2 | AF52: 59.7 | AG52: 70.9 | AH52: B
A53: A486990 | B53: 노타 | E53: -23.1 | F53: -36.3 | G53: -909.8 | H53: 33.7 | I53: -275 | J53: -8 | K53: 18030 | L53: 162729 | M53: 29.3 | N53: 211080.2 | O53: 0.77 | P53: 8.56 | Q53: 31.97 | R53: 35.08 | S53: -3.1 | T53: -8.1 | U53: -33.22 | V53: 20550 | W53: 22857.5 | X53: 29485 | Y53: 0 | Z53: 0 | AA53: 0 | AB53: 11411.19 | AC53: 3844 | AD53: 21.7 | AE53: 30.8 | AF53: 48.5 | AG53: 31.6 | AH53: D
A54: A469610 | B54: 이노테크 | E54: 5.7 | F54: -24.9 | G54: -41.7 | H54: 2.7 | I54: -17.3 | J54: -29.8 | K54: 13320 | L54: 110845 | M54: 14.8 | N54: 192666.45 | O54: 0.58 | P54: 9.37 | Q54: 41.07 | R54: 42.46 | S54: -1.4 | T54: -3.48 | U54: -3.34 | V54: 14529 | W54: 15279 | X54: 19460.5 | Y54: 0 | Z54: 0 | AA54: 0 | AB54: 7347.64 | AC54: 1184 | AD54: 62 | AE54: 48 | AF54: 26.1 | AG54: 47.8 | AH54: D
A55: A494120 | B55: 큐리오시스 | E55: 41.4 | F55: 164.4 | G55: 621.4 | H55: -55.5 | I55: 20.2 | J55: -490.5 | K55: 25300 | L55: 91126 | M55: 23.1 | N55: 117584.25 | O55: 0.77 | P55: 8.62 | Q55: 42.21 | R55: 46.57 | S55: -4.4 | T55: -8.99 | U55: -2.32 | V55: 25535 | W55: 26500 | X55: 39723.333 | Y55: 0 | Z55: 0 | AA55: 0 | AB55: 9129.51 | AC55: 1846 | AD55: 44.8 | AE55: 62.9 | AF55: 48.5 | AG55: 54.6 | AH55: C
A56: A061090 | B56: 세나테크놀로지 | E56: 5.1 | F56: 45.9 | G56: -60.9 | H56: 2.7 | I56: 9.4 | J56: -14.6 | K56: 36300 | L56: 14031 | M56: 5.1 | N56: 27038 | O56: 0.52 | P56: 6.43 | Q56: 48.74 | R56: 49.29 | S56: -0.5 | T56: -0.68 | U56: -10.92 | V56: 33020 | W56: 35200 | X56: 40982.5 | Y56: 1 | Z56: 1 | AA56: 0 | AB56: 18216.26 | AC56: 2050 | AD56: 87.1 | AE56: 60.7 | AF56: 14.9 | AG56: 59.5 | AH56: C
A57: A403850 | B57: 더핑크퐁컴퍼니 | E57: 7.5 | F57: 50.2 | G57: 47.3 | H57: -9.8 | I57: 296.8 | J57: 305.7 | K57: 10440 | L57: 113824 | M57: 11.9 | N57: 82450.6 | O57: 1.38 | P57: 4.43 | Q57: 40.14 | R57: 43.48 | S57: -3.3 | T57: -4.04 | U57: -8.66 | V57: 10751 | W57: 11103 | X57: 13629.833 | Y57: 0 | Z57: 0 | AA57: 0 | AB57: 2498.55 | AC57: 1564 | AD57: 58.2 | AE57: 72.2 | AF57: 93.3 | AG57: 72.2 | AH57: B
A58: A388210 | B58: 씨엠티엑스 | E58: -28.5 | F58: -401.8 | G58: -307.6 | H58: 264.7 | I58: 348.2 | J58: -73.4 | K58: 68900 | L58: 94674 | M58: 65.2 | N58: 72931.8 | O58: 1.3 | P58: 6.27 | Q58: 27.08 | R58: 30.67 | S58: -3.6 | T58: -10.17 | U58: -35 | V58: 86520 | W58: 96430 | X58: 118125 | Y58: 0 | Z58: 0 | AA58: 0 | AB58: 51014.52 | AC58: 7328 | AD58: 7.3 | AE58: 46.7 | AF58: 88.1 | AG58: 43.2 | AH58: D
... A65: A279570 | B65: 케이뱅크 | E65: -20 | F65: 140.1 | G65: 8819.9 | H65: -61 | I65: -266.1 | J65: 533.5 | K65: 5320 | L65: 1214065 | M65: 64.6 | N65: 4935065.9 | O65: 0.25 | P65: 3.94 | Q65: 36.65 | R65: 39.26 | S65: -2.6 | T65: -2.74 | U65: -11.77 | V65: 5629 | W65: 6108.5 | X65: 5981.8333 | Y65: 0 | Z65: 0 | AA65: 0 | AB65: 2341.15 | AC65: 21502 | AD65: 57.5 | AE65: 46 | AF65: 3 | AG65: 40.8 | AH65: D
A66: A493280 | B66: 아이엠바이오로직스 | K66: 20500 | L66: 142838 | M66: 29.3 | N66: 105215.7 | O66: 1.36 | P66: 6.73 | Q66: 33.12 | R66: 35.07 | S66: -2 | T66: -5.75 | U66: -22.79 | V66: 21760 | W66: 23500 | X66: 36680.833 | Y66: 0 | Z66: 0 | AA66: 0 | AB66: 10266.84 | AC66: 3012 | AD66: 40.5 | AF66: 91 | AH66: -
A67: A394420 | B67: 리센스메디컬 | K67: 14080 | L67: 326181 | M67: 45.9 | N67: 277203.35 | O67: 1.18 | P67: 9.39 | Q67: 37.54 | R67: 41.57 | S67: -4 | T67: -12.87 | U67: -24.71 | V67: 17137 | W67: 18728.5 | X67: 23386 | Y67: 0 | Z67: 0 | AA67: 0 | AB67: 9442.11 | AC67: 1487 | AD67: 26.9 | AF67: 83.6 | AH67: -
A68: A439960 | B68: 코스모로보틱스 | K68: 12150 | L68: 508575 | M68: 61.8 | N68: 2284073.8 | O68: 0.22 | P68: 9.31 | Q68: 43.64 | R68: 44.78 | S68: -1.1 | T68: -5.52 | U68: -44.65 | V68: 14324 | W68: 18278.5 | Y68: 0 | Z68: 0 | AA68: 0 | AB68: 18392.46 | AC68: 3962 | AD68: 34.7 | AF68: 1.5 | AH68: -
A69: A477850 | B69: 마키나락스 | K69: 27100 | L69: 7894689 | M69: 2139.5 | N69: 2497127.7 | O69: 3.16 | P69: 12.79 | Q69: 69.76 | R69: 68.37 | S69: 1.4 | T69: 10.61 | U69: 34.49 | V69: 21289 | W69: 19640 | Y69: 1 | Z69: 1 | AA69: 0 | AB69: 16606.75 | AC69: 5264 | AD69: 100 | AF69: 100 | AH69: -
A70: A153890 | B70: 져스텍 | K70: 13080 | L70: 3660585 | M70: 478.8 | T70: -1.65 | Y70: 0 | Z70: 0 | AA70: 0 | AC70: 1507 | AH70: -
A71: A475040 | B71: 스트라드비젼 | K71: 4460 | L71: 14088228 | M71: 628.3 | T71: -1 | Y71: 0 | Z71: 0 | AA71: 0 | AC71: 2394 | AH71: -

Sheet RSI과매도
A1: 코드 | B1: 코드명 | C1: 상장일 | D1: days_since_ipo | E1: 기관_일간 | F1: 기관_5일 | G1: 기관_20일 | H1: 외국인_일간 | I1: 외국인_5일 | J1: 외국인_20일 | K1: 현재가 | L1: 거래량 | M1: 거래대금(억) | N1: 20일평균거래량 | O1: RVOL(20) | P1: 변동성(30D) | Q1: RSI(14) | R1: 전일RSI(14) | S1: RSI변화량 | T1: 1일수익률(%) | U1: 20일수익률(%) | V1: 10일이평 | W1: 20일이평 | X1: 60일이평 | Y1: 10일선돌파 | Z1: 20일선돌파 | AA1: 60일선돌파 | AB1: BB폭 | AC1: 시가총액(억) | AD1: 모멘텀스코어 | AE1: 수급스코어 | AF1: 거래량스코어 | AG1: 종합스코어 | AH1: 등급
A2: A309710 | B2: 아이티켐 | E2: 0 | F2: 0 | G2: 0 | H2: 0 | I2: 0 | J2: 0 | K2: 21000 | L2: 0 | M2: 0 | N2: 0 | P2: 0 | Q2: 18.31 | R2: 18.31 | S2: 0 | T2: 0 | U2: 0 | V2: 21000 | W2: 21000 | X2: 21000 | Y2: 0 | Z2: 0 | AA2: 0 | AB2: 0 | AC2: 2684 | AD2: 46.1 | AE2: 46.5 | AH2: -
A3: A452450 | B3: 피아이이 | E3: 0 | F3: 0 | G3: 4.3 | H3: 9.7 | I3: 15.7 | J3: 61.1 | K3: 3055 | L3: 127167 | M3: 3.9 | N3: 152463.95 | O3: 0.83 | P3: 4.01 | Q3: 24.38 | R3: 25.19 | S3: -0.8 | T3: -2.24 | U3: -29.61 | V3: 3448.5 | W3: 3894.5 | X3: 5382.3333 | Y3: 0 | Z3: 0 | AA3: 0 | AB3: 2191.18 | AC3: 1101 | AD3: 17.6 | AE3: 56.1 | AF3: 74.6 | AG3: 48.2 | AH3: D
A4: A474650 | B4: 링크솔루션 | E4: -0.9 | F4: -4.2 | G4: 27.8 | H4: 6.7 | I4: 31.9 | J4: 355.5 | K4: 24050 | L4: 31476 | M4: 7.6 | N4: 56390.25 | O4: 0.56 | P4: 5.36 | Q4: 24.71 | R4: 24.01 | S4: 0.7 | T4: 0.84 | U4: -37.12 | V4: 27820 | W4: 32380 | X4: 46405 | Y4: 0 | Z4: 0 | AA4: 0 | AB4: 23970.35 | AC4: 1383 | AD4: 24.5 | AE4: 54.4 | AF4: 33.6 | AG4: 41.3 | AH4: D
A5: A476060 | B5: 온코닉테라퓨틱스 | E5: -2.5 | F5: -8.9 | G5: -165 | H5: 92.4 | I5: 430.6 | J5: 837.4 | K5: 10880 | L5: 287418 | M5: 31.3 | N5: 255260.8 | O5: 1.13 | P5: 4.51 | Q5: 25.92 | R5: 26.22 | S5: -0.3 | T5: -0.82 | U5: -31.49 | V5: 12456 | W5: 13958.5 | X5: 18202.667 | Y5: 0 | Z5: 0 | AA5: 0 | AB5: 7225.81 | AC5: 4940 | AD5: 22.8 | AE5: 61.6 | AF5: 91 | AG5: 55.8 | AH5: C
A6: A478340 | B6: 나라스페이스테크놀로지 | E6: 0.1 | F6: -103 | G6: -230.2 | H6: 2.9 | I6: 72.8 | J6: 734.4 | K6: 11300 | L6: 49927 | M6: 5.6 | N6: 151201 | O6: 0.33 | P6: 6.27 | Q6: 26.46 | R6: 26.02 | S6: 0.4 | T6: 0.71 | U6: -48.05 | V6: 12848 | W6: 15475 | X6: 25676.667 | Y6: 0 | Z6: 0 | AA6: 0 | AB6: 13823.91 | AC6: 1307 | AD6: 22.1 | AE6: 50.6 | AF6: 6 | AG6: 33.1 | AH6: D
A7: A079900 | B7: 전진건설로봇 | E7: 2.1 | F7: -38.4 | G7: -300.8 | H7: 47.1 | I7: 45.5 | J7: 246.3 | K7: 33950 | L7: 36761 | M7: 12.5 | N7: 78904.5 | O7: 0.47 | P7: 5.59 | Q7: 26.57 | R7: 27.17 | S7: -0.6 | T7: -1.59 | U7: -33.04 | V7: 37405 | W7: 44050 | X7: 55719.167 | Y7: 0 | Z7: 0 | AA7: 0 | AB7: 34149.96 | AC7: 4954 | AD7: 18.3 | AE7: 58.6 | AF7: 23.9 | AG7: 39.6 | AH7: D
A8: A474170 | B8: 루미르 | E8: -0.2 | F8: -0.9 | G8: -37.6 | H8: 6.1 | I8: 33.2 | J8: 173.4 | K8: 6630 | L8: 60196 | M8: 4 | N8: 148222.25 | O8: 0.41 | P8: 4.37 | Q8: 27.96 | R8: 26.04 | S8: 1.9 | T8: 2 | U8: -35.82 | V8: 7209 | W8: 7997.5 | X8: 11746.833 | Y8: 0 | Z8: 0 | AA8: 0 | AB8: 4043.84 | AC8: 1181 | AD8: 31.3 | AE8: 53.1 | AF8: 14.2 | AG8: 38.8 | AH8: D
A9: A125490 | B9: 한라캐스트 | E9: 21.4 | F9: 33.8 | G9: 431.7 | H9: 45.2 | I9: 159 | J9: -253.7 | K9: 7530 | L9: 388592 | M9: 29.3 | N9: 606329 | O9: 0.64 | P9: 5.56 | Q9: 28.33 | R9: 28.22 | S9: 0.1 | T9: 0.13 | U9: -40.66 | V9: 8502 | W9: 9754 | X9: 13353.833 | Y9: 0 | Z9: 0 | AA9: 0 | AB9: 6864.32 | AC9: 2749 | AD9: 21.7 | AE9: 74.6 | AF9: 49.3 | AG9: 53.7 | AH9: C
A10: A488900 | B10: 비츠로넥스텍 | E10: -0.2 | F10: -2.2 | G10: -43.5 | H10: 10.3 | I10: 45 | J10: 154.6 | K10: 7220 | L10: 62280 | M10: 4.5 | N10: 79431.05 | O10: 0.78 | P10: 5.8 | Q10: 28.38 | R10: 27.52 | S10: 0.9 | T10: 1.12 | U10: -36.05 | V10: 8067 | W10: 9068.5 | X10: 14162 | Y10: 0 | Z10: 0 | AA10: 0 | AB10: 5585.06 | AC10: 2092 | AD10: 28.5 | AE10: 54.3 | AF10: 68.7 | AG10: 49.4 | AH10: D
A11: A439260 | B11: 대한조선 | E11: 0.8 | F11: -171 | G11: -22.5 | H11: 47 | I11: 403.3 | J11: 255 | K11: 47000 | L11: 44207 | M11: 20.8 | N11: 79055.7 | O11: 0.56 | P11: 3.5 | Q11: 28.4 | R11: 29.16 | S11: -0.8 | T11: -1.36 | U11: -21.67 | V11: 51045 | W11: 55467.5 | X11: 69895.833 | Y11: 0 | Z11: 0 | AA11: 0 | AB11: 22342.45 | AC11: 17902 | AD11: 30.8 | AE11: 63.7 | AF11: 33.6 | AG11: 47.8 | AH11: D
A12: A217590 | B12: 티엠씨 | E12: 2.1 | F12: -189.4 | G12: 447.6 | H12: 28.2 | I12: 268.4 | J12: 909.6 | K12: 10560 | L12: 193614 | M12: 20.4 | N12: 395602.25 | O12: 0.49 | P12: 8.02 | Q12: 28.6 | R12: 28.03 | S12: 0.6 | T12: 0.96 | U12: -52.54 | V12: 11924 | W12: 14545 | X12: 22894.5 | Y12: 0 | Z12: 0 | AA12: 0 | AB12: 13066.79 | AC12: 2544 | AD12: 25.6 | AE12: 69.6 | AF12: 26.1 | AG12: 47.7 | AH12: D
A13: A459510 | B13: 나우로보틱스 | E13: -0.4 | F13: -1.7 | G13: -396.4 | H13: 18.2 | I13: 37.5 | J13: 177.3 | K13: 12600 | L13: 32715 | M13: 4.1 | N13: 62541.25 | O13: 0.52 | P13: 4.88 | Q13: 28.88 | R13: 27.8 | S13: 1.1 | T13: 1.2 | U13: -32.84 | V13: 13815 | W13: 15398 | X13: 21330.5 | Y13: 0 | Z13: 0 | AA13: 0 | AB13: 8608.29 | AC13: 1635 | AD13: 33.3 | AE13: 52.1 | AF13: 29.9 | AG13: 42 | AH13: D
A14: A476830 | B14: 알지노믹스 | E14: -223.2 | F14: -835.3 | G14: -2233 | H14: 143.2 | I14: -340.3 | J14: -3483.7 | K14: 30600 | L14: 250378 | M14: 76.6 | N14: 513541.05 | O14: 0.49 | P14: 7.12 | Q14: 29.04 | R14: 30.02 | S14: -1 | T14: -4.08 | U14: -34.05 | V14: 39125 | W14: 42487.5 | X14: 65725 | Y14: 0 | Z14: 0 | AA14: 0 | AB14: 21284.25 | AC14: 4292 | AD14: 12.5 | AE14: 21.4 | AF14: 26.1 | AG14: 19.7 | AH14: F
... A18: A488280 | B18: 에스투더블유 | E18: -1.6 | F18: -7.8 | G18: -66.2 | H18: 12.6 | I18: 60.6 | J18: 152 | K18: 9550 | L18: 44146 | M18: 4.2 | N18: 108830.55 | O18: 0.41 | P18: 6.75 | Q18: 29.86 | R18: 29.56 | S18: 0.3 | T18: 0.53 | U18: -36.59 | V18: 10816 | W18: 12833 | X18: 19005.833 | Y18: 0 | Z18: 0 | AA18: 0 | AB18: 9033.37 | AC18: 1032 | AD18: 27 | AE18: 50.1 | AF18: 14.2 | AG18: 36 | AH18: D

Sheet RSI과매수
A1: 코드 | B1: 코드명 | C1: 상장일 | D1: days_since_ipo | E1: 기관_일간 | F1: 기관_5일 | G1: 기관_20일 | H1: 외국인_일간 | I1: 외국인_5일 | J1: 외국인_20일 | K1: 현재가 | L1: 거래량 | M1: 거래대금(억) | N1: 20일평균거래량 | O1: RVOL(20) | P1: 변동성(30D) | Q1: RSI(14) | R1: 전일RSI(14) | S1: RSI변화량 | T1: 1일수익률(%) | U1: 20일수익률(%) | V1: 10일이평 | W1: 20일이평 | X1: 60일이평 | Y1: 10일선돌파 | Z1: 20일선돌파 | AA1: 60일선돌파 | AB1: BB폭 | AC1: 시가총액(억) | AD1: 모멘텀스코어 | AE1: 수급스코어 | AF1: 거래량스코어 | AG1: 종합스코어 | AH1: 등급
A2: A477850 | B2: 마키나락스 | K2: 29650 | L2: 5670663 | M2: 1681.4 | N2: 2759232.7 | O2: 2.06 | P2: 12.65 | Q2: 71.1 | R2: 69.76 | S2: 1.3 | T2: 9.41 | U2: 47.51 | V2: 22611 | W2: 20117.5 | Y2: 1 | Z2: 1 | AA2: 0 | AB2: 18765.04 | AC2: 5264 | AD2: 99.6 | AF2: 100 | AH2: -

Sheet 외국인순매수TOP
A1: 코드 | B1: 코드명 | C1: 상장일 | D1: days_since_ipo | E1: 기관_일간 | F1: 기관_5일 | G1: 기관_20일 | H1: 외국인_일간 | I1: 외국인_5일 | J1: 외국인_20일 | K1: 현재가 | L1: 거래량 | M1: 거래대금(억) | N1: 20일평균거래량 | O1: RVOL(20) | P1: 변동성(30D) | Q1: RSI(14) | R1: 전일RSI(14) | S1: RSI변화량 | T1: 1일수익률(%) | U1: 20일수익률(%) | V1: 10일이평 | W1: 20일이평 | X1: 60일이평 | Y1: 10일선돌파 | Z1: 20일선돌파 | AA1: 60일선돌파 | AB1: BB폭 | AC1: 시가총액(억) | AD1: 모멘텀스코어 | AE1: 수급스코어 | AF1: 거래량스코어 | AG1: 종합스코어 | AH1: 등급
A2: A064400 | B2: LG씨엔에스 | E2: -841 | F2: -770.1 | G2: -1129.1 | H2: 2350.6 | I2: 1317.5 | J2: 368.5 | K2: 69100 | L2: 1324415 | M2: 915.2 | N2: 1335695.3 | O2: 0.99 | P2: 8.76 | Q2: 36 | R2: 37.64 | S2: -1.6 | T2: -2.95 | U2: -25.7 | V2: 75010 | W2: 81385 | X2: 81620 | Y2: 0 | Z2: 0 | AA2: 0 | AB2: 32171.86 | AC2: 66948 | AD2: 30.6 | AE2: 49.4 | AF2: 80.6 | AG2: 50 | AH2: D
A3: A062040 | B3: 산일전기 | E3: 196 | F3: -2399.1 | G3: 4360.4 | H3: 342.1 | I3: 398.5 | J3: -4665.6 | K3: 179600 | L3: 241174 | M3: 433.1 | N3: 331192 | O3: 0.73 | P3: 5.32 | Q3: 35.08 | R3: 34.51 | S3: 0.6 | T3: 0.79 | U3: -15.68 | V3: 215270 | W3: 226060 | X3: 239951.67 | Y3: 0 | Z3: 0 | AA3: 0 | AB3: 89632.53 | AC3: 54986 | AD3: 49.7 | AE3: 68 | AF3: 61.2 | AG3: 61.2 | AH3: C
A4: A483650 | B4: 달바글로벌 | E4: -389.5 | F4: 489.4 | G4: 622.1 | H4: 308.8 | I4: 338.4 | J4: 6004.9 | K4: 199900 | L4: 154428 | M4: 308.7 | N4: 180360.1 | O4: 0.86 | P4: 5.04 | Q4: 43.55 | R4: 50.19 | S4: -6.6 | T4: -8.09 | U4: -5.26 | V4: 225140 | W4: 216100 | X4: 214310 | Y4: 0 | Z4: 0 | AA4: 0 | AB4: 60619.2 | AC4: 24957 | AD4: 42.3 | AE4: 77.1 | AF4: 76.1 | AG4: 66.5 | AH4: B
A5: A476830 | B5: 알지노믹스 | E5: -223.2 | F5: -835.3 | G5: -2233 | H5: 143.2 | I5: -340.3 | J5: -3483.7 | K5: 30600 | L5: 250378 | M5: 76.6 | N5: 513541.05 | O5: 0.49 | P5: 7.12 | Q5: 29.04 | R5: 30.02 | S5: -1 | T5: -4.08 | U5: -34.05 | V5: 39125 | W5: 42487.5 | X5: 65725 | Y5: 0 | Z5: 0 | AA5: 0 | AB5: 21284.25 | AC5: 4292 | AD5: 12.5 | AE5: 21.4 | AF5: 26.1 | AG5: 19.7 | AH5: F
A6: A456160 | B6: 지투지바이오 | E6: -109.8 | F6: -607.6 | G6: -1174.4 | H6: 111.2 | I6: 498.1 | J6: 893.5 | K6: 31600 | L6: 139130 | M6: 44 | N6: 188483.65 | O6: 0.74 | P6: 6.9 | Q6: 30.28 | R6: 30.71 | S6: -0.4 | T6: -1.4 | U6: -31.6 | V6: 37600 | W6: 40565 | X6: 58581.667 | Y6: 0 | Z6: 0 | AA6: 0 | AB6: 19327.92 | AC6: 5255 | AD6: 24.8 | AE6: 50.1 | AF6: 64.9 | AG6: 45.5 | AH6: D
A7: A476060 | B7: 온코닉테라퓨틱스 | E7: -2.5 | F7: -8.9 | G7: -165 | H7: 92.4 | I7: 430.6 | J7: 837.4 | K7: 10880 | L7: 287418 | M7: 31.3 | N7: 255260.8 | O7: 1.13 | P7: 4.51 | Q7: 25.92 | R7: 26.22 | S7: -0.3 | T7: -0.82 | U7: -31.49 | V7: 12456 | W7: 13958.5 | X7: 18202.667 | Y7: 0 | Z7: 0 | AA7: 0 | AB7: 7225.81 | AC7: 4940 | AD7: 22.8 | AE7: 61.6 | AF7: 91 | AG7: 55.8 | AH7: C
A8: A448900 | B8: 한국피아이엠 | E8: -5.9 | F8: -128.9 | G8: -151.8 | H8: 79.6 | I8: 326.2 | J8: 630.9 | K8: 46000 | L8: 50816 | M8: 23.4 | N8: 80402 | O8: 0.63 | P8: 6.76 | Q8: 30.01 | R8: 29.19 | S8: 0.8 | T8: 1.43 | U8: -40.65 | V8: 52645 | W8: 63287.5 | X8: 87917.5 | Y8: 0 | Z8: 0 | AA8: 0 | AB8: 54513.19 | AC8: 2794 | AD8: 30.9 | AE8: 53.8 | AF8: 47.8 | AG8: 45.7 | AH8: D
A9: A490470 | B9: 세미파이브 | E9: -7 | F9: -8.1 | G9: -1724.1 | H9: 69 | I9: -189.6 | J9: 1581.3 | K9: 18780 | L9: 367505 | M9: 69 | N9: 457458.5 | O9: 0.8 | P9: 5.92 | Q9: 32.7 | R9: 27.81 | S9: 4.9 | T9: 6.7 | U9: -30.32 | V9: 20029 | W9: 22539.5 | X9: 32417.333 | Y9: 0 | Z9: 0 | AA9: 0 | AB9: 12570.39 | AC9: 6390 | AD9: 47.5 | AE9: 41.3 | AF9: 70.1 | AG9: 48.9 | AH9: D
A10: A466100 | B10: 클로봇 | E10: 154.2 | F10: 251.8 | G10: 281.2 | H10: 66.2 | I10: 263.5 | J10: 1226.9 | K10: 25150 | L10: 243091 | M10: 61.1 | N10: 221270.75 | O10: 1.1 | P10: 5.76 | Q10: 33.14 | R10: 30.95 | S10: 2.2 | T10: 2.65 | U10: -26.35 | V10: 27486.7 | W10: 30072.7 | X10: 38696.15 | Y10: 0 | Z10: 0 | AA10: 0 | AB10: 13383.89 | AC10: 6403 | AD10: 48.6 | AE10: 91.1 | AF10: 89.6 | AG10: 78 | AH10: B
A11: A486990 | B11: 노타 | E11: -0.4 | F11: -37 | G11: -974.3 | H11: 56.1 | I11: -9.1 | J11: 120.7 | K11: 18010 | L11: 103371 | M11: 18.6 | N11: 202482.8 | O11: 0.51 | P11: 8.48 | Q11: 31.94 | R11: 31.97 | S11: 0 | T11: -0.11 | U11: -33.91 | V11: 20206 | W11: 22395.5 | X11: 29232.667 | Y11: 0 | Z11: 0 | AA11: 0 | AB11: 11408.93 | AC11: 3844 | AD11: 30 | AE11: 44.2 | AF11: 28.4 | AG11: 36.8 | AH11: D
A12: A079900 | B12: 전진건설로봇 | E12: 2.1 | F12: -38.4 | G12: -300.8 | H12: 47.1 | I12: 45.5 | J12: 246.3 | K12: 33950 | L12: 36761 | M12: 12.5 | N12: 78904.5 | O12: 0.47 | P12: 5.59 | Q12: 26.57 | R12: 27.17 | S12: -0.6 | T12: -1.59 | U12: -33.04 | V12: 37405 | W12: 44050 | X12: 55719.167 | Y12: 0 | Z12: 0 | AA12: 0 | AB12: 34149.96 | AC12: 4954 | AD12: 18.3 | AE12: 58.6 | AF12: 23.9 | AG12: 39.6 | AH12: D
A13: A439260 | B13: 대한조선 | E13: 0.8 | F13: -171 | G13: -22.5 | H13: 47 | I13: 403.3 | J13: 255 | K13: 47000 | L13: 44207 | M13: 20.8 | N13: 79055.7 | O13: 0.56 | P13: 3.5 | Q13: 28.4 | R13: 29.16 | S13: -0.8 | T13: -1.36 | U13: -21.67 | V13: 51045 | W13: 55467.5 | X13: 69895.833 | Y13: 0 | Z13: 0 | AA13: 0 | AB13: 22342.45 | AC13: 17902 | AD13: 30.8 | AE13: 63.7 | AF13: 33.6 | AG13: 47.8 | AH13: D
... A21: A415640 | B21: KB발해인프라 | E21: -15.2 | F21: -78.7 | G21: -73.7 | H21: 26.2 | I21: 512.3 | J21: 821.2 | K21: 10730 | L21: 188204 | M21: 20.2 | N21: 160985.8 | O21: 1.17 | P21: 2.01 | Q21: 63.81 | R21: 64.13 | S21: -0.3 | T21: -0.09 | U21: 8.38 | V21: 10406 | W21: 10189 | X21: 9995.6667 | Y21: 1 | Z21: 1 | AA21: 1 | AB21: 1367.33 | AC21: 13149 | AD21: 85.3 | AE21: 51.2 | AF21: 92.5 | AG21: 69.7 | AH21: B

Sheet 기관순매수TOP
A1: 코드 | B1: 코드명 | C1: 상장일 | D1: days_since_ipo | E1: 기관_일간 | F1: 기관_5일 | G1: 기관_20일 | H1: 외국인_일간 | I1: 외국인_5일 | J1: 외국인_20일 | K1: 현재가 | L1: 거래량 | M1: 거래대금(억) | N1: 20일평균거래량 | O1: RVOL(20) | P1: 변동성(30D) | Q1: RSI(14) | R1: 전일RSI(14) | S1: RSI변화량 | T1: 1일수익률(%) | U1: 20일수익률(%) | V1: 10일이평 | W1: 20일이평 | X1: 60일이평 | Y1: 10일선돌파 | Z1: 20일선돌파 | AA1: 60일선돌파 | AB1: BB폭 | AC1: 시가총액(억) | AD1: 모멘텀스코어 | AE1: 수급스코어 | AF1: 거래량스코어 | AG1: 종합스코어 | AH1: 등급
A2: A388210 | B2: 씨엠티엑스 | E2: 196.5 | F2: -120.2 | G2: -275.1 | H2: 34.1 | I2: 564.1 | J2: 108.6 | K2: 75900 | L2: 90294 | M2: 68.5 | N2: 73644.5 | O2: 1.23 | P2: 6.48 | Q2: 34.49 | R2: 27.08 | S2: 7.4 | T2: 10.16 | U2: -31.81 | V2: 84650 | W2: 94660 | X2: 117265 | Y2: 0 | Z2: 0 | AA2: 0 | AB2: 52083.07 | AC2: 7328 | AD2: 47.8 | AE2: 64.9 | AF2: 94 | AG2: 65.6 | AH2: B
A3: A062040 | B3: 산일전기 | E3: 196 | F3: -2399.1 | G3: 4360.4 | H3: 342.1 | I3: 398.5 | J3: -4665.6 | K3: 179600 | L3: 241174 | M3: 433.1 | N3: 331192 | O3: 0.73 | P3: 5.32 | Q3: 35.08 | R3: 34.51 | S3: 0.6 | T3: 0.79 | U3: -15.68 | V3: 215270 | W3: 226060 | X3: 239951.67 | Y3: 0 | Z3: 0 | AA3: 0 | AB3: 89632.53 | AC3: 54986 | AD3: 49.7 | AE3: 68 | AF3: 61.2 | AG3: 61.2 | AH3: C
A4: A466100 | B4: 클로봇 | E4: 154.2 | F4: 251.8 | G4: 281.2 | H4: 66.2 | I4: 263.5 | J4: 1226.9 | K4: 25150 | L4: 243091 | M4: 61.1 | N4: 221270.75 | O4: 1.1 | P4: 5.76 | Q4: 33.14 | R4: 30.95 | S4: 2.2 | T4: 2.65 | U4: -26.35 | V4: 27486.7 | W4: 30072.7 | X4: 38696.15 | Y4: 0 | Z4: 0 | AA4: 0 | AB4: 13383.89 | AC4: 6403 | AD4: 48.6 | AE4: 91.1 | AF4: 89.6 | AG4: 78 | AH4: B
A5: A475830 | B5: 오름테라퓨틱 | E5: 99.1 | F5: 151.7 | G5: 2739.2 | H5: -41.3 | I5: -172.4 | J5: -2628.9 | K5: 46300 | L5: 83367 | M5: 38.6 | N5: 185078.3 | O5: 0.45 | P5: 7.82 | Q5: 35.37 | R5: 36.39 | S5: -1 | T5: -2.63 | U5: -34.88 | V5: 52925 | W5: 57342.5 | X5: 70499.167 | Y5: 0 | Z5: 0 | AA5: 0 | AB5: 26664.83 | AC5: 10056 | AD5: 21.2 | AE5: 50.5 | AF5: 19.4 | AG5: 35.5 | AH5: D
A6: A473980 | B6: 노머스 | E6: 80.4 | F6: 215.2 | G6: 4.4 | H6: -58.7 | I6: -139.9 | J6: 70 | K6: 11490 | L6: 102379 | M6: 11.8 | N6: 81120.75 | O6: 1.26 | P6: 5.9 | Q6: 46.18 | R6: 43.38 | S6: 2.8 | T6: 3.14 | U6: -20.76 | V6: 10859 | W6: 11334 | X6: 14574.667 | Y6: 1 | Z6: 1 | AA6: 0 | AB6: 4543.4 | AC6: 1271 | AD6: 81.6 | AE6: 51.7 | AF6: 95.5 | AG6: 69.4 | AH6: B
A7: A403850 | B7: 더핑크퐁컴퍼니 | E7: 58.5 | F7: 109.5 | G7: 123 | H7: -30.1 | I7: 256.3 | J7: 255.6 | K7: 10900 | L7: 172250 | M7: 18.8 | N7: 86743.65 | O7: 1.99 | P7: 4.52 | Q7: 44.9 | R7: 40.14 | S7: 4.8 | T7: 4.41 | U7: -4.55 | V7: 10753 | W7: 11077 | X7: 13527.5 | Y7: 1 | Z7: 0 | AA7: 0 | AB7: 2486.86 | AC7: 1564 | AD7: 91.6 | AE7: 69.2 | AF7: 98.5 | AG7: 81.8 | AH7: A
A8: A491000 | B8: 리브스메드 | E8: 58.3 | F8: 32.3 | G8: 440.7 | H8: -33.4 | I8: -124.7 | J8: -272.6 | K8: 36750 | L8: 132892 | M8: 48.8 | N8: 218446 | O8: 0.61 | P8: 6.98 | Q8: 42.93 | R8: 38.63 | S8: 4.3 | T8: 6.52 | U8: -9.48 | V8: 35530 | W8: 37707.5 | X8: 52457.5 | Y8: 1 | Z8: 0 | AA8: 0 | AB8: 12886 | AC8: 9189 | AD8: 87.7 | AE8: 48.8 | AF8: 44 | AG8: 59.5 | AH8: C
A9: A031210 | B9: 서울보증보험 | E9: 37.7 | F9: 137 | G9: 404.2 | H9: -24.4 | I9: 5 | J9: -562.1 | K9: 42350 | L9: 33193 | M9: 14.1 | N9: 45264.25 | O9: 0.73 | P9: 2.56 | Q9: 45.92 | R9: 47.95 | S9: -2 | T9: -1.05 | U9: -5.04 | V9: 41945 | W9: 42832.5 | X9: 45146.667 | Y9: 1 | Z9: 0 | AA9: 0 | AB9: 7225.03 | AC9: 29569 | AD9: 76 | AE9: 56.7 | AF9: 61.2 | AG9: 63.4 | AH9: C
A10: A125490 | B10: 한라캐스트 | E10: 21.4 | F10: 33.8 | G10: 431.7 | H10: 45.2 | I10: 159 | J10: -253.7 | K10: 7530 | L10: 388592 | M10: 29.3 | N10: 606329 | O10: 0.64 | P10: 5.56 | Q10: 28.33 | R10: 28.22 | S10: 0.1 | T10: 0.13 | U10: -40.66 | V10: 8502 | W10: 9754 | X10: 13353.833 | Y10: 0 | Z10: 0 | AA10: 0 | AB10: 6864.32 | AC10: 2749 | AD10: 21.7 | AE10: 74.6 | AF10: 49.3 | AG10: 53.7 | AH10: C
A11: A494120 | B11: 큐리오시스 | E11: 20.9 | F11: 203.5 | G11: 636.7 | H11: -14 | I11: -65.8 | J11: -505.2 | K11: 24200 | L11: 46941 | M11: 11.4 | N11: 118563.6 | O11: 0.4 | P11: 8.64 | Q11: 40.42 | R11: 42.21 | S11: -1.8 | T11: -4.35 | U11: -10.37 | V11: 25160 | W11: 26360 | X11: 39245 | Y11: 0 | Z11: 0 | AA11: 0 | AB11: 9330.94 | AC11: 1846 | AD11: 37.8 | AE11: 54.3 | AF11: 9.7 | AG11: 40.4 | AH11: D
A12: A482630 | B12: 삼양엔씨켐 | E12: 19.8 | F12: -3.6 | G12: 699.9 | H12: 38.9 | I12: 98.9 | J12: -235.5 | K12: 13040 | L12: 200497 | M12: 26.1 | N12: 480961.2 | O12: 0.42 | P12: 7.32 | Q12: 35.54 | R12: 33.2 | S12: 2.3 | T12: 3.57 | U12: -15.6 | V12: 15420 | W12: 16993 | X12: 18145.167 | Y12: 0 | Z12: 0 | AA12: 0 | AB12: 8524.69 | AC12: 2854 | AD12: 57.4 | AE12: 68.8 | AF12: 17.9 | AG12: 55.2 | AH12: C
A13: A484870 | B13: 엠앤씨솔루션 | E13: 10.5 | F13: 122.3 | G13: 323.1 | H13: -28.3 | I13: -35.7 | J13: -577.6 | K13: 28600 | L13: 25982 | M13: 7.4 | N13: 111239 | O13: 0.23 | P13: 10.4 | Q13: 50.95 | R13: 53.14 | S13: -2.2 | T13: -4.19 | U13: 19.17 | V13: 28020 | W13: 27999.85 | X13: 30745.817 | Y13: 1 | Z13: 1 | AA13: 0 | AB13: 12641.71 | AC13: 2618 | AD13: 70.7 | AE13: 50.3 | AF13: 3 | AG13: 47 | AH13: D
... A21: A439260 | B21: 대한조선 | E21: 0.8 | F21: -171 | G21: -22.5 | H21: 47 | I21: 403.3 | J21: 255 | K21: 47000 | L21: 44207 | M21: 20.8 | N21: 79055.7 | O21: 0.56 | P21: 3.5 | Q21: 28.4 | R21: 29.16 | S21: -0.8 | T21: -1.36 | U21: -21.67 | V21: 51045 | W21: 55467.5 | X21: 69895.833 | Y21: 0 | Z21: 0 | AA21: 0 | AB21: 22342.45 | AC21: 17902 | AD21: 30.8 | AE21: 63.7 | AF21: 33.6 | AG21: 47.8 | AH21: D

Sheet RVOL_TOP
A1: 코드 | B1: 코드명 | C1: 상장일 | D1: days_since_ipo | E1: 기관_일간 | F1: 기관_5일 | G1: 기관_20일 | H1: 외국인_일간 | I1: 외국인_5일 | J1: 외국인_20일 | K1: 현재가 | L1: 거래량 | M1: 거래대금(억) | N1: 20일평균거래량 | O1: RVOL(20) | P1: 변동성(30D) | Q1: RSI(14) | R1: 전일RSI(14) | S1: RSI변화량 | T1: 1일수익률(%) | U1: 20일수익률(%) | V1: 10일이평 | W1: 20일이평 | X1: 60일이평 | Y1: 10일선돌파 | Z1: 20일선돌파 | AA1: 60일선돌파 | AB1: BB폭 | AC1: 시가총액(억) | AD1: 모멘텀스코어 | AE1: 수급스코어 | AF1: 거래량스코어 | AG1: 종합스코어 | AH1: 등급
A2: A477850 | B2: 마키나락스 | K2: 29650 | L2: 5670663 | M2: 1681.4 | N2: 2759232.7 | O2: 2.06 | P2: 12.65 | Q2: 71.1 | R2: 69.76 | S2: 1.3 | T2: 9.41 | U2: 47.51 | V2: 22611 | W2: 20117.5 | Y2: 1 | Z2: 1 | AA2: 0 | AB2: 18765.04 | AC2: 5264 | AD2: 99.6 | AF2: 100 | AH2: -
A3: A403850 | B3: 더핑크퐁컴퍼니 | E3: 58.5 | F3: 109.5 | G3: 123 | H3: -30.1 | I3: 256.3 | J3: 255.6 | K3: 10900 | L3: 172250 | M3: 18.8 | N3: 86743.65 | O3: 1.99 | P3: 4.52 | Q3: 44.9 | R3: 40.14 | S3: 4.8 | T3: 4.41 | U3: -4.55 | V3: 10753 | W3: 11077 | X3: 13527.5 | Y3: 1 | Z3: 0 | AA3: 0 | AB3: 2486.86 | AC3: 1564 | AD3: 91.6 | AE3: 69.2 | AF3: 98.5 | AG3: 81.8 | AH3: A
A4: A336680 | B4: 탑런토탈솔루션 | E4: 0 | F4: 0 | G4: 0 | H4: 1.8 | I4: 10.3 | J4: 5.5 | K4: 2585 | L4: 29183 | M4: 0.8 | N4: 21527.4 | O4: 1.36 | P4: 2.57 | Q4: 29.69 | R4: 31.05 | S4: -1.4 | T4: -1.34 | U4: -14.4 | V4: 2713 | W4: 2800.5 | X4: 3333.75 | Y4: 0 | Z4: 0 | AA4: 0 | AB4: 597.46 | AC4: 1012 | AD4: 35.9 | AE4: 50.5 | AF4: 97 | AG4: 55.4 | AH4: C
A5: A473980 | B5: 노머스 | E5: 80.4 | F5: 215.2 | G5: 4.4 | H5: -58.7 | I5: -139.9 | J5: 70 | K5: 11490 | L5: 102379 | M5: 11.8 | N5: 81120.75 | O5: 1.26 | P5: 5.9 | Q5: 46.18 | R5: 43.38 | S5: 2.8 | T5: 3.14 | U5: -20.76 | V5: 10859 | W5: 11334 | X5: 14574.667 | Y5: 1 | Z5: 1 | AA5: 0 | AB5: 4543.4 | AC5: 1271 | AD5: 81.6 | AE5: 51.7 | AF5: 95.5 | AG5: 69.4 | AH5: B
A6: A388210 | B6: 씨엠티엑스 | E6: 196.5 | F6: -120.2 | G6: -275.1 | H6: 34.1 | I6: 564.1 | J6: 108.6 | K6: 75900 | L6: 90294 | M6: 68.5 | N6: 73644.5 | O6: 1.23 | P6: 6.48 | Q6: 34.49 | R6: 27.08 | S6: 7.4 | T6: 10.16 | U6: -31.81 | V6: 84650 | W6: 94660 | X6: 117265 | Y6: 0 | Z6: 0 | AA6: 0 | AB6: 52083.07 | AC6: 7328 | AD6: 47.8 | AE6: 64.9 | AF6: 94 | AG6: 65.6 | AH6: B
A7: A415640 | B7: KB발해인프라 | E7: -15.2 | F7: -78.7 | G7: -73.7 | H7: 26.2 | I7: 512.3 | J7: 821.2 | K7: 10730 | L7: 188204 | M7: 20.2 | N7: 160985.8 | O7: 1.17 | P7: 2.01 | Q7: 63.81 | R7: 64.13 | S7: -0.3 | T7: -0.09 | U7: 8.38 | V7: 10406 | W7: 10189 | X7: 9995.6667 | Y7: 1 | Z7: 1 | AA7: 1 | AB7: 1367.33 | AC7: 13149 | AD7: 85.3 | AE7: 51.2 | AF7: 92.5 | AG7: 69.7 | AH7: B
A8: A476060 | B8: 온코닉테라퓨틱스 | E8: -2.5 | F8: -8.9 | G8: -165 | H8: 92.4 | I8: 430.6 | J8: 837.4 | K8: 10880 | L8: 287418 | M8: 31.3 | N8: 255260.8 | O8: 1.13 | P8: 4.51 | Q8: 25.92 | R8: 26.22 | S8: -0.3 | T8: -0.82 | U8: -31.49 | V8: 12456 | W8: 13958.5 | X8: 18202.667 | Y8: 0 | Z8: 0 | AA8: 0 | AB8: 7225.81 | AC8: 4940 | AD8: 22.8 | AE8: 61.6 | AF8: 91 | AG8: 55.8 | AH8: C
