Workbook

Sheet POST IPO 보고서
B2: POST IPO 모니터링 보고서
B3: 기준일: 2026-07-13 | 분석 대상: 68개 종목 | 2년 이내 신규 상장주
B6: 전체 종목 | D6: A등급 | F6: B등급 | H6: 50점 이상 종목수 | J6: RSI>65
B7: 68 | D7: 1 | F7: 9 | H7: 23 | J7: =COUNTIF(INDEX(전체!$1:$1048576,0,MATCH("RSI(14)",전체!$1:$1,0)),">=65") -> 1
B10: ▶ 추천종목 (종합스코어 50점 이상) | Q10: 구분 | R10: 종목수
B11: 순위 | C11: 종목명 | D11: 종합점수 | E11: 모멘텀 | F11: 수급 | G11: 거래량 | H11: RSI | I11: 등급 | J11: RSI신호 | K11: 등급변화 | L11: 점수변화량 | M11: 모멘텀Δ | N11: 수급Δ | O11: 거래량Δ | Q11: 강세 (A+B등급) | R11: 10
B12: 1 | C12: 동방메디컬 | D12: 83 | E12: 93.4 | F12: 71.9 | G12: 95.4 | H12: 53.89 | I12: A | K12: =IFERROR(IF(I12=INDEX(전체_전일자!1:1048576,MATCH(C12,전체_전일자!B:B,0),MATCH("등급",전체_전일자!1:1,0)),"유지",INDEX(전체_전일자!1:1048576,MATCH(C12,전체_전일자!B:B,0),MATCH("등급",전체_전일자!1:1,0))&" → "&I12),"") -> B → A | L12: =IFERROR(D12-INDEX(전체_전일자!1:1048576,MATCH(C12,전체_전일자!B:B,0),MATCH("종합스코어",전체_전일자!1:1,0)),"") -> 12.1 | M12: =IFERROR(E12-INDEX(전체_전일자!1:1048576,MATCH(C12,전체_전일자!B:B,0),MATCH("모멘텀스코어",전체_전일자!1:1,0)),"") -> 4.8 | N12: =IFERROR(F12-INDEX(전체_전일자!1:1048576,MATCH(C12,전체_전일자!B:B,0),MATCH("수급스코어",전체_전일자!1:1,0)),"") -> 20.8 | O12: =IFERROR(G12-INDEX(전체_전일자!1:1048576,MATCH(C12,전체_전일자!B:B,0),MATCH("거래량스코어",전체_전일자!1:1,0)),"") -> 1.6 | Q12: 중립 (C등급) | R12: 13
B13: 2 | C13: 세나테크놀로지 | D13: 78.5 | E13: 82.6 | F13: 68.6 | G13: 96.9 | H13: 58.98 | I13: B | K13: =IFERROR(IF(I13=INDEX(전체_전일자!1:1048576,MATCH(C13,전체_전일자!B:B,0),MATCH("등급",전체_전일자!1:1,0)),"유지",INDEX(전체_전일자!1:1048576,MATCH(C13,전체_전일자!B:B,0),MATCH("등급",전체_전일자!1:1,0))&" → "&I13),"") -> A → B | L13: =IFERROR(D13-INDEX(전체_전일자!1:1048576,MATCH(C13,전체_전일자!B:B,0),MATCH("종합스코어",전체_전일자!1:1,0)),"") -> -7 | M13: =IFERROR(E13-INDEX(전체_전일자!1:1048576,MATCH(C13,전체_전일자!B:B,0),MATCH("모멘텀스코어",전체_전일자!1:1,0)),"") -> -15.5 | N13: =IFERROR(F13-INDEX(전체_전일자!1:1048576,MATCH(C13,전체_전일자!B:B,0),MATCH("수급스코어",전체_전일자!1:1,0)),"") -> -3.5 | O13: =IFERROR(G13-INDEX(전체_전일자!1:1048576,MATCH(C13,전체_전일자!B:B,0),MATCH("거래량스코어",전체_전일자!1:1,0)),"") -> -3.1 | Q13: 약세 (D+F등급) | R13: 38
B14: 3 | C14: 케이뱅크 | D14: 73 | E14: 86.8 | F14: 82.2 | G14: 29.2 | H14: 46.46 | I14: B | K14: =IFERROR(IF(I14=INDEX(전체_전일자!1:1048576,MATCH(C14,전체_전일자!B:B,0),MATCH("등급",전체_전일자!1:1,0)),"유지",INDEX(전체_전일자!1:1048576,MATCH(C14,전체_전일자!B:B,0),MATCH("등급",전체_전일자!1:1,0))&" → "&I14),"") -> D → B | L14: =IFERROR(D14-INDEX(전체_전일자!1:1048576,MATCH(C14,전체_전일자!B:B,0),MATCH("종합스코어",전체_전일자!1:1,0)),"") -> 24.2 | M14: =IFERROR(E14-INDEX(전체_전일자!1:1048576,MATCH(C14,전체_전일자!B:B,0),MATCH("모멘텀스코어",전체_전일자!1:1,0)),"") -> 44.4 | N14: =IFERROR(F14-INDEX(전체_전일자!1:1048576,MATCH(C14,전체_전일자!B:B,0),MATCH("수급스코어",전체_전일자!1:1,0)),"") -> 15.3 | O14: =IFERROR(G14-INDEX(전체_전일자!1:1048576,MATCH(C14,전체_전일자!B:B,0),MATCH("거래량스코어",전체_전일자!1:1,0)),"") -> 16.1
B15: 4 | C15: 씨엠티엑스 | D15: 72 | E15: 76.8 | F15: 60.5 | G15: 93.8 | H15: 42.32 | I15: B | K15: =IFERROR(IF(I15=INDEX(전체_전일자!1:1048576,MATCH(C15,전체_전일자!B:B,0),MATCH("등급",전체_전일자!1:1,0)),"유지",INDEX(전체_전일자!1:1048576,MATCH(C15,전체_전일자!B:B,0),MATCH("등급",전체_전일자!1:1,0))&" → "&I15),"") -> 유지 | L15: =IFERROR(D15-INDEX(전체_전일자!1:1048576,MATCH(C15,전체_전일자!B:B,0),MATCH("종합스코어",전체_전일자!1:1,0)),"") -> 5.9 | M15: =IFERROR(E15-INDEX(전체_전일자!1:1048576,MATCH(C15,전체_전일자!B:B,0),MATCH("모멘텀스코어",전체_전일자!1:1,0)),"") -> 8.7 | N15: =IFERROR(F15-INDEX(전체_전일자!1:1048576,MATCH(C15,전체_전일자!B:B,0),MATCH("수급스코어",전체_전일자!1:1,0)),"") -> 0.2 | O15: =IFERROR(G15-INDEX(전체_전일자!1:1048576,MATCH(C15,전체_전일자!B:B,0),MATCH("거래량스코어",전체_전일자!1:1,0)),"") -> 16.1
B16: 5 | C16: 토모큐브 | D16: 70.2 | E16: 60.9 | F16: 67.5 | G16: 90.8 | H16: 41.9 | I16: B | K16: =IFERROR(IF(I16=INDEX(전체_전일자!1:1048576,MATCH(C16,전체_전일자!B:B,0),MATCH("등급",전체_전일자!1:1,0)),"유지",INDEX(전체_전일자!1:1048576,MATCH(C16,전체_전일자!B:B,0),MATCH("등급",전체_전일자!1:1,0))&" → "&I16),"") -> C → B | L16: =IFERROR(D16-INDEX(전체_전일자!1:1048576,MATCH(C16,전체_전일자!B:B,0),MATCH("종합스코어",전체_전일자!1:1,0)),"") -> 16.8 | M16: =IFERROR(E16-INDEX(전체_전일자!1:1048576,MATCH(C16,전체_전일자!B:B,0),MATCH("모멘텀스코어",전체_전일자!1:1,0)),"") -> 7.9 | N16: =IFERROR(F16-INDEX(전체_전일자!1:1048576,MATCH(C16,전체_전일자!B:B,0),MATCH("수급스코어",전체_전일자!1:1,0)),"") -> 23.5 | O16: =IFERROR(G16-INDEX(전체_전일자!1:1048576,MATCH(C16,전체_전일자!B:B,0),MATCH("거래량스코어",전체_전일자!1:1,0)),"") -> 13.1
B17: 6 | C17: 명인제약 | D17: 68.3 | E17: 66.2 | F17: 64.3 | G17: 81.5 | H17: 44.73 | I17: B | K17: =IFERROR(IF(I17=INDEX(전체_전일자!1:1048576,MATCH(C17,전체_전일자!B:B,0),MATCH("등급",전체_전일자!1:1,0)),"유지",INDEX(전체_전일자!1:1048576,MATCH(C17,전체_전일자!B:B,0),MATCH("등급",전체_전일자!1:1,0))&" → "&I17),"") -> C → B | L17: =IFERROR(D17-INDEX(전체_전일자!1:1048576,MATCH(C17,전체_전일자!B:B,0),MATCH("종합스코어",전체_전일자!1:1,0)),"") -> 9.7 | M17: =IFERROR(E17-INDEX(전체_전일자!1:1048576,MATCH(C17,전체_전일자!B:B,0),MATCH("모멘텀스코어",전체_전일자!1:1,0)),"") -> -5.8 | N17: =IFERROR(F17-INDEX(전체_전일자!1:1048576,MATCH(C17,전체_전일자!B:B,0),MATCH("수급스코어",전체_전일자!1:1,0)),"") -> 10.2 | O17: =IFERROR(G17-INDEX(전체_전일자!1:1048576,MATCH(C17,전체_전일자!B:B,0),MATCH("거래량스코어",전체_전일자!1:1,0)),"") -> 31.5
B18: 7 | C18: 리브스메드 | D18: 65.7 | E18: 84.1 | F18: 53.3 | G18: 69.2 | H18: 49.01 | I18: B | K18: =IFERROR(IF(I18=INDEX(전체_전일자!1:1048576,MATCH(C18,전체_전일자!B:B,0),MATCH("등급",전체_전일자!1:1,0)),"유지",INDEX(전체_전일자!1:1048576,MATCH(C18,전체_전일자!B:B,0),MATCH("등급",전체_전일자!1:1,0))&" → "&I18),"") -> 유지 | L18: =IFERROR(D18-INDEX(전체_전일자!1:1048576,MATCH(C18,전체_전일자!B:B,0),MATCH("종합스코어",전체_전일자!1:1,0)),"") -> -9.2 | M18: =IFERROR(E18-INDEX(전체_전일자!1:1048576,MATCH(C18,전체_전일자!B:B,0),MATCH("모멘텀스코어",전체_전일자!1:1,0)),"") -> -11.1 | N18: =IFERROR(F18-INDEX(전체_전일자!1:1048576,MATCH(C18,전체_전일자!B:B,0),MATCH("수급스코어",전체_전일자!1:1,0)),"") -> -3.1 | O18: =IFERROR(G18-INDEX(전체_전일자!1:1048576,MATCH(C18,전체_전일자!B:B,0),MATCH("거래량스코어",전체_전일자!1:1,0)),"") -> -21.6
B19: 8 | C19: 더본코리아 | D19: 65.4 | E19: 63.6 | F19: 52.7 | G19: 100 | H19: 40.5 | I19: B | K19: =IFERROR(IF(I19=INDEX(전체_전일자!1:1048576,MATCH(C19,전체_전일자!B:B,0),MATCH("등급",전체_전일자!1:1,0)),"유지",INDEX(전체_전일자!1:1048576,MATCH(C19,전체_전일자!B:B,0),MATCH("등급",전체_전일자!1:1,0))&" → "&I19),"") -> D → B | L19: =IFERROR(D19-INDEX(전체_전일자!1:1048576,MATCH(C19,전체_전일자!B:B,0),MATCH("종합스코어",전체_전일자!1:1,0)),"") -> 26.5 | M19: =IFERROR(E19-INDEX(전체_전일자!1:1048576,MATCH(C19,전체_전일자!B:B,0),MATCH("모멘텀스코어",전체_전일자!1:1,0)),"") -> 25.2 | N19: =IFERROR(F19-INDEX(전체_전일자!1:1048576,MATCH(C19,전체_전일자!B:B,0),MATCH("수급스코어",전체_전일자!1:1,0)),"") -> 8.5 | O19: =IFERROR(G19-INDEX(전체_전일자!1:1048576,MATCH(C19,전체_전일자!B:B,0),MATCH("거래량스코어",전체_전일자!1:1,0)),"") -> 73.8
B20: 9 | C20: KB발해인프라 | D20: 65.3 | E20: 88.9 | F20: 55.8 | G20: 53.8 | H20: 57.01 | I20: B | K20: =IFERROR(IF(I20=INDEX(전체_전일자!1:1048576,MATCH(C20,전체_전일자!B:B,0),MATCH("등급",전체_전일자!1:1,0)),"유지",INDEX(전체_전일자!1:1048576,MATCH(C20,전체_전일자!B:B,0),MATCH("등급",전체_전일자!1:1,0))&" → "&I20),"") -> C → B | L20: =IFERROR(D20-INDEX(전체_전일자!1:1048576,MATCH(C20,전체_전일자!B:B,0),MATCH("종합스코어",전체_전일자!1:1,0)),"") -> 0.3 | M20: =IFERROR(E20-INDEX(전체_전일자!1:1048576,MATCH(C20,전체_전일자!B:B,0),MATCH("모멘텀스코어",전체_전일자!1:1,0)),"") -> 14.4 | N20: =IFERROR(F20-INDEX(전체_전일자!1:1048576,MATCH(C20,전체_전일자!B:B,0),MATCH("수급스코어",전체_전일자!1:1,0)),"") -> -4.9 | O20: =IFERROR(G20-INDEX(전체_전일자!1:1048576,MATCH(C20,전체_전일자!B:B,0),MATCH("거래량스코어",전체_전일자!1:1,0)),"") -> -7.7
B21: 10 | C21: 넥스트바이오메디컬 | D21: 65.2 | E21: 55.9 | F21: 68 | G21: 72.3 | H21: 39.35 | I21: B | K21: =IFERROR(IF(I21=INDEX(전체_전일자!1:1048576,MATCH(C21,전체_전일자!B:B,0),MATCH("등급",전체_전일자!1:1,0)),"유지",INDEX(전체_전일자!1:1048576,MATCH(C21,전체_전일자!B:B,0),MATCH("등급",전체_전일자!1:1,0))&" → "&I21),"") -> D → B | L21: =IFERROR(D21-INDEX(전체_전일자!1:1048576,MATCH(C21,전체_전일자!B:B,0),MATCH("종합스코어",전체_전일자!1:1,0)),"") -> 19.6 | M21: =IFERROR(E21-INDEX(전체_전일자!1:1048576,MATCH(C21,전체_전일자!B:B,0),MATCH("모멘텀스코어",전체_전일자!1:1,0)),"") -> 19 | N21: =IFERROR(F21-INDEX(전체_전일자!1:1048576,MATCH(C21,전체_전일자!B:B,0),MATCH("수급스코어",전체_전일자!1:1,0)),"") -> 16.1 | O21: =IFERROR(G21-INDEX(전체_전일자!1:1048576,MATCH(C21,전체_전일자!B:B,0),MATCH("거래량스코어",전체_전일자!1:1,0)),"") -> 29.2
B22: 11 | C22: 달바글로벌 | D22: 60.9 | E22: 72.9 | F22: 63 | G22: 37.7 | H22: 43.76 | I22: C | K22: =IFERROR(IF(I22=INDEX(전체_전일자!1:1048576,MATCH(C22,전체_전일자!B:B,0),MATCH("등급",전체_전일자!1:1,0)),"유지",INDEX(전체_전일자!1:1048576,MATCH(C22,전체_전일자!B:B,0),MATCH("등급",전체_전일자!1:1,0))&" → "&I22),"") -> 유지 | L22: =IFERROR(D22-INDEX(전체_전일자!1:1048576,MATCH(C22,전체_전일자!B:B,0),MATCH("종합스코어",전체_전일자!1:1,0)),"") -> 3.3 | M22: =IFERROR(E22-INDEX(전체_전일자!1:1048576,MATCH(C22,전체_전일자!B:B,0),MATCH("모멘텀스코어",전체_전일자!1:1,0)),"") -> 29.6 | N22: =IFERROR(F22-INDEX(전체_전일자!1:1048576,MATCH(C22,전체_전일자!B:B,0),MATCH("수급스코어",전체_전일자!1:1,0)),"") -> 1.4 | O22: =IFERROR(G22-INDEX(전체_전일자!1:1048576,MATCH(C22,전체_전일자!B:B,0),MATCH("거래량스코어",전체_전일자!1:1,0)),"") -> -31.5
B23: 12 | C23: 듀켐바이오 | D23: 60.8 | E23: 66.8 | F23: 42.2 | G23: 98.5 | H23: 40.29 | I23: C | K23: =IFERROR(IF(I23=INDEX(전체_전일자!1:1048576,MATCH(C23,전체_전일자!B:B,0),MATCH("등급",전체_전일자!1:1,0)),"유지",INDEX(전체_전일자!1:1048576,MATCH(C23,전체_전일자!B:B,0),MATCH("등급",전체_전일자!1:1,0))&" → "&I23),"") -> D → C | L23: =IFERROR(D23-INDEX(전체_전일자!1:1048576,MATCH(C23,전체_전일자!B:B,0),MATCH("종합스코어",전체_전일자!1:1,0)),"") -> 23.7 | M23: =IFERROR(E23-INDEX(전체_전일자!1:1048576,MATCH(C23,전체_전일자!B:B,0),MATCH("모멘텀스코어",전체_전일자!1:1,0)),"") -> 26.6 | N23: =IFERROR(F23-INDEX(전체_전일자!1:1048576,MATCH(C23,전체_전일자!B:B,0),MATCH("수급스코어",전체_전일자!1:1,0)),"") -> -1.2 | O23: =IFERROR(G23-INDEX(전체_전일자!1:1048576,MATCH(C23,전체_전일자!B:B,0),MATCH("거래량스코어",전체_전일자!1:1,0)),"") -> 81.6
B24: 13 | C24: 큐리오시스 | D24: 58.4 | E24: 86.9 | F24: 54.8 | G24: 24.6 | H24: 43.32 | I24: C | K24: =IFERROR(IF(I24=INDEX(전체_전일자!1:1048576,MATCH(C24,전체_전일자!B:B,0),MATCH("등급",전체_전일자!1:1,0)),"유지",INDEX(전체_전일자!1:1048576,MATCH(C24,전체_전일자!B:B,0),MATCH("등급",전체_전일자!1:1,0))&" → "&I24),"") -> 유지 | L24: =IFERROR(D24-INDEX(전체_전일자!1:1048576,MATCH(C24,전체_전일자!B:B,0),MATCH("종합스코어",전체_전일자!1:1,0)),"") -> 2.4 | M24: =IFERROR(E24-INDEX(전체_전일자!1:1048576,MATCH(C24,전체_전일자!B:B,0),MATCH("모멘텀스코어",전체_전일자!1:1,0)),"") -> 11.9 | N24: =IFERROR(F24-INDEX(전체_전일자!1:1048576,MATCH(C24,전체_전일자!B:B,0),MATCH("수급스코어",전체_전일자!1:1,0)),"") -> -5.4 | O24: =IFERROR(G24-INDEX(전체_전일자!1:1048576,MATCH(C24,전체_전일자!B:B,0),MATCH("거래량스코어",전체_전일자!1:1,0)),"") -> 7.7
B25: 14 | C25: 성우 | D25: 58.3 | E25: 69.2 | F25: 51.7 | G25: 58.5 | H25: 39.21 | I25: C | K25: =IFERROR(IF(I25=INDEX(전체_전일자!1:1048576,MATCH(C25,전체_전일자!B:B,0),MATCH("등급",전체_전일자!1:1,0)),"유지",INDEX(전체_전일자!1:1048576,MATCH(C25,전체_전일자!B:B,0),MATCH("등급",전체_전일자!1:1,0))&" → "&I25),"") -> D → C | L25: =IFERROR(D25-INDEX(전체_전일자!1:1048576,MATCH(C25,전체_전일자!B:B,0),MATCH("종합스코어",전체_전일자!1:1,0)),"") -> 8.3 | M25: =IFERROR(E25-INDEX(전체_전일자!1:1048576,MATCH(C25,전체_전일자!B:B,0),MATCH("모멘텀스코어",전체_전일자!1:1,0)),"") -> 0.8 | N25: =IFERROR(F25-INDEX(전체_전일자!1:1048576,MATCH(C25,전체_전일자!B:B,0),MATCH("수급스코어",전체_전일자!1:1,0)),"") -> 1.4 | O25: =IFERROR(G25-INDEX(전체_전일자!1:1048576,MATCH(C25,전체_전일자!B:B,0),MATCH("거래량스코어",전체_전일자!1:1,0)),"") -> 37
... B31: 20 | C31: 더핑크퐁컴퍼니 | D31: 53.7 | E31: 48.6 | F31: 61.9 | G31: 40.8 | H31: 38.97 | I31: C | K31: =IFERROR(IF(I31=INDEX(전체_전일자!1:1048576,MATCH(C31,전체_전일자!B:B,0),MATCH("등급",전체_전일자!1:1,0)),"유지",INDEX(전체_전일자!1:1048576,MATCH(C31,전체_전일자!B:B,0),MATCH("등급",전체_전일자!1:1,0))&" → "&I31),"") -> 유지 | L31: =IFERROR(D31-INDEX(전체_전일자!1:1048576,MATCH(C31,전체_전일자!B:B,0),MATCH("종합스코어",전체_전일자!1:1,0)),"") -> -7.9 | M31: =IFERROR(E31-INDEX(전체_전일자!1:1048576,MATCH(C31,전체_전일자!B:B,0),MATCH("모멘텀스코어",전체_전일자!1:1,0)),"") -> 12.9 | N31: =IFERROR(F31-INDEX(전체_전일자!1:1048576,MATCH(C31,전체_전일자!B:B,0),MATCH("수급스코어",전체_전일자!1:1,0)),"") -> -4.3 | O31: =IFERROR(G31-INDEX(전체_전일자!1:1048576,MATCH(C31,전체_전일자!B:B,0),MATCH("거래량스코어",전체_전일자!1:1,0)),"") -> -48.4
B32: 21 | C32: 에이유브랜즈 | D32: 52.4 | E32: 99.6 | F32: 39.7 | G32: 13.1 | H32: 65.94 | I32: C | J32: ★ | K32: =IFERROR(IF(I32=INDEX(전체_전일자!1:1048576,MATCH(C32,전체_전일자!B:B,0),MATCH("등급",전체_전일자!1:1,0)),"유지",INDEX(전체_전일자!1:1048576,MATCH(C32,전체_전일자!B:B,0),MATCH("등급",전체_전일자!1:1,0))&" → "&I32),"") -> B → C | L32: =IFERROR(D32-INDEX(전체_전일자!1:1048576,MATCH(C32,전체_전일자!B:B,0),MATCH("종합스코어",전체_전일자!1:1,0)),"") -> -14.8 | M32: =IFERROR(E32-INDEX(전체_전일자!1:1048576,MATCH(C32,전체_전일자!B:B,0),MATCH("모멘텀스코어",전체_전일자!1:1,0)),"") -> 4 | N32: =IFERROR(F32-INDEX(전체_전일자!1:1048576,MATCH(C32,전체_전일자!B:B,0),MATCH("수급스코어",전체_전일자!1:1,0)),"") -> 1.5 | O32: =IFERROR(G32-INDEX(전체_전일자!1:1048576,MATCH(C32,전체_전일자!B:B,0),MATCH("거래량스코어",전체_전일자!1:1,0)),"") -> -83.8
B33: 22 | C33: 아스테라시스 | D33: 50.7 | E33: 50.1 | F33: 51.9 | G33: 48.5 | H33: 34.48 | I33: C | K33: =IFERROR(IF(I33=INDEX(전체_전일자!1:1048576,MATCH(C33,전체_전일자!B:B,0),MATCH("등급",전체_전일자!1:1,0)),"유지",INDEX(전체_전일자!1:1048576,MATCH(C33,전체_전일자!B:B,0),MATCH("등급",전체_전일자!1:1,0))&" → "&I33),"") -> F → C | L33: =IFERROR(D33-INDEX(전체_전일자!1:1048576,MATCH(C33,전체_전일자!B:B,0),MATCH("종합스코어",전체_전일자!1:1,0)),"") -> 21.4 | M33: =IFERROR(E33-INDEX(전체_전일자!1:1048576,MATCH(C33,전체_전일자!B:B,0),MATCH("모멘텀스코어",전체_전일자!1:1,0)),"") -> 25.4 | N33: =IFERROR(F33-INDEX(전체_전일자!1:1048576,MATCH(C33,전체_전일자!B:B,0),MATCH("수급스코어",전체_전일자!1:1,0)),"") -> 9.9 | O33: =IFERROR(G33-INDEX(전체_전일자!1:1048576,MATCH(C33,전체_전일자!B:B,0),MATCH("거래량스코어",전체_전일자!1:1,0)),"") -> 43.9
B34: 23 | C34: 대한조선 | D34: 50.5 | E34: 34.7 | F34: 49.7 | G34: 76.2 | H34: 29.64 | I34: C | K34: =IFERROR(IF(I34=INDEX(전체_전일자!1:1048576,MATCH(C34,전체_전일자!B:B,0),MATCH("등급",전체_전일자!1:1,0)),"유지",INDEX(전체_전일자!1:1048576,MATCH(C34,전체_전일자!B:B,0),MATCH("등급",전체_전일자!1:1,0))&" → "&I34),"") -> D → C | L34: =IFERROR(D34-INDEX(전체_전일자!1:1048576,MATCH(C34,전체_전일자!B:B,0),MATCH("종합스코어",전체_전일자!1:1,0)),"") -> 4.5 | M34: =IFERROR(E34-INDEX(전체_전일자!1:1048576,MATCH(C34,전체_전일자!B:B,0),MATCH("모멘텀스코어",전체_전일자!1:1,0)),"") -> 12.6 | N34: =IFERROR(F34-INDEX(전체_전일자!1:1048576,MATCH(C34,전체_전일자!B:B,0),MATCH("수급스코어",전체_전일자!1:1,0)),"") -> 0.5 | O34: =IFERROR(G34-INDEX(전체_전일자!1:1048576,MATCH(C34,전체_전일자!B:B,0),MATCH("거래량스코어",전체_전일자!1:1,0)),"") -> 2.4

Sheet 추천종목
A1: 코드 | B1: 코드명 | C1: 상장일 | D1: 현재가 | E1: 거래대금(억) | F1: 종합스코어 | G1: 모멘텀스코어 | H1: 수급스코어 | I1: 거래량스코어 | J1: RSI변화량 | K1: RSI(14) | L1: 전일RSI(14) | M1: RVOL(20) | N1: 기관_일간 | O1: 외국인_일간 | P1: 10일선돌파 | Q1: 20일선돌파 | R1: 60일선돌파 | S1: 변동성(30D) | T1: BB폭
A2: A240550 | B2: 동방메디컬 | D2: 6110 | E2: 12.9 | F2: 83 | G2: 93.4 | H2: 71.9 | I2: 95.4 | J2: -0.2 | K2: 53.89 | L2: 54.09 | M2: 1.89 | N2: 30 | O2: 15.8 | P2: 1 | Q2: 1 | R2: 0 | S2: 4.71 | T2: 1506.81
A3: A061090 | B3: 세나테크놀로지 | D3: 42750 | E3: 31.3 | F3: 78.5 | G3: 82.6 | H3: 68.6 | I3: 96.9 | J3: -6.3 | K3: 58.98 | L3: 65.23 | M3: 1.93 | N3: 5.4 | O3: -0.6 | P3: 1 | Q3: 1 | R3: 1 | S3: 6.79 | T3: 18368.28
A4: A279570 | B4: 케이뱅크 | D4: 5650 | E4: 117.1 | F4: 73 | G4: 86.8 | H4: 82.2 | I4: 29.2 | J4: 3.4 | K4: 46.46 | L4: 43.02 | M4: 0.6 | N4: 256.9 | O4: 135 | P4: 1 | Q4: 0 | R4: 0 | S4: 3.92 | T4: 2285.97
A5: A388210 | B5: 씨엠티엑스 | D5: 84700 | E5: 88.7 | F5: 72 | G5: 76.8 | H5: 60.5 | I5: 93.8 | J5: -0.2 | K5: 42.32 | L5: 42.5 | M5: 1.46 | N5: 20.6 | O5: -137.5 | P5: 1 | Q5: 0 | R5: 0 | S5: 6.8 | T5: 44714.61
A6: A475960 | B6: 토모큐브 | D6: 33250 | E6: 23.2 | F6: 70.2 | G6: 60.9 | H6: 67.5 | I6: 90.8 | J6: -0.9 | K6: 41.9 | L6: 42.75 | M6: 1.44 | N6: 2.1 | O6: 14.5 | P6: 0 | Q6: 0 | R6: 0 | S6: 5.67 | T6: 8994.99
A7: A317450 | B7: 명인제약 | D7: 42400 | E7: 8.8 | F7: 68.3 | G7: 66.2 | H7: 64.3 | I7: 81.5 | J7: -2.8 | K7: 44.73 | L7: 47.57 | M7: 1.06 | N7: 3.8 | O7: 6.8 | P7: 0 | Q7: 0 | R7: 0 | S7: 3.09 | T7: 5094.42
A8: A491000 | B8: 리브스메드 | D8: 40350 | E8: 78 | F8: 65.7 | G8: 84.1 | H8: 53.3 | I8: 69.2 | J8: -2.8 | K8: 49.01 | L8: 51.85 | M8: 0.89 | N8: 28.7 | O8: -164.2 | P8: 1 | Q8: 1 | R8: 0 | S8: 7.37 | T8: 13122.33
A9: A475560 | B9: 더본코리아 | D9: 14600 | E9: 10 | F9: 65.4 | G9: 63.6 | H9: 52.7 | I9: 100 | J9: -0.2 | K9: 40.5 | L9: 40.68 | M9: 3.19 | N9: 0 | O9: 2.9 | P9: 0 | Q9: 0 | R9: 0 | S9: 3.07 | T9: 2095.23
A10: A415640 | B10: KB발해인프라 | D10: 10580 | E10: 11.2 | F10: 65.3 | G10: 88.9 | H10: 55.8 | I10: 53.8 | J10: -10.4 | K10: 57.01 | L10: 67.45 | M10: 0.73 | N10: -6.4 | O10: 10.8 | P10: 1 | Q10: 1 | R10: 1 | S10: 2.1 | T10: 1469.21
A11: A389650 | B11: 넥스트바이오메디컬 | D11: 36600 | E11: 18.2 | F11: 65.2 | G11: 55.9 | H11: 68 | I11: 72.3 | J11: -2.1 | K11: 39.35 | L11: 41.45 | M11: 0.94 | N11: 11.4 | O11: 26.1 | P11: 0 | Q11: 0 | R11: 0 | S11: 6.69 | T11: 8125.88
A12: A483650 | B12: 달바글로벌 | D12: 199500 | E12: 218.5 | F12: 60.9 | G12: 72.9 | H12: 63 | I12: 37.7 | J12: 0.8 | K12: 43.76 | L12: 42.99 | M12: 0.64 | N12: -62.5 | O12: 394.5 | P12: 0 | Q12: 0 | R12: 0 | S12: 5 | T12: 58838.41
A13: A176750 | B13: 듀켐바이오 | D13: 6090 | E13: 4.7 | F13: 60.8 | G13: 66.8 | H13: 42.2 | I13: 98.5 | J13: 0.9 | K13: 40.29 | L13: 39.37 | M13: 3.09 | N13: -0.1 | O13: -3.3 | P13: 0 | Q13: 0 | R13: 0 | S13: 3.6 | T13: 923.46
... A51: A475400 | B51: 씨메스 | D51: 15760 | E51: 6.8 | F51: 38.8 | G51: 12.2 | H51: 38.7 | I51: 79.2 | J51: -4.1 | K51: 31.64 | L51: 35.71 | M51: 1 | N51: -12.3 | O51: -8 | P51: 0 | Q51: 0 | R51: 0 | S51: 5.79 | T51: 10079.41

Sheet A등급
A1: 코드 | B1: 코드명 | C1: 상장일 | D1: days_since_ipo | E1: 기관_일간 | F1: 기관_5일 | G1: 기관_20일 | H1: 외국인_일간 | I1: 외국인_5일 | J1: 외국인_20일 | K1: 현재가 | L1: 거래량 | M1: 거래대금(억) | N1: 20일평균거래량 | O1: RVOL(20) | P1: 변동성(30D) | Q1: RSI(14) | R1: 전일RSI(14) | S1: RSI변화량 | T1: 1일수익률(%) | U1: 20일수익률(%) | V1: 10일이평 | W1: 20일이평 | X1: 60일이평 | Y1: 10일선돌파 | Z1: 20일선돌파 | AA1: 60일선돌파 | AB1: BB폭 | AC1: 시가총액(억) | AD1: 모멘텀스코어 | AE1: 수급스코어 | AF1: 거래량스코어 | AG1: 종합스코어 | AH1: 등급
A2: A240550 | B2: 동방메디컬 | E2: 30 | F2: 83.7 | G2: 100.6 | H2: 15.8 | I2: 10 | J2: -27.6 | K2: 6110 | L2: 210542 | M2: 12.9 | N2: 111122.1 | O2: 1.89 | P2: 4.71 | Q2: 53.89 | R2: 54.09 | S2: -0.2 | T2: -0.16 | U2: 1.83 | V2: 5819 | W2: 5615.5 | X2: 6549.3333 | Y2: 1 | Z2: 1 | AA2: 0 | AB2: 1506.81 | AC2: 1267 | AD2: 93.4 | AE2: 71.9 | AF2: 95.4 | AG2: 83 | AH2: A

Sheet 전체
A1: 코드 | B1: 코드명 | C1: 상장일 | D1: days_since_ipo | E1: 기관_일간 | F1: 기관_5일 | G1: 기관_20일 | H1: 외국인_일간 | I1: 외국인_5일 | J1: 외국인_20일 | K1: 현재가 | L1: 거래량 | M1: 거래대금(억) | N1: 20일평균거래량 | O1: RVOL(20) | P1: 변동성(30D) | Q1: RSI(14) | R1: 전일RSI(14) | S1: RSI변화량 | T1: 1일수익률(%) | U1: 20일수익률(%) | V1: 10일이평 | W1: 20일이평 | X1: 60일이평 | Y1: 10일선돌파 | Z1: 20일선돌파 | AA1: 60일선돌파 | AB1: BB폭 | AC1: 시가총액(억) | AD1: 모멘텀스코어 | AE1: 수급스코어 | AF1: 거래량스코어 | AG1: 종합스코어 | AH1: 등급
A2: A062040 | B2: 산일전기 | E2: -781.3 | F2: -2425.4 | G2: -2549.8 | H2: -509.8 | I2: 3242.9 | J2: 1609.6 | K2: 169800 | L2: 274401 | M2: 465.9 | N2: 316704.35 | O2: 0.87 | P2: 5.62 | Q2: 34.5 | R2: 39.05 | S2: -4.5 | T2: -10.21 | U2: -32.35 | V2: 207610 | W2: 219880 | X2: 239991.67 | Y2: 0 | Z2: 0 | AA2: 0 | AB2: 102599.31 | AC2: 51618 | AD2: 20.5 | AE2: 30.8 | AF2: 66.2 | AG2: 34.8 | AH2: D
A3: A079900 | B3: 전진건설로봇 | E3: 0 | F3: -37 | G3: -203.8 | H3: 6.6 | I3: 103.8 | J3: 340.2 | K3: 33400 | L3: 45334 | M3: 15.1 | N3: 70580.9 | O3: 0.64 | P3: 5.36 | Q3: 28.42 | R3: 31.06 | S3: -2.6 | T3: -5.92 | U3: -43.49 | V3: 36655 | W3: 41680 | X3: 54624.167 | Y3: 0 | Z3: 0 | AA3: 0 | AB3: 30100.33 | AC3: 4597 | AD3: 17 | AE3: 54.2 | AF3: 37.7 | AG3: 39.7 | AH3: D
A4: A389650 | B4: 넥스트바이오메디컬 | E4: 11.4 | F4: 85.6 | G4: 325.8 | H4: 26.1 | I4: 1.6 | J4: -260.4 | K4: 36600 | L4: 49858 | M4: 18.2 | N4: 53213.1 | O4: 0.94 | P4: 6.69 | Q4: 39.35 | R4: 41.45 | S4: -2.1 | T4: -3.3 | U4: -10.84 | V4: 39590 | W4: 40277.5 | X4: 48185 | Y4: 0 | Z4: 0 | AA4: 0 | AB4: 8125.88 | AC4: 2909 | AD4: 55.9 | AE4: 68 | AF4: 72.3 | AG4: 65.2 | AH4: B
A5: A461300 | B5: 아이스크림미디어 | E5: 0 | F5: -24.1 | G5: -296.3 | H5: -12.4 | I5: -38.2 | J5: 62 | K5: 15900 | L5: 23565 | M5: 3.7 | N5: 46817.05 | O5: 0.5 | P5: 2.92 | Q5: 44.2 | R5: 43.72 | S5: 0.5 | T5: 0.25 | U5: -5.24 | V5: 16169 | W5: 16426.5 | X5: 16906.667 | Y5: 0 | Z5: 0 | AA5: 0 | AB5: 1940.98 | AC5: 2047 | AD5: 69.9 | AE5: 33.4 | AF5: 18.5 | AG5: 41.4 | AH5: D
A6: A308430 | B6: 셀비온 | E6: 0.5 | F6: 2.5 | G6: 104.7 | H6: -7.4 | I6: 13.8 | J6: -92.4 | K6: 13510 | L6: 34240 | M6: 4.6 | N6: 35625.25 | O6: 0.96 | P6: 4.89 | Q6: 28.59 | R6: 33.27 | S6: -4.7 | T6: -9.57 | U6: -25.15 | V6: 15888 | W6: 16368.5 | X6: 23818.667 | Y6: 0 | Z6: 0 | AA6: 0 | AB6: 5043.21 | AC6: 1648 | AD6: 20.6 | AE6: 54.5 | AF6: 73.8 | AG6: 48.2 | AH6: D
A7: A474170 | B7: 루미르 | E7: 0.2 | F7: -0.1 | G7: -30.8 | H7: -12.7 | I7: 4.3 | J7: 179.1 | K7: 6440 | L7: 74256 | M7: 4.8 | N7: 130878.45 | O7: 0.57 | P7: 4.42 | Q7: 29.53 | R7: 32.92 | S7: -3.4 | T7: -7.6 | U7: -32.71 | V7: 7037 | W7: 7688 | X7: 11492.333 | Y7: 0 | Z7: 0 | AA7: 0 | AB7: 3510.3 | AC7: 1114 | AD7: 17.4 | AE7: 48.2 | AF7: 24.6 | AG7: 34.2 | AH7: D
A8: A475400 | B8: 씨메스 | E8: -12.3 | F8: -29.5 | G8: -144.9 | H8: -8 | I8: 64.4 | J8: 158.9 | K8: 15760 | L8: 43416 | M8: 6.8 | N8: 43579.1 | O8: 1 | P8: 5.79 | Q8: 31.64 | R8: 35.71 | S8: -4.1 | T8: -9.48 | U8: -38.68 | V8: 17492 | W8: 19358.5 | X8: 26539.5 | Y8: 0 | Z8: 0 | AA8: 0 | AB8: 10079.41 | AC8: 1801 | AD8: 12.2 | AE8: 38.7 | AF8: 79.2 | AG8: 38.8 | AH8: D
A9: A466100 | B9: 클로봇 | E9: -28 | F9: 289.7 | G9: 327.8 | H9: -40.2 | I9: 236.6 | J9: 1088.9 | K9: 24500 | L9: 168264 | M9: 41.2 | N9: 210017.55 | O9: 0.8 | P9: 5.98 | Q9: 34.84 | R9: 39.25 | S9: -4.4 | T9: -9.09 | U9: -31.75 | V9: 26872.9 | W9: 29124.05 | X9: 38183.4 | Y9: 0 | Z9: 0 | AA9: 0 | AB9: 12424.52 | AC9: 6034 | AD9: 23 | AE9: 59.8 | AF9: 63.8 | AG9: 49.6 | AH9: D
A10: A458650 | B10: 성우 | E10: 0 | F10: 0.7 | G10: 30.3 | H10: -3.1 | I10: 0.8 | J10: 14.5 | K10: 8500 | L10: 21552 | M10: 1.8 | N10: 28601.9 | O10: 0.75 | P10: 4.29 | Q10: 39.21 | R10: 41.22 | S10: -2 | T10: -2.75 | U10: -25.04 | V10: 8486 | W10: 8980 | X10: 11606.833 | Y10: 1 | Z10: 0 | AA10: 0 | AB10: 3707.72 | AC10: 1219 | AD10: 69.2 | AE10: 51.7 | AF10: 58.5 | AG10: 58.3 | AH10: C
A11: A376270 | B11: HEM파마 | E11: -8.7 | F11: -28.3 | G11: -19.6 | H11: 8.4 | I11: 14 | J11: -11.5 | K11: 41100 | L11: 10894 | M11: 4.5 | N11: 15067.65 | O11: 0.72 | P11: 5.07 | Q11: 40.55 | R11: 41.09 | S11: -0.5 | T11: -0.72 | U11: -14.91 | V11: 42270 | W11: 44427.5 | X11: 52722.5 | Y11: 0 | Z11: 0 | AA11: 0 | AB11: 14749.17 | AC11: 2928 | AD11: 59.2 | AE11: 42.5 | AF11: 52.3 | AG11: 49.5 | AH11: D
A12: A475560 | B12: 더본코리아 | E12: 0 | F12: -1.5 | G12: 12 | H12: 2.9 | I12: 7.8 | J12: 19.6 | K12: 14600 | L12: 68563 | M12: 10 | N12: 21468.3 | O12: 3.19 | P12: 3.07 | Q12: 40.5 | R12: 40.68 | S12: -0.2 | T12: -0.14 | U12: -10.04 | V12: 14691 | W12: 14900.5 | X12: 17558 | Y12: 0 | Z12: 0 | AA12: 0 | AB12: 2095.23 | AC12: 2155 | AD12: 63.6 | AE12: 52.7 | AF12: 100 | AG12: 65.4 | AH12: B
A13: A475960 | B13: 토모큐브 | E13: 2.1 | F13: 0.6 | G13: 15.5 | H13: 14.5 | I13: 27.5 | J13: 53.9 | K13: 33250 | L13: 69920 | M13: 23.2 | N13: 48532.1 | O13: 1.44 | P13: 5.67 | Q13: 41.9 | R13: 42.75 | S13: -0.9 | T13: -1.34 | U13: -13.19 | V13: 33860 | W13: 35177.5 | X13: 44284.167 | Y13: 0 | Z13: 0 | AA13: 0 | AB13: 8994.99 | AC13: 4651 | AD13: 60.9 | AE13: 67.5 | AF13: 90.8 | AG13: 70.2 | AH13: B
... A43: A439260 | B43: 대한조선 | E43: -72.6 | F43: -417.2 | G43: -229.7 | H43: 56.1 | I43: 443.5 | J43: 432.4 | K43: 46450 | L43: 74971 | M43: 34.8 | N43: 76921.25 | O43: 0.97 | P43: 3.53 | Q43: 29.64 | R43: 31.99 | S43: -2.3 | T43: -3.73 | U43: -27.76 | V43: 50145 | W43: 53892.5 | X43: 68514.167 | Y43: 0 | Z43: 0 | AA43: 0 | AB43: 21695.83 | AC43: 16854 | AD43: 34.7 | AE43: 49.7 | AF43: 76.2 | AG43: 50.5 | AH43: C
A44: A309710 | B44: 아이티켐 | E44: 0 | F44: 0 | G44: 0 | H44: 0 | I44: 0 | J44: 0 | K44: 21000 | L44: 0 | M44: 0 | N44: 0 | P44: 0 | Q44: 21.52 | R44: 21.52 | S44: 0 | T44: 0 | U44: 0 | V44: 21000 | W44: 21000 | X44: 21000 | Y44: 0 | Z44: 0 | AA44: 0 | AB44: 0 | AC44: 2684 | AD44: 54.7 | AE44: 48.5 | AH44: -
A45: A456160 | B45: 지투지바이오 | E45: 117.5 | F45: -312.4 | G45: -970 | H45: -31.7 | I45: 482.9 | J45: 861.2 | K45: 31650 | L45: 228272 | M45: 72.2 | N45: 190491.05 | O45: 1.2 | P45: 6.88 | Q45: 30.58 | R45: 31.42 | S45: -0.8 | T45: -2.47 | U45: -30.21 | V45: 36040 | W45: 39235 | X45: 57315 | Y45: 0 | Z45: 0 | AA45: 0 | AB45: 20613.02 | AC45: 5047 | AD45: 35.7 | AE45: 53.2 | AF45: 87.7 | AG45: 54.9 | AH45: C
A46: A484590 | B46: 삼양컴텍 | E46: 0.6 | F46: -29.3 | G46: -39.3 | H46: -10.8 | I46: 7 | J46: -152.8 | K46: 6060 | L46: 232387 | M46: 14.1 | N46: 354637.85 | O46: 0.66 | P46: 6.26 | Q46: 36.45 | R46: 38.47 | S46: -2 | T46: -4.72 | U46: -24.63 | V46: 6666 | W46: 7364 | X46: 9483 | Y46: 0 | Z46: 0 | AA46: 0 | AB46: 4482.72 | AC46: 2365 | AD46: 43.4 | AE46: 39.2 | AF46: 40.8 | AG46: 40.8 | AH46: D
A47: A125490 | B47: 한라캐스트 | E47: -13.8 | F47: 64.6 | G47: 58 | H47: -34.1 | I47: 156.6 | J47: 337.3 | K47: 7810 | L47: 384464 | M47: 30 | N47: 485317.55 | O47: 0.79 | P47: 6.32 | Q47: 34.22 | R47: 37.81 | S47: -3.6 | T47: -8.33 | U47: -37.32 | V47: 8373 | W47: 9266 | X47: 13184.333 | Y47: 0 | Z47: 0 | AA47: 0 | AB47: 5447.34 | AC47: 2723 | AD47: 17.8 | AE47: 52.6 | AF47: 61.5 | AG47: 43.9 | AH47: D
A48: A318060 | B48: 그래피 | E48: 0 | F48: -49.2 | G48: 12.5 | H48: 19.1 | I48: -143 | J48: -61.1 | K48: 17330 | L48: 138384 | M48: 24 | N48: 120854.45 | O48: 1.15 | P48: 5.99 | Q48: 41.11 | R48: 44.82 | S48: -3.7 | T48: -6.32 | U48: -21.23 | V48: 17315 | W48: 18053.5 | X48: 25742.833 | Y48: 1 | Z48: 0 | AA48: 0 | AB48: 7750.15 | AC48: 2045 | AD48: 64.9 | AE48: 42.1 | AF48: 86.2 | AG48: 57.8 | AH48: C
A49: A488280 | B49: 에스투더블유 | E49: 0 | F49: -12.4 | G49: -67 | H49: -7.2 | I49: 41.7 | J49: 179.7 | K49: 9570 | L49: 44253 | M49: 4.2 | N49: 104308.25 | O49: 0.42 | P49: 6.79 | Q49: 32.18 | R49: 34.22 | S49: -2 | T49: -6.54 | U49: -41.11 | V49: 10505 | W49: 12219 | X49: 18766 | Y49: 0 | Z49: 0 | AA49: 0 | AB49: 8537.69 | AC49: 1010 | AD49: 20.7 | AE49: 48.8 | AF49: 10 | AG49: 32.6 | AH49: D
A50: A317450 | B50: 명인제약 | E50: 3.8 | F50: 16.2 | G50: -219.2 | H50: 6.8 | I50: 17.4 | J50: 209.6 | K50: 42400 | L50: 20697 | M50: 8.8 | N50: 19547.1 | O50: 1.06 | P50: 3.09 | Q50: 44.73 | R50: 47.57 | S50: -2.8 | T50: -1.97 | U50: -4.61 | V50: 42645 | W50: 42692.5 | X50: 48325.833 | Y50: 0 | Z50: 0 | AA50: 0 | AB50: 5094.42 | AC50: 6132 | AD50: 66.2 | AE50: 64.3 | AF50: 81.5 | AG50: 68.3 | AH50: B
A51: A486990 | B51: 노타 | E51: -0.5 | F51: -17.3 | G51: -431.7 | H51: 0.4 | I51: 145.7 | J51: 85.6 | K51: 17570 | L51: 140035 | M51: 24.6 | N51: 187934.1 | O51: 0.75 | P51: 5.96 | Q51: 32.2 | R51: 35.49 | S51: -3.3 | T51: -8.15 | U51: -35.17 | V51: 19896 | W51: 21520.5 | X51: 28769.333 | Y51: 0 | Z51: 0 | AA51: 0 | AB51: 10471.92 | AC51: 3590 | AD51: 17.8 | AE51: 46.9 | AF51: 58.5 | AG51: 40.5 | AH51: D
A52: A469610 | B52: 이노테크 | E52: 3.9 | F52: 1.3 | G52: -42.2 | H52: -13.7 | I52: 15.5 | J52: -36.5 | K52: 13110 | L52: 91208 | M52: 12 | N52: 196760.9 | O52: 0.46 | P52: 9.28 | Q52: 41.2 | R52: 44.07 | S52: -2.9 | T52: -6.22 | U52: -13.92 | V52: 13881 | W52: 15063 | X52: 19185.167 | Y52: 0 | Z52: 0 | AA52: 0 | AB52: 7796.94 | AC52: 1150 | AD52: 49.3 | AE52: 50.8 | AF52: 16.9 | AG52: 43.6 | AH52: D
A53: A494120 | B53: 큐리오시스 | E53: 27.8 | F53: 240.5 | G53: 655.5 | H53: -16.6 | I53: -78.6 | J53: -472.2 | K53: 25350 | L53: 68486 | M53: 17.4 | N53: 120983.35 | O53: 0.57 | P53: 8.35 | Q53: 43.32 | R53: 43.87 | S53: -0.5 | T53: -1.17 | U53: -2.5 | V53: 25305 | W53: 26245 | X53: 38356.667 | Y53: 1 | Z53: 0 | AA53: 0 | AB53: 9341.5 | AC53: 1949 | AD53: 86.9 | AE53: 54.8 | AF53: 24.6 | AG53: 58.4 | AH53: C
A54: A061090 | B54: 세나테크놀로지 | E54: 5.4 | F54: 20.4 | G54: -133.9 | H54: -0.6 | I54: 185.1 | J54: 180.1 | K54: 42750 | L54: 73274 | M54: 31.3 | N54: 37969.85 | O54: 1.93 | P54: 6.79 | Q54: 58.98 | R54: 65.23 | S54: -6.3 | T54: -6.15 | U54: 4.65 | V54: 36930 | W54: 35120 | X54: 41120.833 | Y54: 1 | Z54: 1 | AA54: 1 | AB54: 18368.28 | AC54: 2250 | AD54: 82.6 | AE54: 68.6 | AF54: 96.9 | AG54: 78.5 | AH54: B
A55: A403850 | B55: 더핑크퐁컴퍼니 | E55: -0.3 | F55: 125.7 | G55: 94.7 | H55: -16 | I55: 192.4 | J55: 227.5 | K55: 10100 | L55: 55183 | M55: 5.6 | N55: 83999.55 | O55: 0.66 | P55: 4.62 | Q55: 38.97 | R55: 43.56 | S55: -4.6 | T55: -5.7 | U55: -13.9 | V55: 10734 | W55: 10922 | X55: 13305.167 | Y55: 0 | Z55: 0 | AA55: 0 | AB55: 2314.53 | AC55: 1448 | AD55: 48.6 | AE55: 61.9 | AF55: 40.8 | AG55: 53.7 | AH55: C
A56: A388210 | B56: 씨엠티엑스 | E56: 20.6 | F56: 228.5 | G56: -70.9 | H56: -137.5 | I56: 177.2 | J56: 86 | K56: 84700 | L56: 104666 | M56: 88.7 | N56: 71488.2 | O56: 1.46 | P56: 6.8 | Q56: 42.32 | R56: 42.5 | S56: -0.2 | T56: -0.35 | U56: -24.78 | V56: 83130 | W56: 91585 | X56: 115520 | Y56: 1 | Z56: 0 | AA56: 0 | AB56: 44714.61 | AC56: 8129 | AD56: 76.8 | AE56: 60.5 | AF56: 93.8 | AG56: 72 | AH56: B
... A63: A279570 | B63: 케이뱅크 | E63: 256.9 | F63: 403.7 | G63: 5506.9 | H63: 135 | I63: 86.8 | J63: -852.9 | K63: 5650 | L63: 2072931 | M63: 117.1 | N63: 3437601 | O63: 0.6 | P63: 3.92 | Q63: 46.46 | R63: 43.02 | S63: 3.4 | T63: 2.36 | U63: -19.05 | V63: 5537 | W63: 5943.5 | X63: 5939.5 | Y63: 1 | Z63: 0 | AA63: 0 | AB63: 2285.97 | AC63: 22516 | AD63: 86.8 | AE63: 82.2 | AF63: 29.2 | AG63: 73 | AH63: B
A64: A493280 | B64: 아이엠바이오로직스 | K64: 19900 | L64: 73212 | M64: 14.6 | N64: 108908.75 | O64: 0.67 | P64: 6.81 | Q64: 33.88 | R64: 36.69 | S64: -2.8 | T64: -7.44 | U64: -24.91 | V64: 21395 | W64: 22517.5 | X64: 34935.833 | Y64: 0 | Z64: 0 | AA64: 0 | AB64: 8912.52 | AC64: 2777 | AD64: 30.3 | AF64: 43.1 | AH64: -
A65: A394420 | B65: 리센스메디컬 | K65: 13970 | L65: 226759 | M65: 31.7 | N65: 284262.55 | O65: 0.8 | P65: 9.4 | Q65: 38.13 | R65: 38.66 | S65: -0.5 | T65: -1.76 | U65: -23.66 | V65: 15876 | W65: 18133 | X65: 23024.167 | Y65: 0 | Z65: 0 | AA65: 0 | AB65: 11693.3 | AC65: 1393 | AD65: 52.2 | AF65: 63.8 | AH65: -
A66: A439960 | B66: 코스모로보틱스 | K66: 11700 | L66: 727816 | M66: 85.2 | N66: 1915644.9 | O66: 0.38 | P66: 9.31 | Q66: 43.07 | R66: 45.18 | S66: -2.1 | T66: -8.81 | U66: -53.39 | V66: 13335 | W66: 16894.5 | Y66: 0 | Z66: 0 | AA66: 0 | AB66: 18841.78 | AC66: 3712 | AD66: 21.8 | AF66: 2.3 | AH66: -
A67: A477850 | B67: 마키나락스 | K67: 24600 | L67: 1948613 | M67: 479.4 | N67: 2826469.9 | O67: 0.69 | P67: 12.92 | Q67: 64.52 | R67: 71.04 | S67: -6.5 | T67: -16.89 | U67: 11.31 | V67: 24370 | W67: 20777.5 | Y67: 1 | Z67: 1 | AA67: 0 | AB67: 20708.35 | AC67: 4962 | AD67: 70.1 | AF67: 48.5 | AH67: -
A68: A153890 | B68: 져스텍 | K68: 9670 | L68: 645713 | M68: 62.4 | T68: -20.67 | V68: 13415 | Y68: 0 | Z68: 0 | AA68: 0 | AC68: 1013 | AH68: -
A69: A475040 | B69: 스트라드비젼 | K69: 3730 | L69: 2969414 | M69: 110.8 | T69: -16.83 | V69: 4882.5 | Y69: 0 | Z69: 0 | AA69: 0 | AC69: 1829 | AH69: -

Sheet 전체_전일자
A1: 코드 | B1: 코드명 | C1: 상장일 | D1: days_since_ipo | E1: 기관_일간 | F1: 기관_5일 | G1: 기관_20일 | H1: 외국인_일간 | I1: 외국인_5일 | J1: 외국인_20일 | K1: 현재가 | L1: 거래량 | M1: 거래대금(억) | N1: 20일평균거래량 | O1: RVOL(20) | P1: 변동성(30D) | Q1: RSI(14) | R1: 전일RSI(14) | S1: RSI변화량 | T1: 1일수익률(%) | U1: 20일수익률(%) | V1: 10일이평 | W1: 20일이평 | X1: 60일이평 | Y1: 10일선돌파 | Z1: 20일선돌파 | AA1: 60일선돌파 | AB1: BB폭 | AC1: 시가총액(억) | AD1: 모멘텀스코어 | AE1: 수급스코어 | AF1: 거래량스코어 | AG1: 종합스코어 | AH1: 등급
A2: A062040 | B2: 산일전기 | E2: -211.6 | F2: -2050.7 | G2: -182.7 | H2: 705.9 | I2: 3371.9 | J2: -619.9 | K2: 189100 | L2: 191350 | M2: 361.8 | N2: 321438.85 | O2: 0.6 | P2: 5.36 | Q2: 39.05 | R2: 35.14 | S2: 3.9 | T2: 5.29 | U2: -18.32 | V2: 212680 | W2: 223940 | X2: 240221.67 | Y2: 0 | Z2: 0 | AA2: 0 | AB2: 95032.83 | AC2: 51618 | AD2: 39.3 | AE2: 41.3 | AF2: 37.7 | AG2: 40 | AH2: D
A3: A079900 | B3: 전진건설로봇 | E3: -0.6 | F3: -36.9 | G3: -224.6 | H3: 88.2 | I3: 106.3 | J3: 217.2 | K3: 35500 | L3: 45380 | M3: 16.1 | N3: 75050.4 | O3: 0.6 | P3: 5.64 | Q3: 31.06 | R3: 26.38 | S3: 4.7 | T3: 4.57 | U3: -37.94 | V3: 37280 | W3: 42965 | X3: 55197.5 | Y3: 0 | Z3: 0 | AA3: 0 | AB3: 32673.05 | AC3: 4597 | AD3: 13.9 | AE3: 53.4 | AF3: 37.7 | AG3: 38.4 | AH3: D
A4: A389650 | B4: 넥스트바이오메디컬 | E4: 19.6 | F4: 115.2 | G4: 376.2 | H4: 0.8 | I4: -56.4 | J4: -342 | K4: 37850 | L4: 33086 | M4: 12.5 | N4: 53601.75 | O4: 0.62 | P4: 6.72 | Q4: 41.45 | R4: 41.1 | S4: 0.4 | T4: 0.4 | U4: -11.46 | V4: 40330 | W4: 40500 | X4: 48631.667 | Y4: 0 | Z4: 0 | AA4: 0 | AB4: 7409.18 | AC4: 2909 | AD4: 36.9 | AE4: 51.9 | AF4: 43.1 | AG4: 45.6 | AH4: D
A5: A461300 | B5: 아이스크림미디어 | E5: -14.4 | F5: -25 | G5: -296.3 | H5: 3.5 | I5: -22.2 | J5: 101.6 | K5: 15860 | L5: 25278 | M5: 4 | N5: 47740.5 | O5: 0.53 | P5: 2.97 | Q5: 43.72 | R5: 42 | S5: 1.7 | T5: 0.95 | U5: -3.29 | V5: 16211 | W5: 16470.5 | X5: 16900.833 | Y5: 0 | Z5: 0 | AA5: 0 | AB5: 1901.22 | AC5: 2047 | AD5: 43.7 | AE5: 27.1 | AF5: 33.8 | AG5: 33.4 | AH5: D
A6: A308430 | B6: 셀비온 | E6: 0 | F6: 3.1 | G6: 105.9 | H6: 3.2 | I6: 14.6 | J6: -113.2 | K6: 14940 | L6: 15615 | M6: 2.3 | N6: 35611.55 | O6: 0.44 | P6: 4.68 | Q6: 33.27 | R6: 30.15 | S6: 3.1 | T6: 2.89 | U6: -18.41 | V6: 16258 | W6: 16595.5 | X6: 24145.167 | Y6: 0 | Z6: 0 | AA6: 0 | AB6: 4509.39 | AC6: 1648 | AD6: 27.1 | AE6: 49.6 | AF6: 24.6 | AG6: 37.8 | AH6: D
A7: A474170 | B7: 루미르 | E7: 0.3 | F7: -1.1 | G7: -34.6 | H7: 7.2 | I7: 10.5 | J7: 193.9 | K7: 6970 | L7: 40109 | M7: 2.8 | N7: 140687.95 | O7: 0.29 | P7: 4.54 | Q7: 32.92 | R7: 28 | S7: 4.9 | T7: 5.13 | U7: -30.51 | V7: 7180 | W7: 7844.5 | X7: 11631.333 | Y7: 0 | Z7: 0 | AA7: 0 | AB7: 3676.66 | AC7: 1114 | AD7: 20.4 | AE7: 50.7 | AF7: 3.1 | AG7: 32.1 | AH7: D
A8: A475400 | B8: 씨메스 | E8: -11.5 | F8: -31.7 | G8: -179 | H8: 35.2 | I8: 87 | J8: 177.3 | K8: 17410 | L8: 48821 | M8: 8.5 | N8: 44414.9 | O8: 1.1 | P8: 5.64 | Q8: 35.71 | R8: 29.43 | S8: 6.3 | T8: 7.6 | U8: -33.93 | V8: 17956 | W8: 19855.5 | X8: 26783.5 | Y8: 0 | Z8: 0 | AA8: 0 | AB8: 10929.53 | AC8: 1801 | AD8: 29.7 | AE8: 45.6 | AF8: 86.2 | AG8: 49 | AH8: D
A9: A466100 | B9: 클로봇 | E9: 83.5 | F9: 272 | G9: 333.6 | H9: 82.9 | I9: 295.7 | J9: 1192.3 | K9: 26950 | L9: 168395 | M9: 45.4 | N9: 210730.5 | O9: 0.8 | P9: 5.94 | Q9: 39.25 | R9: 33.5 | S9: 5.8 | T9: 7.16 | U9: -21.94 | V9: 27468.1 | W9: 29693.95 | X9: 38466.5 | Y9: 0 | Z9: 0 | AA9: 0 | AB9: 12991.37 | AC9: 6034 | AD9: 42.6 | AE9: 89.4 | AF9: 63.1 | AG9: 70.1 | AH9: B
A10: A458650 | B10: 성우 | E10: 0 | F10: 0.7 | G10: 18.9 | H10: 4.7 | I10: 3.6 | J10: 17.3 | K10: 8740 | L10: 12749 | M10: 1.1 | N10: 29485 | O10: 0.43 | P10: 4.42 | Q10: 41.22 | R10: 31.28 | S10: 9.9 | T10: 9.11 | U10: -22.17 | V10: 8526 | W10: 9122 | X10: 11685.833 | Y10: 1 | Z10: 0 | AA10: 0 | AB10: 4206.65 | AC10: 1219 | AD10: 68.4 | AE10: 50.3 | AF10: 21.5 | AG10: 50 | AH10: D
A11: A376270 | B11: HEM파마 | E11: -5.3 | F11: -16.9 | G11: -11.8 | H11: 18.2 | I11: -10.4 | J11: -29.6 | K11: 41400 | L11: 10359 | M11: 4.3 | N11: 15049 | O11: 0.69 | P11: 5.08 | Q11: 41.09 | R11: 37.26 | S11: 3.8 | T11: 3.76 | U11: -11.91 | V11: 42635 | W11: 44787.5 | X11: 53080.833 | Y11: 0 | Z11: 0 | AA11: 0 | AB11: 14785.25 | AC11: 2928 | AD11: 41.4 | AE11: 36.1 | AF11: 52.3 | AG11: 40.9 | AH11: D
A12: A475560 | B12: 더본코리아 | E12: -0.4 | F12: -1.7 | G12: 12 | H12: 4.7 | I12: 7.5 | J12: 19.4 | K12: 14620 | L12: 8441 | M12: 1.2 | N12: 18555.65 | O12: 0.45 | P12: 3.07 | Q12: 40.68 | R12: 37.81 | S12: 2.9 | T12: 1.6 | U12: -9.47 | V12: 14709 | W12: 14982 | X12: 17667.167 | Y12: 0 | Z12: 0 | AA12: 0 | AB12: 2371.82 | AC12: 2155 | AD12: 38.4 | AE12: 44.2 | AF12: 26.2 | AG12: 38.9 | AH12: D
A13: A475960 | B13: 토모큐브 | E13: -25.6 | F13: -2.8 | G13: 2.3 | H13: 57.9 | I13: 2.4 | J13: 15.3 | K13: 33700 | L13: 44399 | M13: 15 | N13: 46879.75 | O13: 0.95 | P13: 5.67 | Q13: 42.75 | R13: 37.39 | S13: 5.4 | T13: 6.48 | U13: -10.37 | V13: 34315 | W13: 35430 | X13: 44651.667 | Y13: 0 | Z13: 0 | AA13: 0 | AB13: 9204.22 | AC13: 4651 | AD13: 53 | AE13: 44 | AF13: 77.7 | AG13: 53.4 | AH13: C
... A43: A439260 | B43: 대한조선 | E43: -159.3 | F43: -400.9 | G43: -156.4 | H43: 112.9 | I43: 460 | J43: 325.4 | K43: 48250 | L43: 72364 | M43: 34.9 | N43: 77924.9 | O43: 0.93 | P43: 3.49 | Q43: 31.99 | R43: 28.32 | S43: 3.7 | T43: 2.66 | U43: -22.05 | V43: 50890 | W43: 54785 | X43: 69250 | Y43: 0 | Z43: 0 | AA43: 0 | AB43: 22367.49 | AC43: 16854 | AD43: 22.1 | AE43: 49.2 | AF43: 73.8 | AG43: 46 | AH43: D
A44: A309710 | B44: 아이티켐 | E44: 0 | F44: 0 | G44: 0 | H44: 0 | I44: 0 | J44: 0 | K44: 21000 | L44: 0 | M44: 0 | N44: 0 | P44: 0 | Q44: 21.52 | R44: 21.52 | S44: 0 | T44: 0 | U44: 0 | V44: 21000 | W44: 21000 | X44: 21000 | Y44: 0 | Z44: 0 | AA44: 0 | AB44: 0 | AC44: 2684 | AD44: 29.8 | AE44: 42.8 | AH44: -
A45: A456160 | B45: 지투지바이오 | E45: -98 | F45: -454.9 | G45: -1115.1 | H45: 116.9 | I45: 570.6 | J45: 1011.4 | K45: 32450 | L45: 168563 | M45: 54.7 | N45: 187391.45 | O45: 0.9 | P45: 6.95 | Q45: 31.42 | R45: 29.5 | S45: 1.9 | T45: 2.69 | U45: -28.45 | V45: 37245 | W45: 39920 | X45: 57959.167 | Y45: 0 | Z45: 0 | AA45: 0 | AB45: 20031.91 | AC45: 5047 | AD45: 15.5 | AE45: 49.3 | AF45: 72.3 | AG45: 43.8 | AH45: D
A46: A484590 | B46: 삼양컴텍 | E46: -0.2 | F46: -14.8 | G46: -135.5 | H46: 38.7 | I46: -98.8 | J46: -68.2 | K46: 6360 | L46: 257613 | M46: 16.4 | N46: 364208.65 | O46: 0.71 | P46: 6.34 | Q46: 38.47 | R46: 32.19 | S46: 6.3 | T46: 9.28 | U46: -19.8 | V46: 6777 | W46: 7463 | X46: 9583 | Y46: 0 | Z46: 0 | AA46: 0 | AB46: 4352.38 | AC46: 2365 | AD46: 47.8 | AE46: 38.4 | AF46: 56.9 | AG46: 44.9 | AH46: D
A47: A125490 | B47: 한라캐스트 | E47: 35.5 | F47: 70.4 | G47: 36.5 | H47: 69.9 | I47: 197.1 | J47: -403.1 | K47: 8520 | L47: 585418 | M47: 49.9 | N47: 525589.1 | O47: 1.11 | P47: 6.21 | Q47: 37.81 | R47: 28.02 | S47: 9.8 | T47: 13.15 | U47: -37.49 | V47: 8520 | W47: 9498.5 | X47: 13278.167 | Y47: 0 | Z47: 0 | AA47: 0 | AB47: 5939.19 | AC47: 2723 | AD47: 38.4 | AE47: 72.2 | AF47: 87.7 | AG47: 65.2 | AH47: B
A48: A318060 | B48: 그래피 | E48: -6.9 | F48: -44.9 | G48: 12.5 | H48: 22.7 | I48: -173 | J48: -101.8 | K48: 18500 | L48: 72822 | M48: 13.5 | N48: 117396.8 | O48: 0.62 | P48: 5.97 | Q48: 44.82 | R48: 40.75 | S48: 4.1 | T48: 5.47 | U48: -15.33 | V48: 17322 | W48: 18287 | X48: 26069.833 | Y48: 1 | Z48: 1 | AA48: 0 | AB48: 8440 | AC48: 2045 | AD48: 69.3 | AE48: 30.8 | AF48: 43.1 | AG48: 44.8 | AH48: D
A49: A488280 | B49: 에스투더블유 | E49: -5.1 | F49: -14.8 | G49: -67 | H49: 14.2 | I49: 67.9 | J49: 184 | K49: 10240 | L49: 34699 | M49: 3.6 | N49: 104860.9 | O49: 0.33 | P49: 6.92 | Q49: 34.22 | R49: 29.97 | S49: 4.2 | T49: 7.23 | U49: -35.35 | V49: 10747 | W49: 12553 | X49: 18909.167 | Y49: 0 | Z49: 0 | AA49: 0 | AB49: 8859.61 | AC49: 1010 | AD49: 26.2 | AE49: 44.9 | AF49: 7.7 | AG49: 31.8 | AH49: D
A50: A317450 | B50: 명인제약 | E50: 7.2 | F50: 11.6 | G50: -365.7 | H50: 9 | I50: 12 | J50: 281.6 | K50: 43250 | L50: 14079 | M50: 6.1 | N50: 20953.9 | O50: 0.67 | P50: 3.09 | Q50: 47.57 | R50: 42.59 | S50: 5 | T50: 2.98 | U50: -0.23 | V50: 42735 | W50: 42795 | X50: 48557.5 | Y50: 1 | Z50: 1 | AA50: 0 | AB50: 5309.2 | AC50: 6132 | AD50: 72 | AE50: 54.1 | AF50: 50 | AG50: 58.6 | AH50: C
A51: A486990 | B51: 노타 | E51: 8.4 | F51: -28.2 | G51: -572.3 | H51: 71.2 | I51: 124.6 | J51: 95.5 | K51: 19130 | L51: 121355 | M51: 23.2 | N51: 189961.45 | O51: 0.64 | P51: 6.36 | Q51: 35.49 | R51: 30.77 | S51: 4.7 | T51: 6.22 | U51: -29.41 | V51: 20184 | W51: 21997 | X51: 29015.667 | Y51: 0 | Z51: 0 | AA51: 0 | AB51: 10883.37 | AC51: 3590 | AD51: 27.7 | AE51: 57.3 | AF51: 47.7 | AG51: 46.5 | AH51: D
A52: A469610 | B52: 이노테크 | E52: -1.1 | F52: -2.7 | G52: -47 | H52: 30.1 | I52: 21.5 | J52: -33.8 | K52: 13980 | L52: 65799 | M52: 9.2 | N52: 194358.95 | O52: 0.34 | P52: 9.23 | Q52: 44.07 | R52: 40.82 | S52: 3.2 | T52: 5.59 | U52: -7.97 | V52: 14085 | W52: 15169 | X52: 19295.167 | Y52: 0 | Z52: 0 | AA52: 0 | AB52: 7588.38 | AC52: 1150 | AD52: 53.5 | AE52: 45.8 | AF52: 9.2 | AG52: 40.8 | AH52: D
A53: A494120 | B53: 큐리오시스 | E53: 9.4 | F53: 238.2 | G53: 623.5 | H53: 24.5 | I53: -49.2 | J53: -473.3 | K53: 25650 | L53: 47585 | M53: 12.2 | N53: 119053.35 | O53: 0.4 | P53: 8.67 | Q53: 43.87 | R53: 40.48 | S53: 3.4 | T53: 5.99 | U53: -6.04 | V53: 25270 | W53: 26277.5 | X53: 38834.167 | Y53: 1 | Z53: 0 | AA53: 0 | AB53: 9308.81 | AC53: 1949 | AD53: 75 | AE53: 60.2 | AF53: 16.9 | AG53: 56 | AH53: C
A54: A061090 | B54: 세나테크놀로지 | E54: 7.6 | F54: 45.6 | G54: -136.8 | H54: 170 | I54: 188.3 | J54: 127.6 | K54: 45550 | L54: 250858 | M54: 114.3 | N54: 36395.65 | O54: 6.89 | P54: 7.3 | Q54: 65.23 | R54: 51.53 | S54: 13.7 | T54: 21.47 | U54: 5.32 | V54: 35700 | W54: 35025 | X54: 41072.5 | Y54: 1 | Z54: 1 | AA54: 1 | AB54: 17802.86 | AC54: 2250 | AD54: 98.1 | AE54: 72.1 | AF54: 100 | AG54: 85.5 | AH54: A
A55: A403850 | B55: 더핑크퐁컴퍼니 | E55: 12.6 | F55: 120 | G55: 95.3 | H55: -17.1 | I55: 199.6 | J55: 216.1 | K55: 10710 | L55: 100361 | M55: 10.7 | N55: 84761.1 | O55: 1.18 | P55: 4.52 | Q55: 43.56 | R55: 45.1 | S55: -1.5 | T55: -1.74 | U55: -12.07 | V55: 10805 | W55: 11003.5 | X55: 13424.5 | Y55: 0 | Z55: 0 | AA55: 0 | AB55: 2287.47 | AC55: 1448 | AD55: 35.7 | AE55: 66.2 | AF55: 89.2 | AG55: 61.6 | AH55: C
A56: A388210 | B56: 씨엠티엑스 | E56: 122.4 | F56: 184.1 | G56: -347.7 | H56: -106.7 | I56: 336.3 | J56: 108.4 | K56: 85000 | L56: 69067 | M56: 58.7 | N56: 72432.35 | O56: 0.95 | P56: 6.8 | Q56: 42.5 | R56: 34.32 | S56: 8.2 | T56: 11.99 | U56: -28.33 | V56: 84210 | W56: 92980 | X56: 116445 | Y56: 1 | Z56: 0 | AA56: 0 | AB56: 47787.46 | AC56: 8129 | AD56: 68.1 | AE56: 60.3 | AF56: 77.7 | AG56: 66.1 | AH56: B
... A63: A279570 | B63: 케이뱅크 | E63: 185.5 | F63: 188.8 | G63: 6960 | H63: 88 | I63: -164.3 | J63: -613.7 | K63: 5520 | L63: 1540151 | M63: 85 | N63: 3916588.8 | O63: 0.39 | P63: 3.9 | Q63: 43.02 | R63: 36.62 | S63: 6.4 | T63: 4.15 | U63: -15.98 | V63: 5536 | W63: 6010 | X63: 5951 | Y63: 0 | Z63: 0 | AA63: 0 | AB63: 2438.33 | AC63: 22516 | AD63: 42.4 | AE63: 66.9 | AF63: 13.1 | AG63: 48.8 | AH63: D
A64: A493280 | B64: 아이엠바이오로직스 | K64: 21500 | L64: 75173 | M64: 16.2 | N64: 107492.35 | O64: 0.7 | P64: 6.85 | Q64: 36.69 | R64: 32.81 | S64: 3.9 | T64: 5.91 | U64: -23.08 | V64: 21775 | W64: 22847.5 | X64: 35619.167 | Y64: 0 | Z64: 0 | AA64: 0 | AB64: 9214.01 | AC64: 2777 | AD64: 34.7 | AF64: 54.6 | AH64: -
A65: A394420 | B65: 리센스메디컬 | K65: 14220 | L65: 266498 | M65: 37.9 | N65: 282086.2 | O65: 0.94 | P65: 9.45 | Q65: 38.66 | R65: 36.65 | S65: 2 | T65: 4.56 | U65: -17.57 | V65: 16489 | W65: 18349.5 | X65: 23134.667 | Y65: 0 | Z65: 0 | AA65: 0 | AB65: 11051.75 | AC65: 1393 | AD65: 36.6 | AF65: 75.4 | AH65: -
A66: A439960 | B66: 코스모로보틱스 | K66: 12830 | L66: 690992 | M66: 88.7 | N66: 2136841 | O66: 0.32 | P66: 9.34 | Q66: 45.18 | R66: 43.77 | S66: 1.4 | T66: 5.08 | U66: -33.63 | V66: 13712 | W66: 17564.5 | Y66: 0 | Z66: 0 | AA66: 0 | AB66: 19496.36 | AC66: 3712 | AD66: 33.3 | AF66: 6.2 | AH66: -
A67: A477850 | B67: 마키나락스 | K67: 29600 | L67: 3084271 | M67: 912.9 | N67: 2884658.5 | O67: 1.07 | P67: 12.59 | Q67: 71.04 | R67: 71.1 | S67: -0.1 | T67: -0.17 | U67: 56.61 | V67: 23731 | W67: 20652.5 | Y67: 1 | Z67: 1 | AA67: 0 | AB67: 20452.28 | AC67: 4962 | AD67: 72.6 | AF67: 84.6 | AH67: -
A68: A153890 | B68: 져스텍 | K68: 12190 | L68: 620901 | M68: 75.7 | T68: -2.56 | V68: 14201 | Y68: 0 | Z68: 0 | AA68: 0 | AC68: 1013 | AH68: -
A69: A475040 | B69: 스트라드비젼 | K69: 4485 | L69: 2303190 | M69: 103.3 | T69: -0.22 | Y69: 0 | Z69: 0 | AA69: 0 | AC69: 1829 | AH69: -

Sheet RSI과매도
A1: 코드 | B1: 코드명 | C1: 상장일 | D1: days_since_ipo | E1: 기관_일간 | F1: 기관_5일 | G1: 기관_20일 | H1: 외국인_일간 | I1: 외국인_5일 | J1: 외국인_20일 | K1: 현재가 | L1: 거래량 | M1: 거래대금(억) | N1: 20일평균거래량 | O1: RVOL(20) | P1: 변동성(30D) | Q1: RSI(14) | R1: 전일RSI(14) | S1: RSI변화량 | T1: 1일수익률(%) | U1: 20일수익률(%) | V1: 10일이평 | W1: 20일이평 | X1: 60일이평 | Y1: 10일선돌파 | Z1: 20일선돌파 | AA1: 60일선돌파 | AB1: BB폭 | AC1: 시가총액(억) | AD1: 모멘텀스코어 | AE1: 수급스코어 | AF1: 거래량스코어 | AG1: 종합스코어 | AH1: 등급
A2: A309710 | B2: 아이티켐 | E2: 0 | F2: 0 | G2: 0 | H2: 0 | I2: 0 | J2: 0 | K2: 21000 | L2: 0 | M2: 0 | N2: 0 | P2: 0 | Q2: 21.52 | R2: 21.52 | S2: 0 | T2: 0 | U2: 0 | V2: 21000 | W2: 21000 | X2: 21000 | Y2: 0 | Z2: 0 | AA2: 0 | AB2: 0 | AC2: 2684 | AD2: 54.7 | AE2: 48.5 | AH2: -
A3: A079900 | B3: 전진건설로봇 | E3: 0 | F3: -37 | G3: -203.8 | H3: 6.6 | I3: 103.8 | J3: 340.2 | K3: 33400 | L3: 45334 | M3: 15.1 | N3: 70580.9 | O3: 0.64 | P3: 5.36 | Q3: 28.42 | R3: 31.06 | S3: -2.6 | T3: -5.92 | U3: -43.49 | V3: 36655 | W3: 41680 | X3: 54624.167 | Y3: 0 | Z3: 0 | AA3: 0 | AB3: 30100.33 | AC3: 4597 | AD3: 17 | AE3: 54.2 | AF3: 37.7 | AG3: 39.7 | AH3: D
A4: A474650 | B4: 링크솔루션 | E4: 0 | F4: -17 | G4: 20.2 | H4: -14 | I4: 30.2 | J4: 426.1 | K4: 23900 | L4: 21102 | M4: 5 | N4: 52724.2 | O4: 0.4 | P4: 5.67 | Q4: 28.47 | R4: 31.14 | S4: -2.7 | T4: -7.36 | U4: -43.16 | V4: 26710 | W4: 30752.5 | X4: 45225 | Y4: 0 | Z4: 0 | AA4: 0 | AB4: 22374.85 | AC4: 1294 | AD4: 12 | AE4: 51.7 | AF4: 6.9 | AG4: 30.8 | AH4: D
A5: A308430 | B5: 셀비온 | E5: 0.5 | F5: 2.5 | G5: 104.7 | H5: -7.4 | I5: 13.8 | J5: -92.4 | K5: 13510 | L5: 34240 | M5: 4.6 | N5: 35625.25 | O5: 0.96 | P5: 4.89 | Q5: 28.59 | R5: 33.27 | S5: -4.7 | T5: -9.57 | U5: -25.15 | V5: 15888 | W5: 16368.5 | X5: 23818.667 | Y5: 0 | Z5: 0 | AA5: 0 | AB5: 5043.21 | AC5: 1648 | AD5: 20.6 | AE5: 54.5 | AF5: 73.8 | AG5: 48.2 | AH5: D
A6: A478340 | B6: 나라스페이스테크놀로지 | E6: 0 | F6: -0.1 | G6: -223.9 | H6: -26.3 | I6: -12.5 | J6: 771.9 | K6: 10940 | L6: 80753 | M6: 8.8 | N6: 139117.65 | O6: 0.58 | P6: 6.72 | Q6: 28.78 | R6: 31.82 | S6: -3 | T6: -10.77 | U6: -46.76 | V6: 12497 | W6: 14517.5 | X6: 24831.667 | Y6: 0 | Z6: 0 | AA6: 0 | AB6: 12187.89 | AC6: 1208 | AD6: 5.1 | AE6: 39.6 | AF6: 27.7 | AG6: 26.9 | AH6: F
A7: A474170 | B7: 루미르 | E7: 0.2 | F7: -0.1 | G7: -30.8 | H7: -12.7 | I7: 4.3 | J7: 179.1 | K7: 6440 | L7: 74256 | M7: 4.8 | N7: 130878.45 | O7: 0.57 | P7: 4.42 | Q7: 29.53 | R7: 32.92 | S7: -3.4 | T7: -7.6 | U7: -32.71 | V7: 7037 | W7: 7688 | X7: 11492.333 | Y7: 0 | Z7: 0 | AA7: 0 | AB7: 3510.3 | AC7: 1114 | AD7: 17.4 | AE7: 48.2 | AF7: 24.6 | AG7: 34.2 | AH7: D
A8: A439260 | B8: 대한조선 | E8: -72.6 | F8: -417.2 | G8: -229.7 | H8: 56.1 | I8: 443.5 | J8: 432.4 | K8: 46450 | L8: 74971 | M8: 34.8 | N8: 76921.25 | O8: 0.97 | P8: 3.53 | Q8: 29.64 | R8: 31.99 | S8: -2.3 | T8: -3.73 | U8: -27.76 | V8: 50145 | W8: 53892.5 | X8: 68514.167 | Y8: 0 | Z8: 0 | AA8: 0 | AB8: 21695.83 | AC8: 16854 | AD8: 34.7 | AE8: 49.7 | AF8: 76.2 | AG8: 50.5 | AH8: C

Sheet 외국인순매수TOP
A1: 코드 | B1: 코드명 | C1: 상장일 | D1: days_since_ipo | E1: 기관_일간 | F1: 기관_5일 | G1: 기관_20일 | H1: 외국인_일간 | I1: 외국인_5일 | J1: 외국인_20일 | K1: 현재가 | L1: 거래량 | M1: 거래대금(억) | N1: 20일평균거래량 | O1: RVOL(20) | P1: 변동성(30D) | Q1: RSI(14) | R1: 전일RSI(14) | S1: RSI변화량 | T1: 1일수익률(%) | U1: 20일수익률(%) | V1: 10일이평 | W1: 20일이평 | X1: 60일이평 | Y1: 10일선돌파 | Z1: 20일선돌파 | AA1: 60일선돌파 | AB1: BB폭 | AC1: 시가총액(억) | AD1: 모멘텀스코어 | AE1: 수급스코어 | AF1: 거래량스코어 | AG1: 종합스코어 | AH1: 등급
A2: A483650 | B2: 달바글로벌 | E2: -62.5 | F2: -606.3 | G2: 636 | H2: 394.5 | I2: 1247 | J2: 6686.2 | K2: 199500 | L2: 109507 | M2: 218.5 | N2: 170822.55 | O2: 0.64 | P2: 5 | Q2: 43.76 | R2: 42.99 | S2: 0.8 | T2: 0.81 | U2: 1.32 | V2: 217830 | W2: 216440 | X2: 214720 | Y2: 0 | Z2: 0 | AA2: 0 | AB2: 58838.41 | AC2: 24707 | AD2: 72.9 | AE2: 63 | AF2: 37.7 | AG2: 60.9 | AH2: C
A3: A279570 | B3: 케이뱅크 | E3: 256.9 | F3: 403.7 | G3: 5506.9 | H3: 135 | I3: 86.8 | J3: -852.9 | K3: 5650 | L3: 2072931 | M3: 117.1 | N3: 3437601 | O3: 0.6 | P3: 3.92 | Q3: 46.46 | R3: 43.02 | S3: 3.4 | T3: 2.36 | U3: -19.05 | V3: 5537 | W3: 5943.5 | X3: 5939.5 | Y3: 1 | Z3: 0 | AA3: 0 | AB3: 2285.97 | AC3: 22516 | AD3: 86.8 | AE3: 82.2 | AF3: 29.2 | AG3: 73 | AH3: B
A4: A439260 | B4: 대한조선 | E4: -72.6 | F4: -417.2 | G4: -229.7 | H4: 56.1 | I4: 443.5 | J4: 432.4 | K4: 46450 | L4: 74971 | M4: 34.8 | N4: 76921.25 | O4: 0.97 | P4: 3.53 | Q4: 29.64 | R4: 31.99 | S4: -2.3 | T4: -3.73 | U4: -27.76 | V4: 50145 | W4: 53892.5 | X4: 68514.167 | Y4: 0 | Z4: 0 | AA4: 0 | AB4: 21695.83 | AC4: 16854 | AD4: 34.7 | AE4: 49.7 | AF4: 76.2 | AG4: 50.5 | AH4: C
A5: A475830 | B5: 오름테라퓨틱 | E5: -57.9 | F5: 233.4 | G5: 1028.4 | H5: 40 | I5: -51.6 | J5: -488.9 | K5: 45400 | L5: 106537 | M5: 48.4 | N5: 153557.05 | O5: 0.69 | P5: 7.94 | Q5: 35.18 | R5: 38.04 | S5: -2.9 | T5: -6.78 | U5: -28.16 | V5: 51185 | W5: 55492.5 | X5: 69200.833 | Y5: 0 | Z5: 0 | AA5: 0 | AB5: 26711.22 | AC5: 9752 | AD5: 32.2 | AE5: 52.6 | AF5: 48.5 | AG5: 45.7 | AH5: D
A6: A217590 | B6: 티엠씨 | E6: 0 | F6: -79 | G6: 766.2 | H6: 29.7 | I6: 143.7 | J6: 860.3 | K6: 10900 | L6: 261798 | M6: 28.5 | N6: 378573.25 | O6: 0.69 | P6: 8.35 | Q6: 33.16 | R6: 35.44 | S6: -2.3 | T6: -7.08 | U6: -42.57 | V6: 11730 | W6: 13642.5 | X6: 22170 | Y6: 0 | Z6: 0 | AA6: 0 | AB6: 10862.15 | AC6: 2542 | AD6: 18.9 | AE6: 67 | AF6: 48.5 | AG6: 48.9 | AH6: D
A7: A389650 | B7: 넥스트바이오메디컬 | E7: 11.4 | F7: 85.6 | G7: 325.8 | H7: 26.1 | I7: 1.6 | J7: -260.4 | K7: 36600 | L7: 49858 | M7: 18.2 | N7: 53213.1 | O7: 0.94 | P7: 6.69 | Q7: 39.35 | R7: 41.45 | S7: -2.1 | T7: -3.3 | U7: -10.84 | V7: 39590 | W7: 40277.5 | X7: 48185 | Y7: 0 | Z7: 0 | AA7: 0 | AB7: 8125.88 | AC7: 2909 | AD7: 55.9 | AE7: 68 | AF7: 72.3 | AG7: 65.2 | AH7: B
A8: A318060 | B8: 그래피 | E8: 0 | F8: -49.2 | G8: 12.5 | H8: 19.1 | I8: -143 | J8: -61.1 | K8: 17330 | L8: 138384 | M8: 24 | N8: 120854.45 | O8: 1.15 | P8: 5.99 | Q8: 41.11 | R8: 44.82 | S8: -3.7 | T8: -6.32 | U8: -21.23 | V8: 17315 | W8: 18053.5 | X8: 25742.833 | Y8: 1 | Z8: 0 | AA8: 0 | AB8: 7750.15 | AC8: 2045 | AD8: 64.9 | AE8: 42.1 | AF8: 86.2 | AG8: 57.8 | AH8: C
A9: A240550 | B9: 동방메디컬 | E9: 30 | F9: 83.7 | G9: 100.6 | H9: 15.8 | I9: 10 | J9: -27.6 | K9: 6110 | L9: 210542 | M9: 12.9 | N9: 111122.1 | O9: 1.89 | P9: 4.71 | Q9: 53.89 | R9: 54.09 | S9: -0.2 | T9: -0.16 | U9: 1.83 | V9: 5819 | W9: 5615.5 | X9: 6549.3333 | Y9: 1 | Z9: 1 | AA9: 0 | AB9: 1506.81 | AC9: 1267 | AD9: 93.4 | AE9: 71.9 | AF9: 95.4 | AG9: 83 | AH9: A
A10: A287840 | B10: 인투셀 | E10: 1.3 | F10: 0.6 | G10: 16.6 | H10: 15.6 | I10: -67.8 | J10: -188.6 | K10: 22450 | L10: 42320 | M10: 9.5 | N10: 61985.7 | O10: 0.68 | P10: 6.95 | Q10: 43.97 | R10: 45.69 | S10: -1.7 | T10: -2.81 | U10: -9.84 | V10: 23035 | W10: 23425 | X10: 29745 | Y10: 0 | Z10: 0 | AA10: 0 | AB10: 5378.29 | AC10: 3267 | AD10: 62.1 | AE10: 54.5 | AF10: 44.6 | AG10: 54.8 | AH10: C
A11: A475960 | B11: 토모큐브 | E11: 2.1 | F11: 0.6 | G11: 15.5 | H11: 14.5 | I11: 27.5 | J11: 53.9 | K11: 33250 | L11: 69920 | M11: 23.2 | N11: 48532.1 | O11: 1.44 | P11: 5.67 | Q11: 41.9 | R11: 42.75 | S11: -0.9 | T11: -1.34 | U11: -13.19 | V11: 33860 | W11: 35177.5 | X11: 44284.167 | Y11: 0 | Z11: 0 | AA11: 0 | AB11: 8994.99 | AC11: 4651 | AD11: 60.9 | AE11: 67.5 | AF11: 90.8 | AG11: 70.2 | AH11: B
A12: A415640 | B12: KB발해인프라 | E12: -6.4 | F12: -54.7 | G12: -20.4 | H12: 10.8 | I12: 343.3 | J12: 776.9 | K12: 10580 | L12: 105955 | M12: 11.2 | N12: 144553.3 | O12: 0.73 | P12: 2.1 | Q12: 57.01 | R12: 67.45 | S12: -10.4 | T12: -3.29 | U12: 6.33 | V12: 10548 | W12: 10277 | X12: 10023.167 | Y12: 1 | Z12: 1 | AA12: 1 | AB12: 1469.21 | AC12: 12904 | AD12: 88.9 | AE12: 55.8 | AF12: 53.8 | AG12: 65.3 | AH12: B
A13: A376270 | B13: HEM파마 | E13: -8.7 | F13: -28.3 | G13: -19.6 | H13: 8.4 | I13: 14 | J13: -11.5 | K13: 41100 | L13: 10894 | M13: 4.5 | N13: 15067.65 | O13: 0.72 | P13: 5.07 | Q13: 40.55 | R13: 41.09 | S13: -0.5 | T13: -0.72 | U13: -14.91 | V13: 42270 | W13: 44427.5 | X13: 52722.5 | Y13: 0 | Z13: 0 | AA13: 0 | AB13: 14749.17 | AC13: 2928 | AD13: 59.2 | AE13: 42.5 | AF13: 52.3 | AG13: 49.5 | AH13: D
... A21: A486990 | B21: 노타 | E21: -0.5 | F21: -17.3 | G21: -431.7 | H21: 0.4 | I21: 145.7 | J21: 85.6 | K21: 17570 | L21: 140035 | M21: 24.6 | N21: 187934.1 | O21: 0.75 | P21: 5.96 | Q21: 32.2 | R21: 35.49 | S21: -3.3 | T21: -8.15 | U21: -35.17 | V21: 19896 | W21: 21520.5 | X21: 28769.333 | Y21: 0 | Z21: 0 | AA21: 0 | AB21: 10471.92 | AC21: 3590 | AD21: 17.8 | AE21: 46.9 | AF21: 58.5 | AG21: 40.5 | AH21: D

Sheet 기관순매수TOP
A1: 코드 | B1: 코드명 | C1: 상장일 | D1: days_since_ipo | E1: 기관_일간 | F1: 기관_5일 | G1: 기관_20일 | H1: 외국인_일간 | I1: 외국인_5일 | J1: 외국인_20일 | K1: 현재가 | L1: 거래량 | M1: 거래대금(억) | N1: 20일평균거래량 | O1: RVOL(20) | P1: 변동성(30D) | Q1: RSI(14) | R1: 전일RSI(14) | S1: RSI변화량 | T1: 1일수익률(%) | U1: 20일수익률(%) | V1: 10일이평 | W1: 20일이평 | X1: 60일이평 | Y1: 10일선돌파 | Z1: 20일선돌파 | AA1: 60일선돌파 | AB1: BB폭 | AC1: 시가총액(억) | AD1: 모멘텀스코어 | AE1: 수급스코어 | AF1: 거래량스코어 | AG1: 종합스코어 | AH1: 등급
A2: A279570 | B2: 케이뱅크 | E2: 256.9 | F2: 403.7 | G2: 5506.9 | H2: 135 | I2: 86.8 | J2: -852.9 | K2: 5650 | L2: 2072931 | M2: 117.1 | N2: 3437601 | O2: 0.6 | P2: 3.92 | Q2: 46.46 | R2: 43.02 | S2: 3.4 | T2: 2.36 | U2: -19.05 | V2: 5537 | W2: 5943.5 | X2: 5939.5 | Y2: 1 | Z2: 0 | AA2: 0 | AB2: 2285.97 | AC2: 22516 | AD2: 86.8 | AE2: 82.2 | AF2: 29.2 | AG2: 73 | AH2: B
A3: A064400 | B3: LG씨엔에스 | E3: 154.2 | F3: -98.2 | G3: -1288.2 | H3: -738.4 | I3: 2652.8 | J3: 3081.7 | K3: 68200 | L3: 1381965 | M3: 942.5 | N3: 1262484.4 | O3: 1.09 | P3: 6.57 | Q3: 36.27 | R3: 38.69 | S3: -2.4 | T3: -4.08 | U3: -29.4 | V3: 73510 | W3: 78880 | X3: 81893.333 | Y3: 0 | Z3: 0 | AA3: 0 | AB3: 29476.93 | AC3: 63945 | AD3: 39.9 | AE3: 52.3 | AF3: 84.6 | AG3: 55 | AH3: C
A4: A456160 | B4: 지투지바이오 | E4: 117.5 | F4: -312.4 | G4: -970 | H4: -31.7 | I4: 482.9 | J4: 861.2 | K4: 31650 | L4: 228272 | M4: 72.2 | N4: 190491.05 | O4: 1.2 | P4: 6.88 | Q4: 30.58 | R4: 31.42 | S4: -0.8 | T4: -2.47 | U4: -30.21 | V4: 36040 | W4: 39235 | X4: 57315 | Y4: 0 | Z4: 0 | AA4: 0 | AB4: 20613.02 | AC4: 5047 | AD4: 35.7 | AE4: 53.2 | AF4: 87.7 | AG4: 54.9 | AH4: C
A5: A240550 | B5: 동방메디컬 | E5: 30 | F5: 83.7 | G5: 100.6 | H5: 15.8 | I5: 10 | J5: -27.6 | K5: 6110 | L5: 210542 | M5: 12.9 | N5: 111122.1 | O5: 1.89 | P5: 4.71 | Q5: 53.89 | R5: 54.09 | S5: -0.2 | T5: -0.16 | U5: 1.83 | V5: 5819 | W5: 5615.5 | X5: 6549.3333 | Y5: 1 | Z5: 1 | AA5: 0 | AB5: 1506.81 | AC5: 1267 | AD5: 93.4 | AE5: 71.9 | AF5: 95.4 | AG5: 83 | AH5: A
A6: A098070 | B6: 한텍 | E6: 29.2 | F6: -98.3 | G6: -355.8 | H6: -18.5 | I6: 191.7 | J6: 321.8 | K6: 24100 | L6: 46553 | M6: 11.2 | N6: 50934.95 | O6: 0.91 | P6: 5.38 | Q6: 37.18 | R6: 37.5 | S6: -0.3 | T6: -0.62 | U6: -25.85 | V6: 24900 | W6: 27035 | X6: 35118.333 | Y6: 0 | Z6: 0 | AA6: 0 | AB6: 13309.41 | AC6: 2563 | AD6: 50.3 | AE6: 50.8 | AF6: 70.8 | AG6: 54.6 | AH6: C
A7: A491000 | B7: 리브스메드 | E7: 28.7 | F7: 276.7 | G7: 353.8 | H7: -164.2 | I7: -241.9 | J7: 42.6 | K7: 40350 | L7: 193402 | M7: 78 | N7: 217836.05 | O7: 0.89 | P7: 7.37 | Q7: 49.01 | R7: 51.85 | S7: -2.8 | T7: -4.5 | U7: 0 | V7: 36535 | W7: 37755 | X7: 51777.5 | Y7: 1 | Z7: 1 | AA7: 0 | AB7: 13122.33 | AC7: 9077 | AD7: 84.1 | AE7: 53.3 | AF7: 69.2 | AG7: 65.7 | AH7: B
A8: A494120 | B8: 큐리오시스 | E8: 27.8 | F8: 240.5 | G8: 655.5 | H8: -16.6 | I8: -78.6 | J8: -472.2 | K8: 25350 | L8: 68486 | M8: 17.4 | N8: 120983.35 | O8: 0.57 | P8: 8.35 | Q8: 43.32 | R8: 43.87 | S8: -0.5 | T8: -1.17 | U8: -2.5 | V8: 25305 | W8: 26245 | X8: 38356.667 | Y8: 1 | Z8: 0 | AA8: 0 | AB8: 9341.5 | AC8: 1949 | AD8: 86.9 | AE8: 54.8 | AF8: 24.6 | AG8: 58.4 | AH8: C
A9: A388210 | B9: 씨엠티엑스 | E9: 20.6 | F9: 228.5 | G9: -70.9 | H9: -137.5 | I9: 177.2 | J9: 86 | K9: 84700 | L9: 104666 | M9: 88.7 | N9: 71488.2 | O9: 1.46 | P9: 6.8 | Q9: 42.32 | R9: 42.5 | S9: -0.2 | T9: -0.35 | U9: -24.78 | V9: 83130 | W9: 91585 | X9: 115520 | Y9: 1 | Z9: 0 | AA9: 0 | AB9: 44714.61 | AC9: 8129 | AD9: 76.8 | AE9: 60.5 | AF9: 93.8 | AG9: 72 | AH9: B
A10: A482630 | B10: 삼양엔씨켐 | E10: 20.1 | F10: 73.2 | G10: 590.7 | H10: -37 | I10: 17.5 | J10: -289.2 | K10: 13850 | L10: 172010 | M10: 23.8 | N10: 447354.25 | O10: 0.38 | P10: 7.36 | Q10: 40.52 | R10: 42.7 | S10: -2.2 | T10: -4.61 | U10: -20.63 | V10: 14844 | W10: 16669 | X10: 18031.833 | Y10: 0 | Z10: 0 | AA10: 0 | AB10: 9137.09 | AC10: 3025 | AD10: 49.2 | AE10: 56.1 | AF10: 2.3 | AG10: 43.3 | AH10: D
A11: A389650 | B11: 넥스트바이오메디컬 | E11: 11.4 | F11: 85.6 | G11: 325.8 | H11: 26.1 | I11: 1.6 | J11: -260.4 | K11: 36600 | L11: 49858 | M11: 18.2 | N11: 53213.1 | O11: 0.94 | P11: 6.69 | Q11: 39.35 | R11: 41.45 | S11: -2.1 | T11: -3.3 | U11: -10.84 | V11: 39590 | W11: 40277.5 | X11: 48185 | Y11: 0 | Z11: 0 | AA11: 0 | AB11: 8125.88 | AC11: 2909 | AD11: 55.9 | AE11: 68 | AF11: 72.3 | AG11: 65.2 | AH11: B
A12: A490470 | B12: 세미파이브 | E12: 8.7 | F12: 88.9 | G12: -1803.2 | H12: -142.2 | I12: -36.6 | J12: 2042.2 | K12: 19300 | L12: 436115 | M12: 84.2 | N12: 434294.1 | O12: 1 | P12: 6.87 | Q12: 37.84 | R12: 42.67 | S12: -4.8 | T12: -10.44 | U12: -29.56 | V12: 19879 | W12: 21769.5 | X12: 31869.833 | Y12: 0 | Z12: 0 | AA12: 0 | AB12: 10341.64 | AC12: 6104 | AD12: 25.2 | AE12: 49.3 | AF12: 79.2 | AG12: 48.1 | AH12: D
A13: A061090 | B13: 세나테크놀로지 | E13: 5.4 | F13: 20.4 | G13: -133.9 | H13: -0.6 | I13: 185.1 | J13: 180.1 | K13: 42750 | L13: 73274 | M13: 31.3 | N13: 37969.85 | O13: 1.93 | P13: 6.79 | Q13: 58.98 | R13: 65.23 | S13: -6.3 | T13: -6.15 | U13: 4.65 | V13: 36930 | W13: 35120 | X13: 41120.833 | Y13: 1 | Z13: 1 | AA13: 1 | AB13: 18368.28 | AC13: 2250 | AD13: 82.6 | AE13: 68.6 | AF13: 96.9 | AG13: 78.5 | AH13: B
... A21: A473980 | B21: 노머스 | E21: 1 | F21: 169 | G21: 44.2 | H21: 1.4 | I21: -114.2 | J21: 63.9 | K21: 11030 | L21: 32392 | M21: 3.6 | N21: 80579.85 | O21: 0.4 | P21: 5.94 | Q21: 43.22 | R21: 47.51 | S21: -4.3 | T21: -5.32 | U21: -17.93 | V21: 11147 | W21: 11112 | X21: 14325.5 | Y21: 0 | Z21: 0 | AA21: 0 | AB21: 3472.26 | AC21: 1125 | AD21: 51.3 | AE21: 60.4 | AF21: 6.9 | AG21: 47 | AH21: D

Sheet RVOL_TOP
A1: 코드 | B1: 코드명 | C1: 상장일 | D1: days_since_ipo | E1: 기관_일간 | F1: 기관_5일 | G1: 기관_20일 | H1: 외국인_일간 | I1: 외국인_5일 | J1: 외국인_20일 | K1: 현재가 | L1: 거래량 | M1: 거래대금(억) | N1: 20일평균거래량 | O1: RVOL(20) | P1: 변동성(30D) | Q1: RSI(14) | R1: 전일RSI(14) | S1: RSI변화량 | T1: 1일수익률(%) | U1: 20일수익률(%) | V1: 10일이평 | W1: 20일이평 | X1: 60일이평 | Y1: 10일선돌파 | Z1: 20일선돌파 | AA1: 60일선돌파 | AB1: BB폭 | AC1: 시가총액(억) | AD1: 모멘텀스코어 | AE1: 수급스코어 | AF1: 거래량스코어 | AG1: 종합스코어 | AH1: 등급
A2: A475560 | B2: 더본코리아 | E2: 0 | F2: -1.5 | G2: 12 | H2: 2.9 | I2: 7.8 | J2: 19.6 | K2: 14600 | L2: 68563 | M2: 10 | N2: 21468.3 | O2: 3.19 | P2: 3.07 | Q2: 40.5 | R2: 40.68 | S2: -0.2 | T2: -0.14 | U2: -10.04 | V2: 14691 | W2: 14900.5 | X2: 17558 | Y2: 0 | Z2: 0 | AA2: 0 | AB2: 2095.23 | AC2: 2155 | AD2: 63.6 | AE2: 52.7 | AF2: 100 | AG2: 65.4 | AH2: B
A3: A176750 | B3: 듀켐바이오 | E3: -0.1 | F3: -0.1 | G3: 0.6 | H3: -3.3 | I3: -2.7 | J3: -11.9 | K3: 6090 | L3: 77888 | M3: 4.7 | N3: 25209.2 | O3: 3.09 | P3: 3.6 | Q3: 40.29 | R3: 39.37 | S3: 0.9 | T3: 0.5 | U3: -5.14 | V3: 6150 | W3: 6317.5 | X3: 7428.8333 | Y3: 0 | Z3: 0 | AA3: 0 | AB3: 923.46 | AC3: 1678 | AD3: 66.8 | AE3: 42.2 | AF3: 98.5 | AG3: 60.8 | AH3: C
A4: A061090 | B4: 세나테크놀로지 | E4: 5.4 | F4: 20.4 | G4: -133.9 | H4: -0.6 | I4: 185.1 | J4: 180.1 | K4: 42750 | L4: 73274 | M4: 31.3 | N4: 37969.85 | O4: 1.93 | P4: 6.79 | Q4: 58.98 | R4: 65.23 | S4: -6.3 | T4: -6.15 | U4: 4.65 | V4: 36930 | W4: 35120 | X4: 41120.833 | Y4: 1 | Z4: 1 | AA4: 1 | AB4: 18368.28 | AC4: 2250 | AD4: 82.6 | AE4: 68.6 | AF4: 96.9 | AG4: 78.5 | AH4: B
A5: A240550 | B5: 동방메디컬 | E5: 30 | F5: 83.7 | G5: 100.6 | H5: 15.8 | I5: 10 | J5: -27.6 | K5: 6110 | L5: 210542 | M5: 12.9 | N5: 111122.1 | O5: 1.89 | P5: 4.71 | Q5: 53.89 | R5: 54.09 | S5: -0.2 | T5: -0.16 | U5: 1.83 | V5: 5819 | W5: 5615.5 | X5: 6549.3333 | Y5: 1 | Z5: 1 | AA5: 0 | AB5: 1506.81 | AC5: 1267 | AD5: 93.4 | AE5: 71.9 | AF5: 95.4 | AG5: 83 | AH5: A
A6: A388210 | B6: 씨엠티엑스 | E6: 20.6 | F6: 228.5 | G6: -70.9 | H6: -137.5 | I6: 177.2 | J6: 86 | K6: 84700 | L6: 104666 | M6: 88.7 | N6: 71488.2 | O6: 1.46 | P6: 6.8 | Q6: 42.32 | R6: 42.5 | S6: -0.2 | T6: -0.35 | U6: -24.78 | V6: 83130 | W6: 91585 | X6: 115520 | Y6: 1 | Z6: 0 | AA6: 0 | AB6: 44714.61 | AC6: 8129 | AD6: 76.8 | AE6: 60.5 | AF6: 93.8 | AG6: 72 | AH6: B
A7: A468530 | B7: 프로티나 | E7: 1.6 | F7: -4.5 | G7: 78.4 | H7: -51 | I7: -56.7 | J7: -97 | K7: 23000 | L7: 87957 | M7: 20.2 | N7: 60583.75 | O7: 1.45 | P7: 7.87 | Q7: 34.42 | R7: 39.55 | S7: -5.1 | T7: -13.37 | U7: -32.55 | V7: 25830 | W7: 28752.5 | X7: 42022.5 | Y7: 0 | Z7: 0 | AA7: 0 | AB7: 16342.03 | AC7: 2477 | AD7: 17.2 | AE7: 38.4 | AF7: 92.3 | AG7: 42.8 | AH7: D
A8: A475960 | B8: 토모큐브 | E8: 2.1 | F8: 0.6 | G8: 15.5 | H8: 14.5 | I8: 27.5 | J8: 53.9 | K8: 33250 | L8: 69920 | M8: 23.2 | N8: 48532.1 | O8: 1.44 | P8: 5.67 | Q8: 41.9 | R8: 42.75 | S8: -0.9 | T8: -1.34 | U8: -13.19 | V8: 33860 | W8: 35177.5 | X8: 44284.167 | Y8: 0 | Z8: 0 | AA8: 0 | AB8: 8994.99 | AC8: 4651 | AD8: 60.9 | AE8: 67.5 | AF8: 90.8 | AG8: 70.2 | AH8: B
A9: A452450 | B9: 피아이이 | E9: 0 | F9: 0 | G9: 4.2 | H9: -0.6 | I9: 25.6 | J9: 69.1 | K9: 3085 | L9: 188633 | M9: 5.8 | N9: 153977.1 | O9: 1.23 | P9: 5.05 | Q9: 31.65 | R9: 36.65 | S9: -5 | T9: -10.32 | U9: -35.05 | V9: 3391.5 | W9: 3749.75 | X9: 5304.4167 | Y9: 0 | Z9: 0 | AA9: 0 | AB9: 2022.1 | AC9: 1079 | AD9: 13.1 | AE9: 55.7 | AF9: 89.2 | AG9: 49.6 | AH9: D
A10: A456160 | B10: 지투지바이오 | E10: 117.5 | F10: -312.4 | G10: -970 | H10: -31.7 | I10: 482.9 | J10: 861.2 | K10: 31650 | L10: 228272 | M10: 72.2 | N10: 190491.05 | O10: 1.2 | P10: 6.88 | Q10: 30.58 | R10: 31.42 | S10: -0.8 | T10: -2.47 | U10: -30.21 | V10: 36040 | W10: 39235 | X10: 57315 | Y10: 0 | Z10: 0 | AA10: 0 | AB10: 20613.02 | AC10: 5047 | AD10: 35.7 | AE10: 53.2 | AF10: 87.7 | AG10: 54.9 | AH10: C
