Workbook

Sheet POST IPO 보고서
B2: POST IPO 모니터링 보고서
B3: 기준일: 2026-07-08 | 분석 대상: 70개 종목 | 2년 이내 신규 상장주
B6: 전체 종목 | D6: A등급 | F6: B등급 | H6: 50점 이상 종목수 | J6: RSI>65
B7: 70 | D7: 0 | F7: 6 | H7: 27 | J7: =COUNTIF(INDEX(전체!$A:$XFD,0,MATCH("RSI(14)",전체!$1:$1,0)),">=65")
B10: ▶ 추천종목 (종합스코어 50점 이상) | Q10: 구분 | R10: 종목수
B11: 순위 | C11: 종목명 | D11: 종합점수 | E11: 모멘텀 | F11: 수급 | G11: 거래량 | H11: RSI | I11: 등급 | J11: RSI신호 | K11: 등급변화 | L11: 점수변화량 | M11: 모멘텀Δ | N11: 수급Δ | O11: 거래량Δ | Q11: 강세 (A+B등급) | R11: 6
B12: 1 | C12: KB발해인프라 | D12: 78.1 | E12: 90.7 | F12: 75.6 | G12: 65.7 | H12: 64.08 | I12: B | K12: =IFERROR(IF(I12=INDEX(전체_전일자!1:1048576,MATCH(C12,전체_전일자!B:B,0),MATCH("등급",전체_전일자!1:1,0)),"유지",INDEX(전체_전일자!1:1048576,MATCH(C12,전체_전일자!B:B,0),MATCH("등급",전체_전일자!1:1,0))&" → "&I12),"") | L12: =IFERROR(D12-INDEX(전체_전일자!1:1048576,MATCH(C12,전체_전일자!B:B,0),MATCH("종합스코어",전체_전일자!1:1,0)),"") | M12: =IFERROR(E12-INDEX(전체_전일자!1:1048576,MATCH(C12,전체_전일자!B:B,0),MATCH("모멘텀스코어",전체_전일자!1:1,0)),"") | N12: =IFERROR(F12-INDEX(전체_전일자!1:1048576,MATCH(C12,전체_전일자!B:B,0),MATCH("수급스코어",전체_전일자!1:1,0)),"") | O12: =IFERROR(G12-INDEX(전체_전일자!1:1048576,MATCH(C12,전체_전일자!B:B,0),MATCH("거래량스코어",전체_전일자!1:1,0)),"") | Q12: 중립 (C등급) | R12: 21
B13: 2 | C13: 서울보증보험 | D13: 77.4 | E13: 89.3 | F13: 62.4 | G13: 97 | H13: 48.17 | I13: B | K13: =IFERROR(IF(I13=INDEX(전체_전일자!1:1048576,MATCH(C13,전체_전일자!B:B,0),MATCH("등급",전체_전일자!1:1,0)),"유지",INDEX(전체_전일자!1:1048576,MATCH(C13,전체_전일자!B:B,0),MATCH("등급",전체_전일자!1:1,0))&" → "&I13),"") | L13: =IFERROR(D13-INDEX(전체_전일자!1:1048576,MATCH(C13,전체_전일자!B:B,0),MATCH("종합스코어",전체_전일자!1:1,0)),"") | M13: =IFERROR(E13-INDEX(전체_전일자!1:1048576,MATCH(C13,전체_전일자!B:B,0),MATCH("모멘텀스코어",전체_전일자!1:1,0)),"") | N13: =IFERROR(F13-INDEX(전체_전일자!1:1048576,MATCH(C13,전체_전일자!B:B,0),MATCH("수급스코어",전체_전일자!1:1,0)),"") | O13: =IFERROR(G13-INDEX(전체_전일자!1:1048576,MATCH(C13,전체_전일자!B:B,0),MATCH("거래량스코어",전체_전일자!1:1,0)),"") | Q13: 약세 (D+F등급) | R13: 36
B14: 3 | C14: 명인제약 | D14: 70.8 | E14: 89.2 | F14: 64.2 | G14: 59.7 | H14: 45.77 | I14: B | K14: =IFERROR(IF(I14=INDEX(전체_전일자!1:1048576,MATCH(C14,전체_전일자!B:B,0),MATCH("등급",전체_전일자!1:1,0)),"유지",INDEX(전체_전일자!1:1048576,MATCH(C14,전체_전일자!B:B,0),MATCH("등급",전체_전일자!1:1,0))&" → "&I14),"") | L14: =IFERROR(D14-INDEX(전체_전일자!1:1048576,MATCH(C14,전체_전일자!B:B,0),MATCH("종합스코어",전체_전일자!1:1,0)),"") | M14: =IFERROR(E14-INDEX(전체_전일자!1:1048576,MATCH(C14,전체_전일자!B:B,0),MATCH("모멘텀스코어",전체_전일자!1:1,0)),"") | N14: =IFERROR(F14-INDEX(전체_전일자!1:1048576,MATCH(C14,전체_전일자!B:B,0),MATCH("수급스코어",전체_전일자!1:1,0)),"") | O14: =IFERROR(G14-INDEX(전체_전일자!1:1048576,MATCH(C14,전체_전일자!B:B,0),MATCH("거래량스코어",전체_전일자!1:1,0)),"")
B15: 4 | C15: 노머스 | D15: 69.9 | E15: 85.2 | F15: 56.4 | G15: 80.6 | H15: 43.62 | I15: B | K15: =IFERROR(IF(I15=INDEX(전체_전일자!1:1048576,MATCH(C15,전체_전일자!B:B,0),MATCH("등급",전체_전일자!1:1,0)),"유지",INDEX(전체_전일자!1:1048576,MATCH(C15,전체_전일자!B:B,0),MATCH("등급",전체_전일자!1:1,0))&" → "&I15),"") | L15: =IFERROR(D15-INDEX(전체_전일자!1:1048576,MATCH(C15,전체_전일자!B:B,0),MATCH("종합스코어",전체_전일자!1:1,0)),"") | M15: =IFERROR(E15-INDEX(전체_전일자!1:1048576,MATCH(C15,전체_전일자!B:B,0),MATCH("모멘텀스코어",전체_전일자!1:1,0)),"") | N15: =IFERROR(F15-INDEX(전체_전일자!1:1048576,MATCH(C15,전체_전일자!B:B,0),MATCH("수급스코어",전체_전일자!1:1,0)),"") | O15: =IFERROR(G15-INDEX(전체_전일자!1:1048576,MATCH(C15,전체_전일자!B:B,0),MATCH("거래량스코어",전체_전일자!1:1,0)),"")
B16: 5 | C16: 더핑크퐁컴퍼니 | D16: 68.8 | E16: 58.2 | F16: 72.2 | G16: 76.1 | H16: 40.17 | I16: B | K16: =IFERROR(IF(I16=INDEX(전체_전일자!1:1048576,MATCH(C16,전체_전일자!B:B,0),MATCH("등급",전체_전일자!1:1,0)),"유지",INDEX(전체_전일자!1:1048576,MATCH(C16,전체_전일자!B:B,0),MATCH("등급",전체_전일자!1:1,0))&" → "&I16),"") | L16: =IFERROR(D16-INDEX(전체_전일자!1:1048576,MATCH(C16,전체_전일자!B:B,0),MATCH("종합스코어",전체_전일자!1:1,0)),"") | M16: =IFERROR(E16-INDEX(전체_전일자!1:1048576,MATCH(C16,전체_전일자!B:B,0),MATCH("모멘텀스코어",전체_전일자!1:1,0)),"") | N16: =IFERROR(F16-INDEX(전체_전일자!1:1048576,MATCH(C16,전체_전일자!B:B,0),MATCH("수급스코어",전체_전일자!1:1,0)),"") | O16: =IFERROR(G16-INDEX(전체_전일자!1:1048576,MATCH(C16,전체_전일자!B:B,0),MATCH("거래량스코어",전체_전일자!1:1,0)),"")
B17: 6 | C17: 에이유브랜즈 | D17: 65.1 | E17: 97.7 | F17: 53.3 | G17: 45.5 | H17: 56.63 | I17: B | K17: =IFERROR(IF(I17=INDEX(전체_전일자!1:1048576,MATCH(C17,전체_전일자!B:B,0),MATCH("등급",전체_전일자!1:1,0)),"유지",INDEX(전체_전일자!1:1048576,MATCH(C17,전체_전일자!B:B,0),MATCH("등급",전체_전일자!1:1,0))&" → "&I17),"") | L17: =IFERROR(D17-INDEX(전체_전일자!1:1048576,MATCH(C17,전체_전일자!B:B,0),MATCH("종합스코어",전체_전일자!1:1,0)),"") | M17: =IFERROR(E17-INDEX(전체_전일자!1:1048576,MATCH(C17,전체_전일자!B:B,0),MATCH("모멘텀스코어",전체_전일자!1:1,0)),"") | N17: =IFERROR(F17-INDEX(전체_전일자!1:1048576,MATCH(C17,전체_전일자!B:B,0),MATCH("수급스코어",전체_전일자!1:1,0)),"") | O17: =IFERROR(G17-INDEX(전체_전일자!1:1048576,MATCH(C17,전체_전일자!B:B,0),MATCH("거래량스코어",전체_전일자!1:1,0)),"")
B18: 7 | C18: LG씨엔에스 | D18: 63.8 | E18: 49.1 | F18: 66.5 | G18: 79.1 | H18: 37.64 | I18: C | K18: =IFERROR(IF(I18=INDEX(전체_전일자!1:1048576,MATCH(C18,전체_전일자!B:B,0),MATCH("등급",전체_전일자!1:1,0)),"유지",INDEX(전체_전일자!1:1048576,MATCH(C18,전체_전일자!B:B,0),MATCH("등급",전체_전일자!1:1,0))&" → "&I18),"") | L18: =IFERROR(D18-INDEX(전체_전일자!1:1048576,MATCH(C18,전체_전일자!B:B,0),MATCH("종합스코어",전체_전일자!1:1,0)),"") | M18: =IFERROR(E18-INDEX(전체_전일자!1:1048576,MATCH(C18,전체_전일자!B:B,0),MATCH("모멘텀스코어",전체_전일자!1:1,0)),"") | N18: =IFERROR(F18-INDEX(전체_전일자!1:1048576,MATCH(C18,전체_전일자!B:B,0),MATCH("수급스코어",전체_전일자!1:1,0)),"") | O18: =IFERROR(G18-INDEX(전체_전일자!1:1048576,MATCH(C18,전체_전일자!B:B,0),MATCH("거래량스코어",전체_전일자!1:1,0)),"")
B19: 8 | C19: 클로봇 | D19: 60.3 | E19: 32.6 | F19: 88.5 | G19: 31.3 | H19: 31.03 | I19: C | K19: =IFERROR(IF(I19=INDEX(전체_전일자!1:1048576,MATCH(C19,전체_전일자!B:B,0),MATCH("등급",전체_전일자!1:1,0)),"유지",INDEX(전체_전일자!1:1048576,MATCH(C19,전체_전일자!B:B,0),MATCH("등급",전체_전일자!1:1,0))&" → "&I19),"") | L19: =IFERROR(D19-INDEX(전체_전일자!1:1048576,MATCH(C19,전체_전일자!B:B,0),MATCH("종합스코어",전체_전일자!1:1,0)),"") | M19: =IFERROR(E19-INDEX(전체_전일자!1:1048576,MATCH(C19,전체_전일자!B:B,0),MATCH("모멘텀스코어",전체_전일자!1:1,0)),"") | N19: =IFERROR(F19-INDEX(전체_전일자!1:1048576,MATCH(C19,전체_전일자!B:B,0),MATCH("수급스코어",전체_전일자!1:1,0)),"") | O19: =IFERROR(G19-INDEX(전체_전일자!1:1048576,MATCH(C19,전체_전일자!B:B,0),MATCH("거래량스코어",전체_전일자!1:1,0)),"")
B20: 9 | C20: 동방메디컬 | D20: 59.8 | E20: 85 | F20: 53.6 | G20: 37.3 | H20: 45.77 | I20: C | K20: =IFERROR(IF(I20=INDEX(전체_전일자!1:1048576,MATCH(C20,전체_전일자!B:B,0),MATCH("등급",전체_전일자!1:1,0)),"유지",INDEX(전체_전일자!1:1048576,MATCH(C20,전체_전일자!B:B,0),MATCH("등급",전체_전일자!1:1,0))&" → "&I20),"") | L20: =IFERROR(D20-INDEX(전체_전일자!1:1048576,MATCH(C20,전체_전일자!B:B,0),MATCH("종합스코어",전체_전일자!1:1,0)),"") | M20: =IFERROR(E20-INDEX(전체_전일자!1:1048576,MATCH(C20,전체_전일자!B:B,0),MATCH("모멘텀스코어",전체_전일자!1:1,0)),"") | N20: =IFERROR(F20-INDEX(전체_전일자!1:1048576,MATCH(C20,전체_전일자!B:B,0),MATCH("수급스코어",전체_전일자!1:1,0)),"") | O20: =IFERROR(G20-INDEX(전체_전일자!1:1048576,MATCH(C20,전체_전일자!B:B,0),MATCH("거래량스코어",전체_전일자!1:1,0)),"")
B21: 10 | C21: 세나테크놀로지 | D21: 59.5 | E21: 87.1 | F21: 60.7 | G21: 14.9 | H21: 48.72 | I21: C | K21: =IFERROR(IF(I21=INDEX(전체_전일자!1:1048576,MATCH(C21,전체_전일자!B:B,0),MATCH("등급",전체_전일자!1:1,0)),"유지",INDEX(전체_전일자!1:1048576,MATCH(C21,전체_전일자!B:B,0),MATCH("등급",전체_전일자!1:1,0))&" → "&I21),"") | L21: =IFERROR(D21-INDEX(전체_전일자!1:1048576,MATCH(C21,전체_전일자!B:B,0),MATCH("종합스코어",전체_전일자!1:1,0)),"") | M21: =IFERROR(E21-INDEX(전체_전일자!1:1048576,MATCH(C21,전체_전일자!B:B,0),MATCH("모멘텀스코어",전체_전일자!1:1,0)),"") | N21: =IFERROR(F21-INDEX(전체_전일자!1:1048576,MATCH(C21,전체_전일자!B:B,0),MATCH("수급스코어",전체_전일자!1:1,0)),"") | O21: =IFERROR(G21-INDEX(전체_전일자!1:1048576,MATCH(C21,전체_전일자!B:B,0),MATCH("거래량스코어",전체_전일자!1:1,0)),"")
B22: 11 | C22: 달바글로벌 | D22: 58.9 | E22: 64.6 | F22: 62.9 | G22: 40.3 | H22: 50.19 | I22: C | K22: =IFERROR(IF(I22=INDEX(전체_전일자!1:1048576,MATCH(C22,전체_전일자!B:B,0),MATCH("등급",전체_전일자!1:1,0)),"유지",INDEX(전체_전일자!1:1048576,MATCH(C22,전체_전일자!B:B,0),MATCH("등급",전체_전일자!1:1,0))&" → "&I22),"") | L22: =IFERROR(D22-INDEX(전체_전일자!1:1048576,MATCH(C22,전체_전일자!B:B,0),MATCH("종합스코어",전체_전일자!1:1,0)),"") | M22: =IFERROR(E22-INDEX(전체_전일자!1:1048576,MATCH(C22,전체_전일자!B:B,0),MATCH("모멘텀스코어",전체_전일자!1:1,0)),"") | N22: =IFERROR(F22-INDEX(전체_전일자!1:1048576,MATCH(C22,전체_전일자!B:B,0),MATCH("수급스코어",전체_전일자!1:1,0)),"") | O22: =IFERROR(G22-INDEX(전체_전일자!1:1048576,MATCH(C22,전체_전일자!B:B,0),MATCH("거래량스코어",전체_전일자!1:1,0)),"")
B23: 12 | C23: 온코닉테라퓨틱스 | D23: 57.1 | E23: 23.3 | F23: 62.6 | G23: 94 | H23: 26.14 | I23: C | K23: =IFERROR(IF(I23=INDEX(전체_전일자!1:1048576,MATCH(C23,전체_전일자!B:B,0),MATCH("등급",전체_전일자!1:1,0)),"유지",INDEX(전체_전일자!1:1048576,MATCH(C23,전체_전일자!B:B,0),MATCH("등급",전체_전일자!1:1,0))&" → "&I23),"") | L23: =IFERROR(D23-INDEX(전체_전일자!1:1048576,MATCH(C23,전체_전일자!B:B,0),MATCH("종합스코어",전체_전일자!1:1,0)),"") | M23: =IFERROR(E23-INDEX(전체_전일자!1:1048576,MATCH(C23,전체_전일자!B:B,0),MATCH("모멘텀스코어",전체_전일자!1:1,0)),"") | N23: =IFERROR(F23-INDEX(전체_전일자!1:1048576,MATCH(C23,전체_전일자!B:B,0),MATCH("수급스코어",전체_전일자!1:1,0)),"") | O23: =IFERROR(G23-INDEX(전체_전일자!1:1048576,MATCH(C23,전체_전일자!B:B,0),MATCH("거래량스코어",전체_전일자!1:1,0)),"")
B24: 13 | C24: 그래피 | D24: 56.1 | E24: 85.8 | F24: 21.3 | G24: 98.5 | H24: 46.03 | I24: C | K24: =IFERROR(IF(I24=INDEX(전체_전일자!1:1048576,MATCH(C24,전체_전일자!B:B,0),MATCH("등급",전체_전일자!1:1,0)),"유지",INDEX(전체_전일자!1:1048576,MATCH(C24,전체_전일자!B:B,0),MATCH("등급",전체_전일자!1:1,0))&" → "&I24),"") | L24: =IFERROR(D24-INDEX(전체_전일자!1:1048576,MATCH(C24,전체_전일자!B:B,0),MATCH("종합스코어",전체_전일자!1:1,0)),"") | M24: =IFERROR(E24-INDEX(전체_전일자!1:1048576,MATCH(C24,전체_전일자!B:B,0),MATCH("모멘텀스코어",전체_전일자!1:1,0)),"") | N24: =IFERROR(F24-INDEX(전체_전일자!1:1048576,MATCH(C24,전체_전일자!B:B,0),MATCH("수급스코어",전체_전일자!1:1,0)),"") | O24: =IFERROR(G24-INDEX(전체_전일자!1:1048576,MATCH(C24,전체_전일자!B:B,0),MATCH("거래량스코어",전체_전일자!1:1,0)),"")
B25: 14 | C25: 넥스트바이오메디컬 | D25: 56 | E25: 64.7 | F25: 50.5 | G25: 56.7 | H25: 43.82 | I25: C | K25: =IFERROR(IF(I25=INDEX(전체_전일자!1:1048576,MATCH(C25,전체_전일자!B:B,0),MATCH("등급",전체_전일자!1:1,0)),"유지",INDEX(전체_전일자!1:1048576,MATCH(C25,전체_전일자!B:B,0),MATCH("등급",전체_전일자!1:1,0))&" → "&I25),"") | L25: =IFERROR(D25-INDEX(전체_전일자!1:1048576,MATCH(C25,전체_전일자!B:B,0),MATCH("종합스코어",전체_전일자!1:1,0)),"") | M25: =IFERROR(E25-INDEX(전체_전일자!1:1048576,MATCH(C25,전체_전일자!B:B,0),MATCH("모멘텀스코어",전체_전일자!1:1,0)),"") | N25: =IFERROR(F25-INDEX(전체_전일자!1:1048576,MATCH(C25,전체_전일자!B:B,0),MATCH("수급스코어",전체_전일자!1:1,0)),"") | O25: =IFERROR(G25-INDEX(전체_전일자!1:1048576,MATCH(C25,전체_전일자!B:B,0),MATCH("거래량스코어",전체_전일자!1:1,0)),"")
... B38: 27 | C38: 한라캐스트 | D38: 50.1 | E38: 13.2 | F38: 75 | G38: 43.3 | H38: 27.98 | I38: C | K38: =IFERROR(IF(I38=INDEX(전체_전일자!1:1048576,MATCH(C38,전체_전일자!B:B,0),MATCH("등급",전체_전일자!1:1,0)),"유지",INDEX(전체_전일자!1:1048576,MATCH(C38,전체_전일자!B:B,0),MATCH("등급",전체_전일자!1:1,0))&" → "&I38),"") | L38: =IFERROR(D38-INDEX(전체_전일자!1:1048576,MATCH(C38,전체_전일자!B:B,0),MATCH("종합스코어",전체_전일자!1:1,0)),"") | M38: =IFERROR(E38-INDEX(전체_전일자!1:1048576,MATCH(C38,전체_전일자!B:B,0),MATCH("모멘텀스코어",전체_전일자!1:1,0)),"") | N38: =IFERROR(F38-INDEX(전체_전일자!1:1048576,MATCH(C38,전체_전일자!B:B,0),MATCH("수급스코어",전체_전일자!1:1,0)),"") | O38: =IFERROR(G38-INDEX(전체_전일자!1:1048576,MATCH(C38,전체_전일자!B:B,0),MATCH("거래량스코어",전체_전일자!1:1,0)),"")

Sheet 추천종목
A1: 코드 | B1: 코드명 | C1: 상장일 | D1: 현재가 | E1: 거래대금(억) | F1: 종합스코어 | G1: 모멘텀스코어 | H1: 수급스코어 | I1: 거래량스코어 | J1: RSI변화량 | K1: RSI(14) | L1: 전일RSI(14) | M1: RVOL(20) | N1: 기관_일간 | O1: 외국인_일간 | P1: 10일선돌파 | Q1: 20일선돌파 | R1: 60일선돌파 | S1: 변동성(30D) | T1: BB폭
A2: A415640 | B2: KB발해인프라 | D2: 10740 | E2: 16.6 | F2: 78.1 | G2: 90.7 | H2: 75.6 | I2: 65.7 | J2: -14.7 | K2: 64.08 | L2: 78.73 | M2: 0.9 | N2: 13.8 | O2: 30.6 | P2: 1 | Q2: 1 | R2: 1 | S2: 2.01 | T2: 1294.1
A3: A031210 | B3: 서울보증보험 | D3: 42800 | E3: 30.5 | F3: 77.4 | G3: 89.3 | H3: 62.4 | I3: 97 | J3: -3.8 | K3: 48.17 | L3: 51.98 | M3: 1.56 | N3: 4.3 | O3: -2.7 | P3: 1 | Q3: 0 | R3: 0 | S3: 2.56 | T3: 7369.64
A4: A317450 | B4: 명인제약 | D4: 43000 | E4: 8.4 | F4: 70.8 | G4: 89.2 | H4: 64.2 | I4: 59.7 | J4: -2.7 | K4: 45.77 | L4: 48.51 | M4: 0.87 | N4: 5.5 | O4: 5.7 | P4: 1 | Q4: 1 | R4: 0 | S4: 3.03 | T4: 5280.95
A5: A473980 | B5: 노머스 | D5: 11140 | E5: 9.9 | F5: 69.9 | G5: 85.2 | H5: 56.4 | I5: 80.6 | J5: 2.2 | K5: 43.62 | L5: 41.44 | M5: 1.09 | N5: 62.4 | O5: -33.4 | P5: 1 | Q5: 0 | R5: 0 | S5: 5.86 | T5: 5317.84
A6: A403850 | B6: 더핑크퐁컴퍼니 | D6: 10440 | E6: 8.8 | F6: 68.8 | G6: 58.2 | H6: 72.2 | I6: 76.1 | J6: -3.3 | K6: 40.17 | L6: 43.51 | M6: 1.04 | N6: 7.5 | O6: -9.8 | P6: 0 | Q6: 0 | R6: 0 | S6: 4.43 | T6: 2498.55
A7: A481070 | B7: 에이유브랜즈 | D7: 15070 | E7: 2.9 | F7: 65.1 | G7: 97.7 | H7: 53.3 | I7: 45.5 | J7: 3.5 | K7: 56.63 | L7: 53.11 | M7: 0.75 | N7: 2 | O7: 0 | P7: 1 | Q7: 1 | R7: 0 | S7: 5.55 | T7: 3623.37
A8: A064400 | B8: LG씨엔에스 | D8: 71200 | E8: 1032.1 | F8: 63.8 | G8: 49.1 | H8: 66.5 | I8: 79.1 | J8: -2.2 | K8: 37.64 | L8: 39.89 | M8: 1.07 | N8: 358.4 | O8: -1083.9 | P8: 0 | Q8: 0 | R8: 0 | S8: 9.16 | T8: 31612.81
A9: A466100 | B9: 클로봇 | D9: 24500 | E9: 33 | F9: 60.3 | G9: 32.6 | H9: 88.5 | I9: 31.3 | J9: -3 | K9: 31.03 | L9: 34.06 | M9: 0.6 | N9: 21 | O9: 59.8 | P9: 0 | Q9: 0 | R9: 0 | S9: 5.79 | T9: 13029.9
A10: A240550 | B10: 동방메디컬 | D10: 5700 | E10: 3.8 | F10: 59.8 | G10: 85 | H10: 53.6 | I10: 37.3 | J10: -3.8 | K10: 45.77 | L10: 49.52 | M10: 0.62 | N10: 0.1 | O10: -1.4 | P10: 1 | Q10: 1 | R10: 0 | S10: 4.57 | T10: 1536.24
A11: A061090 | B11: 세나테크놀로지 | D11: 36300 | E11: 5.1 | F11: 59.5 | G11: 87.1 | H11: 60.7 | I11: 14.9 | J11: -0.6 | K11: 48.72 | L11: 49.27 | M11: 0.52 | N11: 5.1 | O11: 2.7 | P11: 1 | Q11: 1 | R11: 0 | S11: 6.43 | T11: 18216.26
A12: A483650 | B12: 달바글로벌 | D12: 217500 | E12: 286 | F12: 58.9 | G12: 64.6 | H12: 62.9 | I12: 40.3 | J12: -5.6 | K12: 50.19 | L12: 55.81 | M12: 0.67 | N12: 267.6 | O12: -76.4 | P12: 0 | Q12: 1 | R12: 1 | S12: 4.83 | T12: 58996.74
A13: A476060 | B13: 온코닉테라퓨틱스 | D13: 10970 | E13: 38.8 | F13: 57.1 | G13: 23.3 | H13: 62.6 | I13: 94 | J13: -2.5 | K13: 26.14 | L13: 28.6 | M13: 1.38 | N13: -1 | O13: 123.1 | P13: 0 | Q13: 0 | R13: 0 | S13: 4.51 | T13: 6825.27
... A51: A079900 | B51: 전진건설로봇 | D51: 34500 | E51: 19.4 | F51: 37.2 | G51: 15.9 | H51: 48.1 | I51: 41.8 | J51: -3.6 | K51: 27.04 | L51: 30.65 | M51: 0.7 | N51: 0 | O51: 23.3 | P51: 0 | Q51: 0 | R51: 0 | S51: 5.61 | T51: 33298.16

Sheet 전체
A1: 코드 | B1: 코드명 | C1: 상장일 | D1: days_since_ipo | E1: 기관_일간 | F1: 기관_5일 | G1: 기관_20일 | H1: 외국인_일간 | I1: 외국인_5일 | J1: 외국인_20일 | K1: 현재가 | L1: 거래량 | M1: 거래대금(억) | N1: 20일평균거래량 | O1: RVOL(20) | P1: 변동성(30D) | Q1: RSI(14) | R1: 전일RSI(14) | S1: RSI변화량 | T1: 1일수익률(%) | U1: 20일수익률(%) | V1: 10일이평 | W1: 20일이평 | X1: 60일이평 | Y1: 10일선돌파 | Z1: 20일선돌파 | AA1: 60일선돌파 | AB1: BB폭 | AC1: 시가총액(억) | AD1: 모멘텀스코어 | AE1: 수급스코어 | AF1: 거래량스코어 | AG1: 종합스코어 | AH1: 등급
A2: A062040 | B2: 산일전기 | E2: -1112.6 | F2: -1875.2 | G2: 6834.9 | H2: 1784.4 | I2: -1823.4 | J2: -7952.4 | K2: 178200 | L2: 448109 | M2: 798.5 | N2: 335915.95 | O2: 1.33 | P2: 5.3 | Q2: 34.5 | R2: 37.88 | S2: -3.4 | T2: -7.86 | U2: -18.44 | V2: 220260 | W2: 227730 | X2: 239516.67 | Y2: 0 | Z2: 0 | AA2: 0 | AB2: 79993.71 | AC2: 54557 | AD2: 34.9 | AE2: 33.2 | AF2: 91 | AG2: 45.3 | AH2: D
A3: A079900 | B3: 전진건설로봇 | E3: 0 | F3: -42.3 | G3: -259.3 | H3: 23.3 | I3: -36.6 | J3: 193.8 | K3: 34500 | L3: 56106 | M3: 19.4 | N3: 79685.1 | O3: 0.7 | P3: 5.61 | Q3: 27.04 | R3: 30.65 | S3: -3.6 | T3: -8.12 | U3: -32.22 | V3: 37980 | W3: 44887.5 | X3: 56283.333 | Y3: 0 | Z3: 0 | AA3: 0 | AB3: 33298.16 | AC3: 5034 | AD3: 15.9 | AE3: 48.1 | AF3: 41.8 | AG3: 37.2 | AH3: D
A4: A389650 | B4: 넥스트바이오메디컬 | E4: 9.6 | F4: 91 | G4: 507.1 | H4: -72.2 | I4: -136 | J4: -366.8 | K4: 39350 | L4: 47422 | M4: 18.7 | N4: 57273.75 | O4: 0.83 | P4: 6.72 | Q4: 43.82 | R4: 47.2 | S4: -3.4 | T4: -4.72 | U4: 1.16 | V4: 40515 | W4: 40890 | X4: 49555.833 | Y4: 0 | Z4: 0 | AA4: 0 | AB4: 6680.6 | AC4: 3257 | AD4: 64.7 | AE4: 50.5 | AF4: 56.7 | AG4: 56 | AH4: C
A5: A461300 | B5: 아이스크림미디어 | E5: -7.9 | F5: -7.1 | G5: -431 | H5: 12.1 | I5: 9.6 | J5: 217 | K5: 16390 | L5: 22893 | M5: 3.8 | N5: 52305.3 | O5: 0.44 | P5: 2.91 | Q5: 48.05 | R5: 46.08 | S5: 2 | T5: 1.11 | U5: 0.92 | V5: 16392 | W5: 16519.5 | X5: 16888 | Y5: 0 | Z5: 0 | AA5: 0 | AB5: 1703.38 | AC5: 2184 | AD5: 73.6 | AE5: 48.1 | AF5: 9.7 | AG5: 48.1 | AH5: D
A6: A308430 | B6: 셀비온 | E6: 0.3 | F6: 8.6 | G6: 137.1 | H6: 5.8 | I6: -16.6 | J6: -140.7 | K6: 14800 | L6: 34823 | M6: 5.2 | N6: 37476.4 | O6: 0.93 | P6: 4.63 | Q6: 31.1 | R6: 35.28 | S6: -4.2 | T6: -7.5 | U6: -16.29 | V6: 16399 | W6: 16927.5 | X6: 24685 | Y6: 0 | Z6: 0 | AA6: 0 | AB6: 4052.83 | AC6: 1910 | AD6: 35.2 | AE6: 57.9 | AF6: 67.2 | AG6: 53 | AH6: C
A7: A474170 | B7: 루미르 | E7: -0.6 | F7: -1 | G7: -38.1 | H7: 8.3 | I7: 20.7 | J7: 165.3 | K7: 6500 | L7: 66052 | M7: 4.3 | N7: 153335 | O7: 0.43 | P7: 4.33 | Q7: 26.34 | R7: 28.81 | S7: -2.5 | T7: -6.47 | U7: -36.27 | V7: 7317 | W7: 8182.5 | X7: 11865.5 | Y7: 0 | Z7: 0 | AA7: 0 | AB7: 4319.89 | AC7: 1158 | AD7: 17 | AE7: 56.2 | AF7: 7.5 | AG7: 34.7 | AH7: D
A8: A475400 | B8: 씨메스 | E8: -9.6 | F8: -66 | G8: -28.1 | H8: 25.1 | I8: 65.6 | J8: 123.3 | K8: 16030 | L8: 42936 | M8: 6.9 | N8: 48247.1 | O8: 0.89 | P8: 5.4 | Q8: 29.68 | R8: 31.43 | S8: -1.8 | T8: -4.81 | U8: -33.35 | V8: 18411 | W8: 20716 | X8: 27206.167 | Y8: 0 | Z8: 0 | AA8: 0 | AB8: 11943.44 | AC8: 1893 | AD8: 30.8 | AE8: 50 | AF8: 63.4 | AG8: 46.9 | AH8: D
A9: A466100 | B9: 클로봇 | E9: 21 | F9: 90.5 | G9: 357.2 | H9: 59.8 | I9: 185.6 | J9: 1217 | K9: 24500 | L9: 134601 | M9: 33 | N9: 224691.35 | O9: 0.6 | P9: 5.79 | Q9: 31.03 | R9: 34.06 | S9: -3 | T9: -7.2 | U9: -23.25 | V9: 27889 | W9: 30522.5 | X9: 38978.683 | Y9: 0 | Z9: 0 | AA9: 0 | AB9: 13029.9 | AC9: 6238 | AD9: 32.6 | AE9: 88.5 | AF9: 31.3 | AG9: 60.3 | AH9: C
A10: A458650 | B10: 성우 | E10: 0 | F10: 0.7 | G10: 18.9 | H10: -3 | I10: -4.6 | J10: 15.3 | K10: 7870 | L10: 18689 | M10: 1.5 | N10: 30720.2 | O10: 0.61 | P10: 3.98 | Q10: 29.11 | R10: 32.16 | S10: -3 | T10: -5.52 | U10: -26.45 | V10: 8506 | W10: 9403 | X10: 11830.333 | Y10: 0 | Z10: 0 | AA10: 0 | AB10: 4705.25 | AC10: 1184 | AD10: 33.7 | AE10: 51.4 | AF10: 35.1 | AG10: 42.8 | AH10: D
A11: A336680 | B11: 탑런토탈솔루션 | E11: 0 | F11: 0 | G11: 0 | H11: 1.2 | I11: 8.9 | J11: 3.9 | K11: 2620 | L11: 11431 | M11: 0.3 | N11: 20863.55 | O11: 0.55 | P11: 2.56 | Q11: 30.99 | R11: 34.3 | S11: -3.3 | T11: -2.96 | U11: -12.67 | V11: 2722.5 | W11: 2822.25 | X11: 3354.9167 | Y11: 0 | Z11: 0 | AA11: 0 | AB11: 592.27 | AC11: 1026 | AD11: 50.9 | AE11: 53.5 | AF11: 22.4 | AG11: 46.5 | AH11: D
A12: A376270 | B12: HEM파마 | E12: -7.2 | F12: 0 | G12: 24.4 | H12: 2.9 | I12: -42.7 | J12: -69.8 | K12: 40200 | L12: 17695 | M12: 7.1 | N12: 15617.4 | O12: 1.13 | P12: 5.26 | Q12: 37.17 | R12: 40.73 | S12: -3.6 | T12: -5.41 | U12: -6.07 | V12: 43015 | W12: 45195 | X12: 53802.5 | Y12: 0 | Z12: 0 | AA12: 0 | AB12: 13997.99 | AC12: 2896 | AD12: 53.6 | AE12: 43.6 | AF12: 83.6 | AG12: 54.6 | AH12: C
A13: A475560 | B13: 더본코리아 | E13: -0.1 | F13: -1.3 | G13: 14.6 | H13: 1.6 | I13: 6.7 | J13: 19.8 | K13: 14650 | L13: 11430 | M13: 1.7 | N13: 18638.8 | O13: 0.61 | P13: 3.06 | Q13: 40.07 | R13: 44.01 | S13: -3.9 | T13: -3.11 | U13: -6.69 | V13: 14662 | W13: 15141 | X13: 17885.333 | Y13: 0 | Z13: 0 | AA13: 0 | AB13: 2612.03 | AC13: 2172 | AD13: 60.9 | AE13: 51.6 | AF13: 35.1 | AG13: 51.1 | AH13: C
... A45: A439260 | B45: 대한조선 | E45: -102.7 | F45: -124.2 | G45: -76.1 | H45: 95.4 | I45: 292.7 | J45: 124.9 | K45: 47650 | L45: 101875 | M45: 48.5 | N45: 81034.4 | O45: 1.26 | P45: 3.53 | Q45: 29.06 | R45: 33.04 | S45: -4 | T45: -6.2 | U45: -22.01 | V45: 51705 | W45: 56117.5 | X45: 70575.833 | Y45: 0 | Z45: 0 | AA45: 0 | AB45: 21248.56 | AC45: 18149 | AD45: 35 | AE45: 49.1 | AF45: 86.6 | AG45: 52.4 | AH45: C
A46: A309710 | B46: 아이티켐 | E46: 0 | F46: 0 | G46: 0 | H46: 0 | I46: 0 | J46: 0 | K46: 21000 | L46: 0 | M46: 0 | N46: 0 | P46: 0 | Q46: 17.73 | R46: 17.73 | S46: 0 | T46: 0 | U46: 0 | V46: 21000 | W46: 21000 | X46: 21000 | Y46: 0 | Z46: 0 | AA46: 0 | AB46: 0 | AC46: 2684 | AD46: 55.1 | AE46: 50.6 | AH46: -
A47: A456160 | B47: 지투지바이오 | E47: -163 | F47: -417.9 | G47: -1244.2 | H47: 183.3 | I47: -82.3 | J47: 971.7 | K47: 32050 | L47: 178455 | M47: 57.2 | N47: 189052.6 | O47: 0.94 | P47: 6.92 | Q47: 30.46 | R47: 33.85 | S47: -3.4 | T47: -9.72 | U47: -31.37 | V47: 38460 | W47: 41295 | X47: 59241.667 | Y47: 0 | Z47: 0 | AA47: 0 | AB47: 18059.56 | AC47: 5330 | AD47: 16 | AE47: 37.2 | AF47: 69.4 | AG47: 37.3 | AH47: D
A48: A484590 | B48: 삼양컴텍 | E48: -13.3 | F48: 1.5 | G48: -166.8 | H48: -30.1 | I48: -155.6 | J48: -220.8 | K48: 5920 | L48: 362343 | M48: 21.5 | N48: 460454.2 | O48: 0.79 | P48: 6.06 | Q48: 32.8 | R48: 36.1 | S48: -3.3 | T48: -8.5 | U48: -19.35 | V48: 6913 | W48: 7645.5 | X48: 9779.6667 | Y48: 0 | Z48: 0 | AA48: 0 | AB48: 3950.28 | AC48: 2440 | AD48: 30.9 | AE48: 27.4 | AF48: 53.7 | AG48: 33.7 | AH48: D
A49: A125490 | B49: 한라캐스트 | E49: 9.4 | F49: 11.6 | G49: 1343.2 | H49: 67.1 | I49: 68 | J49: -1076.3 | K49: 7520 | L49: 551991 | M49: 41.5 | N49: 744089.7 | O49: 0.74 | P49: 5.54 | Q49: 27.98 | R49: 30.87 | S49: -2.9 | T49: -8.29 | U49: -35.78 | V49: 8644 | W49: 10012 | X49: 13450.833 | Y49: 0 | Z49: 0 | AA49: 0 | AB49: 6999.5 | AC49: 2745 | AD49: 13.2 | AE49: 75 | AF49: 43.3 | AG49: 50.1 | AH49: C
A50: A318060 | B50: 그래피 | E50: -35.7 | F50: -28.2 | G50: 29.5 | H50: -129.7 | I50: -154.3 | J50: -96.1 | K50: 19030 | L50: 303340 | M50: 57.7 | N50: 114013.8 | O50: 2.66 | P50: 5.75 | Q50: 46.03 | R50: 41.82 | S50: 4.2 | T50: 5.43 | U50: -12.91 | V50: 16941 | W50: 18697.5 | X50: 26665.833 | Y50: 1 | Z50: 1 | AA50: 0 | AB50: 9578.32 | AC50: 2126 | AD50: 85.8 | AE50: 21.3 | AF50: 98.5 | AG50: 56.1 | AH50: C
A51: A488280 | B51: 에스투더블유 | E51: -1.8 | F51: -10 | G51: -66.7 | H51: 10.1 | I51: 18.9 | J51: 136.7 | K51: 9500 | L51: 64274 | M51: 6.1 | N51: 111840.7 | O51: 0.57 | P51: 6.82 | Q51: 29.67 | R51: 31.67 | S51: -2 | T51: -7.59 | U51: -35.59 | V51: 11131 | W51: 13108.5 | X51: 19114.833 | Y51: 0 | Z51: 0 | AA51: 0 | AB51: 8702.44 | AC51: 1026 | AD51: 18.8 | AE51: 51.8 | AF51: 23.9 | AG51: 36.3 | AH51: D
A52: A317450 | B52: 명인제약 | E52: 5.5 | F52: 4.4 | G52: -544.4 | H52: 5.7 | I52: 25.7 | J52: 384 | K52: 43000 | L52: 19595 | M52: 8.4 | N52: 22644.6 | O52: 0.87 | P52: 3.03 | Q52: 45.77 | R52: 48.51 | S52: -2.7 | T52: -1.83 | U52: -1.71 | V52: 42270 | W52: 42865 | X52: 49010 | Y52: 1 | Z52: 1 | AA52: 0 | AB52: 5280.95 | AC52: 6278 | AD52: 89.2 | AE52: 64.2 | AF52: 59.7 | AG52: 70.8 | AH52: B
A53: A486990 | B53: 노타 | E53: -23.1 | F53: -36.3 | G53: -909.8 | H53: 33.7 | I53: -275 | J53: -8 | K53: 18030 | L53: 162729 | M53: 29.3 | N53: 211080.2 | O53: 0.77 | P53: 8.56 | Q53: 31.51 | R53: 34.59 | S53: -3.1 | T53: -8.1 | U53: -33.22 | V53: 20550 | W53: 22857.5 | X53: 29485 | Y53: 0 | Z53: 0 | AA53: 0 | AB53: 11411.19 | AC53: 3849 | AD53: 21.7 | AE53: 30.8 | AF53: 50 | AG53: 31.9 | AH53: D
A54: A469610 | B54: 이노테크 | E54: 5.7 | F54: -24.9 | G54: -41.7 | H54: 2.7 | I54: -17.3 | J54: -29.8 | K54: 13320 | L54: 110845 | M54: 14.8 | N54: 192666.45 | O54: 0.58 | P54: 9.37 | Q54: 40.98 | R54: 42.36 | S54: -1.4 | T54: -3.48 | U54: -3.34 | V54: 14529 | W54: 15279 | X54: 19460.5 | Y54: 0 | Z54: 0 | AA54: 0 | AB54: 7347.64 | AC54: 1191 | AD54: 62 | AE54: 48 | AF54: 26.1 | AG54: 47.8 | AH54: D
A55: A494120 | B55: 큐리오시스 | E55: 41.4 | F55: 164.4 | G55: 621.4 | H55: -55.5 | I55: 20.2 | J55: -490.5 | K55: 25300 | L55: 91126 | M55: 23.1 | N55: 117584.25 | O55: 0.77 | P55: 8.62 | Q55: 42.5 | R55: 46.86 | S55: -4.4 | T55: -8.99 | U55: -2.32 | V55: 25535 | W55: 26500 | X55: 39723.333 | Y55: 0 | Z55: 0 | AA55: 0 | AB55: 9129.51 | AC55: 1930 | AD55: 44.8 | AE55: 62.9 | AF55: 50 | AG55: 54.9 | AH55: C
A56: A061090 | B56: 세나테크놀로지 | E56: 5.1 | F56: 45.9 | G56: -60.9 | H56: 2.7 | I56: 9.4 | J56: -14.6 | K56: 36300 | L56: 14031 | M56: 5.1 | N56: 27038 | O56: 0.52 | P56: 6.43 | Q56: 48.72 | R56: 49.27 | S56: -0.6 | T56: -0.68 | U56: -10.92 | V56: 33020 | W56: 35200 | X56: 40982.5 | Y56: 1 | Z56: 1 | AA56: 0 | AB56: 18216.26 | AC56: 1985 | AD56: 87.1 | AE56: 60.7 | AF56: 14.9 | AG56: 59.5 | AH56: C
A57: A403850 | B57: 더핑크퐁컴퍼니 | E57: 7.5 | F57: 50.2 | G57: 47.3 | H57: -9.8 | I57: 296.8 | J57: 305.7 | K57: 10440 | L57: 83824 | M57: 8.8 | N57: 80950.6 | O57: 1.04 | P57: 4.43 | Q57: 40.17 | R57: 43.51 | S57: -3.3 | T57: -4.04 | U57: -8.66 | V57: 10751 | W57: 11103 | X57: 13629.833 | Y57: 0 | Z57: 0 | AA57: 0 | AB57: 2498.55 | AC57: 1498 | AD57: 58.2 | AE57: 72.2 | AF57: 76.1 | AG57: 68.8 | AH57: B
A58: A388210 | B58: 씨엠티엑스 | E58: -28.5 | F58: -401.8 | G58: -307.6 | H58: 264.7 | I58: 348.2 | J58: -73.4 | K58: 68900 | L58: 94674 | M58: 65.2 | N58: 72931.8 | O58: 1.3 | P58: 6.27 | Q58: 27 | R58: 30.59 | S58: -3.6 | T58: -10.17 | U58: -35 | V58: 86520 | W58: 96430 | X58: 118125 | Y58: 0 | Z58: 0 | AA58: 0 | AB58: 51014.52 | AC58: 6652 | AD58: 7.3 | AE58: 46.7 | AF58: 89.6 | AG58: 43.5 | AH58: D
... A65: A279570 | B65: 케이뱅크 | E65: -20 | F65: 140.1 | G65: 8819.9 | H65: -61 | I65: -266.1 | J65: 533.5 | K65: 5320 | L65: 1181560 | M65: 62.9 | N65: 4933440.7 | O65: 0.24 | P65: 3.94 | Q65: 36.75 | R65: 39.38 | S65: -2.6 | T65: -2.74 | U65: -11.77 | V65: 5629 | W65: 6108.5 | X65: 5981.8333 | Y65: 0 | Z65: 0 | AA65: 0 | AB65: 2341.15 | AC65: 21583 | AD65: 57.5 | AE65: 46 | AF65: 3 | AG65: 40.8 | AH65: D
A66: A493280 | B66: 아이엠바이오로직스 | K66: 20500 | L66: 140804 | M66: 28.9 | N66: 105114 | O66: 1.34 | P66: 6.73 | Q66: 33.12 | R66: 35.07 | S66: -2 | T66: -5.75 | U66: -22.79 | V66: 21760 | W66: 23500 | X66: 36680.833 | Y66: 0 | Z66: 0 | AA66: 0 | AB66: 10266.84 | AC66: 3041 | AD66: 40.5 | AF66: 92.5 | AH66: -
A67: A394420 | B67: 리센스메디컬 | K67: 14080 | L67: 324469 | M67: 45.7 | N67: 277117.75 | O67: 1.17 | P67: 9.39 | Q67: 37.54 | R67: 41.57 | S67: -4 | T67: -12.87 | U67: -24.71 | V67: 17137 | W67: 18728.5 | X67: 23386 | Y67: 0 | Z67: 0 | AA67: 0 | AB67: 9442.11 | AC67: 1540 | AD67: 26.9 | AF67: 85.1 | AH67: -
A68: A439960 | B68: 코스모로보틱스 | K68: 12150 | L68: 504288 | M68: 61.3 | N68: 2283859.4 | O68: 0.22 | P68: 9.31 | Q68: 43.64 | R68: 44.78 | S68: -1.1 | T68: -5.52 | U68: -44.65 | V68: 14324 | W68: 18278.5 | Y68: 0 | Z68: 0 | AA68: 0 | AB68: 18392.46 | AC68: 3943 | AD68: 34.4 | AF68: 1.5 | AH68: -
A69: A477850 | B69: 마키나락스 | K69: 27100 | L69: 7858462 | M69: 2129.6 | N69: 2495316.4 | O69: 3.15 | P69: 12.79 | Q69: 69.76 | R69: 68.37 | S69: 1.4 | T69: 10.61 | U69: 34.49 | V69: 21289 | W69: 19640 | Y69: 1 | Z69: 1 | AA69: 0 | AB69: 16606.75 | AC69: 4812 | AD69: 100 | AF69: 100 | AH69: -
A70: A153890 | B70: 져스텍 | K70: 13080 | L70: 3643768 | M70: 476.6 | T70: -1.65 | Y70: 0 | Z70: 0 | AA70: 0 | AC70: 1576 | AH70: -
A71: A475040 | B71: 스트라드비젼 | K71: 4460 | L71: 13929297 | M71: 621.2 | T71: -1 | Y71: 0 | Z71: 0 | AA71: 0 | AC71: 2375 | AH71: -

Sheet 전체_전일자
A1: 코드 | B1: 코드명 | C1: 상장일 | D1: days_since_ipo | E1: 기관_일간 | F1: 기관_5일 | G1: 기관_20일 | H1: 외국인_일간 | I1: 외국인_5일 | J1: 외국인_20일 | K1: 현재가 | L1: 거래량 | M1: 거래대금(억) | N1: 20일평균거래량 | O1: RVOL(20) | P1: 변동성(30D) | Q1: RSI(14) | R1: 전일RSI(14) | S1: RSI변화량 | T1: 1일수익률(%) | U1: 20일수익률(%) | V1: 10일이평 | W1: 20일이평 | X1: 60일이평 | Y1: 10일선돌파 | Z1: 20일선돌파 | AA1: 60일선돌파 | AB1: BB폭 | AC1: 시가총액(억) | AD1: 모멘텀스코어 | AE1: 수급스코어 | AF1: 거래량스코어 | AG1: 종합스코어 | AH1: 등급
A2: A062040 | B2: 산일전기 | E2: -516 | F2: 1529.7 | G2: 8099.6 | H2: 920.2 | I2: -4343.5 | J2: -10283.9 | K2: 193400 | L2: 266174 | M2: 514.8 | N2: 325200.75 | O2: 0.82 | P2: 5.17 | Q2: 37.88 | R2: 41.25 | S2: -3.4 | T2: -6.57 | U2: -14.04 | V2: 224740 | W2: 229745 | X2: 238921.67 | Y2: 0 | Z2: 0 | AA2: 0 | AB2: 66630.38 | AC2: 54557 | AD2: 30.8 | AE2: 50.6 | AF2: 58.2 | AG2: 46.2 | AH2: D
A3: A079900 | B3: 전진건설로봇 | E3: -38.4 | F3: -42.3 | G3: -279.3 | H3: -61.4 | I3: -84.4 | J3: 153.2 | K3: 37550 | L3: 81218 | M3: 30.5 | N3: 80377.1 | O3: 1.01 | P3: 5.49 | Q3: 30.65 | R3: 30.71 | S3: -0.1 | T3: -0.13 | U3: -27.51 | V3: 38670 | W3: 45707.5 | X3: 56841.667 | Y3: 0 | Z3: 0 | AA3: 0 | AB3: 32258.47 | AC3: 5034 | AD3: 32.2 | AE3: 20.9 | AF3: 71.6 | AG3: 34.4 | AH3: D
A4: A389650 | B4: 넥스트바이오메디컬 | E4: 39.9 | F4: 101.9 | G4: 505.2 | H4: 46.5 | I4: -87.5 | J4: -276.4 | K4: 41300 | L4: 56311 | M4: 23.3 | N4: 57392.45 | O4: 0.98 | P4: 6.7 | Q4: 47.2 | R4: 45.4 | S4: 1.8 | T4: 2.23 | U4: 0.85 | V4: 40770 | W4: 40867.5 | X4: 49913.333 | Y4: 1 | Z4: 1 | AA4: 0 | AB4: 6774.44 | AC4: 3257 | AD4: 88.8 | AE4: 66.5 | AF4: 70.1 | AG4: 73.9 | AH4: B
A5: A461300 | B5: 아이스크림미디어 | E5: -1 | F5: 3.2 | G5: -484.6 | H5: -3.9 | I5: 10.7 | J5: 238.7 | K5: 16210 | L5: 51847 | M5: 8.4 | N5: 54993.85 | O5: 0.94 | P5: 2.99 | Q5: 46.08 | R5: 47.38 | S5: -1.3 | T5: -0.86 | U5: -3.17 | V5: 16370 | W5: 16512 | X5: 16870.333 | Y5: 0 | Z5: 0 | AA5: 0 | AB5: 1717.47 | AC5: 2184 | AD5: 59.3 | AE5: 42.9 | AF5: 68.7 | AG5: 53 | AH5: C
A6: A308430 | B6: 셀비온 | E6: 0.3 | F6: 13.5 | G6: 136.1 | H6: 1.5 | I6: -31.6 | J6: -163.8 | K6: 16000 | L6: 21440 | M6: 3.4 | N6: 37131.6 | O6: 0.58 | P6: 4.5 | Q6: 35.28 | R6: 37.17 | S6: -1.9 | T6: -2.97 | U6: -10.76 | V6: 16591 | W6: 17071.5 | X6: 24946.667 | Y6: 0 | Z6: 0 | AA6: 0 | AB6: 3595.23 | AC6: 1910 | AD6: 42.5 | AE6: 50.8 | AF6: 26.9 | AG6: 43.5 | AH6: D
A7: A474170 | B7: 루미르 | E7: 0.2 | F7: -2.6 | G7: -38.5 | H7: -4.6 | I7: 6.8 | J7: 166 | K7: 6950 | L7: 77774 | M7: 5.4 | N7: 156907.3 | O7: 0.5 | P7: 4.45 | Q7: 28.81 | R7: 30.77 | S7: -2 | T7: -4.53 | U7: -30.43 | V7: 7448 | W7: 8367.5 | X7: 11980.667 | Y7: 0 | Z7: 0 | AA7: 0 | AB7: 4370.97 | AC7: 1158 | AD7: 16 | AE7: 47.9 | AF7: 17.2 | AG7: 32.2 | AH7: D
A8: A475400 | B8: 씨메스 | E8: -0.6 | F8: -64.7 | G8: -36.8 | H8: 6.4 | I8: 43.2 | J8: 100.9 | K8: 16840 | L8: 28593 | M8: 4.8 | N8: 48459.05 | O8: 0.59 | P8: 5.39 | Q8: 31.43 | R8: 32.85 | S8: -1.4 | T8: -3.66 | U8: -33.31 | V8: 18858 | W8: 21117 | X8: 27439.833 | Y8: 0 | Z8: 0 | AA8: 0 | AB8: 11462.92 | AC8: 1893 | AD8: 18 | AE8: 48.2 | AF8: 29.9 | AG8: 35.5 | AH8: D
A9: A466100 | B9: 클로봇 | E9: 58.9 | F9: 102.8 | G9: 283.6 | H9: 68 | I9: 161.2 | J9: 1276.1 | K9: 26400 | L9: 175267 | M9: 46.3 | N9: 234232.2 | O9: 0.75 | P9: 5.78 | Q9: 34.06 | R9: 35.07 | S9: -1 | T9: -2.22 | U9: -23.01 | V9: 28588.4 | W9: 30893.5 | X9: 39309.933 | Y9: 0 | Z9: 0 | AA9: 0 | AB9: 11837.32 | AC9: 6238 | AD9: 37 | AE9: 89.6 | AF9: 51.5 | AG9: 66.2 | AH9: B
A10: A458650 | B10: 성우 | E10: 0.7 | F10: 8.9 | G10: 18.7 | H10: 1 | I10: -4 | J10: 10.5 | K10: 8330 | L10: 14069 | M10: 1.2 | N10: 31517.25 | O10: 0.45 | P10: 3.93 | Q10: 32.16 | R10: 32.22 | S10: -0.1 | T10: -0.12 | U10: -24.34 | V10: 8588 | W10: 9544.5 | X10: 11908.833 | Y10: 0 | Z10: 0 | AA10: 0 | AB10: 4613.54 | AC10: 1184 | AD10: 38.8 | AE10: 55.2 | AF10: 11.9 | AG10: 41.6 | AH10: D
A11: A336680 | B11: 탑런토탈솔루션 | E11: 0 | F11: 0 | G11: 0 | H11: 5.6 | I11: 7.5 | J11: 4.5 | K11: 2700 | L11: 51429 | M11: 1.4 | N11: 21843.15 | O11: 2.35 | P11: 2.55 | Q11: 34.3 | R11: 37.57 | S11: -3.3 | T11: -2.53 | U11: -9.24 | V11: 2729.5 | W11: 2841.25 | X11: 3373.75 | Y11: 0 | Z11: 0 | AA11: 0 | AB11: 580.99 | AC11: 1026 | AD11: 44 | AE11: 52.1 | AF11: 98.5 | AG11: 59 | AH11: C
A12: A376270 | B12: HEM파마 | E12: 0 | F12: 11.4 | G12: 31.6 | H12: -7 | I12: -31.3 | J12: -77.7 | K12: 42500 | L12: 10426 | M12: 4.4 | N12: 15163.8 | O12: 0.69 | P12: 5.2 | Q12: 40.73 | R12: 36.82 | S12: 3.9 | T12: 3.91 | U12: -1.16 | V12: 43395 | W12: 45325 | X12: 54187.5 | Y12: 0 | Z12: 0 | AA12: 0 | AB12: 13427.66 | AC12: 2896 | AD12: 63.6 | AE12: 42.4 | AF12: 41 | AG12: 48.5 | AH12: D
A13: A475560 | B13: 더본코리아 | E13: -1 | F13: -1.5 | G13: 14.3 | H13: -3.1 | I13: 10.9 | J13: 21.4 | K13: 15120 | L13: 43452 | M13: 6.6 | N13: 18935.7 | O13: 2.29 | P13: 3.05 | Q13: 44.01 | R13: 39.17 | S13: 4.8 | T13: 2.79 | U13: -5.5 | V13: 14751 | W13: 15193.5 | X13: 17991.167 | Y13: 1 | Z13: 0 | AA13: 0 | AB13: 2614.52 | AC13: 2172 | AD13: 82.9 | AE13: 45 | AF13: 94 | AG13: 66.2 | AH13: B
... A45: A439260 | B45: 대한조선 | E45: -83.4 | F45: -23.8 | G45: 41 | H45: 132.2 | I45: 235.1 | J45: -56.1 | K45: 50800 | L45: 91653 | M45: 46.6 | N45: 79419.15 | O45: 1.15 | P45: 3.41 | Q45: 33.04 | R45: 34.87 | S45: -1.8 | T45: -2.5 | U45: -16.58 | V45: 52450 | W45: 56790 | X45: 71231.667 | Y45: 0 | Z45: 0 | AA45: 0 | AB45: 20168.45 | AC45: 18149 | AD45: 38.3 | AE45: 52.1 | AF45: 84.3 | AG45: 54.4 | AH45: C
A46: A309710 | B46: 아이티켐 | E46: 0 | F46: 0 | G46: 0 | H46: 0 | I46: 0 | J46: 0 | K46: 21000 | L46: 0 | M46: 0 | N46: 0 | P46: 0 | Q46: 17.73 | R46: 17.73 | S46: 0 | T46: 0 | U46: 0 | V46: 21000 | W46: 21000 | X46: 21000 | Y46: 0 | Z46: 0 | AA46: 0 | AB46: 0 | AC46: 2684 | AD46: 49 | AE46: 47.8 | AH46: -
A47: A456160 | B47: 지투지바이오 | E47: -59.1 | F47: -129.7 | G47: -1158.4 | H47: 103.1 | I47: -363.1 | J47: 915.2 | K47: 35500 | L47: 135062 | M47: 47.9 | N47: 185235.85 | O47: 0.73 | P47: 6.79 | Q47: 33.85 | R47: 33.95 | S47: -0.1 | T47: -0.28 | U47: -26.58 | V47: 39315 | W47: 42027.5 | X47: 59865.833 | Y47: 0 | Z47: 0 | AA47: 0 | AB47: 16509.33 | AC47: 5330 | AD47: 37 | AE47: 33.9 | AF47: 47.8 | AG47: 37.6 | AH47: D
A48: A484590 | B48: 삼양컴텍 | E48: -5.3 | F48: 56.4 | G48: -213.6 | H48: 3 | I48: -104.4 | J48: -152.4 | K48: 6470 | L48: 279811 | M48: 18.1 | N48: 455581.7 | O48: 0.61 | P48: 5.95 | Q48: 36.1 | R48: 37.96 | S48: -1.9 | T48: -4.29 | U48: -10.01 | V48: 7058 | W48: 7716.5 | X48: 9882.6667 | Y48: 0 | Z48: 0 | AA48: 0 | AB48: 3635.5 | AC48: 2440 | AD48: 38.8 | AE48: 37.4 | AF48: 32.8 | AG48: 36.9 | AH48: D
A49: A125490 | B49: 한라캐스트 | E49: 12.2 | F49: 36 | G49: 1347.6 | H49: 8.5 | I49: -41.3 | J49: -1210.4 | K49: 8200 | L49: 365528 | M49: 30 | N49: 755949.4 | O49: 0.48 | P49: 5.47 | Q49: 30.87 | R49: 32.04 | S49: -1.2 | T49: -3.07 | U49: -30.51 | V49: 8811 | W49: 10221.5 | X49: 13546.167 | Y49: 0 | Z49: 0 | AA49: 0 | AB49: 6754.95 | AC49: 2745 | AD49: 21.6 | AE49: 59.7 | AF49: 13.4 | AG49: 39 | AH49: D
A50: A318060 | B50: 그래피 | E50: -2 | F50: -7.7 | G50: 102.5 | H50: -4.1 | I50: -45.8 | J50: 46.1 | K50: 18050 | L50: 109188 | M50: 19.7 | N50: 103168.05 | O50: 1.06 | P50: 5.63 | Q50: 41.82 | R50: 35.15 | S50: 6.7 | T50: 8.34 | U50: -20.83 | V50: 16830 | W50: 18838.5 | X50: 26930.333 | Y50: 1 | Z50: 0 | AA50: 0 | AB50: 9964.35 | AC50: 2126 | AD50: 77.7 | AE50: 37.7 | AF50: 74.6 | AG50: 57.1 | AH50: C
A51: A488280 | B51: 에스투더블유 | E51: -4 | F51: -10.2 | G51: -58.6 | H51: 12 | I51: 35.6 | J51: 163.1 | K51: 10280 | L51: 40909 | M51: 4.2 | N51: 115972.95 | O51: 0.35 | P51: 7.15 | Q51: 31.67 | R51: 32.56 | S51: -0.9 | T51: -3.2 | U51: -35.75 | V51: 11551 | W51: 13371 | X51: 19215.5 | Y51: 0 | Z51: 0 | AA51: 0 | AB51: 8146.69 | AC51: 1026 | AD51: 18.5 | AE51: 48.9 | AF51: 7.5 | AG51: 31.5 | AH51: D
A52: A317450 | B52: 명인제약 | E52: 0.3 | F52: -4.9 | G52: -560.4 | H52: -2.3 | I52: 22.8 | J52: 384.1 | K52: 43800 | L52: 16402 | M52: 7.2 | N52: 22184.85 | O52: 0.74 | P52: 3.06 | Q52: 48.51 | R52: 48.51 | S52: 0 | T52: 0 | U52: 0 | V52: 42200 | W52: 42902.5 | X52: 49246.667 | Y52: 1 | Z52: 1 | AA52: 0 | AB52: 5336.47 | AC52: 6278 | AD52: 86.4 | AE52: 48.9 | AF52: 49.3 | AG52: 60.2 | AH52: C
A53: A486990 | B53: 노타 | E53: -1.7 | F53: 4.9 | G53: -889.1 | H53: -15.7 | I53: -271.4 | J53: -105.6 | K53: 19620 | L53: 135820 | M53: 26.6 | N53: 223854.6 | O53: 0.61 | P53: 8.47 | Q53: 34.59 | R53: 37.44 | S53: -2.8 | T53: -6.35 | U53: -35.03 | V53: 20972 | W53: 23306 | X53: 29748.667 | Y53: 0 | Z53: 0 | AA53: 0 | AB53: 11049.04 | AC53: 3849 | AD53: 15.9 | AE53: 24.7 | AF53: 32.8 | AG53: 23.7 | AH53: F
A54: A469610 | B54: 이노테크 | E54: -2.3 | F54: -32.5 | G54: -50.1 | H54: -16.2 | I54: -29.5 | J54: -28.1 | K54: 13800 | L54: 75583 | M54: 10.4 | N54: 189680.05 | O54: 0.4 | P54: 9.56 | Q54: 42.36 | R54: 45.36 | S54: -3 | T54: -6.82 | U54: -3.43 | V54: 14600 | W54: 15302 | X54: 19541.833 | Y54: 0 | Z54: 0 | AA54: 0 | AB54: 7259.95 | AC54: 1191 | AD54: 39.8 | AE54: 27.1 | AF54: 9.7 | AG54: 27.4 | AH54: F
A55: A494120 | B55: 큐리오시스 | E55: 141 | F55: 73 | G55: 588.7 | H55: -16.9 | I55: 167.7 | J55: -435.9 | K55: 27800 | L55: 151492 | M55: 42.1 | N55: 115115.65 | O55: 1.32 | P55: 8.52 | Q55: 46.86 | R55: 40.12 | S55: 6.7 | T55: 11.87 | U55: 4.51 | V55: 25910 | W55: 26530 | X55: 40168.333 | Y55: 1 | Z55: 1 | AA55: 0 | AB55: 9081.28 | AC55: 1930 | AD55: 94.1 | AE55: 65.4 | AF55: 91 | AG55: 79.1 | AH55: B
A56: A061090 | B56: 세나테크놀로지 | E56: 1.9 | F56: 41 | G56: -65.8 | H56: 16.7 | I56: 4 | J56: 21.9 | K56: 36550 | L56: 34099 | M56: 12.5 | N56: 29660.25 | O56: 1.15 | P56: 6.44 | Q56: 49.27 | R56: 49.79 | S56: -0.5 | T56: -0.68 | U56: -17.68 | V56: 32375 | W56: 35422.5 | X56: 41025.833 | Y56: 1 | Z56: 1 | AA56: 0 | AB56: 18833.85 | AC56: 1985 | AD56: 73.5 | AE56: 61.6 | AF56: 84.3 | AG56: 69.7 | AH56: B
A57: A403850 | B57: 더핑크퐁컴퍼니 | E57: 47.5 | F57: 41.1 | G57: 28.7 | H57: 265.3 | I57: 307.2 | J57: 333.7 | K57: 10880 | L57: 338565 | M57: 36.8 | N57: 84417.8 | O57: 4.01 | P57: 4.45 | Q57: 43.51 | R57: 41.88 | S57: 1.6 | T57: 1.49 | U57: -0.27 | V57: 10722 | W57: 11152.5 | X57: 13739.167 | Y57: 1 | Z57: 0 | AA57: 0 | AB57: 2436.68 | AC57: 1498 | AD57: 84.9 | AE57: 85.7 | AF57: 100 | AG57: 88.3 | AH57: A
A58: A388210 | B58: 씨엠티엑스 | E58: -82.5 | F58: -249.5 | G58: -199.2 | H58: 122.7 | I58: 73.5 | J58: -405.9 | K58: 76700 | L58: 50233 | M58: 38.5 | N58: 71828.45 | O58: 0.7 | P58: 6.15 | Q58: 30.59 | R58: 33.39 | S58: -2.8 | T58: -6.46 | U58: -28.65 | V58: 88990 | W58: 98285 | X58: 119055 | Y58: 0 | Z58: 0 | AA58: 0 | AB58: 44881.76 | AC58: 6652 | AD58: 13.8 | AE58: 38.5 | AF58: 43.3 | AG58: 32 | AH58: D
... A65: A279570 | B65: 케이뱅크 | E65: -4.7 | F65: 218.2 | G65: 9292.2 | H65: -101.8 | I65: -371 | J65: 576.7 | K65: 5470 | L65: 983911 | M65: 53.8 | N65: 6642472.3 | O65: 0.15 | P65: 3.93 | Q65: 39.38 | R65: 41.79 | S65: -2.4 | T65: -2.32 | U65: -5.36 | V65: 5684 | W65: 6144 | X65: 5994.3333 | Y65: 0 | Z65: 0 | AA65: 0 | AB65: 2228.99 | AC65: 21583 | AD65: 50.5 | AE65: 46.4 | AF65: 1.5 | AG65: 38.6 | AH65: D
A66: A493280 | B66: 아이엠바이오로직스 | K66: 21750 | L66: 80203 | M66: 17.4 | N66: 101906.7 | O66: 0.79 | P66: 6.71 | Q66: 35.07 | R66: 32.56 | S66: 2.5 | T66: 4.07 | U66: -16.83 | V66: 22000 | W66: 23802.5 | X66: 37130 | Y66: 0 | Z66: 0 | AA66: 0 | AB66: 10207.15 | AC66: 3041 | AD66: 51.2 | AF66: 56.7 | AH66: -
A67: A394420 | B67: 리센스메디컬 | K67: 16160 | L67: 223092 | M67: 36.1 | N67: 263760.7 | O67: 0.85 | P67: 9.16 | Q67: 41.57 | R67: 43.46 | S67: -1.9 | T67: -5.33 | U67: -16.05 | V67: 17879 | W67: 18959.5 | X67: 23531.333 | Y67: 0 | Z67: 0 | AA67: 0 | AB67: 8426.95 | AC67: 1540 | AD67: 36.9 | AF67: 62.7 | AH67: -
A68: A439960 | B68: 코스모로보틱스 | K68: 12860 | L68: 563989 | M68: 72.5 | N68: 2325668.5 | O68: 0.24 | P68: 9.3 | Q68: 44.78 | R68: 45.9 | S68: -1.1 | T68: -5.3 | U68: -51.1 | V68: 14995 | W68: 18768.5 | Y68: 0 | Z68: 0 | AA68: 0 | AB68: 17753.26 | AC68: 3943 | AD68: 23.2 | AF68: 3 | AH68: -
A69: A477850 | B69: 마키나락스 | K69: 24500 | L69: 4966524 | M69: 1216.8 | N69: 2126740.5 | O69: 2.34 | P69: 12.93 | Q69: 68.37 | R69: 75.71 | S69: -7.3 | T69: -19.41 | U69: 11.87 | V69: 19984 | W69: 19292.5 | Y69: 1 | Z69: 1 | AA69: 0 | AB69: 15150.54 | AC69: 4812 | AD69: 68.4 | AF69: 96.3 | AH69: -
A70: A153890 | B70: 져스텍 | K70: 13300 | L70: 4576192 | M70: 608.6 | T70: -4.73 | Y70: 0 | Z70: 0 | AA70: 0 | AC70: 1576 | AH70: -
A71: A475040 | B71: 스트라드비젼 | K71: 4505 | L71: 10979078 | M71: 494.6 | T71: -8.34 | Y71: 0 | Z71: 0 | AA71: 0 | AC71: 2375 | AH71: -

Sheet RSI과매도
A1: 코드 | B1: 코드명 | C1: 상장일 | D1: days_since_ipo | E1: 기관_일간 | F1: 기관_5일 | G1: 기관_20일 | H1: 외국인_일간 | I1: 외국인_5일 | J1: 외국인_20일 | K1: 현재가 | L1: 거래량 | M1: 거래대금(억) | N1: 20일평균거래량 | O1: RVOL(20) | P1: 변동성(30D) | Q1: RSI(14) | R1: 전일RSI(14) | S1: RSI변화량 | T1: 1일수익률(%) | U1: 20일수익률(%) | V1: 10일이평 | W1: 20일이평 | X1: 60일이평 | Y1: 10일선돌파 | Z1: 20일선돌파 | AA1: 60일선돌파 | AB1: BB폭 | AC1: 시가총액(억) | AD1: 모멘텀스코어 | AE1: 수급스코어 | AF1: 거래량스코어 | AG1: 종합스코어 | AH1: 등급
A2: A309710 | B2: 아이티켐 | E2: 0 | F2: 0 | G2: 0 | H2: 0 | I2: 0 | J2: 0 | K2: 21000 | L2: 0 | M2: 0 | N2: 0 | P2: 0 | Q2: 17.73 | R2: 17.73 | S2: 0 | T2: 0 | U2: 0 | V2: 21000 | W2: 21000 | X2: 21000 | Y2: 0 | Z2: 0 | AA2: 0 | AB2: 0 | AC2: 2684 | AD2: 55.1 | AE2: 50.6 | AH2: -
A3: A474650 | B3: 링크솔루션 | E3: -1.3 | F3: -22.8 | G3: 39 | H3: 8.8 | I3: 33.9 | J3: 352.9 | K3: 23850 | L3: 33084 | M3: 7.9 | N3: 57434.95 | O3: 0.58 | P3: 5.39 | Q3: 23.88 | R3: 26.93 | S3: -3.1 | T3: -9.83 | U3: -36.82 | V3: 28430 | W3: 33090 | X3: 47009.167 | Y3: 0 | Z3: 0 | AA3: 0 | AB3: 23207.03 | AC3: 1372 | AD3: 4.1 | AE3: 57.8 | AF3: 26.1 | AG3: 35.4 | AH3: D
A4: A452450 | B4: 피아이이 | E4: 0 | F4: 0 | G4: 4.3 | H4: 1.2 | I4: -12.1 | J4: 42.5 | K4: 3125 | L4: 91780 | M4: 2.9 | N4: 152595.25 | O4: 0.6 | P4: 4.1 | Q4: 25.31 | R4: 28.15 | S4: -2.8 | T4: -6.86 | U4: -29.14 | V4: 3513 | W4: 3958.75 | X4: 5420.0833 | Y4: 0 | Z4: 0 | AA4: 0 | AB4: 2080.91 | AC4: 1126 | AD4: 21.7 | AE4: 52.9 | AF4: 31.3 | AG4: 39.2 | AH4: D
A5: A476060 | B5: 온코닉테라퓨틱스 | E5: -1 | F5: -9.5 | G5: -313 | H5: 123.1 | I5: 249.6 | J5: 833 | K5: 10970 | L5: 353754 | M5: 38.8 | N5: 255809.85 | O5: 1.38 | P5: 4.51 | Q5: 26.14 | R5: 28.6 | S5: -2.5 | T5: -6.24 | U5: -30.44 | V5: 12765 | W5: 14208.5 | X5: 18373.833 | Y5: 0 | Z5: 0 | AA5: 0 | AB5: 6825.27 | AC5: 4981 | AD5: 23.3 | AE5: 62.6 | AF5: 94 | AG5: 57.1 | AH5: C
A6: A474170 | B6: 루미르 | E6: -0.6 | F6: -1 | G6: -38.1 | H6: 8.3 | I6: 20.7 | J6: 165.3 | K6: 6500 | L6: 66052 | M6: 4.3 | N6: 153335 | O6: 0.43 | P6: 4.33 | Q6: 26.34 | R6: 28.81 | S6: -2.5 | T6: -6.47 | U6: -36.27 | V6: 7317 | W6: 8182.5 | X6: 11865.5 | Y6: 0 | Z6: 0 | AA6: 0 | AB6: 4319.89 | AC6: 1158 | AD6: 17 | AE6: 56.2 | AF6: 7.5 | AG6: 34.7 | AH6: D
A7: A478340 | B7: 나라스페이스테크놀로지 | E7: 0 | F7: -103.2 | G7: -231 | H7: 9.4 | I7: 82.6 | J7: 731.8 | K7: 11220 | L7: 84160 | M7: 9.4 | N7: 157321.3 | O7: 0.53 | P7: 6.31 | Q7: 26.44 | R7: 28.13 | S7: -1.7 | T7: -7.2 | U7: -45.53 | V7: 13090 | W7: 15997.5 | X7: 26038.333 | Y7: 0 | Z7: 0 | AA7: 0 | AB7: 14292.95 | AC7: 1298 | AD7: 13.1 | AE7: 56.8 | AF7: 19.4 | AG7: 36.2 | AH7: D
A8: A388210 | B8: 씨엠티엑스 | E8: -28.5 | F8: -401.8 | G8: -307.6 | H8: 264.7 | I8: 348.2 | J8: -73.4 | K8: 68900 | L8: 94674 | M8: 65.2 | N8: 72931.8 | O8: 1.3 | P8: 6.27 | Q8: 27 | R8: 30.59 | S8: -3.6 | T8: -10.17 | U8: -35 | V8: 86520 | W8: 96430 | X8: 118125 | Y8: 0 | Z8: 0 | AA8: 0 | AB8: 51014.52 | AC8: 6652 | AD8: 7.3 | AE8: 46.7 | AF8: 89.6 | AG8: 43.5 | AH8: D
A9: A079900 | B9: 전진건설로봇 | E9: 0 | F9: -42.3 | G9: -259.3 | H9: 23.3 | I9: -36.6 | J9: 193.8 | K9: 34500 | L9: 56106 | M9: 19.4 | N9: 79685.1 | O9: 0.7 | P9: 5.61 | Q9: 27.04 | R9: 30.65 | S9: -3.6 | T9: -8.12 | U9: -32.22 | V9: 37980 | W9: 44887.5 | X9: 56283.333 | Y9: 0 | Z9: 0 | AA9: 0 | AB9: 33298.16 | AC9: 5034 | AD9: 15.9 | AE9: 48.1 | AF9: 41.8 | AG9: 37.2 | AH9: D
A10: A488900 | B10: 비츠로넥스텍 | E10: 0.1 | F10: -2.4 | G10: -43.3 | H10: 0.6 | I10: 21.7 | J10: 155.6 | K10: 7140 | L10: 77992 | M10: 5.6 | N10: 80306 | O10: 0.97 | P10: 5.77 | Q10: 27.68 | R10: 30.17 | S10: -2.5 | T10: -7.63 | U10: -35.85 | V10: 8158 | W10: 9272 | X10: 14331.167 | Y10: 0 | Z10: 0 | AA10: 0 | AB10: 5634.25 | AC10: 2069 | AD10: 14.3 | AE10: 55.4 | AF10: 72.4 | AG10: 46.5 | AH10: D
A11: A489500 | B11: 엘케이켐 | E11: 0 | F11: 2.7 | G11: 29.1 | H11: 5.8 | I11: -10.8 | J11: 129.1 | K11: 17990 | L11: 43278 | M11: 7.8 | N11: 42971.95 | O11: 1.01 | P11: 5.69 | Q11: 27.75 | R11: 30.95 | S11: -3.2 | T11: -8.87 | U11: -31.86 | V11: 21183 | W11: 24574 | X11: 30016.333 | Y11: 0 | Z11: 0 | AA11: 0 | AB11: 15777.6 | AC11: 1150 | AD11: 15.1 | AE11: 59.7 | AF11: 74.6 | AG11: 49.3 | AH11: D
A12: A217590 | B12: 티엠씨 | E12: -2.2 | F12: -235.4 | G12: 437.2 | H12: 57.5 | I12: 259.1 | J12: 931.7 | K12: 10460 | L12: 257026 | M12: 26.9 | N12: 545426.35 | O12: 0.47 | P12: 8.02 | Q12: 27.77 | R12: 29.2 | S12: -1.4 | T12: -5.94 | U12: -53.72 | V12: 12180 | W12: 15129.5 | X12: 23121.833 | Y12: 0 | Z12: 0 | AA12: 0 | AB12: 14144.4 | AC12: 2520 | AD12: 18.7 | AE12: 62.9 | AF12: 11.9 | AG12: 39.4 | AH12: D
A13: A490470 | B13: 세미파이브 | E13: 1.3 | F13: -19 | G13: -1688.1 | H13: -4.5 | I13: -318.1 | J13: 1476.7 | K13: 17600 | L13: 377216 | M13: 66.4 | N13: 477833.05 | O13: 0.79 | P13: 5.67 | Q13: 27.98 | R13: 31.08 | S13: -3.1 | T13: -9.04 | U13: -33.21 | V13: 20316 | W13: 22948 | X13: 32626 | Y13: 0 | Z13: 0 | AA13: 0 | AB13: 12633.27 | AC13: 5988 | AD13: 12.8 | AE13: 40.3 | AF13: 53.7 | AG13: 34.7 | AH13: D
A14: A125490 | B14: 한라캐스트 | E14: 9.4 | F14: 11.6 | G14: 1343.2 | H14: 67.1 | I14: 68 | J14: -1076.3 | K14: 7520 | L14: 551991 | M14: 41.5 | N14: 744089.7 | O14: 0.74 | P14: 5.54 | Q14: 27.98 | R14: 30.87 | S14: -2.9 | T14: -8.29 | U14: -35.78 | V14: 8644 | W14: 10012 | X14: 13450.833 | Y14: 0 | Z14: 0 | AA14: 0 | AB14: 6999.5 | AC14: 2745 | AD14: 13.2 | AE14: 75 | AF14: 43.3 | AG14: 50.1 | AH14: C
... A23: A380550 | B23: 뉴로핏 | E23: -6.9 | F23: -2 | G23: -296.9 | H23: 15.4 | I23: 35.8 | J23: 414.7 | K23: 8650 | L23: 100883 | M23: 8.7 | N23: 134672.5 | O23: 0.75 | P23: 5.94 | Q23: 29.98 | R23: 33.5 | S23: -3.5 | T23: -8.95 | U23: -28.22 | V23: 9920 | W23: 10875.5 | X23: 15709.167 | Y23: 0 | Z23: 0 | AA23: 0 | AB23: 5047.03 | AC23: 1055 | AD23: 20 | AE23: 54.5 | AF23: 45.5 | AG23: 42.4 | AH23: D

Sheet 외국인순매수TOP
A1: 코드 | B1: 코드명 | C1: 상장일 | D1: days_since_ipo | E1: 기관_일간 | F1: 기관_5일 | G1: 기관_20일 | H1: 외국인_일간 | I1: 외국인_5일 | J1: 외국인_20일 | K1: 현재가 | L1: 거래량 | M1: 거래대금(억) | N1: 20일평균거래량 | O1: RVOL(20) | P1: 변동성(30D) | Q1: RSI(14) | R1: 전일RSI(14) | S1: RSI변화량 | T1: 1일수익률(%) | U1: 20일수익률(%) | V1: 10일이평 | W1: 20일이평 | X1: 60일이평 | Y1: 10일선돌파 | Z1: 20일선돌파 | AA1: 60일선돌파 | AB1: BB폭 | AC1: 시가총액(억) | AD1: 모멘텀스코어 | AE1: 수급스코어 | AF1: 거래량스코어 | AG1: 종합스코어 | AH1: 등급
A2: A062040 | B2: 산일전기 | E2: -1112.6 | F2: -1875.2 | G2: 6834.9 | H2: 1784.4 | I2: -1823.4 | J2: -7952.4 | K2: 178200 | L2: 448109 | M2: 798.5 | N2: 335915.95 | O2: 1.33 | P2: 5.3 | Q2: 34.5 | R2: 37.88 | S2: -3.4 | T2: -7.86 | U2: -18.44 | V2: 220260 | W2: 227730 | X2: 239516.67 | Y2: 0 | Z2: 0 | AA2: 0 | AB2: 79993.71 | AC2: 54557 | AD2: 34.9 | AE2: 33.2 | AF2: 91 | AG2: 45.3 | AH2: D
A3: A388210 | B3: 씨엠티엑스 | E3: -28.5 | F3: -401.8 | G3: -307.6 | H3: 264.7 | I3: 348.2 | J3: -73.4 | K3: 68900 | L3: 94674 | M3: 65.2 | N3: 72931.8 | O3: 1.3 | P3: 6.27 | Q3: 27 | R3: 30.59 | S3: -3.6 | T3: -10.17 | U3: -35 | V3: 86520 | W3: 96430 | X3: 118125 | Y3: 0 | Z3: 0 | AA3: 0 | AB3: 51014.52 | AC3: 6652 | AD3: 7.3 | AE3: 46.7 | AF3: 89.6 | AG3: 43.5 | AH3: D
A4: A456160 | B4: 지투지바이오 | E4: -163 | F4: -417.9 | G4: -1244.2 | H4: 183.3 | I4: -82.3 | J4: 971.7 | K4: 32050 | L4: 178455 | M4: 57.2 | N4: 189052.6 | O4: 0.94 | P4: 6.92 | Q4: 30.46 | R4: 33.85 | S4: -3.4 | T4: -9.72 | U4: -31.37 | V4: 38460 | W4: 41295 | X4: 59241.667 | Y4: 0 | Z4: 0 | AA4: 0 | AB4: 18059.56 | AC4: 5330 | AD4: 16 | AE4: 37.2 | AF4: 69.4 | AG4: 37.3 | AH4: D
A5: A448900 | B5: 한국피아이엠 | E5: -75.1 | F5: -109.2 | G5: -333.1 | H5: 128.8 | I5: 285.2 | J5: 496.5 | K5: 45350 | L5: 63468 | M5: 28.8 | N5: 83466.75 | O5: 0.76 | P5: 6.73 | Q5: 28.77 | R5: 31.29 | S5: -2.5 | T5: -9.66 | U5: -42.23 | V5: 53785 | W5: 64862.5 | X5: 88612.5 | Y5: 0 | Z5: 0 | AA5: 0 | AB5: 53427.59 | AC5: 2755 | AD5: 8.3 | AE5: 51.3 | AF5: 47.8 | AG5: 37.7 | AH5: D
A6: A476060 | B6: 온코닉테라퓨틱스 | E6: -1 | F6: -9.5 | G6: -313 | H6: 123.1 | I6: 249.6 | J6: 833 | K6: 10970 | L6: 353754 | M6: 38.8 | N6: 255809.85 | O6: 1.38 | P6: 4.51 | Q6: 26.14 | R6: 28.6 | S6: -2.5 | T6: -6.24 | U6: -30.44 | V6: 12765 | W6: 14208.5 | X6: 18373.833 | Y6: 0 | Z6: 0 | AA6: 0 | AB6: 6825.27 | AC6: 4981 | AD6: 23.3 | AE6: 62.6 | AF6: 94 | AG6: 57.1 | AH6: C
A7: A476830 | B7: 알지노믹스 | E7: -35.6 | F7: -180.1 | G7: -1923.3 | H7: 119.1 | I7: -1112.7 | J7: -3675.5 | K7: 31900 | L7: 217031 | M7: 69.2 | N7: 516714.35 | O7: 0.42 | P7: 7.12 | Q7: 29.6 | R7: 32.09 | S7: -2.5 | T7: -9.12 | U7: -29.81 | V7: 40360 | W7: 43277.5 | X7: 66785.833 | Y7: 0 | Z7: 0 | AA7: 0 | AB7: 18499.46 | AC7: 4475 | AD7: 17 | AE7: 23.9 | AF7: 6 | AG7: 18.2 | AH7: F
A8: A439260 | B8: 대한조선 | E8: -102.7 | F8: -124.2 | G8: -76.1 | H8: 95.4 | I8: 292.7 | J8: 124.9 | K8: 47650 | L8: 101875 | M8: 48.5 | N8: 81034.4 | O8: 1.26 | P8: 3.53 | Q8: 29.06 | R8: 33.04 | S8: -4 | T8: -6.2 | U8: -22.01 | V8: 51705 | W8: 56117.5 | X8: 70575.833 | Y8: 0 | Z8: 0 | AA8: 0 | AB8: 21248.56 | AC8: 18149 | AD8: 35 | AE8: 49.1 | AF8: 86.6 | AG8: 52.4 | AH8: C
A9: A125490 | B9: 한라캐스트 | E9: 9.4 | F9: 11.6 | G9: 1343.2 | H9: 67.1 | I9: 68 | J9: -1076.3 | K9: 7520 | L9: 551991 | M9: 41.5 | N9: 744089.7 | O9: 0.74 | P9: 5.54 | Q9: 27.98 | R9: 30.87 | S9: -2.9 | T9: -8.29 | U9: -35.78 | V9: 8644 | W9: 10012 | X9: 13450.833 | Y9: 0 | Z9: 0 | AA9: 0 | AB9: 6999.5 | AC9: 2745 | AD9: 13.2 | AE9: 75 | AF9: 43.3 | AG9: 50.1 | AH9: C
A10: A098070 | B10: 한텍 | E10: -51.3 | F10: -181.3 | G10: -500.7 | H10: 60.6 | I10: 187.6 | J10: 435.4 | K10: 22750 | L10: 74573 | M10: 17 | N10: 58720.65 | O10: 1.27 | P10: 5.23 | Q10: 31.09 | R10: 33.35 | S10: -2.3 | T10: -5.21 | U10: -26.38 | V10: 25575 | W10: 28232.5 | X10: 36155 | Y10: 0 | Z10: 0 | AA10: 0 | AB10: 13103.48 | AC10: 2530 | AD10: 39 | AE10: 47.4 | AF10: 88.1 | AG10: 53 | AH10: C
A11: A466100 | B11: 클로봇 | E11: 21 | F11: 90.5 | G11: 357.2 | H11: 59.8 | I11: 185.6 | J11: 1217 | K11: 24500 | L11: 134601 | M11: 33 | N11: 224691.35 | O11: 0.6 | P11: 5.79 | Q11: 31.03 | R11: 34.06 | S11: -3 | T11: -7.2 | U11: -23.25 | V11: 27889 | W11: 30522.5 | X11: 38978.683 | Y11: 0 | Z11: 0 | AA11: 0 | AB11: 13029.9 | AC11: 6238 | AD11: 32.6 | AE11: 88.5 | AF11: 31.3 | AG11: 60.3 | AH11: C
A12: A217590 | B12: 티엠씨 | E12: -2.2 | F12: -235.4 | G12: 437.2 | H12: 57.5 | I12: 259.1 | J12: 931.7 | K12: 10460 | L12: 257026 | M12: 26.9 | N12: 545426.35 | O12: 0.47 | P12: 8.02 | Q12: 27.77 | R12: 29.2 | S12: -1.4 | T12: -5.94 | U12: -53.72 | V12: 12180 | W12: 15129.5 | X12: 23121.833 | Y12: 0 | Z12: 0 | AA12: 0 | AB12: 14144.4 | AC12: 2520 | AD12: 18.7 | AE12: 62.9 | AF12: 11.9 | AG12: 39.4 | AH12: D
A13: A486990 | B13: 노타 | E13: -23.1 | F13: -36.3 | G13: -909.8 | H13: 33.7 | I13: -275 | J13: -8 | K13: 18030 | L13: 162729 | M13: 29.3 | N13: 211080.2 | O13: 0.77 | P13: 8.56 | Q13: 31.51 | R13: 34.59 | S13: -3.1 | T13: -8.1 | U13: -33.22 | V13: 20550 | W13: 22857.5 | X13: 29485 | Y13: 0 | Z13: 0 | AA13: 0 | AB13: 11411.19 | AC13: 3849 | AD13: 21.7 | AE13: 30.8 | AF13: 50 | AG13: 31.9 | AH13: D
... A21: A478340 | B21: 나라스페이스테크놀로지 | E21: 0 | F21: -103.2 | G21: -231 | H21: 9.4 | I21: 82.6 | J21: 731.8 | K21: 11220 | L21: 84160 | M21: 9.4 | N21: 157321.3 | O21: 0.53 | P21: 6.31 | Q21: 26.44 | R21: 28.13 | S21: -1.7 | T21: -7.2 | U21: -45.53 | V21: 13090 | W21: 15997.5 | X21: 26038.333 | Y21: 0 | Z21: 0 | AA21: 0 | AB21: 14292.95 | AC21: 1298 | AD21: 13.1 | AE21: 56.8 | AF21: 19.4 | AG21: 36.2 | AH21: D

Sheet 기관순매수TOP
A1: 코드 | B1: 코드명 | C1: 상장일 | D1: days_since_ipo | E1: 기관_일간 | F1: 기관_5일 | G1: 기관_20일 | H1: 외국인_일간 | I1: 외국인_5일 | J1: 외국인_20일 | K1: 현재가 | L1: 거래량 | M1: 거래대금(억) | N1: 20일평균거래량 | O1: RVOL(20) | P1: 변동성(30D) | Q1: RSI(14) | R1: 전일RSI(14) | S1: RSI변화량 | T1: 1일수익률(%) | U1: 20일수익률(%) | V1: 10일이평 | W1: 20일이평 | X1: 60일이평 | Y1: 10일선돌파 | Z1: 20일선돌파 | AA1: 60일선돌파 | AB1: BB폭 | AC1: 시가총액(억) | AD1: 모멘텀스코어 | AE1: 수급스코어 | AF1: 거래량스코어 | AG1: 종합스코어 | AH1: 등급
A2: A064400 | B2: LG씨엔에스 | E2: 358.4 | F2: 1129 | G2: 1043.7 | H2: -1083.9 | I2: 293.7 | J2: -2290.4 | K2: 71200 | L2: 1449549 | M2: 1032.1 | N2: 1357002.6 | O2: 1.07 | P2: 9.16 | Q2: 37.64 | R2: 39.89 | S2: -2.2 | T2: -3.78 | U2: -24.09 | V2: 75930 | W2: 82580 | X2: 81523.333 | Y2: 0 | Z2: 0 | AA2: 0 | AB2: 31612.81 | AC2: 68983 | AD2: 49.1 | AE2: 66.5 | AF2: 79.1 | AG2: 63.8 | AH2: C
A3: A483650 | B3: 달바글로벌 | E3: 267.6 | F3: -437.4 | G3: 5971.6 | H3: -76.4 | I3: 1026.8 | J3: 1405.3 | K3: 217500 | L3: 131493 | M3: 286 | N3: 197319.8 | O3: 0.67 | P3: 4.83 | Q3: 50.19 | R3: 55.81 | S3: -5.6 | T3: -5.43 | U3: 7.67 | V3: 228350 | W3: 216655 | X3: 213961.67 | Y3: 0 | Z3: 1 | AA3: 1 | AB3: 58996.74 | AC3: 27154 | AD3: 64.6 | AE3: 62.9 | AF3: 40.3 | AG3: 58.9 | AH3: C
A4: A473980 | B4: 노머스 | E4: 62.4 | F4: 167.9 | G4: -40.2 | H4: -33.4 | I4: -94.9 | J4: 136.2 | K4: 11140 | L4: 88634 | M4: 9.9 | N4: 81013.9 | O4: 1.09 | P4: 5.86 | Q4: 43.62 | R4: 41.44 | S4: 2.2 | T4: 2.48 | U4: -11.02 | V4: 10724 | W4: 11484.5 | X4: 14706.5 | Y4: 1 | Z4: 0 | AA4: 0 | AB4: 5317.84 | AC4: 1232 | AD4: 85.2 | AE4: 56.4 | AF4: 80.6 | AG4: 69.9 | AH4: B
A5: A494120 | B5: 큐리오시스 | E5: 41.4 | F5: 164.4 | G5: 621.4 | H5: -55.5 | I5: 20.2 | J5: -490.5 | K5: 25300 | L5: 91126 | M5: 23.1 | N5: 117584.25 | O5: 0.77 | P5: 8.62 | Q5: 42.5 | R5: 46.86 | S5: -4.4 | T5: -8.99 | U5: -2.32 | V5: 25535 | W5: 26500 | X5: 39723.333 | Y5: 0 | Z5: 0 | AA5: 0 | AB5: 9129.51 | AC5: 1930 | AD5: 44.8 | AE5: 62.9 | AF5: 50 | AG5: 54.9 | AH5: C
A6: A484870 | B6: 엠앤씨솔루션 | E6: 30 | F6: 117.6 | G6: 432.3 | H6: -13.7 | I6: -5.3 | J6: -650.6 | K6: 29850 | L6: 48036 | M6: 14.3 | N6: 117884.8 | O6: 0.41 | P6: 10.42 | Q6: 53.02 | R6: 57.62 | S6: -4.6 | T6: -7.73 | U6: 28.11 | V6: 27680 | W6: 27769.85 | X6: 30894.15 | Y6: 1 | Z6: 1 | AA6: 0 | AB6: 13094.94 | AC6: 2732 | AD6: 76.8 | AE6: 59.8 | AF6: 4.5 | AG6: 53.8 | AH6: C
A7: A466100 | B7: 클로봇 | E7: 21 | F7: 90.5 | G7: 357.2 | H7: 59.8 | I7: 185.6 | J7: 1217 | K7: 24500 | L7: 134601 | M7: 33 | N7: 224691.35 | O7: 0.6 | P7: 5.79 | Q7: 31.03 | R7: 34.06 | S7: -3 | T7: -7.2 | U7: -23.25 | V7: 27889 | W7: 30522.5 | X7: 38978.683 | Y7: 0 | Z7: 0 | AA7: 0 | AB7: 13029.9 | AC7: 6238 | AD7: 32.6 | AE7: 88.5 | AF7: 31.3 | AG7: 60.3 | AH7: C
A8: A475960 | B8: 토모큐브 | E8: 15 | F8: 44 | G8: 15.7 | H8: -27.5 | I8: -78.7 | J8: -94.1 | K8: 32450 | L8: 52093 | M8: 16.9 | N8: 49189.25 | O8: 1.06 | P8: 5.69 | Q8: 38.68 | R8: 43.05 | S8: -4.4 | T8: -7.15 | U8: -11.82 | V8: 34495 | W8: 35967.5 | X8: 45289.167 | Y8: 0 | Z8: 0 | AA8: 0 | AB8: 8807.79 | AC8: 4343 | AD8: 44.4 | AE8: 51.7 | AF8: 77.6 | AG8: 54.7 | AH8: C
A9: A415640 | B9: KB발해인프라 | E9: 13.8 | F9: -45.8 | G9: 83.8 | H9: 30.6 | I9: 519.9 | J9: 776.5 | K9: 10740 | L9: 154614 | M9: 16.6 | N9: 171699.95 | O9: 0.9 | P9: 2.01 | Q9: 64.08 | R9: 78.73 | S9: -14.7 | T9: -3.68 | U9: 14.5 | V9: 10337 | W9: 10147.5 | X9: 9982.3333 | Y9: 1 | Z9: 1 | AA9: 1 | AB9: 1294.1 | AC9: 13161 | AD9: 90.7 | AE9: 75.6 | AF9: 65.7 | AG9: 78.1 | AH9: B
A10: A389650 | B10: 넥스트바이오메디컬 | E10: 9.6 | F10: 91 | G10: 507.1 | H10: -72.2 | I10: -136 | J10: -366.8 | K10: 39350 | L10: 47422 | M10: 18.7 | N10: 57273.75 | O10: 0.83 | P10: 6.72 | Q10: 43.82 | R10: 47.2 | S10: -3.4 | T10: -4.72 | U10: 1.16 | V10: 40515 | W10: 40890 | X10: 49555.833 | Y10: 0 | Z10: 0 | AA10: 0 | AB10: 6680.6 | AC10: 3257 | AD10: 64.7 | AE10: 50.5 | AF10: 56.7 | AG10: 56 | AH10: C
A11: A125490 | B11: 한라캐스트 | E11: 9.4 | F11: 11.6 | G11: 1343.2 | H11: 67.1 | I11: 68 | J11: -1076.3 | K11: 7520 | L11: 551991 | M11: 41.5 | N11: 744089.7 | O11: 0.74 | P11: 5.54 | Q11: 27.98 | R11: 30.87 | S11: -2.9 | T11: -8.29 | U11: -35.78 | V11: 8644 | W11: 10012 | X11: 13450.833 | Y11: 0 | Z11: 0 | AA11: 0 | AB11: 6999.5 | AC11: 2745 | AD11: 13.2 | AE11: 75 | AF11: 43.3 | AG11: 50.1 | AH11: C
A12: A403850 | B12: 더핑크퐁컴퍼니 | E12: 7.5 | F12: 50.2 | G12: 47.3 | H12: -9.8 | I12: 296.8 | J12: 305.7 | K12: 10440 | L12: 83824 | M12: 8.8 | N12: 80950.6 | O12: 1.04 | P12: 4.43 | Q12: 40.17 | R12: 43.51 | S12: -3.3 | T12: -4.04 | U12: -8.66 | V12: 10751 | W12: 11103 | X12: 13629.833 | Y12: 0 | Z12: 0 | AA12: 0 | AB12: 2498.55 | AC12: 1498 | AD12: 58.2 | AE12: 72.2 | AF12: 76.1 | AG12: 68.8 | AH12: B
A13: A469610 | B13: 이노테크 | E13: 5.7 | F13: -24.9 | G13: -41.7 | H13: 2.7 | I13: -17.3 | J13: -29.8 | K13: 13320 | L13: 110845 | M13: 14.8 | N13: 192666.45 | O13: 0.58 | P13: 9.37 | Q13: 40.98 | R13: 42.36 | S13: -1.4 | T13: -3.48 | U13: -3.34 | V13: 14529 | W13: 15279 | X13: 19460.5 | Y13: 0 | Z13: 0 | AA13: 0 | AB13: 7347.64 | AC13: 1191 | AD13: 62 | AE13: 48 | AF13: 26.1 | AG13: 47.8 | AH13: D
... A21: A462860 | B21: 더즌 | E21: 0.9 | F21: 3 | G21: 9.5 | H21: -4.8 | I21: 16.2 | J21: 120 | K21: 1870 | L21: 174055 | M21: 3.3 | N21: 185206.25 | O21: 0.94 | P21: 4.54 | Q21: 30.99 | R21: 33.21 | S21: -2.2 | T21: -4.45 | U21: -24.9 | V21: 2047.4 | W21: 2227.45 | X21: 2919.2333 | Y21: 0 | Z21: 0 | AA21: 0 | AB21: 926.47 | AC21: 1342 | AD21: 41.3 | AE21: 57.6 | AF21: 69.4 | AG21: 55.1 | AH21: C

Sheet RVOL_TOP
A1: 코드 | B1: 코드명 | C1: 상장일 | D1: days_since_ipo | E1: 기관_일간 | F1: 기관_5일 | G1: 기관_20일 | H1: 외국인_일간 | I1: 외국인_5일 | J1: 외국인_20일 | K1: 현재가 | L1: 거래량 | M1: 거래대금(억) | N1: 20일평균거래량 | O1: RVOL(20) | P1: 변동성(30D) | Q1: RSI(14) | R1: 전일RSI(14) | S1: RSI변화량 | T1: 1일수익률(%) | U1: 20일수익률(%) | V1: 10일이평 | W1: 20일이평 | X1: 60일이평 | Y1: 10일선돌파 | Z1: 20일선돌파 | AA1: 60일선돌파 | AB1: BB폭 | AC1: 시가총액(억) | AD1: 모멘텀스코어 | AE1: 수급스코어 | AF1: 거래량스코어 | AG1: 종합스코어 | AH1: 등급
A2: A477850 | B2: 마키나락스 | K2: 27100 | L2: 7858462 | M2: 2129.6 | N2: 2495316.4 | O2: 3.15 | P2: 12.79 | Q2: 69.76 | R2: 68.37 | S2: 1.4 | T2: 10.61 | U2: 34.49 | V2: 21289 | W2: 19640 | Y2: 1 | Z2: 1 | AA2: 0 | AB2: 16606.75 | AC2: 4812 | AD2: 100 | AF2: 100 | AH2: -
A3: A318060 | B3: 그래피 | E3: -35.7 | F3: -28.2 | G3: 29.5 | H3: -129.7 | I3: -154.3 | J3: -96.1 | K3: 19030 | L3: 303340 | M3: 57.7 | N3: 114013.8 | O3: 2.66 | P3: 5.75 | Q3: 46.03 | R3: 41.82 | S3: 4.2 | T3: 5.43 | U3: -12.91 | V3: 16941 | W3: 18697.5 | X3: 26665.833 | Y3: 1 | Z3: 1 | AA3: 0 | AB3: 9578.32 | AC3: 2126 | AD3: 85.8 | AE3: 21.3 | AF3: 98.5 | AG3: 56.1 | AH3: C
A4: A031210 | B4: 서울보증보험 | E4: 4.3 | F4: 88 | G4: 433.3 | H4: -2.7 | I4: 51.2 | J4: -597.7 | K4: 42800 | L4: 71211 | M4: 30.5 | N4: 45568.3 | O4: 1.56 | P4: 2.56 | Q4: 48.17 | R4: 51.98 | S4: -3.8 | T4: -1.83 | U4: -2.73 | V4: 41790 | W4: 42945 | X4: 45240.833 | Y4: 1 | Z4: 0 | AA4: 0 | AB4: 7369.64 | AC4: 29884 | AD4: 89.3 | AE4: 62.4 | AF4: 97 | AG4: 77.4 | AH4: B
A5: A226590 | B5: 엠디바이스 | E5: 0 | F5: -4.4 | G5: -5.5 | H5: -39.3 | I5: -50.9 | J5: -131 | K5: 11760 | L5: 126662 | M5: 14.9 | N5: 89512.7 | O5: 1.42 | P5: 5.83 | Q5: 35.64 | R5: 39.54 | S5: -3.9 | T5: -8.27 | U5: -17.42 | V5: 12357 | W5: 13643 | X5: 20250 | Y5: 0 | Z5: 0 | AA5: 0 | AB5: 6696.81 | AC5: 1260 | AD5: 34.7 | AE5: 35.4 | AF5: 95.5 | AG5: 47.2 | AH5: D
A6: A476060 | B6: 온코닉테라퓨틱스 | E6: -1 | F6: -9.5 | G6: -313 | H6: 123.1 | I6: 249.6 | J6: 833 | K6: 10970 | L6: 353754 | M6: 38.8 | N6: 255809.85 | O6: 1.38 | P6: 4.51 | Q6: 26.14 | R6: 28.6 | S6: -2.5 | T6: -6.24 | U6: -30.44 | V6: 12765 | W6: 14208.5 | X6: 18373.833 | Y6: 0 | Z6: 0 | AA6: 0 | AB6: 6825.27 | AC6: 4981 | AD6: 23.3 | AE6: 62.6 | AF6: 94 | AG6: 57.1 | AH6: C
A7: A493280 | B7: 아이엠바이오로직스 | K7: 20500 | L7: 140804 | M7: 28.9 | N7: 105114 | O7: 1.34 | P7: 6.73 | Q7: 33.12 | R7: 35.07 | S7: -2 | T7: -5.75 | U7: -22.79 | V7: 21760 | W7: 23500 | X7: 36680.833 | Y7: 0 | Z7: 0 | AA7: 0 | AB7: 10266.84 | AC7: 3041 | AD7: 40.5 | AF7: 92.5 | AH7: -
A8: A062040 | B8: 산일전기 | E8: -1112.6 | F8: -1875.2 | G8: 6834.9 | H8: 1784.4 | I8: -1823.4 | J8: -7952.4 | K8: 178200 | L8: 448109 | M8: 798.5 | N8: 335915.95 | O8: 1.33 | P8: 5.3 | Q8: 34.5 | R8: 37.88 | S8: -3.4 | T8: -7.86 | U8: -18.44 | V8: 220260 | W8: 227730 | X8: 239516.67 | Y8: 0 | Z8: 0 | AA8: 0 | AB8: 79993.71 | AC8: 54557 | AD8: 34.9 | AE8: 33.2 | AF8: 91 | AG8: 45.3 | AH8: D
A9: A388210 | B9: 씨엠티엑스 | E9: -28.5 | F9: -401.8 | G9: -307.6 | H9: 264.7 | I9: 348.2 | J9: -73.4 | K9: 68900 | L9: 94674 | M9: 65.2 | N9: 72931.8 | O9: 1.3 | P9: 6.27 | Q9: 27 | R9: 30.59 | S9: -3.6 | T9: -10.17 | U9: -35 | V9: 86520 | W9: 96430 | X9: 118125 | Y9: 0 | Z9: 0 | AA9: 0 | AB9: 51014.52 | AC9: 6652 | AD9: 7.3 | AE9: 46.7 | AF9: 89.6 | AG9: 43.5 | AH9: D
A10: A098070 | B10: 한텍 | E10: -51.3 | F10: -181.3 | G10: -500.7 | H10: 60.6 | I10: 187.6 | J10: 435.4 | K10: 22750 | L10: 74573 | M10: 17 | N10: 58720.65 | O10: 1.27 | P10: 5.23 | Q10: 31.09 | R10: 33.35 | S10: -2.3 | T10: -5.21 | U10: -26.38 | V10: 25575 | W10: 28232.5 | X10: 36155 | Y10: 0 | Z10: 0 | AA10: 0 | AB10: 13103.48 | AC10: 2530 | AD10: 39 | AE10: 47.4 | AF10: 88.1 | AG10: 53 | AH10: C
A11: A439260 | B11: 대한조선 | E11: -102.7 | F11: -124.2 | G11: -76.1 | H11: 95.4 | I11: 292.7 | J11: 124.9 | K11: 47650 | L11: 101875 | M11: 48.5 | N11: 81034.4 | O11: 1.26 | P11: 3.53 | Q11: 29.06 | R11: 33.04 | S11: -4 | T11: -6.2 | U11: -22.01 | V11: 51705 | W11: 56117.5 | X11: 70575.833 | Y11: 0 | Z11: 0 | AA11: 0 | AB11: 21248.56 | AC11: 18149 | AD11: 35 | AE11: 49.1 | AF11: 86.6 | AG11: 52.4 | AH11: C
A12: A394420 | B12: 리센스메디컬 | K12: 14080 | L12: 324469 | M12: 45.7 | N12: 277117.75 | O12: 1.17 | P12: 9.39 | Q12: 37.54 | R12: 41.57 | S12: -4 | T12: -12.87 | U12: -24.71 | V12: 17137 | W12: 18728.5 | X12: 23386 | Y12: 0 | Z12: 0 | AA12: 0 | AB12: 9442.11 | AC12: 1540 | AD12: 26.9 | AF12: 85.1 | AH12: -
